Workbook
Name A130389940C: Data1!$EW$1:$EW$10,Data1!$EW$11:$EW$111
Name A130389940C_Data: Data1!$EW$11:$EW$111
Name A130389940C_Latest: Data1!$EW$111
Name A130389947V: Data3!$AW$1:$AW$10,Data3!$AW$11:$AW$111
Name A130389947V_Data: Data3!$AW$11:$AW$111
Name A130389947V_Latest: Data3!$AW$111
Name A130389954T: Data4!$BK$1:$BK$10,Data4!$BK$11:$BK$111
Name A130389954T_Data: Data4!$BK$11:$BK$111
Name A130389954T_Latest: Data4!$BK$111
Name A130389961R: Data1!$V$1:$V$10,Data1!$V$11:$V$111
Name A130389961R_Data: Data1!$V$11:$V$111
Name A130389961R_Latest: Data1!$V$111
Name A130389968F: Data2!$FL$1:$FL$10,Data2!$FL$11:$FL$111
Name A130389968F_Data: Data2!$FL$11:$FL$111
Name A130389968F_Latest: Data2!$FL$111
Name A130389975C: Data3!$IA$1:$IA$10,Data3!$IA$90:$IA$111
Name A130389975C_Data: Data3!$IA$90:$IA$111
Name A130389975C_Latest: Data3!$IA$111
Name A130389982A: Data3!$DJ$1:$DJ$10,Data3!$DJ$90:$DJ$111
Name A130389982A_Data: Data3!$DJ$90:$DJ$111
Name A130389982A_Latest: Data3!$DJ$111
Name A130389996R: Data4!$DX$1:$DX$10,Data4!$DX$90:$DX$111
Name A130389996R_Data: Data4!$DX$90:$DX$111
Name A130389996R_Latest: Data4!$DX$111
Name A130390003J: Data4!$L$1:$L$10,Data4!$L$90:$L$111
Name A130390003J_Data: Data4!$L$90:$L$111
Name A130390003J_Latest: Data4!$L$111
Name A130390010F: Data4!$EN$1:$EN$10,Data4!$EN$90:$EN$111
Name A130390010F_Data: Data4!$EN$90:$EN$111
Name A130390010F_Latest: Data4!$EN$111
Name A130390017W: Data1!$IN$1:$IN$10,Data1!$IN$90:$IN$111
Name A130390017W_Data: Data1!$IN$90:$IN$111
Name A130390017W_Latest: Data1!$IN$111
Name A130390031T: Data3!$EW$1:$EW$10,Data3!$EW$90:$EW$111
Name A130390031T_Data: Data3!$EW$90:$EW$111
Name A130390031T_Latest: Data3!$EW$111
Name A130390038J: Data2!$EJ$1:$EJ$10,Data2!$EJ$11:$EJ$111
Name A130390038J_Data: Data2!$EJ$11:$EJ$111
Name A130390038J_Latest: Data2!$EJ$111
Name A130390045F: Data3!$V$1:$V$10,Data3!$V$11:$V$111
Name A130390045F_Data: Data3!$V$11:$V$111
Name A130390045F_Latest: Data3!$V$111
Name A130390066T: Data1!$HI$1:$HI$10,Data1!$HI$90:$HI$111
Name A130390066T_Data: Data1!$HI$90:$HI$111
Name A130390066T_Latest: Data1!$HI$111
Name A130390073R: Data2!$CU$1:$CU$10,Data2!$CU$90:$CU$111
Name A130390073R_Data: Data2!$CU$90:$CU$111
Name A130390073R_Latest: Data2!$CU$111
Name A130390080L: Data3!$BH$1:$BH$10,Data3!$BH$11:$BH$111
Name A130390080L_Data: Data3!$BH$11:$BH$111
Name A130390080L_Latest: Data3!$BH$111
Name A130390087C: Data4!$GX$1:$GX$10,Data4!$GX$11:$GX$111
Name A130390087C_Data: Data4!$GX$11:$GX$111
Name A130390087C_Latest: Data4!$GX$111
Name A130390101L: Data5!$BA$1:$BA$10,Data5!$BA$90:$BA$111
Name A130390101L_Data: Data5!$BA$90:$BA$111
Name A130390101L_Latest: Data5!$BA$111
Name A130390171V: Data2!$EL$1:$EL$10,Data2!$EL$90:$EL$111
Name A130390171V_Data: Data2!$EL$90:$EL$111
Name A130390171V_Latest: Data2!$EL$111

Sheet Index
B2: Time Series Workbook
B5: 6401.0 Consumer Price Index, Australia
B6: TABLE 10. CPI: Group, Sub-group and Expenditure Class, Index Numbers by Capital City
D8: Enquiries
A10: Data Item Description | D10: Series Type | E10: Series ID | F10: Series Start | G10: Series End | H10: No. Obs. | I10: Unit | J10: Data Type | K10: Freq. | L10: Collection Month
A12: Index Numbers ; All groups CPI ; Sydney ; | D12: Original | E12: A130397375X | F12: 45383 | G12: 46023 | H12: 22 | I12: Index Numbers | J12: INDEX | K12: Month | L12: 1
A13: Index Numbers ; Food and non-alcoholic beverages ; Sydney ; | D13: Original | E13: A130392957J | F13: 45383 | G13: 46023 | H13: 22 | I13: Index Numbers | J13: INDEX | K13: Month | L13: 1
A14: Index Numbers ; Bread and cereal products ; Sydney ; | D14: Original | E14: A130394343A | F14: 42979 | G14: 46023 | H14: 101 | I14: Index Numbers | J14: INDEX | K14: Month | L14: 1
A15: Index Numbers ; Bread ; Sydney ; | D15: Original | E15: A130398033T | F15: 42979 | G15: 46023 | H15: 101 | I15: Index Numbers | J15: INDEX | K15: Month | L15: 1
A16: Index Numbers ; Cakes and biscuits ; Sydney ; | D16: Original | E16: A130394448W | F16: 42979 | G16: 46023 | H16: 101 | I16: Index Numbers | J16: INDEX | K16: Month | L16: 1
A17: Index Numbers ; Breakfast cereals ; Sydney ; | D17: Original | E17: A130399331J | F17: 42979 | G17: 46023 | H17: 101 | I17: Index Numbers | J17: INDEX | K17: Month | L17: 1
A18: Index Numbers ; Other cereal products ; Sydney ; | D18: Original | E18: A130399352V | F18: 42979 | G18: 46023 | H18: 101 | I18: Index Numbers | J18: INDEX | K18: Month | L18: 1
A19: Index Numbers ; Meat and seafoods ; Sydney ; | D19: Original | E19: A130393055R | F19: 42979 | G19: 46023 | H19: 101 | I19: Index Numbers | J19: INDEX | K19: Month | L19: 1
A20: Index Numbers ; Beef and veal ; Sydney ; | D20: Original | E20: A130394462T | F20: 42979 | G20: 46023 | H20: 101 | I20: Index Numbers | J20: INDEX | K20: Month | L20: 1
A21: Index Numbers ; Pork ; Sydney ; | D21: Original | E21: A130391473V | F21: 42979 | G21: 46023 | H21: 101 | I21: Index Numbers | J21: INDEX | K21: Month | L21: 1
A22: Index Numbers ; Lamb and goat ; Sydney ; | D22: Original | E22: A130396863T | F22: 42979 | G22: 46023 | H22: 101 | I22: Index Numbers | J22: INDEX | K22: Month | L22: 1
A23: Index Numbers ; Poultry ; Sydney ; | D23: Original | E23: A130398096A | F23: 42979 | G23: 46023 | H23: 101 | I23: Index Numbers | J23: INDEX | K23: Month | L23: 1
... A1067: Index Numbers ; Other financial services ; Canberra ; | D1067: Original | E1067: A130392488C | F1067: 42979 | G1067: 46023 | H1067: 101 | I1067: Index Numbers | J1067: INDEX | K1067: Month | L1067: 1
A1069: © Commonwealth of Australia 2026

Sheet Energy Summary
A1: Energy Prices by Capital City — CPI Index
A2: Source: ABS 6401.0 Consumer Price Index, Table 10. Reference period: September 2025 = 100.00. Series Type: Original.
A4: Summary Table — Index Levels & % Change
A6: City | B6: Electricity — Latest | C6: Elec — 1Y ago | D6: Elec — 3Y ago | E6: Elec — 1Y %Δ | F6: Elec — 3Y %Δ | G6: Gas — Latest | H6: Gas — 1Y ago | I6: Gas — 3Y ago | J6: Gas — 1Y %Δ | K6: Gas — 3Y %Δ
A7: Sydney | B7: =Data1!BM111 -> 115.58 | C7: =Data1!BM99 -> 88.39 | D7: =Data1!BM75 -> 93.54 | E7: =B7/C7-1 -> 0.30761398 | F7: =B7/D7-1 -> 0.23562112 | G7: =Data1!BN111 -> 102.71 | H7: =Data1!BN99 -> 94.47 | I7: =Data1!BN75 -> 85.4 | J7: =G7/H7-1 -> 0.087223457 | K7: =G7/I7-1 -> 0.20269321
A8: Melbourne | B8: =Data1!GO111 -> 121.55 | C8: =Data1!GO99 -> 108.1 | D8: =Data1!GO75 -> 107.55 | E8: =B8/C8-1 -> 0.12442183 | F8: =B8/D8-1 -> 0.13017201 | G8: =Data1!GP111 -> 98.39 | H8: =Data1!GP99 -> 92.84 | I8: =Data1!GP75 -> 93.55 | J8: =G8/H8-1 -> 0.059780267 | K8: =G8/I8-1 -> 0.051737039
A9: Brisbane | B9: =Data2!CA111 -> 113.46 | C9: =Data2!CA99 -> 79.29 | D9: =Data2!CA75 -> 88.18 | E9: =B9/C9-1 -> 0.43094968 | F9: =B9/D9-1 -> 0.28668632 | G9: =Data2!CB111 -> 98.35 | H9: =Data2!CB99 -> 97.31 | I9: =Data2!CB75 -> 96.35 | J9: =G9/H9-1 -> 0.010687494 | K9: =G9/I9-1 -> 0.020757654
A10: Adelaide | B10: =Data2!HC111 -> 115.65 | C10: =Data2!HC99 -> 99.14 | D10: =Data2!HC75 -> 96.87 | E10: =B10/C10-1 -> 0.16653218 | F10: =B10/D10-1 -> 0.19386807 | G10: =Data2!HD111 -> 98.56 | H10: =Data2!HD99 -> 95.82 | I10: =Data2!HD75 -> 85.96 | J10: =G10/H10-1 -> 0.028595283 | K10: =G10/I10-1 -> 0.1465798
A11: Perth | B11: =Data3!CO111 -> 90.07 | C11: =Data3!CO99 -> 25.71 | D11: =Data3!CO75 -> 92.86 | E11: =B11/C11-1 -> 2.5033061 | F11: =B11/D11-1 -> -0.030045229 | G11: =Data3!CP111 -> 101.81 | H11: =Data3!CP99 -> 96.91 | I11: =Data3!CP75 -> 85.48 | J11: =G11/H11-1 -> 0.050562377 | K11: =G11/I11-1 -> 0.19103884
A12: Hobart | B12: =Data3!HQ111 -> 112.33 | C12: =Data3!HQ99 -> 98.38 | D12: =Data3!HQ75 -> 101.1 | E12: =B12/C12-1 -> 0.14179711 | F12: =B12/D12-1 -> 0.11107814 | G12: =Data3!HR111 -> 100.79 | H12: =Data3!HR99 -> 97.83 | I12: =Data3!HR75 -> 89.99 | J12: =G12/H12-1 -> 0.030256568 | K12: =G12/I12-1 -> 0.12001333
A13: Darwin | B13: =Data4!DC111 -> 115.92 | C13: =Data4!DC99 -> 96.31 | D13: =Data4!DC75 -> 104.48 | E13: =B13/C13-1 -> 0.20361333 | F13: =B13/D13-1 -> 0.10949464 | G13: =Data4!DD111 -> 114.68 | H13: =Data4!DD99 -> 109.1 | I13: =Data4!DD75 -> 91.4 | J13: =G13/H13-1 -> 0.051145738 | K13: =G13/I13-1 -> 0.2547046
A14: Canberra | B14: =Data4!IE111 -> 114.61 | C14: =Data4!IE99 -> 87.66 | D14: =Data4!IE75 -> 89.44 | E14: =B14/C14-1 -> 0.30743783 | F14: =B14/D14-1 -> 0.28141771 | G14: =Data4!IF111 -> 99.81 | H14: =Data4!IF99 -> 98.44 | I14: =Data4!IF75 -> 80.27 | J14: =G14/H14-1 -> 0.013917107 | K14: =G14/I14-1 -> 0.24342843
A16: Time Series — Electricity & Gas Index by City (Sep 2021 – Sep 2025)
A18: Date | B18: Sydney — Elec | C18: Melbourne — Elec | D18: Brisbane — Elec | E18: Adelaide — Elec | F18: Perth — Elec | G18: Hobart — Elec | H18: Darwin — Elec | I18: Canberra — Elec | J18: Sydney — Gas | K18: Melbourne — Gas | L18: Brisbane — Gas | M18: Adelaide — Gas | N18: Perth — Gas | O18: Hobart — Gas | P18: Darwin — Gas | Q18: Canberra — Gas | S18: Date | T18: Sydney | U18: Melbourne | V18: Brisbane | W18: Adelaide | X18: Perth | Y18: Hobart | Z18: Darwin | AA18: Canberra
A19: =Data1!A60 -> 44470 | B19: =Data1!BM60 -> 72.41 | C19: =Data1!GO60 -> 100.83 | D19: =Data2!CA60 -> 71.14 | E19: =Data2!HC60 -> 84.11 | F19: =Data3!CO60 -> 90.6 | G19: =Data3!HQ60 -> 90.34 | H19: =Data4!DC60 -> 101.44 | I19: =Data4!IE60 -> 82.83 | J19: =Data1!BN60 -> 71.13 | K19: =Data1!GP60 -> 60.92 | L19: =Data2!CB60 -> 84.69 | M19: =Data2!HD60 -> 72.2 | N19: =Data3!CP60 -> 82.13 | O19: =Data3!HR60 -> 82.27 | P19: =Data4!DD60 -> 85.34 | Q19: =Data4!IF60 -> 75.26 | S19: =A19 -> 44470 | T19: =J19 -> 71.13 | U19: =K19 -> 60.92 | V19: =L19 -> 84.69 | W19: =M19 -> 72.2 | X19: =N19 -> 82.13 | Y19: =O19 -> 82.27 | Z19: =P19 -> 85.34 | AA19: =Q19 -> 75.26
A20: =Data1!A61 -> 44501 | B20: =Data1!BM61 -> 73.85 | C20: =Data1!GO61 -> 102.25 | D20: =Data2!CA61 -> 71.14 | E20: =Data2!HC61 -> 84.11 | F20: =Data3!CO61 -> 90.6 | G20: =Data3!HQ61 -> 90.34 | H20: =Data4!DC61 -> 101.44 | I20: =Data4!IE61 -> 82.83 | J20: =Data1!BN61 -> 71.13 | K20: =Data1!GP61 -> 63.74 | L20: =Data2!CB61 -> 84.69 | M20: =Data2!HD61 -> 72.2 | N20: =Data3!CP61 -> 82.13 | O20: =Data3!HR61 -> 82.27 | P20: =Data4!DD61 -> 85.34 | Q20: =Data4!IF61 -> 75.26 | S20: =A20 -> 44501 | T20: =J20 -> 71.13 | U20: =K20 -> 63.74 | V20: =L20 -> 84.69 | W20: =M20 -> 72.2 | X20: =N20 -> 82.13 | Y20: =O20 -> 82.27 | Z20: =P20 -> 85.34 | AA20: =Q20 -> 75.26
A21: =Data1!A62 -> 44531 | B21: =Data1!BM62 -> 74.6 | C21: =Data1!GO62 -> 101.84 | D21: =Data2!CA62 -> 71 | E21: =Data2!HC62 -> 84.27 | F21: =Data3!CO62 -> 90.6 | G21: =Data3!HQ62 -> 90.34 | H21: =Data4!DC62 -> 101.44 | I21: =Data4!IE62 -> 83.25 | J21: =Data1!BN62 -> 72.83 | K21: =Data1!GP62 -> 65.82 | L21: =Data2!CB62 -> 86.1 | M21: =Data2!HD62 -> 72.2 | N21: =Data3!CP62 -> 82.13 | O21: =Data3!HR62 -> 83.17 | P21: =Data4!DD62 -> 87.2 | Q21: =Data4!IF62 -> 75.26 | S21: =A21 -> 44531 | T21: =J21 -> 72.83 | U21: =K21 -> 65.82 | V21: =L21 -> 86.1 | W21: =M21 -> 72.2 | X21: =N21 -> 82.13 | Y21: =O21 -> 83.17 | Z21: =P21 -> 87.2 | AA21: =Q21 -> 75.26
A22: =Data1!A63 -> 44562 | B22: =Data1!BM63 -> 74.45 | C22: =Data1!GO63 -> 101.12 | D22: =Data2!CA63 -> 71 | E22: =Data2!HC63 -> 84.27 | F22: =Data3!CO63 -> 90.6 | G22: =Data3!HQ63 -> 90.34 | H22: =Data4!DC63 -> 101.44 | I22: =Data4!IE63 -> 88.02 | J22: =Data1!BN63 -> 72.83 | K22: =Data1!GP63 -> 66.93 | L22: =Data2!CB63 -> 86.1 | M22: =Data2!HD63 -> 72.2 | N22: =Data3!CP63 -> 82.13 | O22: =Data3!HR63 -> 83.86 | P22: =Data4!DD63 -> 87.2 | Q22: =Data4!IF63 -> 75.26 | S22: =A22 -> 44562 | T22: =J22 -> 72.83 | U22: =K22 -> 66.93 | V22: =L22 -> 86.1 | W22: =M22 -> 72.2 | X22: =N22 -> 82.13 | Y22: =O22 -> 83.86 | Z22: =P22 -> 87.2 | AA22: =Q22 -> 75.26
A23: =Data1!A64 -> 44593 | B23: =Data1!BM64 -> 74.45 | C23: =Data1!GO64 -> 100.26 | D23: =Data2!CA64 -> 70.15 | E23: =Data2!HC64 -> 84.27 | F23: =Data3!CO64 -> 90.6 | G23: =Data3!HQ64 -> 90.34 | H23: =Data4!DC64 -> 101.44 | I23: =Data4!IE64 -> 88.02 | J23: =Data1!BN64 -> 72.83 | K23: =Data1!GP64 -> 69.27 | L23: =Data2!CB64 -> 86.1 | M23: =Data2!HD64 -> 72.2 | N23: =Data3!CP64 -> 82.13 | O23: =Data3!HR64 -> 83.86 | P23: =Data4!DD64 -> 87.2 | Q23: =Data4!IF64 -> 75.26 | S23: =A23 -> 44593 | T23: =J23 -> 72.83 | U23: =K23 -> 69.27 | V23: =L23 -> 86.1 | W23: =M23 -> 72.2 | X23: =N23 -> 82.13 | Y23: =O23 -> 83.86 | Z23: =P23 -> 87.2 | AA23: =Q23 -> 75.26
A24: =Data1!A65 -> 44621 | B24: =Data1!BM65 -> 74.31 | C24: =Data1!GO65 -> 100.26 | D24: =Data2!CA65 -> 70.15 | E24: =Data2!HC65 -> 84.27 | F24: =Data3!CO65 -> 90.6 | G24: =Data3!HQ65 -> 90.34 | H24: =Data4!DC65 -> 101.44 | I24: =Data4!IE65 -> 88.02 | J24: =Data1!BN65 -> 72.83 | K24: =Data1!GP65 -> 69.25 | L24: =Data2!CB65 -> 86.87 | M24: =Data2!HD65 -> 72.2 | N24: =Data3!CP65 -> 82.13 | O24: =Data3!HR65 -> 86.47 | P24: =Data4!DD65 -> 89.11 | Q24: =Data4!IF65 -> 75.26 | S24: =A24 -> 44621 | T24: =J24 -> 72.83 | U24: =K24 -> 69.25 | V24: =L24 -> 86.87 | W24: =M24 -> 72.2 | X24: =N24 -> 82.13 | Y24: =O24 -> 86.47 | Z24: =P24 -> 89.11 | AA24: =Q24 -> 75.26
A25: =Data1!A66 -> 44652 | B25: =Data1!BM66 -> 73.01 | C25: =Data1!GO66 -> 100.39 | D25: =Data2!CA66 -> 70.45 | E25: =Data2!HC66 -> 84.4 | F25: =Data3!CO66 -> 90.6 | G25: =Data3!HQ66 -> 90.34 | H25: =Data4!DC66 -> 101.44 | I25: =Data4!IE66 -> 88.02 | J25: =Data1!BN66 -> 72.31 | K25: =Data1!GP66 -> 69.25 | L25: =Data2!CB66 -> 86.87 | M25: =Data2!HD66 -> 72.2 | N25: =Data3!CP66 -> 82.13 | O25: =Data3!HR66 -> 86.47 | P25: =Data4!DD66 -> 89.11 | Q25: =Data4!IF66 -> 75.26 | S25: =A25 -> 44652 | T25: =J25 -> 72.31 | U25: =K25 -> 69.25 | V25: =L25 -> 86.87 | W25: =M25 -> 72.2 | X25: =N25 -> 82.13 | Y25: =O25 -> 86.47 | Z25: =P25 -> 89.11 | AA25: =Q25 -> 75.26
A26: =Data1!A67 -> 44682 | B26: =Data1!BM67 -> 73.44 | C26: =Data1!GO67 -> 100.01 | D26: =Data2!CA67 -> 70.08 | E26: =Data2!HC67 -> 85.54 | F26: =Data3!CO67 -> 90.6 | G26: =Data3!HQ67 -> 90.34 | H26: =Data4!DC67 -> 101.44 | I26: =Data4!IE67 -> 88.02 | J26: =Data1!BN67 -> 70.99 | K26: =Data1!GP67 -> 66.21 | L26: =Data2!CB67 -> 86.87 | M26: =Data2!HD67 -> 71.37 | N26: =Data3!CP67 -> 82.13 | O26: =Data3!HR67 -> 86.47 | P26: =Data4!DD67 -> 89.11 | Q26: =Data4!IF67 -> 75.26 | S26: =A26 -> 44682 | T26: =J26 -> 70.99 | U26: =K26 -> 66.21 | V26: =L26 -> 86.87 | W26: =M26 -> 71.37 | X26: =N26 -> 82.13 | Y26: =O26 -> 86.47 | Z26: =P26 -> 89.11 | AA26: =Q26 -> 75.26
A27: =Data1!A68 -> 44713 | B27: =Data1!BM68 -> 77.73 | C27: =Data1!GO68 -> 99.57 | D27: =Data2!CA68 -> 72.7 | E27: =Data2!HC68 -> 87.11 | F27: =Data3!CO68 -> 90.6 | G27: =Data3!HQ68 -> 90.34 | H27: =Data4!DC68 -> 101.44 | I27: =Data4!IE68 -> 89.66 | J27: =Data1!BN68 -> 72.95 | K27: =Data1!GP68 -> 69.38 | L27: =Data2!CB68 -> 88.31 | M27: =Data2!HD68 -> 73.62 | N27: =Data3!CP68 -> 82.13 | O27: =Data3!HR68 -> 87.3 | P27: =Data4!DD68 -> 87.02 | Q27: =Data4!IF68 -> 75.26 | S27: =A27 -> 44713 | T27: =J27 -> 72.95 | U27: =K27 -> 69.38 | V27: =L27 -> 88.31 | W27: =M27 -> 73.62 | X27: =N27 -> 82.13 | Y27: =O27 -> 87.3 | Z27: =P27 -> 87.02 | AA27: =Q27 -> 75.26
A28: =Data1!A69 -> 44743 | B28: =Data1!BM69 -> 92.38 | C28: =Data1!GO69 -> 107.05 | D28: =Data2!CA69 -> 84.34 | E28: =Data2!HC69 -> 94.89 | F28: =Data3!CO69 -> 14.2 | G28: =Data3!HQ69 -> 101.1 | H28: =Data4!DC69 -> 104.48 | I28: =Data4!IE69 -> 88.56 | J28: =Data1!BN69 -> 81.87 | K28: =Data1!GP69 -> 76.67 | L28: =Data2!CB69 -> 93.91 | M28: =Data2!HD69 -> 84.46 | N28: =Data3!CP69 -> 84.62 | O28: =Data3!HR69 -> 87.57 | P28: =Data4!DD69 -> 87.02 | Q28: =Data4!IF69 -> 78.12 | S28: =A28 -> 44743 | T28: =J28 -> 81.87 | U28: =K28 -> 76.67 | V28: =L28 -> 93.91 | W28: =M28 -> 84.46 | X28: =N28 -> 84.62 | Y28: =O28 -> 87.57 | Z28: =P28 -> 87.02 | AA28: =Q28 -> 78.12
A29: =Data1!A70 -> 44774 | B29: =Data1!BM70 -> 93.08 | C29: =Data1!GO70 -> 108.12 | D29: =Data2!CA70 -> 88.1 | E29: =Data2!HC70 -> 96.81 | F29: =Data3!CO70 -> 14.2 | G29: =Data3!HQ70 -> 101.1 | H29: =Data4!DC70 -> 104.48 | I29: =Data4!IE70 -> 89.2 | J29: =Data1!BN70 -> 81.87 | K29: =Data1!GP70 -> 78.28 | L29: =Data2!CB70 -> 93.91 | M29: =Data2!HD70 -> 83.85 | N29: =Data3!CP70 -> 84.62 | O29: =Data3!HR70 -> 87.57 | P29: =Data4!DD70 -> 87.02 | Q29: =Data4!IF70 -> 80.27 | S29: =A29 -> 44774 | T29: =J29 -> 81.87 | U29: =K29 -> 78.28 | V29: =L29 -> 93.91 | W29: =M29 -> 83.85 | X29: =N29 -> 84.62 | Y29: =O29 -> 87.57 | Z29: =P29 -> 87.02 | AA29: =Q29 -> 80.27
A30: =Data1!A71 -> 44805 | B30: =Data1!BM71 -> 92.4 | C30: =Data1!GO71 -> 108.12 | D30: =Data2!CA71 -> 55.51 | E30: =Data2!HC71 -> 97.12 | F30: =Data3!CO71 -> 14.2 | G30: =Data3!HQ71 -> 101.1 | H30: =Data4!DC71 -> 104.48 | I30: =Data4!IE71 -> 89.61 | J30: =Data1!BN71 -> 82.63 | K30: =Data1!GP71 -> 78.28 | L30: =Data2!CB71 -> 94.14 | M30: =Data2!HD71 -> 85.59 | N30: =Data3!CP71 -> 84.62 | O30: =Data3!HR71 -> 88.57 | P30: =Data4!DD71 -> 88.18 | Q30: =Data4!IF71 -> 80.27 | S30: =A30 -> 44805 | T30: =J30 -> 82.63 | U30: =K30 -> 78.28 | V30: =L30 -> 94.14 | W30: =M30 -> 85.59 | X30: =N30 -> 84.62 | Y30: =O30 -> 88.57 | Z30: =P30 -> 88.18 | AA30: =Q30 -> 80.27
... A70: =Data1!A111 -> 46023 | B70: =Data1!BM111 -> 115.58 | C70: =Data1!GO111 -> 121.55 | D70: =Data2!CA111 -> 113.46 | E70: =Data2!HC111 -> 115.65 | F70: =Data3!CO111 -> 90.07 | G70: =Data3!HQ111 -> 112.33 | H70: =Data4!DC111 -> 115.92 | I70: =Data4!IE111 -> 114.61 | J70: =Data1!BN111 -> 102.71 | K70: =Data1!GP111 -> 98.39 | L70: =Data2!CB111 -> 98.35 | M70: =Data2!HD111 -> 98.56 | N70: =Data3!CP111 -> 101.81 | O70: =Data3!HR111 -> 100.79 | P70: =Data4!DD111 -> 114.68 | Q70: =Data4!IF111 -> 99.81 | S70: =A70 -> 46023 | T70: =J70 -> 102.71 | U70: =K70 -> 98.39 | V70: =L70 -> 98.35 | W70: =M70 -> 98.56 | X70: =N70 -> 101.81 | Y70: =O70 -> 100.79 | Z70: =P70 -> 114.68 | AA70: =Q70 -> 99.81
A72: Notes:
A73: • Index reference: Sep 2025 = 100.00. Index Numbers are CPI sub-group indices, not nominal $ prices.
A74: • "Electricity" and "Gas and other household fuels" series for each capital city, ABS 6401.0 Table 10 (Original).
A75: • Large 1Y movements in Electricity (esp. Perth, Brisbane, Sydney) reflect timing of Commonwealth/State energy bill rebates, which reduced the index sharply in 2024 then unwound as rebates expired.
A76: • Time series starts Sep 2021 (earliest period with data for all 8 capitals on this reference base).
A78: Rebased Time Series — Sep 2021 = 1.00
A79: Each series divided by its Sep 2021 value. Values >1 mean prices rose vs baseline; <1 mean prices fell.
A80: Date | B80: Sydney — Elec | C80: Melbourne — Elec | D80: Brisbane — Elec | E80: Adelaide — Elec | F80: Perth — Elec | G80: Hobart — Elec | H80: Darwin — Elec | I80: Canberra — Elec | J80: Sydney — Gas | K80: Melbourne — Gas | L80: Brisbane — Gas | M80: Adelaide — Gas | N80: Perth — Gas | O80: Hobart — Gas | P80: Darwin — Gas | Q80: Canberra — Gas | AE80: Date | AF80: Sydney | AG80: Melbourne | AH80: Brisbane | AI80: Adelaide | AJ80: Perth | AK80: Hobart | AL80: Darwin | AM80: Canberra
A81: =A19 -> 44470 | B81: =B19/B$19 -> 1 | C81: =C19/C$19 -> 1 | D81: =D19/D$19 -> 1 | E81: =E19/E$19 -> 1 | F81: =F19/F$19 -> 1 | G81: =G19/G$19 -> 1 | H81: =H19/H$19 -> 1 | I81: =I19/I$19 -> 1 | ... Q81: =Q19/Q$19 -> 1 | AE81: =A81 -> 44470 | AF81: =J81 -> 1 | AG81: =K81 -> 1 | AH81: =L81 -> 1 | AI81: =M81 -> 1 | AJ81: =N81 -> 1 | AK81: =O81 -> 1 | AL81: =P81 -> 1 | AM81: =Q81 -> 1
A82: =A20 -> 44501 | B82: =B20/B$19 -> 1.0198868 | C82: =C20/C$19 -> 1.0140831 | D82: =D20/D$19 -> 1 | E82: =E20/E$19 -> 1 | F82: =F20/F$19 -> 1 | G82: =G20/G$19 -> 1 | H82: =H20/H$19 -> 1 | I82: =I20/I$19 -> 1 | ... Q82: =Q20/Q$19 -> 1 | AE82: =A82 -> 44501 | AF82: =J82 -> 1 | AG82: =K82 -> 1.0462902 | AH82: =L82 -> 1 | AI82: =M82 -> 1 | AJ82: =N82 -> 1 | AK82: =O82 -> 1 | AL82: =P82 -> 1 | AM82: =Q82 -> 1
A83: =A21 -> 44531 | B83: =B21/B$19 -> 1.0302444 | C83: =C21/C$19 -> 1.0100169 | D83: =D21/D$19 -> 0.99803205 | E83: =E21/E$19 -> 1.0019023 | F83: =F21/F$19 -> 1 | G83: =G21/G$19 -> 1 | H83: =H21/H$19 -> 1 | I83: =I21/I$19 -> 1.0050706 | ... Q83: =Q21/Q$19 -> 1 | AE83: =A83 -> 44531 | AF83: =J83 -> 1.0238999 | AG83: =K83 -> 1.0804334 | AH83: =L83 -> 1.016649 | AI83: =M83 -> 1 | AJ83: =N83 -> 1 | AK83: =O83 -> 1.0109396 | AL83: =P83 -> 1.0217952 | AM83: =Q83 -> 1
A84: =A22 -> 44562 | B84: =B22/B$19 -> 1.0281729 | C84: =C22/C$19 -> 1.0028761 | D84: =D22/D$19 -> 0.99803205 | E84: =E22/E$19 -> 1.0019023 | F84: =F22/F$19 -> 1 | G84: =G22/G$19 -> 1 | H84: =H22/H$19 -> 1 | I84: =I22/I$19 -> 1.0626585 | ... Q84: =Q22/Q$19 -> 1 | AE84: =A84 -> 44562 | AF84: =J84 -> 1.0238999 | AG84: =K84 -> 1.098654 | AH84: =L84 -> 1.016649 | AI84: =M84 -> 1 | AJ84: =N84 -> 1 | AK84: =O84 -> 1.0193266 | AL84: =P84 -> 1.0217952 | AM84: =Q84 -> 1
A85: =A23 -> 44593 | B85: =B23/B$19 -> 1.0281729 | C85: =C23/C$19 -> 0.99434692 | D85: =D23/D$19 -> 0.98608378 | E85: =E23/E$19 -> 1.0019023 | F85: =F23/F$19 -> 1 | G85: =G23/G$19 -> 1 | H85: =H23/H$19 -> 1 | I85: =I23/I$19 -> 1.0626585 | ... Q85: =Q23/Q$19 -> 1 | AE85: =A85 -> 44593 | AF85: =J85 -> 1.0238999 | AG85: =K85 -> 1.137065 | AH85: =L85 -> 1.016649 | AI85: =M85 -> 1 | AJ85: =N85 -> 1 | AK85: =O85 -> 1.0193266 | AL85: =P85 -> 1.0217952 | AM85: =Q85 -> 1
...

Sheet Telecom Prices
A1: Telecommunications & Communication Prices — ABS CPI (Sydney + 7 capitals)
A2: Source: ABS 6401.0 Consumer Price Index, Table 10. Index reference period: September 2025 = 100.00. All series Original (not seasonally adjusted).
A4: Note: ABS rebased these series with September 2025 = 100; only 22 months of data are available (Dec 2023 – Sep 2025). Two related series are shown: 'Telecommunication equipment and services' and the broader 'Communication' group.
A6: A. Telecommunication Equipment and Services — Monthly Index, Dec 2023 – Sep 2025 (Sep 2025 = 100) | L6: Summary Statistics
A7: Month | B7: Sydney | C7: Melbourne | D7: Brisbane | E7: Adelaide | F7: Perth | G7: Hobart | H7: Darwin | I7: Canberra | J7: 8-Capital Avg | L7: City | M7: First (Dec-23) | N7: Latest (Sep-25) | O7: Min | P7: Max | Q7: Mean | R7: Std Dev | S7: % Change (Dec-23 → Sep-25) | T7: YoY % (Sep-25 vs Sep-24) | U7: MoM % (latest)
A8: =Data1!A90 -> 45383 | B8: =Data1!DA90 -> 98.61 | C8: =Data1!IC90 -> 98.61 | D8: =Data2!DO90 -> 98.63 | E8: =Data2!IQ90 -> 98.66 | F8: =Data3!EC90 -> 98.57 | G8: =Data4!O90 -> 98.48 | H8: =Data4!EQ90 -> 98.73 | I8: =Data5!AC90 -> 98.64 | J8: =AVERAGE(B8:I8) -> 98.61625 | L8: Telecommunication Equipment & Services
A9: =Data1!A91 -> 45413 | B9: =Data1!DA91 -> 98.06 | C9: =Data1!IC91 -> 98.06 | D9: =Data2!DO91 -> 98.07 | E9: =Data2!IQ91 -> 98.11 | F9: =Data3!EC91 -> 98.03 | G9: =Data4!O91 -> 97.94 | H9: =Data4!EQ91 -> 98.16 | I9: =Data5!AC91 -> 98.09 | J9: =AVERAGE(B9:I9) -> 98.065 | L9: Sydney | M9: =B8 -> 98.61 | N9: =B29 -> 99.65 | O9: =MIN(B8:B29) -> 97.51 | P9: =MAX(B8:B29) -> 100.24 | Q9: =AVERAGE(B8:B29) -> 99.071364 | R9: =STDEV(B8:B29) -> 0.72044494 | S9: =B29/B8-1 -> 0.010546598 | T9: =B29/B17-1 -> 0.011264461 | U9: =B29/B28-1 -> -0.0009023461
A10: =Data1!A92 -> 45444 | B10: =Data1!DA92 -> 97.51 | C10: =Data1!IC92 -> 97.52 | D10: =Data2!DO92 -> 97.53 | E10: =Data2!IQ92 -> 97.56 | F10: =Data3!EC92 -> 97.48 | G10: =Data4!O92 -> 97.4 | H10: =Data4!EQ92 -> 97.61 | I10: =Data5!AC92 -> 97.54 | J10: =AVERAGE(B10:I10) -> 97.51875 | L10: Melbourne | M10: =C8 -> 98.61 | N10: =C29 -> 99.66 | O10: =MIN(C8:C29) -> 97.52 | P10: =MAX(C8:C29) -> 100.23 | Q10: =AVERAGE(C8:C29) -> 99.075455 | R10: =STDEV(C8:C29) -> 0.71972036 | S10: =C29/C8-1 -> 0.010648007 | T10: =C29/C17-1 -> 0.011365943 | U10: =C29/C28-1 -> -0.00090225564 | V10: =C30/C29-1 -> -1
A11: =Data1!A93 -> 45474 | B11: =Data1!DA93 -> 99.02 | C11: =Data1!IC93 -> 99.02 | D11: =Data2!DO93 -> 99.03 | E11: =Data2!IQ93 -> 99.06 | F11: =Data3!EC93 -> 98.99 | G11: =Data4!O93 -> 98.91 | H11: =Data4!EQ93 -> 99.11 | I11: =Data5!AC93 -> 99.04 | J11: =AVERAGE(B11:I11) -> 99.0225 | L11: Brisbane | M11: =D8 -> 98.63 | N11: =D29 -> 99.66 | O11: =MIN(D8:D29) -> 97.53 | P11: =MAX(D8:D29) -> 100.23 | Q11: =AVERAGE(D8:D29) -> 99.081818 | R11: =STDEV(D8:D29) -> 0.71722107 | S11: =D29/D8-1 -> 0.01044307 | T11: =D29/D17-1 -> 0.011263318 | U11: =D29/D28-1 -> -0.00090225564
A12: =Data1!A94 -> 45505 | B12: =Data1!DA94 -> 98.48 | C12: =Data1!IC94 -> 98.48 | D12: =Data2!DO94 -> 98.49 | E12: =Data2!IQ94 -> 98.51 | F12: =Data3!EC94 -> 98.45 | G12: =Data4!O94 -> 98.39 | H12: =Data4!EQ94 -> 98.56 | I12: =Data5!AC94 -> 98.5 | J12: =AVERAGE(B12:I12) -> 98.4825 | L12: Adelaide | M12: =E8 -> 98.66 | N12: =E29 -> 99.68 | O12: =MIN(E8:E29) -> 97.56 | P12: =MAX(E8:E29) -> 100.25 | Q12: =AVERAGE(E8:E29) -> 99.101818 | R12: =STDEV(E8:E29) -> 0.71136111 | S12: =E29/E8-1 -> 0.010338536 | T12: =E29/E17-1 -> 0.01115845 | U12: =E29/E28-1 -> -0.00090207477
A13: =Data1!A95 -> 45536 | B13: =Data1!DA95 -> 98.53 | C13: =Data1!IC95 -> 98.54 | D13: =Data2!DO95 -> 98.55 | E13: =Data2!IQ95 -> 98.57 | F13: =Data3!EC95 -> 98.51 | G13: =Data4!O95 -> 98.44 | H13: =Data4!EQ95 -> 98.62 | I13: =Data5!AC95 -> 98.56 | J13: =AVERAGE(B13:I13) -> 98.54 | L13: Perth | M13: =F8 -> 98.57 | N13: =F29 -> 99.63 | O13: =MIN(F8:F29) -> 97.48 | P13: =MAX(F8:F29) -> 100.25 | Q13: =AVERAGE(F8:F29) -> 99.052273 | R13: =STDEV(F8:F29) -> 0.72611774 | S13: =F29/F8-1 -> 0.010753779 | T13: =F29/F17-1 -> 0.011369404 | U13: =F29/F28-1 -> -0.00090252708
A14: =Data1!A96 -> 45566 | B14: =Data1!DA96 -> 99.24 | C14: =Data1!IC96 -> 99.25 | D14: =Data2!DO96 -> 99.26 | E14: =Data2!IQ96 -> 99.29 | F14: =Data3!EC96 -> 99.22 | G14: =Data4!O96 -> 99.13 | H14: =Data4!EQ96 -> 99.35 | I14: =Data5!AC96 -> 99.27 | J14: =AVERAGE(B14:I14) -> 99.25125 | L14: Hobart | M14: =G8 -> 98.48 | N14: =G29 -> 99.57 | O14: =MIN(G8:G29) -> 97.4 | P14: =MAX(G8:G29) -> 100.28 | Q14: =AVERAGE(G8:G29) -> 98.997273 | R14: =STDEV(G8:G29) -> 0.74181362 | S14: =G29/G8-1 -> 0.011068237 | T14: =G29/G17-1 -> 0.011684617 | U14: =G29/G28-1 -> -0.0010033109
A15: =Data1!A97 -> 45597 | B15: =Data1!DA97 -> 99.13 | C15: =Data1!IC97 -> 99.14 | D15: =Data2!DO97 -> 99.15 | E15: =Data2!IQ97 -> 99.18 | F15: =Data3!EC97 -> 99.1 | G15: =Data4!O97 -> 99.01 | H15: =Data4!EQ97 -> 99.24 | I15: =Data5!AC97 -> 99.16 | J15: =AVERAGE(B15:I15) -> 99.13875 | L15: Darwin | M15: =H8 -> 98.73 | N15: =H29 -> 99.72 | O15: =MIN(H8:H29) -> 97.61 | P15: =MAX(H8:H29) -> 100.29 | Q15: =AVERAGE(H8:H29) -> 99.138182 | R15: =STDEV(H8:H29) -> 0.70353283 | S15: =H29/H8-1 -> 0.010027347 | T15: =H29/H17-1 -> 0.010948905 | U15: =H29/H28-1 -> -0.00090171326
A16: =Data1!A98 -> 45627 | B16: =Data1!DA98 -> 98.91 | C16: =Data1!IC98 -> 98.92 | D16: =Data2!DO98 -> 98.93 | E16: =Data2!IQ98 -> 98.96 | F16: =Data3!EC98 -> 98.88 | G16: =Data4!O98 -> 98.8 | H16: =Data4!EQ98 -> 99.01 | I16: =Data5!AC98 -> 98.94 | J16: =AVERAGE(B16:I16) -> 98.91875 | L16: Canberra | M16: =I8 -> 98.64 | N16: =I29 -> 99.67 | O16: =MIN(I8:I29) -> 97.54 | P16: =MAX(I8:I29) -> 100.24 | Q16: =AVERAGE(I8:I29) -> 99.09 | R16: =STDEV(I8:I29) -> 0.71504246 | S16: =I29/I8-1 -> 0.010442011 | T16: =I29/I17-1 -> 0.011262175 | U16: =I29/I28-1 -> -0.0009021652
A17: =Data1!A99 -> 45658 | B17: =Data1!DA99 -> 98.54 | C17: =Data1!IC99 -> 98.54 | D17: =Data2!DO99 -> 98.55 | E17: =Data2!IQ99 -> 98.58 | F17: =Data3!EC99 -> 98.51 | G17: =Data4!O99 -> 98.42 | H17: =Data4!EQ99 -> 98.64 | I17: =Data5!AC99 -> 98.56 | J17: =AVERAGE(B17:I17) -> 98.5425 | L17: 8-Capital Avg | M17: =J8 -> 98.61625 | N17: =J29 -> 99.655 | O17: =MIN(J8:J29) -> 97.51875 | P17: =MAX(J8:J29) -> 100.235 | Q17: =AVERAGE(J8:J29) -> 99.076023 | R17: =STDEV(J8:J29) -> 0.7190574 | S17: =J29/J8-1 -> 0.010533254 | T17: =J29/J17-1 -> 0.011289545 | U17: =J29/J28-1 -> -0.00091482136
A18: =Data1!A100 -> 45689 | B18: =Data1!DA100 -> 99.23 | C18: =Data1!IC100 -> 99.24 | D18: =Data2!DO100 -> 99.24 | E18: =Data2!IQ100 -> 99.26 | F18: =Data3!EC100 -> 99.22 | G18: =Data4!O100 -> 99.18 | H18: =Data4!EQ100 -> 99.28 | I18: =Data5!AC100 -> 99.25 | J18: =AVERAGE(B18:I18) -> 99.2375 | L18: Communication (broader group)
A19: =Data1!A101 -> 45717 | B19: =Data1!DA101 -> 99.06 | C19: =Data1!IC101 -> 99.07 | D19: =Data2!DO101 -> 99.08 | E19: =Data2!IQ101 -> 99.1 | F19: =Data3!EC101 -> 99.04 | G19: =Data4!O101 -> 98.98 | H19: =Data4!EQ101 -> 99.14 | I19: =Data5!AC101 -> 99.08 | J19: =AVERAGE(B19:I19) -> 99.06875 | L19: Sydney | M19: =B33 -> 98.52 | N19: =B54 -> 99.72 | O19: =MIN(B33:B54) -> 97.2 | P19: =MAX(B33:B54) -> 100.24 | Q19: =AVERAGE(B33:B54) -> 98.975909 | R19: =STDEV(B33:B54) -> 0.79237232 | S19: =B54/B33-1 -> 0.012180268 | T19: =B54/B42-1 -> 0.014136072 | U19: =B54/B53-1 -> -0.00090171326
A20: =Data1!A102 -> 45748 | B20: =Data1!DA102 -> 99.27 | C20: =Data1!IC102 -> 99.27 | D20: =Data2!DO102 -> 99.28 | E20: =Data2!IQ102 -> 99.31 | F20: =Data3!EC102 -> 99.24 | G20: =Data4!O102 -> 99.17 | H20: =Data4!EQ102 -> 99.35 | I20: =Data5!AC102 -> 99.29 | J20: =AVERAGE(B20:I20) -> 99.2725 | L20: Melbourne | M20: =C33 -> 98.54 | N20: =C54 -> 99.71 | O20: =MIN(C33:C54) -> 97.25 | P20: =MAX(C33:C54) -> 100.24 | Q20: =AVERAGE(C33:C54) -> 98.991364 | R20: =STDEV(C33:C54) -> 0.78008116 | S20: =C54/C33-1 -> 0.011873351 | T20: =C54/C42-1 -> 0.013622039 | U20: =C54/C53-1 -> -0.00090180361
A21: =Data1!A103 -> 45778 | B21: =Data1!DA103 -> 98.89 | C21: =Data1!IC103 -> 98.89 | D21: =Data2!DO103 -> 98.89 | E21: =Data2!IQ103 -> 98.89 | F21: =Data3!EC103 -> 98.89 | G21: =Data4!O103 -> 98.89 | H21: =Data4!EQ103 -> 98.89 | I21: =Data5!AC103 -> 98.89 | J21: =AVERAGE(B21:I21) -> 98.89 | L21: Brisbane | M21: =D33 -> 98.56 | N21: =D54 -> 99.71 | O21: =MIN(D33:D54) -> 97.31 | P21: =MAX(D33:D54) -> 100.25 | Q21: =AVERAGE(D33:D54) -> 99.013182 | R21: =STDEV(D33:D54) -> 0.76773251 | S21: =D54/D33-1 -> 0.011668019 | T21: =D54/D42-1 -> 0.01321004 | U21: =D54/D53-1 -> -0.00090180361
A22: =Data1!A104 -> 45809 | B22: =Data1!DA104 -> 97.99 | C22: =Data1!IC104 -> 97.99 | D22: =Data2!DO104 -> 97.99 | E22: =Data2!IQ104 -> 98 | F22: =Data3!EC104 -> 97.99 | G22: =Data4!O104 -> 97.98 | H22: =Data4!EQ104 -> 98 | I22: =Data5!AC104 -> 98 | J22: =AVERAGE(B22:I22) -> 97.9925 | L22: Adelaide | M22: =E33 -> 98.59 | N22: =E54 -> 99.73 | O22: =MIN(E33:E54) -> 97.33 | P22: =MAX(E33:E54) -> 100.27 | Q22: =AVERAGE(E33:E54) -> 99.03 | R22: =STDEV(E33:E54) -> 0.764336 | S22: =E54/E33-1 -> 0.011563039 | T22: =E54/E42-1 -> 0.013207355 | U22: =E54/E53-1 -> -0.00090162292
A23: =Data1!A105 -> 45839 | B23: =Data1!DA105 -> 99.5 | C23: =Data1!IC105 -> 99.5 | D23: =Data2!DO105 -> 99.5 | E23: =Data2!IQ105 -> 99.5 | F23: =Data3!EC105 -> 99.5 | G23: =Data4!O105 -> 99.49 | H23: =Data4!EQ105 -> 99.51 | I23: =Data5!AC105 -> 99.5 | J23: =AVERAGE(B23:I23) -> 99.5 | L23: Perth | M23: =F33 -> 98.51 | N23: =F54 -> 99.68 | O23: =MIN(F33:F54) -> 97.27 | P23: =MAX(F33:F54) -> 100.22 | Q23: =AVERAGE(F33:F54) -> 98.985909 | R23: =STDEV(F33:F54) -> 0.77565124 | S23: =F54/F33-1 -> 0.011876967 | T23: =F54/F42-1 -> 0.013317068 | U23: =F54/F53-1 -> -0.00090207477
A24: =Data1!A106 -> 45870 | B24: =Data1!DA106 -> 100.24 | C24: =Data1!IC106 -> 100.23 | D24: =Data2!DO106 -> 100.23 | E24: =Data2!IQ106 -> 100.22 | F24: =Data3!EC106 -> 100.25 | G24: =Data4!O106 -> 100.28 | H24: =Data4!EQ106 -> 100.2 | I24: =Data5!AC106 -> 100.23 | J24: =AVERAGE(B24:I24) -> 100.235 | L24: Hobart | M24: =G33 -> 98.4 | N24: =G54 -> 99.64 | O24: =MIN(G33:G54) -> 97.12 | P24: =MAX(G33:G54) -> 100.24 | Q24: =AVERAGE(G33:G54) -> 98.910455 | R24: =STDEV(G33:G54) -> 0.80897629 | S24: =G54/G33-1 -> 0.012601626 | T24: =G54/G42-1 -> 0.014250814 | U24: =G54/G53-1 -> -0.00090243658
A25: =Data1!A107 -> 45901 | B25: =Data1!DA107 -> 100 | C25: =Data1!IC107 -> 100 | D25: =Data2!DO107 -> 100 | E25: =Data2!IQ107 -> 100 | F25: =Data3!EC107 -> 100 | G25: =Data4!O107 -> 100 | H25: =Data4!EQ107 -> 100 | I25: =Data5!AC107 -> 100 | J25: =AVERAGE(B25:I25) -> 100 | L25: Darwin | M25: =H33 -> 98.65 | N25: =H54 -> 99.77 | O25: =MIN(H33:H54) -> 97.36 | P25: =MAX(H33:H54) -> 100.31 | Q25: =AVERAGE(H33:H54) -> 99.058182 | R25: =STDEV(H33:H54) -> 0.75953392 | S25: =H54/H33-1 -> 0.011353269 | T25: =H54/H42-1 -> 0.01320199 | U25: =H54/H53-1 -> -0.00090126177
A26: =Data1!A108 -> 45931 | B26: =Data1!DA108 -> 99.75 | C26: =Data1!IC108 -> 99.76 | D26: =Data2!DO108 -> 99.76 | E26: =Data2!IQ108 -> 99.78 | F26: =Data3!EC108 -> 99.73 | G26: =Data4!O108 -> 99.67 | H26: =Data4!EQ108 -> 99.82 | I26: =Data5!AC108 -> 99.77 | J26: =AVERAGE(B26:I26) -> 99.755 | L26: Canberra | M26: =I33 -> 98.51 | N26: =I54 -> 99.76 | O26: =MIN(I33:I54) -> 97.1 | P26: =MAX(I33:I54) -> 100.27 | Q26: =AVERAGE(I33:I54) -> 98.950909 | R26: =STDEV(I33:I54) -> 0.81936624 | S26: =I54/I33-1 -> 0.012689067 | T26: =I54/I42-1 -> 0.015162308 | U26: =I54/I53-1 -> -0.00090135203
A27: =Data1!A109 -> 45962 | B27: =Data1!DA109 -> 100.22 | C27: =Data1!IC109 -> 100.22 | D27: =Data2!DO109 -> 100.23 | E27: =Data2!IQ109 -> 100.25 | F27: =Data3!EC109 -> 100.2 | G27: =Data4!O109 -> 100.14 | H27: =Data4!EQ109 -> 100.29 | I27: =Data5!AC109 -> 100.24 | J27: =AVERAGE(B27:I27) -> 100.22375 | L27: 8-Capital Avg | M27: =J33 -> 98.535 | N27: =J54 -> 99.715 | O27: =MIN(J33:J54) -> 97.2425 | P27: =MAX(J33:J54) -> 100.24625 | Q27: =AVERAGE(J33:J54) -> 98.989489 | R27: =STDEV(J33:J54) -> 0.78302818 | S27: =J54/J33-1 -> 0.01197544 | T27: =J54/J42-1 -> 0.013763042 | U27: =J54/J53-1 -> -0.00090175843
A28: =Data1!A110 -> 45992 | B28: =Data1!DA110 -> 99.74 | C28: =Data1!IC110 -> 99.75 | D28: =Data2!DO110 -> 99.75 | E28: =Data2!IQ110 -> 99.77 | F28: =Data3!EC110 -> 99.72 | G28: =Data4!O110 -> 99.67 | H28: =Data4!EQ110 -> 99.81 | I28: =Data5!AC110 -> 99.76 | J28: =AVERAGE(B28:I28) -> 99.74625
A29: =Data1!A111 -> 46023 | B29: =Data1!DA111 -> 99.65 | C29: =Data1!IC111 -> 99.66 | D29: =Data2!DO111 -> 99.66 | E29: =Data2!IQ111 -> 99.68 | F29: =Data3!EC111 -> 99.63 | G29: =Data4!O111 -> 99.57 | H29: =Data4!EQ111 -> 99.72 | I29: =Data5!AC111 -> 99.67 | J29: =AVERAGE(B29:I29) -> 99.655
A31: B. Communication (CPI sub-group, broader) — Monthly Index, Dec 2023 – Sep 2025 (Sep 2025 = 100)
A32: Month | B32: Sydney | C32: Melbourne | D32: Brisbane | E32: Adelaide | F32: Perth | G32: Hobart | H32: Darwin | I32: Canberra | J32: 8-Capital Avg
A33: =Data1!A90 -> 45383 | B33: =Data1!CY90 -> 98.52 | C33: =Data1!IA90 -> 98.54 | D33: =Data2!DM90 -> 98.56 | E33: =Data2!IO90 -> 98.59 | F33: =Data3!EA90 -> 98.51 | G33: =Data4!M90 -> 98.4 | H33: =Data4!EO90 -> 98.65 | I33: =Data5!AA90 -> 98.51 | J33: =AVERAGE(B33:I33) -> 98.535
A34: =Data1!A91 -> 45413 | B34: =Data1!CY91 -> 97.86 | C34: =Data1!IA91 -> 97.89 | D34: =Data2!DM91 -> 97.93 | E34: =Data2!IO91 -> 97.96 | F34: =Data3!EA91 -> 97.89 | G34: =Data4!M91 -> 97.76 | H34: =Data4!EO91 -> 98 | I34: =Data5!AA91 -> 97.8 | J34: =AVERAGE(B34:I34) -> 97.88625
A35: =Data1!A92 -> 45444 | B35: =Data1!CY92 -> 97.2 | C35: =Data1!IA92 -> 97.25 | D35: =Data2!DM92 -> 97.31 | E35: =Data2!IO92 -> 97.33 | F35: =Data3!EA92 -> 97.27 | G35: =Data4!M92 -> 97.12 | H35: =Data4!EO92 -> 97.36 | I35: =Data5!AA92 -> 97.1 | J35: =AVERAGE(B35:I35) -> 97.2425
A36: =Data1!A93 -> 45474 | B36: =Data1!CY93 -> 98.87 | C36: =Data1!IA93 -> 98.89 | D36: =Data2!DM93 -> 98.92 | E36: =Data2!IO93 -> 98.95 | F36: =Data3!EA93 -> 98.88 | G36: =Data4!M93 -> 98.77 | H36: =Data4!EO93 -> 98.99 | I36: =Data5!AA93 -> 98.83 | J36: =AVERAGE(B36:I36) -> 98.8875
A37: =Data1!A94 -> 45505 | B37: =Data1!CY94 -> 98.36 | C37: =Data1!IA94 -> 98.38 | D37: =Data2!DM94 -> 98.4 | E37: =Data2!IO94 -> 98.42 | F37: =Data3!EA94 -> 98.37 | G37: =Data4!M94 -> 98.28 | H37: =Data4!EO94 -> 98.46 | I37: =Data5!AA94 -> 98.33 | J37: =AVERAGE(B37:I37) -> 98.375
A38: =Data1!A95 -> 45536 | B38: =Data1!CY95 -> 98.4 | C38: =Data1!IA95 -> 98.42 | D38: =Data2!DM95 -> 98.45 | E38: =Data2!IO95 -> 98.47 | F38: =Data3!EA95 -> 98.41 | G38: =Data4!M95 -> 98.31 | H38: =Data4!EO95 -> 98.5 | I38: =Data5!AA95 -> 98.36 | J38: =AVERAGE(B38:I38) -> 98.415
A39: =Data1!A96 -> 45566 | B39: =Data1!CY96 -> 99.02 | C39: =Data1!IA96 -> 99.06 | D39: =Data2!DM96 -> 99.1 | E39: =Data2!IO96 -> 99.13 | F39: =Data3!EA96 -> 99.06 | G39: =Data4!M96 -> 98.93 | H39: =Data4!EO96 -> 99.16 | I39: =Data5!AA96 -> 98.95 | J39: =AVERAGE(B39:I39) -> 99.05125
A40: =Data1!A97 -> 45597 | B40: =Data1!CY97 -> 98.91 | C40: =Data1!IA97 -> 98.94 | D40: =Data2!DM97 -> 98.99 | E40: =Data2!IO97 -> 99.01 | F40: =Data3!EA97 -> 98.94 | G40: =Data4!M97 -> 98.8 | H40: =Data4!EO97 -> 99.05 | I40: =Data5!AA97 -> 98.84 | J40: =AVERAGE(B40:I40) -> 98.935
A41: =Data1!A98 -> 45627 | B41: =Data1!CY98 -> 98.69 | C41: =Data1!IA98 -> 98.72 | D41: =Data2!DM98 -> 98.77 | E41: =Data2!IO98 -> 98.79 | F41: =Data3!EA98 -> 98.73 | G41: =Data4!M98 -> 98.6 | H41: =Data4!EO98 -> 98.83 | I41: =Data5!AA98 -> 98.62 | J41: =AVERAGE(B41:I41) -> 98.71875
A42: =Data1!A99 -> 45658 | B42: =Data1!CY99 -> 98.33 | C42: =Data1!IA99 -> 98.37 | D42: =Data2!DM99 -> 98.41 | E42: =Data2!IO99 -> 98.43 | F42: =Data3!EA99 -> 98.37 | G42: =Data4!M99 -> 98.24 | H42: =Data4!EO99 -> 98.47 | I42: =Data5!AA99 -> 98.27 | J42: =AVERAGE(B42:I42) -> 98.36125
A43: =Data1!A100 -> 45689 | B43: =Data1!CY100 -> 99.07 | C43: =Data1!IA100 -> 99.09 | D43: =Data2!DM100 -> 99.12 | E43: =Data2!IO100 -> 99.13 | F43: =Data3!EA100 -> 99.1 | G43: =Data4!M100 -> 99.02 | H43: =Data4!EO100 -> 99.15 | I43: =Data5!AA100 -> 99.01 | J43: =AVERAGE(B43:I43) -> 99.08625
...

Sheet Data1
B1: Index Numbers ; All groups CPI ; Sydney ; | C1: Index Numbers ; Food and non-alcoholic beverages ; Sydney ; | D1: Index Numbers ; Bread and cereal products ; Sydney ; | E1: Index Numbers ; Bread ; Sydney ; | F1: Index Numbers ; Cakes and biscuits ; Sydney ; | G1: Index Numbers ; Breakfast cereals ; Sydney ; | H1: Index Numbers ; Other cereal products ; Sydney ; | I1: Index Numbers ; Meat and seafoods ; Sydney ; | J1: Index Numbers ; Beef and veal ; Sydney ; | K1: Index Numbers ; Pork ; Sydney ; | L1: Index Numbers ; Lamb and goat ; Sydney ; | M1: Index Numbers ; Poultry ; Sydney ; | N1: Index Numbers ; Other meats ; Sydney ; | O1: Index Numbers ; Fish and other seafood ; Sydney ; | P1: Index Numbers ; Dairy and related products ; Sydney ; | Q1: Index Numbers ; Milk ; Sydney ; | R1: Index Numbers ; Cheese ; Sydney ; | S1: Index Numbers ; Ice cream and other dairy products ; Sydney ; | T1: Index Numbers ; Fruit and vegetables ; Sydney ; | U1: Index Numbers ; Fruit ; Sydney ; | V1: Index Numbers ; Vegetables ; Sydney ; | W1: Index Numbers ; Food products n.e.c. ; Sydney ; | X1: Index Numbers ; Eggs ; Sydney ; | Y1: Index Numbers ; Jams, honey and spreads ; Sydney ; | Z1: Index Numbers ; Food additives and condiments ; Sydney ; | AA1: Index Numbers ; Oils and fats ; Sydney ; | AB1: Index Numbers ; Snacks and confectionery ; Sydney ; | AC1: Index Numbers ; Other food products n.e.c. ; Sydney ; | AD1: Index Numbers ; Non-alcoholic beverages ; Sydney ; | AE1: Index Numbers ; Coffee, tea and cocoa ; Sydney ; | AF1: Index Numbers ; Waters, soft drinks and juices ; Sydney ; | AG1: Index Numbers ; Meals out and take away foods ; Sydney ; | AH1: Index Numbers ; Restaurant meals ; Sydney ; | AI1: Index Numbers ; Take away and fast foods ; Sydney ; | AJ1: Index Numbers ; Alcohol and tobacco ; Sydney ; | AK1: Index Numbers ; Alcoholic beverages ; Sydney ; | AL1: Index Numbers ; Spirits ; Sydney ; | AM1: Index Numbers ; Wine ; Sydney ; | AN1: Index Numbers ; Beer ; Sydney ; | AO1: Index Numbers ; Tobacco ; Sydney ; | AP1: Index Numbers ; Tobacco ; Sydney ; | AQ1: Index Numbers ; Clothing and footwear ; Sydney ; | AR1: Index Numbers ; Garments ; Sydney ; | AS1: Index Numbers ; Garments for men ; Sydney ; | AT1: Index Numbers ; Garments for women ; Sydney ; | AU1: Index Numbers ; Garments for infants and children ; Sydney ; | AV1: Index Numbers ; Footwear ; Sydney ; | AW1: Index Numbers ; Footwear for men ; Sydney ; | AX1: Index Numbers ; Footwear for women ; Sydney ; | AY1: Index Numbers ; Footwear for infants and children ; Sydney ; | AZ1: Index Numbers ; Accessories and clothing services ; Sydney ; | BA1: Index Numbers ; Accessories ; Sydney ; | BB1: Index Numbers ; Cleaning, repair and hire of clothing and footwear ; Sydney ; | BC1: Index Numbers ; Housing ; Sydney ; | BD1: Index Numbers ; Rents ; Sydney ; | BE1: Index Numbers ; Rents ; Sydney ; | BF1: Index Numbers ; New dwelling purchase by owner-occupiers ; Sydney ; | BG1: Index Numbers ; New dwelling purchase by owner-occupiers ; Sydney ; | BH1: Index Numbers ; Other housing ; Sydney ; | BI1: Index Numbers ; Maintenance and repair of the dwelling ; Sydney ; | BJ1: Index Numbers ; Property rates and charges ; Sydney ; | BK1: Index Numbers ; Utilities ; Sydney ; | BL1: Index Numbers ; Water and sewerage ; Sydney ; | BM1: Index Numbers ; Electricity ; Sydney ; | BN1: Index Numbers ; Gas and other household fuels ; Sydney ; | BO1: Index Numbers ; Furnishings, household equipment and services ; Sydney ; | BP1: Index Numbers ; Furniture and furnishings ; Sydney ; | BQ1: Index Numbers ; Furniture ; Sydney ; | BR1: Index Numbers ; Carpets and other floor coverings ; Sydney ; | BS1: Index Numbers ; Household textiles ; Sydney ; | BT1: Index Numbers ; Household textiles ; Sydney ; | BU1: Index Numbers ; Household appliances, utensils and tools ; Sydney ; | BV1: Index Numbers ; Major household appliances ; Sydney ; | BW1: Index Numbers ; Small electric household appliances ; Sydney ; | BX1: Index Numbers ; Glassware, tableware and household utensils ; Sydney ; | BY1: Index Numbers ; Tools and equipment for house and garden ; Sydney ; | BZ1: Index Numbers ; Non-durable household products ; Sydney ; | CA1: Index Numbers ; Cleaning and maintenance products ; Sydney ; | CB1: Index Numbers ; Personal care products ; Sydney ; | CC1: Index Numbers ; Other non-durable household products ; Sydney ; | CD1: Index Numbers ; Domestic and household services ; Sydney ; | CE1: Index Numbers ; Child care ; Sydney ; | CF1: Index Numbers ; Hairdressing and personal grooming services ; Sydney ; | CG1: Index Numbers ; Other household services ; Sydney ; | CH1: Index Numbers ; Health ; Sydney ; | CI1: Index Numbers ; Medical products, appliances and equipment ; Sydney ; | CJ1: Index Numbers ; Pharmaceutical products ; Sydney ; | CK1: Index Numbers ; Therapeutic appliances and equipment ; Sydney ; | CL1: Index Numbers ; Medical, dental and hospital services ; Sydney ; | CM1: Index Numbers ; Medical and hospital services ; Sydney ; | CN1: Index Numbers ; Dental services ; Sydney ; | CO1: Index Numbers ; Transport ; Sydney ; | CP1: Index Numbers ; Private motoring ; Sydney ; | CQ1: Index Numbers ; Motor vehicles ; Sydney ; | CR1: Index Numbers ; Spare parts and accessories for motor vehicles ; Sydney ; | CS1: Index Numbers ; Automotive fuel ; Sydney ; | CT1: Index Numbers ; Maintenance and repair of motor vehicles ; Sydney ; | CU1: Index Numbers ; Other services in respect of motor vehicles ; Sydney ; | CV1: Index Numbers ; Urban transport fares ; Sydney ; | CW1: Index Numbers ; Urban transport fares ; Sydney ; | CX1: Index Numbers ; Communication ; Sydney ; | CY1: Index Numbers ; Communication ; Sydney ; | CZ1: Index Numbers ; Postal services ; Sydney ; | DA1: Index Numbers ; Telecommunication equipment and services ; Sydney ; | DB1: Index Numbers ; Recreation and culture ; Sydney ; | DC1: Index Numbers ; Audio, visual and computing equipment and services ; Sydney ; | DD1: Index Numbers ; Audio, visual and computing equipment ; Sydney ; | DE1: Index Numbers ; Audio, visual and computing media and services ; Sydney ; | DF1: Index Numbers ; Newspapers, books and stationery ; Sydney ; | DG1: Index Numbers ; Books ; Sydney ; | DH1: Index Numbers ; Newspapers, magazines and stationery ; Sydney ; | DI1: Index Numbers ; Holiday travel and accommodation ; Sydney ; | DJ1: Index Numbers ; Domestic holiday travel and accommodation ; Sydney ; | DK1: Index Numbers ; International holiday travel and accommodation ; Sydney ; | DL1: Index Numbers ; Other recreation, sport and culture ; Sydney ; | DM1: Index Numbers ; Equipment for sports, camping and open-air recreation ; Sydney ; | DN1: Index Numbers ; Games, toys and hobbies ; Sydney ; | DO1: Index Numbers ; Pets and related products ; Sydney ; | DP1: Index Numbers ; Veterinary and other services for pets ; Sydney ; | DQ1: Index Numbers ; Sports participation ; Sydney ; | DR1: Index Numbers ; Other recreational, sporting and cultural services ; Sydney ; | DS1: Index Numbers ; Education ; Sydney ; | DT1: Index Numbers ; Education ; Sydney ; | DU1: Index Numbers ; Preschool and primary education ; Sydney ; | DV1: Index Numbers ; Secondary education ; Sydney ; | DW1: Index Numbers ; Tertiary education ; Sydney ; | DX1: Index Numbers ; Insurance and financial services ; Sydney ; | DY1: Index Numbers ; Insurance ; Sydney ; | DZ1: Index Numbers ; Insurance ; Sydney ; | EA1: Index Numbers ; Financial services ; Sydney ; | EB1: Index Numbers ; Deposit and loan facilities (direct charges) ; Sydney ; | EC1: Index Numbers ; Other financial services ; Sydney ; | ED1: Index Numbers ; All groups CPI ; Melbourne ; | EE1: Index Numbers ; Food and non-alcoholic beverages ; Melbourne ; | EF1: Index Numbers ; Bread and cereal products ; Melbourne ; | EG1: Index Numbers ; Bread ; Melbourne ; | EH1: Index Numbers ; Cakes and biscuits ; Melbourne ; | EI1: Index Numbers ; Breakfast cereals ; Melbourne ; | EJ1: Index Numbers ; Other cereal products ; Melbourne ; | EK1: Index Numbers ; Meat and seafoods ; Melbourne ; | EL1: Index Numbers ; Beef and veal ; Melbourne ; | EM1: Index Numbers ; Pork ; Melbourne ; | EN1: Index Numbers ; Lamb and goat ; Melbourne ; | EO1: Index Numbers ; Poultry ; Melbourne ; | EP1: Index Numbers ; Other meats ; Melbourne ; | EQ1: Index Numbers ; Fish and other seafood ; Melbourne ; | ER1: Index Numbers ; Dairy and related products ; Melbourne ; | ES1: Index Numbers ; Milk ; Melbourne ; | ET1: Index Numbers ; Cheese ; Melbourne ; | EU1: Index Numbers ; Ice cream and other dairy products ; Melbourne ; | EV1: Index Numbers ; Fruit and vegetables ; Melbourne ; | EW1: Index Numbers ; Fruit ; Melbourne ; | EX1: Index Numbers ; Vegetables ; Melbourne ; | EY1: Index Numbers ; Food products n.e.c. ; Melbourne ; | EZ1: Index Numbers ; Eggs ; Melbourne ; | FA1: Index Numbers ; Jams, honey and spreads ; Melbourne ; | FB1: Index Numbers ; Food additives and condiments ; Melbourne ; | FC1: Index Numbers ; Oils and fats ; Melbourne ; | FD1: Index Numbers ; Snacks and confectionery ; Melbourne ; | FE1: Index Numbers ; Other food products n.e.c. ; Melbourne ; | FF1: Index Numbers ; Non-alcoholic beverages ; Melbourne ; | FG1: Index Numbers ; Coffee, tea and cocoa ; Melbourne ; | FH1: Index Numbers ; Waters, soft drinks and juices ; Melbourne ; | FI1: Index Numbers ; Meals out and take away foods ; Melbourne ; | FJ1: Index Numbers ; Restaurant meals ; Melbourne ; | FK1: Index Numbers ; Take away and fast foods ; Melbourne ; | FL1: Index Numbers ; Alcohol and tobacco ; Melbourne ; | FM1: Index Numbers ; Alcoholic beverages ; Melbourne ; | FN1: Index Numbers ; Spirits ; Melbourne ; | FO1: Index Numbers ; Wine ; Melbourne ; | FP1: Index Numbers ; Beer ; Melbourne ; | FQ1: Index Numbers ; Tobacco ; Melbourne ; | FR1: Index Numbers ; Tobacco ; Melbourne ; | FS1: Index Numbers ; Clothing and footwear ; Melbourne ; | FT1: Index Numbers ; Garments ; Melbourne ; | FU1: Index Numbers ; Garments for men ; Melbourne ; | FV1: Index Numbers ; Garments for women ; Melbourne ; | FW1: Index Numbers ; Garments for infants and children ; Melbourne ; | FX1: Index Numbers ; Footwear ; Melbourne ; | FY1: Index Numbers ; Footwear for men ; Melbourne ; | FZ1: Index Numbers ; Footwear for women ; Melbourne ; | GA1: Index Numbers ; Footwear for infants and children ; Melbourne ; | GB1: Index Numbers ; Accessories and clothing services ; Melbourne ; | GC1: Index Numbers ; Accessories ; Melbourne ; | GD1: Index Numbers ; Cleaning, repair and hire of clothing and footwear ; Melbourne ; | GE1: Index Numbers ; Housing ; Melbourne ; | GF1: Index Numbers ; Rents ; Melbourne ; | GG1: Index Numbers ; Rents ; Melbourne ; | GH1: Index Numbers ; New dwelling purchase by owner-occupiers ; Melbourne ; | GI1: Index Numbers ; New dwelling purchase by owner-occupiers ; Melbourne ; | GJ1: Index Numbers ; Other housing ; Melbourne ; | GK1: Index Numbers ; Maintenance and repair of the dwelling ; Melbourne ; | GL1: Index Numbers ; Property rates and charges ; Melbourne ; | GM1: Index Numbers ; Utilities ; Melbourne ; | GN1: Index Numbers ; Water and sewerage ; Melbourne ; | GO1: Index Numbers ; Electricity ; Melbourne ; | GP1: Index Numbers ; Gas and other household fuels ; Melbourne ; | GQ1: Index Numbers ; Furnishings, household equipment and services ; Melbourne ; | GR1: Index Numbers ; Furniture and furnishings ; Melbourne ; | GS1: Index Numbers ; Furniture ; Melbourne ; | GT1: Index Numbers ; Carpets and other floor coverings ; Melbourne ; | GU1: Index Numbers ; Household textiles ; Melbourne ; | GV1: Index Numbers ; Household textiles ; Melbourne ; | GW1: Index Numbers ; Household appliances, utensils and tools ; Melbourne ; | GX1: Index Numbers ; Major household appliances ; Melbourne ; | GY1: Index Numbers ; Small electric household appliances ; Melbourne ; | GZ1: Index Numbers ; Glassware, tableware and household utensils ; Melbourne ; | HA1: Index Numbers ; Tools and equipment for house and garden ; Melbourne ; | HB1: Index Numbers ; Non-durable household products ; Melbourne ; | HC1: Index Numbers ; Cleaning and maintenance products ; Melbourne ; | HD1: Index Numbers ; Personal care products ; Melbourne ; | HE1: Index Numbers ; Other non-durable household products ; Melbourne ; | HF1: Index Numbers ; Domestic and household services ; Melbourne ; | HG1: Index Numbers ; Child care ; Melbourne ; | HH1: Index Numbers ; Hairdressing and personal grooming services ; Melbourne ; | HI1: Index Numbers ; Other household services ; Melbourne ; | HJ1: Index Numbers ; Health ; Melbourne ; | HK1: Index Numbers ; Medical products, appliances and equipment ; Melbourne ; | HL1: Index Numbers ; Pharmaceutical products ; Melbourne ; | HM1: Index Numbers ; Therapeutic appliances and equipment ; Melbourne ; | HN1: Index Numbers ; Medical, dental and hospital services ; Melbourne ; | HO1: Index Numbers ; Medical and hospital services ; Melbourne ; | HP1: Index Numbers ; Dental services ; Melbourne ; | HQ1: Index Numbers ; Transport ; Melbourne ; | HR1: Index Numbers ; Private motoring ; Melbourne ; | HS1: Index Numbers ; Motor vehicles ; Melbourne ; | HT1: Index Numbers ; Spare parts and accessories for motor vehicles ; Melbourne ; | HU1: Index Numbers ; Automotive fuel ; Melbourne ; | HV1: Index Numbers ; Maintenance and repair of motor vehicles ; Melbourne ; | HW1: Index Numbers ; Other services in respect of motor vehicles ; Melbourne ; | HX1: Index Numbers ; Urban transport fares ; Melbourne ; | HY1: Index Numbers ; Urban transport fares ; Melbourne ; | HZ1: Index Numbers ; Communication ; Melbourne ; | IA1: Index Numbers ; Communication ; Melbourne ; | IB1: Index Numbers ; Postal services ; Melbourne ; | IC1: Index Numbers ; Telecommunication equipment and services ; Melbourne ; | ID1: Index Numbers ; Recreation and culture ; Melbourne ; | IE1: Index Numbers ; Audio, visual and computing equipment and services ; Melbourne ; | IF1: Index Numbers ; Audio, visual and computing equipment ; Melbourne ; | IG1: Index Numbers ; Audio, visual and computing media and services ; Melbourne ; | IH1: Index Numbers ; Newspapers, books and stationery ; Melbourne ; | II1: Index Numbers ; Books ; Melbourne ; | IJ1: Index Numbers ; Newspapers, magazines and stationery ; Melbourne ; | IK1: Index Numbers ; Holiday travel and accommodation ; Melbourne ; | IL1: Index Numbers ; Domestic holiday travel and accommodation ; Melbourne ; | IM1: Index Numbers ; International holiday travel and accommodation ; Melbourne ; | IN1: Index Numbers ; Other recreation, sport and culture ; Melbourne ; | IO1: Index Numbers ; Equipment for sports, camping and open-air recreation ; Melbourne ; | IP1: Index Numbers ; Games, toys and hobbies ; Melbourne ; | IQ1: Index Numbers ; Pets and related products ; Melbourne ;
A2: Unit | B2: Index Numbers | C2: Index Numbers | D2: Index Numbers | E2: Index Numbers | F2: Index Numbers | G2: Index Numbers | H2: Index Numbers | I2: Index Numbers | J2: Index Numbers | K2: Index Numbers | L2: Index Numbers | M2: Index Numbers | N2: Index Numbers | O2: Index Numbers | P2: Index Numbers | Q2: Index Numbers | R2: Index Numbers | S2: Index Numbers | T2: Index Numbers | U2: Index Numbers | V2: Index Numbers | W2: Index Numbers | X2: Index Numbers | Y2: Index Numbers | Z2: Index Numbers | AA2: Index Numbers | AB2: Index Numbers | AC2: Index Numbers | AD2: Index Numbers | AE2: Index Numbers | AF2: Index Numbers | AG2: Index Numbers | AH2: Index Numbers | AI2: Index Numbers | AJ2: Index Numbers | AK2: Index Numbers | AL2: Index Numbers | AM2: Index Numbers | AN2: Index Numbers | AO2: Index Numbers | AP2: Index Numbers | AQ2: Index Numbers | AR2: Index Numbers | AS2: Index Numbers | AT2: Index Numbers | AU2: Index Numbers | AV2: Index Numbers | AW2: Index Numbers | AX2: Index Numbers | AY2: Index Numbers | AZ2: Index Numbers | BA2: Index Numbers | BB2: Index Numbers | BC2: Index Numbers | BD2: Index Numbers | BE2: Index Numbers | BF2: Index Numbers | BG2: Index Numbers | BH2: Index Numbers | BI2: Index Numbers | BJ2: Index Numbers | BK2: Index Numbers | BL2: Index Numbers | BM2: Index Numbers | BN2: Index Numbers | BO2: Index Numbers | BP2: Index Numbers | BQ2: Index Numbers | BR2: Index Numbers | BS2: Index Numbers | BT2: Index Numbers | BU2: Index Numbers | BV2: Index Numbers | BW2: Index Numbers | BX2: Index Numbers | BY2: Index Numbers | BZ2: Index Numbers | CA2: Index Numbers | CB2: Index Numbers | CC2: Index Numbers | CD2: Index Numbers | CE2: Index Numbers | CF2: Index Numbers | CG2: Index Numbers | CH2: Index Numbers | CI2: Index Numbers | CJ2: Index Numbers | CK2: Index Numbers | CL2: Index Numbers | CM2: Index Numbers | CN2: Index Numbers | CO2: Index Numbers | CP2: Index Numbers | CQ2: Index Numbers | CR2: Index Numbers | CS2: Index Numbers | CT2: Index Numbers | CU2: Index Numbers | CV2: Index Numbers | CW2: Index Numbers | CX2: Index Numbers | CY2: Index Numbers | CZ2: Index Numbers | DA2: Index Numbers | DB2: Index Numbers | DC2: Index Numbers | DD2: Index Numbers | DE2: Index Numbers | DF2: Index Numbers | DG2: Index Numbers | DH2: Index Numbers | DI2: Index Numbers | DJ2: Index Numbers | DK2: Index Numbers | DL2: Index Numbers | DM2: Index Numbers | DN2: Index Numbers | DO2: Index Numbers | DP2: Index Numbers | DQ2: Index Numbers | DR2: Index Numbers | DS2: Index Numbers | DT2: Index Numbers | DU2: Index Numbers | DV2: Index Numbers | DW2: Index Numbers | DX2: Index Numbers | DY2: Index Numbers | DZ2: Index Numbers | EA2: Index Numbers | EB2: Index Numbers | EC2: Index Numbers | ED2: Index Numbers | EE2: Index Numbers | EF2: Index Numbers | EG2: Index Numbers | EH2: Index Numbers | EI2: Index Numbers | EJ2: Index Numbers | EK2: Index Numbers | EL2: Index Numbers | EM2: Index Numbers | EN2: Index Numbers | EO2: Index Numbers | EP2: Index Numbers | EQ2: Index Numbers | ER2: Index Numbers | ES2: Index Numbers | ET2: Index Numbers | EU2: Index Numbers | EV2: Index Numbers | EW2: Index Numbers | EX2: Index Numbers | EY2: Index Numbers | EZ2: Index Numbers | FA2: Index Numbers | FB2: Index Numbers | FC2: Index Numbers | FD2: Index Numbers | FE2: Index Numbers | FF2: Index Numbers | FG2: Index Numbers | FH2: Index Numbers | FI2: Index Numbers | FJ2: Index Numbers | FK2: Index Numbers | FL2: Index Numbers | FM2: Index Numbers | FN2: Index Numbers | FO2: Index Numbers | FP2: Index Numbers | FQ2: Index Numbers | FR2: Index Numbers | FS2: Index Numbers | FT2: Index Numbers | FU2: Index Numbers | FV2: Index Numbers | FW2: Index Numbers | FX2: Index Numbers | FY2: Index Numbers | FZ2: Index Numbers | GA2: Index Numbers | GB2: Index Numbers | GC2: Index Numbers | GD2: Index Numbers | GE2: Index Numbers | GF2: Index Numbers | GG2: Index Numbers | GH2: Index Numbers | GI2: Index Numbers | GJ2: Index Numbers | GK2: Index Numbers | GL2: Index Numbers | GM2: Index Numbers | GN2: Index Numbers | GO2: Index Numbers | GP2: Index Numbers | GQ2: Index Numbers | GR2: Index Numbers | GS2: Index Numbers | GT2: Index Numbers | GU2: Index Numbers | GV2: Index Numbers | GW2: Index Numbers | GX2: Index Numbers | GY2: Index Numbers | GZ2: Index Numbers | HA2: Index Numbers | HB2: Index Numbers | HC2: Index Numbers | HD2: Index Numbers | HE2: Index Numbers | HF2: Index Numbers | HG2: Index Numbers | HH2: Index Numbers | HI2: Index Numbers | HJ2: Index Numbers | HK2: Index Numbers | HL2: Index Numbers | HM2: Index Numbers | HN2: Index Numbers | HO2: Index Numbers | HP2: Index Numbers | HQ2: Index Numbers | HR2: Index Numbers | HS2: Index Numbers | HT2: Index Numbers | HU2: Index Numbers | HV2: Index Numbers | HW2: Index Numbers | HX2: Index Numbers | HY2: Index Numbers | HZ2: Index Numbers | IA2: Index Numbers | IB2: Index Numbers | IC2: Index Numbers | ID2: Index Numbers | IE2: Index Numbers | IF2: Index Numbers | IG2: Index Numbers | IH2: Index Numbers | II2: Index Numbers | IJ2: Index Numbers | IK2: Index Numbers | IL2: Index Numbers | IM2: Index Numbers | IN2: Index Numbers | IO2: Index Numbers | IP2: Index Numbers | IQ2: Index Numbers
