Workbook
Name A117729353V: Data1!$AV$1:$AV$10,Data1!$AV$143:$AV$241
Name A117729353V_Data: Data1!$AV$143:$AV$241
Name A117729353V_Latest: Data1!$AV$241
Name A2309054F: Data1!$B$1:$B$10,Data1!$B$11:$B$241
Name A2309054F_Data: Data1!$B$11:$B$241
Name A2309054F_Latest: Data1!$B$241
Name A2309055J: Data1!$F$1:$F$10,Data1!$F$12:$F$241
Name A2309055J_Data: Data1!$F$12:$F$241
Name A2309055J_Latest: Data1!$F$241
Name A2309056K: Data1!$I$1:$I$10,Data1!$I$15:$I$241
Name A2309056K_Data: Data1!$I$15:$I$241
Name A2309056K_Latest: Data1!$I$241
Name A2309057L: Data1!$L$1:$L$10,Data1!$L$122:$L$241
Name A2309057L_Data: Data1!$L$122:$L$241
Name A2309057L_Latest: Data1!$L$241
Name A2309060A: Data1!$T$1:$T$10,Data1!$T$122:$T$241
Name A2309060A_Data: Data1!$T$122:$T$241
Name A2309060A_Latest: Data1!$T$241
Name A2309063J: Data1!$U$1:$U$10,Data1!$U$122:$U$241
Name A2309063J_Data: Data1!$U$122:$U$241
Name A2309063J_Latest: Data1!$U$241
Name A2309066R: Data1!$V$1:$V$10,Data1!$V$122:$V$241
Name A2309066R_Data: Data1!$V$122:$V$241
Name A2309066R_Latest: Data1!$V$241
Name A2309069W: Data1!$W$1:$W$10,Data1!$W$122:$W$241
Name A2309069W_Data: Data1!$W$122:$W$241
Name A2309069W_Latest: Data1!$W$241
Name A2309072K: Data1!$X$1:$X$10,Data1!$X$122:$X$241
Name A2309072K_Data: Data1!$X$122:$X$241
Name A2309072K_Latest: Data1!$X$241
Name A2309075T: Data1!$AA$1:$AA$10,Data1!$AA$122:$AA$241
Name A2309075T_Data: Data1!$AA$122:$AA$241
Name A2309075T_Latest: Data1!$AA$241
Name A2309084V: Data1!$AQ$1:$AQ$10,Data1!$AQ$122:$AQ$241
Name A2309084V_Data: Data1!$AQ$122:$AQ$241
Name A2309084V_Latest: Data1!$AQ$241
Name A2309099K: Data1!$O$1:$O$10,Data1!$O$122:$O$241
Name A2309099K_Data: Data1!$O$122:$O$241
Name A2309099K_Latest: Data1!$O$241
Name A2309102L: Data1!$Q$1:$Q$10,Data1!$Q$122:$Q$241
Name A2309102L_Data: Data1!$Q$122:$Q$241
Name A2309102L_Latest: Data1!$Q$241
Name A2309105V: Data1!$R$1:$R$10,Data1!$R$122:$R$241
Name A2309105V_Data: Data1!$R$122:$R$241
Name A2309105V_Latest: Data1!$R$241
Name A2309108A: Data1!$S$1:$S$10,Data1!$S$122:$S$241
Name A2309108A_Data: Data1!$S$122:$S$241
Name A2309108A_Latest: Data1!$S$241
Name A2309126F: Data1!$Y$1:$Y$10,Data1!$Y$122:$Y$241
Name A2309126F_Data: Data1!$Y$122:$Y$241
Name A2309126F_Latest: Data1!$Y$241
Name A2309129L: Data1!$Z$1:$Z$10,Data1!$Z$122:$Z$241
Name A2309129L_Data: Data1!$Z$122:$Z$241
Name A2309129L_Latest: Data1!$Z$241
Name A2309135J: Data1!$AE$1:$AE$10,Data1!$AE$122:$AE$241
Name A2309135J_Data: Data1!$AE$122:$AE$241
Name A2309135J_Latest: Data1!$AE$241
Name A2309138R: Data1!$AC$1:$AC$10,Data1!$AC$122:$AC$241
Name A2309138R_Data: Data1!$AC$122:$AC$241
Name A2309138R_Latest: Data1!$AC$241

Sheet Index
B2: Time Series Workbook
B5: 6427.0 Producer Price Indexes, Australia
B6: Table 13. Inputs from selected Subdivisions and Groups to the Manufacturing Division, index numbers and percentage changes
D8: Enquiries
A10: Data Item Description | D10: Series Type | E10: Series ID | F10: Series Start | G10: Series End | H10: No. Obs. | I10: Unit | J10: Data Type | K10: Freq. | L10: Collection Month
A12: Index Numbers ; Manufacturing division ; | D12: Original | E12: A2309054F | F12: 25082 | G12: 46082 | H12: 231 | I12: Index Numbers | J12: INDEX | K12: Quarter | L12: 3
A13: Index Numbers ; Imported materials ; | D13: Original | E13: A2313785L | F13: 25082 | G13: 46082 | H13: 231 | I13: Index Numbers | J13: INDEX | K13: Quarter | L13: 3
A14: Index Numbers ; Domestic materials ; | D14: Original | E14: A2313788V | F14: 25082 | G14: 46082 | H14: 231 | I14: Index Numbers | J14: INDEX | K14: Quarter | L14: 3
A15: Index Numbers ; Manufact. div. less petroleum ; | D15: Original | E15: A2313704X | F15: 32021 | G15: 46082 | H15: 155 | I15: Index Numbers | J15: INDEX | K15: Quarter | L15: 3
A16: Percentage change from previous quarter ; Manufacturing division ; | D16: Original | E16: A2309055J | F16: 25173 | G16: 46082 | H16: 230 | I16: Percent | J16: PERCENT | K16: Quarter | L16: 3
A17: Percentage change from previous quarter ; Imported materials ; | D17: Original | E17: A2313786R | F17: 25173 | G17: 46082 | H17: 230 | I17: Percent | J17: PERCENT | K17: Quarter | L17: 3
A18: Percentage change from previous quarter ; Domestic materials ; | D18: Original | E18: A2313789W | F18: 25173 | G18: 46082 | H18: 230 | I18: Percent | J18: PERCENT | K18: Quarter | L18: 3
A19: Percentage change from corresponding quarter of previous year ; Manufacturing division ; | D19: Original | E19: A2309056K | F19: 25447 | G19: 46082 | H19: 227 | I19: Percent | J19: PERCENT | K19: Quarter | L19: 3
A20: Percentage change from corresponding quarter of previous year ; Imported materials ; | D20: Original | E20: A2313787T | F20: 25447 | G20: 46082 | H20: 227 | I20: Percent | J20: PERCENT | K20: Quarter | L20: 3
A21: Percentage change from corresponding quarter of previous year ; Domestic materials ; | D21: Original | E21: A2313790F | F21: 25447 | G21: 46082 | H21: 227 | I21: Percent | J21: PERCENT | K21: Quarter | L21: 3
A22: Index Numbers ; Agriculture to Manufacturing ; | D22: Original | E22: A2309057L | F22: 35217 | G22: 46082 | H22: 120 | I22: Index Numbers | J22: INDEX | K22: Quarter | L22: 3
A23: Index Numbers ; Mushroom and vegetable growing ; | D23: Original | E23: A3343966C | F23: 37135 | G23: 46082 | H23: 99 | I23: Index Numbers | J23: INDEX | K23: Quarter | L23: 3
... A73: Index Numbers ; Electricity ; | D73: Original | E73: A2309192C | F73: 25628 | G73: 46082 | H73: 225 | I73: Index Numbers | J73: INDEX | K73: Quarter | L73: 3
A75: © Commonwealth of Australia 2026

Sheet Data1
B1: Index Numbers ; Manufacturing division ; | C1: Index Numbers ; Imported materials ; | D1: Index Numbers ; Domestic materials ; | E1: Index Numbers ; Manufact. div. less petroleum ; | F1: Percentage change from previous quarter ; Manufacturing division ; | G1: Percentage change from previous quarter ; Imported materials ; | H1: Percentage change from previous quarter ; Domestic materials ; | I1: Percentage change from corresponding quarter of previous year ; Manufacturing division ; | J1: Percentage change from corresponding quarter of previous year ; Imported materials ; | K1: Percentage change from corresponding quarter of previous year ; Domestic materials ; | L1: Index Numbers ; Agriculture to Manufacturing ; | M1: Index Numbers ; Mushroom and vegetable growing ; | N1: Index Numbers ; Fruit and tree nut growing ; | O1: Index Numbers ; Sheep, beef cattle and grain farming ; | P1: Index Numbers ; Other crop growing ; | Q1: Index Numbers ; Dairy cattle farming ; | R1: Index Numbers ; Poultry farming ; | S1: Index Numbers ; Other livestock farming ; | T1: Index Numbers ; Forestry and logging ; | U1: Index Numbers ; Coal mining ; | V1: Index Numbers ; Oil and gas extraction ; | W1: Index Numbers ; Metal ore mining ; | X1: Index Numbers ; Non-metallic mineral mining and quarrying ; | Y1: Index Numbers ; Construction material mining ; | Z1: Index Numbers ; Other non-metallic mineral mining and quarrying ; | AA1: Index Numbers ; Textile, leather, clothing and footwear ; | AB1: Index Numbers ; Textiles ; | AC1: Index Numbers ; Leather tanning, fur dressing and leather products ; | AD1: Index Numbers ; Textile products ; | AE1: Index Numbers ; Knitted products ; | AF1: Index Numbers ; Wood products ; | AG1: Index Numbers ; Log sawmilling and timber dressing ; | AH1: Index Numbers ; Other wood products ; | AI1: Index Numbers ; Pulp, paper and converted paper products ; | AJ1: Index Numbers ; Petroleum and coal products ; | AK1: Index Numbers ; Basic chemical and chemical products ; | AL1: Index Numbers ; Basic chemicals ; | AM1: Index Numbers ; Other basic chemical products ; | AN1: Index Numbers ; Polymer product and rubber products ; | AO1: Index Numbers ; Polymer products ; | AP1: Index Numbers ; Natural rubber products ; | AQ1: Index Numbers ; Non-metallic mineral products ; | AR1: Index Numbers ; Glass and glass products ; | AS1: Index Numbers ; Primary metal and metal products ; | AT1: Index Numbers ; Basic ferrous metals ; | AU1: Index Numbers ; Basic ferrous metal products ; | AV1: Index Numbers ; Basic non-ferrous metals ; | AW1: Index Numbers ; Basic non-ferrous metal products ; | AX1: Index Numbers ; Fabricated metal products ; | AY1: Index Numbers ; Transport equipment ; | AZ1: Index Numbers ; Motor vehicles and motor vehicle parts ; | BA1: Index Numbers ; Other transport equipment ; | BB1: Index Numbers ; Machinery and equipment ; | BC1: Index Numbers ; Professional and scientific equipment ; | BD1: Index Numbers ; Computer and electronic equipment ; | BE1: Index Numbers ; Electrical equipment ; | BF1: Index Numbers ; Domestic appliances ; | BG1: Index Numbers ; Pump, compressor, heating and ventilation equipment ; | BH1: Index Numbers ; Specialised machinery and equipment ; | BI1: Index Numbers ; Other machinery and equipment ; | BJ1: Index Numbers ; Natural gas ; | BK1: Index Numbers ; Electricity ;
A2: Unit | B2: Index Numbers | C2: Index Numbers | D2: Index Numbers | E2: Index Numbers | F2: Percent | G2: Percent | H2: Percent | I2: Percent | J2: Percent | K2: Percent | L2: Index Numbers | M2: Index Numbers | N2: Index Numbers | O2: Index Numbers | P2: Index Numbers | Q2: Index Numbers | R2: Index Numbers | S2: Index Numbers | T2: Index Numbers | U2: Index Numbers | V2: Index Numbers | W2: Index Numbers | X2: Index Numbers | Y2: Index Numbers | Z2: Index Numbers | AA2: Index Numbers | AB2: Index Numbers | AC2: Index Numbers | AD2: Index Numbers | AE2: Index Numbers | AF2: Index Numbers | AG2: Index Numbers | AH2: Index Numbers | AI2: Index Numbers | AJ2: Index Numbers | AK2: Index Numbers | AL2: Index Numbers | AM2: Index Numbers | AN2: Index Numbers | AO2: Index Numbers | AP2: Index Numbers | AQ2: Index Numbers | AR2: Index Numbers | AS2: Index Numbers | AT2: Index Numbers | AU2: Index Numbers | AV2: Index Numbers | AW2: Index Numbers | AX2: Index Numbers | AY2: Index Numbers | AZ2: Index Numbers | BA2: Index Numbers | BB2: Index Numbers | BC2: Index Numbers | BD2: Index Numbers | BE2: Index Numbers | BF2: Index Numbers | BG2: Index Numbers | BH2: Index Numbers | BI2: Index Numbers | BJ2: Index Numbers | BK2: Index Numbers
A3: Series Type | B3: Original | C3: Original | D3: Original | E3: Original | F3: Original | G3: Original | H3: Original | I3: Original | J3: Original | K3: Original | L3: Original | M3: Original | N3: Original | O3: Original | P3: Original | Q3: Original | R3: Original | S3: Original | T3: Original | U3: Original | V3: Original | W3: Original | X3: Original | Y3: Original | Z3: Original | AA3: Original | AB3: Original | AC3: Original | AD3: Original | AE3: Original | AF3: Original | AG3: Original | AH3: Original | AI3: Original | AJ3: Original | AK3: Original | AL3: Original | AM3: Original | AN3: Original | AO3: Original | AP3: Original | AQ3: Original | AR3: Original | AS3: Original | AT3: Original | AU3: Original | AV3: Original | AW3: Original | AX3: Original | AY3: Original | AZ3: Original | BA3: Original | BB3: Original | BC3: Original | BD3: Original | BE3: Original | BF3: Original | BG3: Original | BH3: Original | BI3: Original | BJ3: Original | BK3: Original
A4: Data Type | B4: INDEX | C4: INDEX | D4: INDEX | E4: INDEX | F4: PERCENT | G4: PERCENT | H4: PERCENT | I4: PERCENT | J4: PERCENT | K4: PERCENT | L4: INDEX | M4: INDEX | N4: INDEX | O4: INDEX | P4: INDEX | Q4: INDEX | R4: INDEX | S4: INDEX | T4: INDEX | U4: INDEX | V4: INDEX | W4: INDEX | X4: INDEX | Y4: INDEX | Z4: INDEX | AA4: INDEX | AB4: INDEX | AC4: INDEX | AD4: INDEX | AE4: INDEX | AF4: INDEX | AG4: INDEX | AH4: INDEX | AI4: INDEX | AJ4: INDEX | AK4: INDEX | AL4: INDEX | AM4: INDEX | AN4: INDEX | AO4: INDEX | AP4: INDEX | AQ4: INDEX | AR4: INDEX | AS4: INDEX | AT4: INDEX | AU4: INDEX | AV4: INDEX | AW4: INDEX | AX4: INDEX | AY4: INDEX | AZ4: INDEX | BA4: INDEX | BB4: INDEX | BC4: INDEX | BD4: INDEX | BE4: INDEX | BF4: INDEX | BG4: INDEX | BH4: INDEX | BI4: INDEX | BJ4: INDEX | BK4: INDEX
A5: Frequency | B5: Quarter | C5: Quarter | D5: Quarter | E5: Quarter | F5: Quarter | G5: Quarter | H5: Quarter | I5: Quarter | J5: Quarter | K5: Quarter | L5: Quarter | M5: Quarter | N5: Quarter | O5: Quarter | P5: Quarter | Q5: Quarter | R5: Quarter | S5: Quarter | T5: Quarter | U5: Quarter | V5: Quarter | W5: Quarter | X5: Quarter | Y5: Quarter | Z5: Quarter | AA5: Quarter | AB5: Quarter | AC5: Quarter | AD5: Quarter | AE5: Quarter | AF5: Quarter | AG5: Quarter | AH5: Quarter | AI5: Quarter | AJ5: Quarter | AK5: Quarter | AL5: Quarter | AM5: Quarter | AN5: Quarter | AO5: Quarter | AP5: Quarter | AQ5: Quarter | AR5: Quarter | AS5: Quarter | AT5: Quarter | AU5: Quarter | AV5: Quarter | AW5: Quarter | AX5: Quarter | AY5: Quarter | AZ5: Quarter | BA5: Quarter | BB5: Quarter | BC5: Quarter | BD5: Quarter | BE5: Quarter | BF5: Quarter | BG5: Quarter | BH5: Quarter | BI5: Quarter | BJ5: Quarter | BK5: Quarter
A6: Collection Month | B6: 3 | C6: 3 | D6: 3 | E6: 3 | F6: 3 | G6: 3 | H6: 3 | I6: 3 | J6: 3 | K6: 3 | L6: 3 | M6: 3 | N6: 3 | O6: 3 | P6: 3 | Q6: 3 | R6: 3 | S6: 3 | T6: 3 | U6: 3 | V6: 3 | W6: 3 | X6: 3 | Y6: 3 | Z6: 3 | AA6: 3 | AB6: 3 | AC6: 3 | AD6: 3 | AE6: 3 | AF6: 3 | AG6: 3 | AH6: 3 | AI6: 3 | AJ6: 3 | AK6: 3 | AL6: 3 | AM6: 3 | AN6: 3 | AO6: 3 | AP6: 3 | AQ6: 3 | AR6: 3 | AS6: 3 | AT6: 3 | AU6: 3 | AV6: 3 | AW6: 3 | AX6: 3 | AY6: 3 | AZ6: 3 | BA6: 3 | BB6: 3 | BC6: 3 | BD6: 3 | BE6: 3 | BF6: 3 | BG6: 3 | BH6: 3 | BI6: 3 | BJ6: 3 | BK6: 3
A7: Series Start | B7: 25082 | C7: 25082 | D7: 25082 | E7: 32021 | F7: 25173 | G7: 25173 | H7: 25173 | I7: 25447 | J7: 25447 | K7: 25447 | L7: 35217 | M7: 37135 | N7: 37135 | O7: 35217 | P7: 37135 | Q7: 35217 | R7: 35217 | S7: 35217 | T7: 35217 | U7: 35217 | V7: 35217 | W7: 35217 | X7: 35217 | Y7: 35217 | Z7: 35217 | AA7: 35217 | AB7: 37135 | AC7: 35217 | AD7: 37135 | AE7: 35217 | AF7: 37135 | AG7: 35217 | AH7: 35217 | AI7: 35217 | AJ7: 37135 | AK7: 37135 | AL7: 35217 | AM7: 37135 | AN7: 37135 | AO7: 37135 | AP7: 35217 | AQ7: 35217 | AR7: 35217 | AS7: 37135 | AT7: 37135 | AU7: 37135 | AV7: 37135 | AW7: 37135 | AX7: 35217 | AY7: 37135 | AZ7: 35217 | BA7: 35217 | BB7: 37135 | BC7: 35217 | BD7: 35217 | BE7: 37135 | BF7: 37135 | BG7: 37135 | BH7: 37135 | BI7: 37135 | BJ7: 25628 | BK7: 25628
A8: Series End | B8: 46082 | C8: 46082 | D8: 46082 | E8: 46082 | F8: 46082 | G8: 46082 | H8: 46082 | I8: 46082 | J8: 46082 | K8: 46082 | L8: 46082 | M8: 46082 | N8: 46082 | O8: 46082 | P8: 46082 | Q8: 46082 | R8: 46082 | S8: 46082 | T8: 46082 | U8: 46082 | V8: 46082 | W8: 46082 | X8: 46082 | Y8: 46082 | Z8: 46082 | AA8: 46082 | AB8: 46082 | AC8: 46082 | AD8: 46082 | AE8: 46082 | AF8: 46082 | AG8: 46082 | AH8: 46082 | AI8: 46082 | AJ8: 46082 | AK8: 46082 | AL8: 46082 | AM8: 46082 | AN8: 46082 | AO8: 46082 | AP8: 46082 | AQ8: 46082 | AR8: 46082 | AS8: 46082 | AT8: 46082 | AU8: 46082 | AV8: 46082 | AW8: 46082 | AX8: 46082 | AY8: 46082 | AZ8: 46082 | BA8: 46082 | BB8: 46082 | BC8: 46082 | BD8: 46082 | BE8: 46082 | BF8: 46082 | BG8: 46082 | BH8: 46082 | BI8: 46082 | BJ8: 46082 | BK8: 46082
A9: No. Obs | B9: 231 | C9: 231 | D9: 231 | E9: 155 | F9: 230 | G9: 230 | H9: 230 | I9: 227 | J9: 227 | K9: 227 | L9: 120 | M9: 99 | N9: 99 | O9: 120 | P9: 99 | Q9: 120 | R9: 120 | S9: 120 | T9: 120 | U9: 120 | V9: 120 | W9: 120 | X9: 120 | Y9: 120 | Z9: 120 | AA9: 120 | AB9: 99 | AC9: 120 | AD9: 99 | AE9: 120 | AF9: 99 | AG9: 120 | AH9: 120 | AI9: 120 | AJ9: 99 | AK9: 99 | AL9: 120 | AM9: 99 | AN9: 99 | AO9: 99 | AP9: 120 | AQ9: 120 | AR9: 120 | AS9: 99 | AT9: 99 | AU9: 99 | AV9: 99 | AW9: 99 | AX9: 120 | AY9: 99 | AZ9: 120 | BA9: 120 | BB9: 99 | BC9: 120 | BD9: 120 | BE9: 99 | BF9: 99 | BG9: 99 | BH9: 99 | BI9: 99 | BJ9: 225 | BK9: 225
A10: Series ID | B10: A2309054F | C10: A2313785L | D10: A2313788V | E10: A2313704X | F10: A2309055J | G10: A2313786R | H10: A2313789W | I10: A2309056K | J10: A2313787T | K10: A2313790F | L10: A2309057L | M10: A3343966C | N10: A3343968J | O10: A2309099K | P10: A3343970V | Q10: A2309102L | R10: A2309105V | S10: A2309108A | T10: A2309060A | U10: A2309063J | V10: A2309066R | W10: A2309069W | X10: A2309072K | Y10: A2309126F | Z10: A2309129L | AA10: A2309075T | AB10: A3343972X | AC10: A2309138R | AD10: A3343974C | AE10: A2309135J | AF10: A3343976J | AG10: A2309141C | AH10: A2309144K | AI10: A2309147T | AJ10: A3343978L | AK10: A3343980X | AL10: A2309150F | AM10: A3343982C | AN10: A3343984J | AO10: A3343986L | AP10: A2309156V | AQ10: A2309084V | AR10: A2309162R | AS10: A3343988T | AT10: A3343990C | AU10: A3343992J | AV10: A117729353V | AW10: A3343994L | AX10: A2309171T | AY10: A3343996T | AZ10: A2309174X | BA10: A2309177F | BB10: A3343998W | BC10: A2309180V | BD10: A2309183A | BE10: A3344000X | BF10: A3344002C | BG10: A3344004J | BH10: A3344006L | BI10: A3344008T | BJ10: A2309195K | BK10: A2309192C
A11: 25082 | B11: 10.7 | C11: 9.9 | D11: 10.9
A12: 25173 | B12: 10.3 | C12: 9.8 | D12: 10.5 | F12: -3.7 | G12: -1 | H12: -3.7
A13: 25263 | B13: 10.5 | C13: 9.9 | D13: 10.7 | F13: 1.9 | G13: 1 | H13: 1.9
A14: 25355 | B14: 10.8 | C14: 9.9 | D14: 11 | F14: 2.9 | G14: 0 | H14: 2.8
A15: 25447 | B15: 10.9 | C15: 9.9 | D15: 11.2 | F15: 0.9 | G15: 0 | H15: 1.8 | I15: 1.9 | J15: 0 | K15: 2.8
A16: 25538 | B16: 10.7 | C16: 9.9 | D16: 11 | F16: -1.8 | G16: 0 | H16: -1.8 | I16: 3.9 | J16: 1 | K16: 4.8
A17: 25628 | B17: 10.8 | C17: 9.9 | D17: 11.1 | F17: 0.9 | G17: 0 | H17: 0.9 | I17: 2.9 | J17: 0 | K17: 3.7 | BJ17: 17.9 | BK17: 11.8
A18: 25720 | B18: 10.9 | C18: 9.9 | D18: 11.2 | F18: 0.9 | G18: 0 | H18: 0.9 | I18: 0.9 | J18: 0 | K18: 1.8 | BJ18: 15.6 | BK18: 12
A19: 25812 | B19: 10.7 | C19: 9.9 | D19: 10.9 | F19: -1.8 | G19: 0 | H19: -2.7 | I19: -1.8 | J19: 0 | K19: -2.7 | BJ19: 14.7 | BK19: 12.3
A20: 25903 | B20: 10.4 | C20: 10 | D20: 10.5 | F20: -2.8 | G20: 1 | H20: -3.7 | I20: -2.8 | J20: 1 | K20: -4.5 | BJ20: 13.7 | BK20: 12.2
A21: 25993 | B21: 10.6 | C21: 10.2 | D21: 10.6 | F21: 1.9 | G21: 2 | H21: 1 | I21: -1.9 | J21: 3 | K21: -4.5 | BJ21: 12.9 | BK21: 12.2
A22: 26085 | B22: 10.7 | C22: 10.3 | D22: 10.8 | F22: 0.9 | G22: 1 | H22: 1.9 | I22: -1.8 | J22: 4 | K22: -3.6 | BJ22: 12.7 | BK22: 12.2
A23: 26177 | B23: 11 | C23: 10.3 | D23: 11.2 | F23: 2.8 | G23: 0 | H23: 3.7 | I23: 2.8 | J23: 4 | K23: 2.8 | BJ23: 13 | BK23: 12.4
A24: 26268 | B24: 10.7 | C24: 10.3 | D24: 10.8 | F24: -2.7 | G24: 0 | H24: -3.6 | I24: 2.9 | J24: 3 | K24: 2.9 | BJ24: 12.1 | BK24: 12.4
A25: 26359 | B25: 10.8 | C25: 10.2 | D25: 11 | F25: 0.9 | G25: -1 | H25: 1.9 | I25: 1.9 | J25: 0 | K25: 3.8 | BJ25: 12.1 | BK25: 12.7
A26: 26451 | B26: 10.9 | C26: 10.3 | D26: 11 | F26: 0.9 | G26: 1 | H26: 0 | I26: 1.9 | J26: 0 | K26: 1.9 | BJ26: 11.3 | BK26: 12.5
A27: 26543 | B27: 11.5 | C27: 10.3 | D27: 11.8 | F27: 5.5 | G27: 0 | H27: 7.3 | I27: 4.5 | J27: 0 | K27: 5.4 | BJ27: 11.6 | BK27: 12.8
A28: 26634 | B28: 11.5 | C28: 10.5 | D28: 11.9 | F28: 0 | G28: 1.9 | H28: 0.8 | I28: 7.5 | J28: 1.9 | K28: 10.2 | BJ28: 10.9 | BK28: 12.6
... A86: 31929 | B86: 48.3 | C86: 59.6 | D86: 43.2 | F86: 0.4 | G86: -1.5 | H86: 1.4 | I86: 14.5 | J86: 10.2 | K86: 17.1 | BJ86: 43.7 | BK86: 48.2
A87: 32021 | B87: 48.8 | C87: 59.8 | D87: 44 | E87: 52.5 | F87: 1 | G87: 0.3 | H87: 1.9 | I87: 8.9 | J87: 1.9 | K87: 14 | BJ87: 42.9 | BK87: 49.8
A88: 32112 | B88: 49.1 | C88: 61 | D88: 43.9 | E88: 53.1 | F88: 0.6 | G88: 2 | H88: -0.2 | I88: 4.5 | J88: 1.7 | K88: 6.6 | BJ88: 44.7 | BK88: 49.9
A89: 32203 | B89: 50.1 | C89: 62 | D89: 44.8 | E89: 55.1 | F89: 2 | G89: 1.6 | H89: 2.1 | I89: 4.2 | J89: 2.5 | K89: 5.2 | BJ89: 45.5 | BK89: 49.9
A90: 32295 | B90: 50.6 | C90: 61.2 | D90: 45.9 | E90: 56.6 | F90: 1 | G90: -1.3 | H90: 2.5 | I90: 4.8 | J90: 2.7 | K90: 6.3 | BJ90: 45.4 | BK90: 50.5
A91: 32387 | B91: 50 | C91: 59.8 | D91: 45.8 | E91: 56.9 | F91: -1.2 | G91: -2.3 | H91: -0.2 | I91: 2.5 | J91: 0 | K91: 4.1 | BJ91: 47.4 | BK91: 52.4
A92: 32478 | B92: 48.7 | C92: 58.2 | D92: 44.5 | E92: 56.9 | F92: -2.6 | G92: -2.7 | H92: -2.8 | I92: -0.8 | J92: -4.6 | K92: 1.4 | BJ92: 48.7 | BK92: 52.5
A93: 32568 | B93: 50 | C93: 58.1 | D93: 46.5 | E93: 56.9 | F93: 2.7 | G93: -0.2 | H93: 4.5 | I93: -0.2 | J93: -6.3 | K93: 3.8 | BJ93: 49.7 | BK93: 52.8
A94: 32660 | B94: 52.9 | C94: 61 | D94: 49.3 | E94: 59.3 | F94: 5.8 | G94: 5 | H94: 6 | I94: 4.5 | J94: -0.3 | K94: 7.4 | BJ94: 49.9 | BK94: 53
A95: 32752 | B95: 53 | C95: 61.7 | D95: 49.2 | E95: 59.2 | F95: 0.2 | G95: 1.1 | H95: -0.2 | I95: 6 | J95: 3.2 | K95: 7.4 | BJ95: 53.2 | BK95: 54.8
A96: 32843 | B96: 52.6 | C96: 61 | D96: 48.9 | E96: 58.5 | F96: -0.8 | G96: -1.1 | H96: -0.6 | I96: 8 | J96: 4.8 | K96: 9.9 | BJ96: 53.3 | BK96: 54.9
A97: 32933 | B97: 53.7 | C97: 62.2 | D97: 50 | E97: 59.2 | F97: 2.1 | G97: 2 | H97: 2.2 | I97: 7.4 | J97: 7.1 | K97: 7.5 | BJ97: 53.6 | BK97: 55.3
...

Sheet Enquiries
B2: Time Series Workbook
B5: 6427.0 Producer Price Indexes, Australia
B6: Table 13. Inputs from selected Subdivisions and Groups to the Manufacturing Division, index numbers and percentage changes
B10: E N Q U I R I E S
B11: For further information about these and related statistics visit www.abs.gov.au/about/contact-us

Sheet Summary Stats
A1: Energy Prices vs Manufacturing Input Costs — Summary Statistics
A2: Source: ABS 6427.0 Producer Price Indexes, Australia — Table 13. Inputs from selected Subdivisions and Groups to the Manufacturing Division. Index reference period 2011-12 = 100.0.
A3: Window: full series. Manufacturing/Imported/Domestic from Sep 1968; Less-petroleum from Mar 1988; Natural gas & Electricity from Mar 1970; Petroleum & coal from Sep 2001. Latest = Sep 2025.
A5: Series | B5: Latest (2025-Q3) | C5: First (start of series) | D5: Min | E5: Max | F5: Mean | G5: Median | H5: Std Dev | I5: Coeff. of Var. | J5: Total change | K5: Annualised %
A6: Manufacturing division (all inputs) | B6: =Data1!B241 -> 173.4 | C6: {=INDEX(Data1!B11:B241,MATCH(TRUE,INDEX(Data1!B11:B241<>"",0),0))} -> 10.7 | D6: =MIN(Data1!B11:B241) -> 10.3 | E6: =MAX(Data1!B11:B241) -> 173.4 | F6: =AVERAGE(Data1!B11:B241) -> 67.751948 | G6: =MEDIAN(Data1!B11:B241) -> 59 | H6: =STDEV(Data1!B11:B241) -> 38.902208 | I6: =H6/F6 -> 0.57418583 | J6: =B6/C6-1 -> 15.205607 | K6: =(B6/C6)^(4/(COUNT(Data1!B11:B241)-1))-1 -> 0.049633438
A7: Imported materials | B7: =Data1!C241 -> 182.4 | C7: {=INDEX(Data1!C11:C241,MATCH(TRUE,INDEX(Data1!C11:C241<>"",0),0))} -> 9.9 | D7: =MIN(Data1!C11:C241) -> 9.8 | E7: =MAX(Data1!C11:C241) -> 182.4 | F7: =AVERAGE(Data1!C11:C241) -> 76.468831 | G7: =MEDIAN(Data1!C11:C241) -> 73.7 | H7: =STDEV(Data1!C11:C241) -> 42.522634 | I7: =H7/F7 -> 0.55607799 | J7: =B7/C7-1 -> 17.424242 | K7: =(B7/C7)^(4/(COUNT(Data1!C11:C241)-1))-1 -> 0.051978288
A8: Domestic materials | B8: =Data1!D241 -> 172.9 | C8: {=INDEX(Data1!D11:D241,MATCH(TRUE,INDEX(Data1!D11:D241<>"",0),0))} -> 10.9 | D8: =MIN(Data1!D11:D241) -> 10.5 | E8: =MAX(Data1!D11:D241) -> 172.9 | F8: =AVERAGE(Data1!D11:D241) -> 65.219481 | G8: =MEDIAN(Data1!D11:D241) -> 53.5 | H8: =STDEV(Data1!D11:D241) -> 38.755156 | I8: =H8/F8 -> 0.59422669 | J8: =B8/C8-1 -> 14.862385 | K8: =(B8/C8)^(4/(COUNT(Data1!D11:D241)-1))-1 -> 0.049242742
A9: Manufact. div. less petroleum | B9: =Data1!E241 -> 179.3 | C9: {=INDEX(Data1!E11:E241,MATCH(TRUE,INDEX(Data1!E11:E241<>"",0),0))} -> 52.5 | D9: =MIN(Data1!E11:E241) -> 52.5 | E9: =MAX(Data1!E11:E241) -> 179.3 | F9: =AVERAGE(Data1!E11:E241) -> 91.136129 | G9: =MEDIAN(Data1!E11:E241) -> 87.9 | H9: =STDEV(Data1!E11:E241) -> 29.382712 | I9: =H9/F9 -> 0.32240465 | J9: =B9/C9-1 -> 2.4152381 | K9: =(B9/C9)^(4/(COUNT(Data1!E11:E241)-1))-1 -> 0.032416866
A10: Petroleum and coal products | B10: =Data1!AJ241 -> 132.6 | C10: {=INDEX(Data1!AJ11:AJ241,MATCH(TRUE,INDEX(Data1!AJ11:AJ241<>"",0),0))} -> 63.4 | D10: =MIN(Data1!AJ11:AJ241) -> 58.2 | E10: =MAX(Data1!AJ11:AJ241) -> 134.3 | F10: =AVERAGE(Data1!AJ11:AJ241) -> 94.412121 | G10: =MEDIAN(Data1!AJ11:AJ241) -> 96 | H10: =STDEV(Data1!AJ11:AJ241) -> 20.881953 | I10: =H10/F10 -> 0.22117873 | J10: =B10/C10-1 -> 1.0914826 | K10: =(B10/C10)^(4/(COUNT(Data1!AJ11:AJ241)-1))-1 -> 0.030575387
A11: Natural gas | B11: =Data1!BJ241 -> 187.3 | C11: {=INDEX(Data1!BJ11:BJ241,MATCH(TRUE,INDEX(Data1!BJ11:BJ241<>"",0),0))} -> 17.9 | D11: =MIN(Data1!BJ11:BJ241) -> 10.9 | E11: =MAX(Data1!BJ11:BJ241) -> 198.2 | F11: =AVERAGE(Data1!BJ11:BJ241) -> 68.301333 | G11: =MEDIAN(Data1!BJ11:BJ241) -> 58.1 | H11: =STDEV(Data1!BJ11:BJ241) -> 47.104618 | I11: =H11/F11 -> 0.68965884 | J11: =B11/C11-1 -> 9.4636872 | K11: =(B11/C11)^(4/(COUNT(Data1!BJ11:BJ241)-1))-1 -> 0.04281833
A12: Electricity | B12: =Data1!BK241 -> 152.2 | C12: {=INDEX(Data1!BK11:BK241,MATCH(TRUE,INDEX(Data1!BK11:BK241<>"",0),0))} -> 11.8 | D12: =MIN(Data1!BK11:BK241) -> 11.8 | E12: =MAX(Data1!BK11:BK241) -> 167.7 | F12: =AVERAGE(Data1!BK11:BK241) -> 70.170222 | G12: =MEDIAN(Data1!BK11:BK241) -> 59 | H12: =STDEV(Data1!BK11:BK241) -> 44.257609 | I12: =H12/F12 -> 0.63071781 | J12: =B12/C12-1 -> 11.898305 | K12: =(B12/C12)^(4/(COUNT(Data1!BK11:BK241)-1))-1 -> 0.046721007
A14: Year-on-year % change statistics
A15: YoY = current quarter index ÷ same quarter prior year − 1.
A17: Series | B17: Latest YoY | C17: Mean YoY | D17: Median YoY | E17: Min YoY | F17: Max YoY | G17: Std Dev (YoY) | H17: Qtrs YoY > 5% | I17: Qtrs YoY > 10%
A18: Manufacturing division (all inputs) | B18: =Data1!B241/Data1!B237-1 -> 0.11583012 | C18: {=AVERAGE(IFERROR(Data1!B15:B241/Data1!B11:B237-1,""))} -> 0.052178774 | D18: {=MEDIAN(IFERROR(Data1!B15:B241/Data1!B11:B237-1,""))} -> 0.040201005 | E18: {=MIN(IFERROR(Data1!B15:B241/Data1!B11:B237-1,""))} -> -0.13489736 | F18: {=MAX(IFERROR(Data1!B15:B241/Data1!B11:B237-1,""))} -> 0.37899543 | G18: {=STDEV(IFERROR(Data1!B15:B241/Data1!B11:B237-1,""))} -> 0.076699284 | H18: {=SUMPRODUCT((Data1!B15:B241/Data1!B11:B237-1>0.05)*1)} -> 97 | I18: {=SUMPRODUCT((Data1!B15:B241/Data1!B11:B237-1>0.1)*1)} -> 48
A19: Imported materials | B19: =Data1!C241/Data1!C237-1 -> 0.065420561 | C19: {=AVERAGE(IFERROR(Data1!C15:C241/Data1!C11:C237-1,""))} -> 0.056786888 | D19: {=MEDIAN(IFERROR(Data1!C15:C241/Data1!C11:C237-1,""))} -> 0.033730159 | E19: {=MIN(IFERROR(Data1!C15:C241/Data1!C11:C237-1,""))} -> -0.16348548 | F19: {=MAX(IFERROR(Data1!C15:C241/Data1!C11:C237-1,""))} -> 0.59821429 | G19: {=STDEV(IFERROR(Data1!C15:C241/Data1!C11:C237-1,""))} -> 0.10581735 | H19: {=SUMPRODUCT((Data1!C15:C241/Data1!C11:C237-1>0.05)*1)} -> 94 | I19: {=SUMPRODUCT((Data1!C15:C241/Data1!C11:C237-1>0.1)*1)} -> 50
A20: Domestic materials | B20: =Data1!D241/Data1!D237-1 -> 0.13302752 | C20: {=AVERAGE(IFERROR(Data1!D15:D241/Data1!D11:D237-1,""))} -> 0.052283805 | D20: {=MEDIAN(IFERROR(Data1!D15:D241/Data1!D11:D237-1,""))} -> 0.040909091 | E20: {=MIN(IFERROR(Data1!D15:D241/Data1!D11:D237-1,""))} -> -0.17449664 | F20: {=MAX(IFERROR(Data1!D15:D241/Data1!D11:D237-1,""))} -> 0.5 | G20: {=STDEV(IFERROR(Data1!D15:D241/Data1!D11:D237-1,""))} -> 0.085635624 | H20: {=SUMPRODUCT((Data1!D15:D241/Data1!D11:D237-1>0.05)*1)} -> 97 | I20: {=SUMPRODUCT((Data1!D15:D241/Data1!D11:D237-1>0.1)*1)} -> 45
A21: Manufact. div. less petroleum | B21: =Data1!E241/Data1!E237-1 -> 0.12343358 | C21: {=AVERAGE(IFERROR(Data1!E15:E241/Data1!E11:E237-1,""))} -> 0.031865449 | D21: {=MEDIAN(IFERROR(Data1!E15:E241/Data1!E11:E237-1,""))} -> 0.030573248 | E21: {=MIN(IFERROR(Data1!E15:E241/Data1!E11:E237-1,""))} -> -0.1352657 | F21: {=MAX(IFERROR(Data1!E15:E241/Data1!E11:E237-1,""))} -> 0.16256158 | G21: {=STDEV(IFERROR(Data1!E15:E241/Data1!E11:E237-1,""))} -> 0.050195464 | H21: {=SUMPRODUCT(--(IFERROR(Data1!E15:E241/Data1!E11:E237-1,0)>0.05))} -> 45 | I21: {=SUMPRODUCT(--(IFERROR(Data1!E15:E241/Data1!E11:E237-1,0)>0.1))} -> 12
A22: Petroleum and coal products | B22: =Data1!AJ241/Data1!AJ237-1 -> 0.0075987842 | C22: {=AVERAGE(IFERROR(Data1!AJ15:AJ241/Data1!AJ11:AJ237-1,""))} -> 0.034410791 | D22: {=MEDIAN(IFERROR(Data1!AJ15:AJ241/Data1!AJ11:AJ237-1,""))} -> 0.030732861 | E22: {=MIN(IFERROR(Data1!AJ15:AJ241/Data1!AJ11:AJ237-1,""))} -> -0.1119334 | F22: {=MAX(IFERROR(Data1!AJ15:AJ241/Data1!AJ11:AJ237-1,""))} -> 0.21869328 | G22: {=STDEV(IFERROR(Data1!AJ15:AJ241/Data1!AJ11:AJ237-1,""))} -> 0.079251556 | H22: {=SUMPRODUCT(--(IFERROR(Data1!AJ15:AJ241/Data1!AJ11:AJ237-1,0)>0.05))} -> 40 | I22: {=SUMPRODUCT(--(IFERROR(Data1!AJ15:AJ241/Data1!AJ11:AJ237-1,0)>0.1))} -> 21
A23: Natural gas | B23: =Data1!BJ241/Data1!BJ237-1 -> -0.012130802 | C23: {=AVERAGE(IFERROR(Data1!BJ15:BJ241/Data1!BJ11:BJ237-1,""))} -> 0.051789556 | D23: {=MEDIAN(IFERROR(Data1!BJ15:BJ241/Data1!BJ11:BJ237-1,""))} -> 0.029471545 | E23: {=MIN(IFERROR(Data1!BJ15:BJ241/Data1!BJ11:BJ237-1,""))} -> -0.27932961 | F23: {=MAX(IFERROR(Data1!BJ15:BJ241/Data1!BJ11:BJ237-1,""))} -> 0.48291572 | G23: {=STDEV(IFERROR(Data1!BJ15:BJ241/Data1!BJ11:BJ237-1,""))} -> 0.11070261 | H23: {=SUMPRODUCT(--(IFERROR(Data1!BJ15:BJ241/Data1!BJ11:BJ237-1,0)>0.05))} -> 96 | I23: {=SUMPRODUCT(--(IFERROR(Data1!BJ15:BJ241/Data1!BJ11:BJ237-1,0)>0.1))} -> 49
A24: Electricity | B24: =Data1!BK241/Data1!BK237-1 -> -0.025608195 | C24: {=AVERAGE(IFERROR(Data1!BK15:BK241/Data1!BK11:BK237-1,""))} -> 0.049794662 | D24: {=MEDIAN(IFERROR(Data1!BK15:BK241/Data1!BK11:BK237-1,""))} -> 0.04379562 | E24: {=MIN(IFERROR(Data1!BK15:BK241/Data1!BK11:BK237-1,""))} -> -0.16594695 | F24: {=MAX(IFERROR(Data1!BK15:BK241/Data1!BK11:BK237-1,""))} -> 0.4265233 | G24: {=STDEV(IFERROR(Data1!BK15:BK241/Data1!BK11:BK237-1,""))} -> 0.077511008 | H24: {=SUMPRODUCT(--(IFERROR(Data1!BK15:BK241/Data1!BK11:BK237-1,0)>0.05))} -> 94 | I24: {=SUMPRODUCT(--(IFERROR(Data1!BK15:BK241/Data1!BK11:BK237-1,0)>0.1))} -> 40
A26: Correlation matrix — quarterly YoY % changes
A27: Pearson correlation of year-on-year % changes. Window: Mar 1970 onward (energy series start) except Petroleum & coal (from Sep 2001).
B29: Mfg division | C29: Imported mat. | D29: Domestic mat. | E29: Less petroleum | F29: Petroleum & coal | G29: Natural gas | H29: Electricity
A30: Mfg division | B30: 1 | C30: {=CORREL(Data1!B21:B241/Data1!B17:B237-1,Data1!C21:C241/Data1!C17:C237-1)} -> 0.713655 | D30: {=CORREL(Data1!B21:B241/Data1!B17:B237-1,Data1!D21:D241/Data1!D17:D237-1)} -> 0.93775327 | E30: {=CORREL(Data1!B91:B241/Data1!B87:B237-1,Data1!E91:E241/Data1!E87:E237-1)} -> 0.88124652 | F30: {=CORREL(Data1!B147:B241/Data1!B143:B237-1,Data1!AJ147:AJ241/Data1!AJ143:AJ237-1)} -> 0.71990912 | G30: {=CORREL(Data1!B21:B241/Data1!B17:B237-1,Data1!BJ21:BJ241/Data1!BJ17:BJ237-1)} -> 0.063430131 | H30: {=CORREL(Data1!B21:B241/Data1!B17:B237-1,Data1!BK21:BK241/Data1!BK17:BK237-1)} -> 0.11654782
A31: Imported materials | C31: 1 | D31: {=CORREL(Data1!C21:C241/Data1!C17:C237-1,Data1!D21:D241/Data1!D17:D237-1)} -> 0.43560891 | E31: {=CORREL(Data1!C91:C241/Data1!C87:C237-1,Data1!E91:E241/Data1!E87:E237-1)} -> 0.81188173 | F31: {=CORREL(Data1!C147:C241/Data1!C143:C237-1,Data1!AJ147:AJ241/Data1!AJ143:AJ237-1)} -> 0.81722625 | G31: {=CORREL(Data1!C21:C241/Data1!C17:C237-1,Data1!BJ21:BJ241/Data1!BJ17:BJ237-1)} -> 0.16861052 | H31: {=CORREL(Data1!C21:C241/Data1!C17:C237-1,Data1!BK21:BK241/Data1!BK17:BK237-1)} -> 0.24229814
A32: Domestic materials | D32: 1 | E32: {=CORREL(Data1!D91:D241/Data1!D87:D237-1,Data1!E91:E241/Data1!E87:E237-1)} -> 0.84293828 | F32: {=CORREL(Data1!D147:D241/Data1!D143:D237-1,Data1!AJ147:AJ241/Data1!AJ143:AJ237-1)} -> 0.60216118 | G32: {=CORREL(Data1!D21:D241/Data1!D17:D237-1,Data1!BJ21:BJ241/Data1!BJ17:BJ237-1)} -> 0.0053687243 | H32: {=CORREL(Data1!D21:D241/Data1!D17:D237-1,Data1!BK21:BK241/Data1!BK17:BK237-1)} -> 0.029744895
A33: Less petroleum | E33: 1 | F33: {=CORREL(Data1!E147:E241/Data1!E143:E237-1,Data1!AJ147:AJ241/Data1!AJ143:AJ237-1)} -> 0.49524101 | G33: {=CORREL(Data1!E91:E241/Data1!E87:E237-1,Data1!BJ91:BJ241/Data1!BJ87:BJ237-1)} -> 0.093321342 | H33: {=CORREL(Data1!E91:E241/Data1!E87:E237-1,Data1!BK91:BK241/Data1!BK87:BK237-1)} -> -0.017852671
A34: Petroleum & coal | F34: 1 | G34: {=CORREL(Data1!AJ147:AJ241/Data1!AJ143:AJ237-1,Data1!BJ147:BJ241/Data1!BJ143:BJ237-1)} -> 0.34066757 | H34: {=CORREL(Data1!AJ147:AJ241/Data1!AJ143:AJ237-1,Data1!BK147:BK241/Data1!BK143:BK237-1)} -> 0.37652415
A35: Natural gas | G35: 1 | H35: {=CORREL(Data1!BJ21:BJ241/Data1!BJ17:BJ237-1,Data1!BK21:BK241/Data1!BK17:BK237-1)} -> 0.54215359
A36: Electricity | H36: 1
A40: What the numbers show:
A41: Natural gas is the most volatile input cost (CV 69%, YoY std dev 11.1%, and 49 quarters with YoY >10% — the worst spike was +48% YoY).
A42: Electricity has grown +1190% since 1970, slightly faster than the Manufacturing division (+1521% since 1968) — but with much more volatility (CV 63% vs 57%).
A43: YoY correlation with overall manufacturing inputs: Natural gas 0.06, Electricity 0.12 — surprisingly weak at the headline level. Petroleum & coal is far more co-moving (0.72), which is why excluding petroleum (the "Manufact. div. less petroleum" series) materially smooths the headline.
A44: In the latest quarter (Sep-2025), headline manufacturing inputs rose +11.6% YoY while Electricity (-2.6%) and Natural gas (-1.2%) actually fell — the input-cost pressure right now is coming from non-energy sources.

Sheet Charts
A1: Energy Prices vs Manufacturing Input Costs — Time Series
A2: Source: ABS 6427.0 PPI Table 13. Index reference period 2011-12 = 100.0. Quarterly data, Sep 1968 to Sep 2025.
A50: Chart data block (linked to Data1)
A51: Quarter | B51: Manufacturing division | C51: Mfg. less petroleum | D51: Petroleum & coal | E51: Natural gas | F51: Electricity | H51: Quarter | I51: Manufacturing division | J51: Mfg. less petroleum | K51: Petroleum & coal | L51: Natural gas | M51: Electricity | O51: Quarter | P51: Manufacturing division | Q51: Mfg. less petroleum | R51: Petroleum & coal | S51: Natural gas | T51: Electricity
A52: =Data1!A11 -> 25082 | B52: =IF(ISBLANK(Data1!B11),NA(),Data1!B11) -> 10.7 | C52: =IF(ISBLANK(Data1!E11),NA(),Data1!E11) -> #N/A | D52: =IF(ISBLANK(Data1!AJ11),NA(),Data1!AJ11) -> #N/A | E52: =IF(ISBLANK(Data1!BJ11),NA(),Data1!BJ11) -> #N/A | F52: =IF(ISBLANK(Data1!BK11),NA(),Data1!BK11) -> #N/A | H52: =A52 -> 25082 | I52: =IF(ISNA(B52),NA(),B52/$B$58*100) -> 99.074074 | J52: {=IF(ISNA(C52),NA(),C52/INDEX($C$52:$C$282,MATCH(TRUE,INDEX(NOT(ISNA($C$52:$C$282)),0),0))*100)} -> #N/A | K52: {=IF(ISNA(D52),NA(),D52/INDEX($D$52:$D$282,MATCH(TRUE,INDEX(NOT(ISNA($D$52:$D$282)),0),0))*100)} -> #N/A | L52: =IF(ISNA(E52),NA(),E52/$E$58*100) -> #N/A | M52: =IF(ISNA(F52),NA(),F52/$F$58*100) -> #N/A | O52: =A52 -> 25082 | P52: #N/A | Q52: #N/A | R52: #N/A | S52: #N/A | T52: #N/A
A53: =Data1!A12 -> 25173 | B53: =IF(ISBLANK(Data1!B12),NA(),Data1!B12) -> 10.3 | C53: =IF(ISBLANK(Data1!E12),NA(),Data1!E12) -> #N/A | D53: =IF(ISBLANK(Data1!AJ12),NA(),Data1!AJ12) -> #N/A | E53: =IF(ISBLANK(Data1!BJ12),NA(),Data1!BJ12) -> #N/A | F53: =IF(ISBLANK(Data1!BK12),NA(),Data1!BK12) -> #N/A | H53: =A53 -> 25173 | I53: =IF(ISNA(B53),NA(),B53/$B$58*100) -> 95.37037 | J53: {=IF(ISNA(C53),NA(),C53/INDEX($C$52:$C$282,MATCH(TRUE,INDEX(NOT(ISNA($C$52:$C$282)),0),0))*100)} -> #N/A | K53: {=IF(ISNA(D53),NA(),D53/INDEX($D$52:$D$282,MATCH(TRUE,INDEX(NOT(ISNA($D$52:$D$282)),0),0))*100)} -> #N/A | L53: =IF(ISNA(E53),NA(),E53/$E$58*100) -> #N/A | M53: =IF(ISNA(F53),NA(),F53/$F$58*100) -> #N/A | O53: =A53 -> 25173 | P53: #N/A | Q53: #N/A | R53: #N/A | S53: #N/A | T53: #N/A
A54: =Data1!A13 -> 25263 | B54: =IF(ISBLANK(Data1!B13),NA(),Data1!B13) -> 10.5 | C54: =IF(ISBLANK(Data1!E13),NA(),Data1!E13) -> #N/A | D54: =IF(ISBLANK(Data1!AJ13),NA(),Data1!AJ13) -> #N/A | E54: =IF(ISBLANK(Data1!BJ13),NA(),Data1!BJ13) -> #N/A | F54: =IF(ISBLANK(Data1!BK13),NA(),Data1!BK13) -> #N/A | H54: =A54 -> 25263 | I54: =IF(ISNA(B54),NA(),B54/$B$58*100) -> 97.222222 | J54: {=IF(ISNA(C54),NA(),C54/INDEX($C$52:$C$282,MATCH(TRUE,INDEX(NOT(ISNA($C$52:$C$282)),0),0))*100)} -> #N/A | K54: {=IF(ISNA(D54),NA(),D54/INDEX($D$52:$D$282,MATCH(TRUE,INDEX(NOT(ISNA($D$52:$D$282)),0),0))*100)} -> #N/A | L54: =IF(ISNA(E54),NA(),E54/$E$58*100) -> #N/A | M54: =IF(ISNA(F54),NA(),F54/$F$58*100) -> #N/A | O54: =A54 -> 25263 | P54: #N/A | Q54: #N/A | R54: #N/A | S54: #N/A | T54: #N/A
A55: =Data1!A14 -> 25355 | B55: =IF(ISBLANK(Data1!B14),NA(),Data1!B14) -> 10.8 | C55: =IF(ISBLANK(Data1!E14),NA(),Data1!E14) -> #N/A | D55: =IF(ISBLANK(Data1!AJ14),NA(),Data1!AJ14) -> #N/A | E55: =IF(ISBLANK(Data1!BJ14),NA(),Data1!BJ14) -> #N/A | F55: =IF(ISBLANK(Data1!BK14),NA(),Data1!BK14) -> #N/A | H55: =A55 -> 25355 | I55: =IF(ISNA(B55),NA(),B55/$B$58*100) -> 100 | J55: {=IF(ISNA(C55),NA(),C55/INDEX($C$52:$C$282,MATCH(TRUE,INDEX(NOT(ISNA($C$52:$C$282)),0),0))*100)} -> #N/A | K55: {=IF(ISNA(D55),NA(),D55/INDEX($D$52:$D$282,MATCH(TRUE,INDEX(NOT(ISNA($D$52:$D$282)),0),0))*100)} -> #N/A | L55: =IF(ISNA(E55),NA(),E55/$E$58*100) -> #N/A | M55: =IF(ISNA(F55),NA(),F55/$F$58*100) -> #N/A | O55: =A55 -> 25355 | P55: #N/A | Q55: #N/A | R55: #N/A | S55: #N/A | T55: #N/A
A56: =Data1!A15 -> 25447 | B56: =IF(ISBLANK(Data1!B15),NA(),Data1!B15) -> 10.9 | C56: =IF(ISBLANK(Data1!E15),NA(),Data1!E15) -> #N/A | D56: =IF(ISBLANK(Data1!AJ15),NA(),Data1!AJ15) -> #N/A | E56: =IF(ISBLANK(Data1!BJ15),NA(),Data1!BJ15) -> #N/A | F56: =IF(ISBLANK(Data1!BK15),NA(),Data1!BK15) -> #N/A | H56: =A56 -> 25447 | I56: =IF(ISNA(B56),NA(),B56/$B$58*100) -> 100.92593 | J56: {=IF(ISNA(C56),NA(),C56/INDEX($C$52:$C$282,MATCH(TRUE,INDEX(NOT(ISNA($C$52:$C$282)),0),0))*100)} -> #N/A | K56: {=IF(ISNA(D56),NA(),D56/INDEX($D$52:$D$282,MATCH(TRUE,INDEX(NOT(ISNA($D$52:$D$282)),0),0))*100)} -> #N/A | L56: =IF(ISNA(E56),NA(),E56/$E$58*100) -> #N/A | M56: =IF(ISNA(F56),NA(),F56/$F$58*100) -> #N/A | O56: =A56 -> 25447 | P56: =IFERROR(IF(OR(ISNA(B56),ISNA(B52)),NA(),B56/B52-1),NA()) -> 0.018691589 | Q56: =IFERROR(IF(OR(ISNA(C56),ISNA(C52)),NA(),C56/C52-1),NA()) -> #N/A | R56: =IFERROR(IF(OR(ISNA(D56),ISNA(D52)),NA(),D56/D52-1),NA()) -> #N/A | S56: =IFERROR(IF(OR(ISNA(E56),ISNA(E52)),NA(),E56/E52-1),NA()) -> #N/A | T56: =IFERROR(IF(OR(ISNA(F56),ISNA(F52)),NA(),F56/F52-1),NA()) -> #N/A
A57: =Data1!A16 -> 25538 | B57: =IF(ISBLANK(Data1!B16),NA(),Data1!B16) -> 10.7 | C57: =IF(ISBLANK(Data1!E16),NA(),Data1!E16) -> #N/A | D57: =IF(ISBLANK(Data1!AJ16),NA(),Data1!AJ16) -> #N/A | E57: =IF(ISBLANK(Data1!BJ16),NA(),Data1!BJ16) -> #N/A | F57: =IF(ISBLANK(Data1!BK16),NA(),Data1!BK16) -> #N/A | H57: =A57 -> 25538 | I57: =IF(ISNA(B57),NA(),B57/$B$58*100) -> 99.074074 | J57: {=IF(ISNA(C57),NA(),C57/INDEX($C$52:$C$282,MATCH(TRUE,INDEX(NOT(ISNA($C$52:$C$282)),0),0))*100)} -> #N/A | K57: {=IF(ISNA(D57),NA(),D57/INDEX($D$52:$D$282,MATCH(TRUE,INDEX(NOT(ISNA($D$52:$D$282)),0),0))*100)} -> #N/A | L57: =IF(ISNA(E57),NA(),E57/$E$58*100) -> #N/A | M57: =IF(ISNA(F57),NA(),F57/$F$58*100) -> #N/A | O57: =A57 -> 25538 | P57: =IFERROR(IF(OR(ISNA(B57),ISNA(B53)),NA(),B57/B53-1),NA()) -> 0.038834951 | Q57: =IFERROR(IF(OR(ISNA(C57),ISNA(C53)),NA(),C57/C53-1),NA()) -> #N/A | R57: =IFERROR(IF(OR(ISNA(D57),ISNA(D53)),NA(),D57/D53-1),NA()) -> #N/A | S57: =IFERROR(IF(OR(ISNA(E57),ISNA(E53)),NA(),E57/E53-1),NA()) -> #N/A | T57: =IFERROR(IF(OR(ISNA(F57),ISNA(F53)),NA(),F57/F53-1),NA()) -> #N/A
A58: =Data1!A17 -> 25628 | B58: =IF(ISBLANK(Data1!B17),NA(),Data1!B17) -> 10.8 | C58: =IF(ISBLANK(Data1!E17),NA(),Data1!E17) -> #N/A | D58: =IF(ISBLANK(Data1!AJ17),NA(),Data1!AJ17) -> #N/A | E58: =IF(ISBLANK(Data1!BJ17),NA(),Data1!BJ17) -> 17.9 | F58: =IF(ISBLANK(Data1!BK17),NA(),Data1!BK17) -> 11.8 | H58: =A58 -> 25628 | I58: =IF(ISNA(B58),NA(),B58/$B$58*100) -> 100 | J58: {=IF(ISNA(C58),NA(),C58/INDEX($C$52:$C$282,MATCH(TRUE,INDEX(NOT(ISNA($C$52:$C$282)),0),0))*100)} -> #N/A | K58: {=IF(ISNA(D58),NA(),D58/INDEX($D$52:$D$282,MATCH(TRUE,INDEX(NOT(ISNA($D$52:$D$282)),0),0))*100)} -> #N/A | L58: =IF(ISNA(E58),NA(),E58/$E$58*100) -> 100 | M58: =IF(ISNA(F58),NA(),F58/$F$58*100) -> 100 | O58: =A58 -> 25628 | P58: =IFERROR(IF(OR(ISNA(B58),ISNA(B54)),NA(),B58/B54-1),NA()) -> 0.028571429 | Q58: =IFERROR(IF(OR(ISNA(C58),ISNA(C54)),NA(),C58/C54-1),NA()) -> #N/A | R58: =IFERROR(IF(OR(ISNA(D58),ISNA(D54)),NA(),D58/D54-1),NA()) -> #N/A | S58: =IFERROR(IF(OR(ISNA(E58),ISNA(E54)),NA(),E58/E54-1),NA()) -> #N/A | T58: =IFERROR(IF(OR(ISNA(F58),ISNA(F54)),NA(),F58/F54-1),NA()) -> #N/A
A59: =Data1!A18 -> 25720 | B59: =IF(ISBLANK(Data1!B18),NA(),Data1!B18) -> 10.9 | C59: =IF(ISBLANK(Data1!E18),NA(),Data1!E18) -> #N/A | D59: =IF(ISBLANK(Data1!AJ18),NA(),Data1!AJ18) -> #N/A | E59: =IF(ISBLANK(Data1!BJ18),NA(),Data1!BJ18) -> 15.6 | F59: =IF(ISBLANK(Data1!BK18),NA(),Data1!BK18) -> 12 | H59: =A59 -> 25720 | I59: =IF(ISNA(B59),NA(),B59/$B$58*100) -> 100.92593 | J59: {=IF(ISNA(C59),NA(),C59/INDEX($C$52:$C$282,MATCH(TRUE,INDEX(NOT(ISNA($C$52:$C$282)),0),0))*100)} -> #N/A | K59: {=IF(ISNA(D59),NA(),D59/INDEX($D$52:$D$282,MATCH(TRUE,INDEX(NOT(ISNA($D$52:$D$282)),0),0))*100)} -> #N/A | L59: =IF(ISNA(E59),NA(),E59/$E$58*100) -> 87.150838 | M59: =IF(ISNA(F59),NA(),F59/$F$58*100) -> 101.69492 | O59: =A59 -> 25720 | P59: =IFERROR(IF(OR(ISNA(B59),ISNA(B55)),NA(),B59/B55-1),NA()) -> 0.0092592593 | Q59: =IFERROR(IF(OR(ISNA(C59),ISNA(C55)),NA(),C59/C55-1),NA()) -> #N/A | R59: =IFERROR(IF(OR(ISNA(D59),ISNA(D55)),NA(),D59/D55-1),NA()) -> #N/A | S59: =IFERROR(IF(OR(ISNA(E59),ISNA(E55)),NA(),E59/E55-1),NA()) -> #N/A | T59: =IFERROR(IF(OR(ISNA(F59),ISNA(F55)),NA(),F59/F55-1),NA()) -> #N/A
A60: =Data1!A19 -> 25812 | B60: =IF(ISBLANK(Data1!B19),NA(),Data1!B19) -> 10.7 | C60: =IF(ISBLANK(Data1!E19),NA(),Data1!E19) -> #N/A | D60: =IF(ISBLANK(Data1!AJ19),NA(),Data1!AJ19) -> #N/A | E60: =IF(ISBLANK(Data1!BJ19),NA(),Data1!BJ19) -> 14.7 | F60: =IF(ISBLANK(Data1!BK19),NA(),Data1!BK19) -> 12.3 | H60: =A60 -> 25812 | I60: =IF(ISNA(B60),NA(),B60/$B$58*100) -> 99.074074 | J60: {=IF(ISNA(C60),NA(),C60/INDEX($C$52:$C$282,MATCH(TRUE,INDEX(NOT(ISNA($C$52:$C$282)),0),0))*100)} -> #N/A | K60: {=IF(ISNA(D60),NA(),D60/INDEX($D$52:$D$282,MATCH(TRUE,INDEX(NOT(ISNA($D$52:$D$282)),0),0))*100)} -> #N/A | L60: =IF(ISNA(E60),NA(),E60/$E$58*100) -> 82.122905 | M60: =IF(ISNA(F60),NA(),F60/$F$58*100) -> 104.23729 | O60: =A60 -> 25812 | P60: =IFERROR(IF(OR(ISNA(B60),ISNA(B56)),NA(),B60/B56-1),NA()) -> -0.018348624 | Q60: =IFERROR(IF(OR(ISNA(C60),ISNA(C56)),NA(),C60/C56-1),NA()) -> #N/A | R60: =IFERROR(IF(OR(ISNA(D60),ISNA(D56)),NA(),D60/D56-1),NA()) -> #N/A | S60: =IFERROR(IF(OR(ISNA(E60),ISNA(E56)),NA(),E60/E56-1),NA()) -> #N/A | T60: =IFERROR(IF(OR(ISNA(F60),ISNA(F56)),NA(),F60/F56-1),NA()) -> #N/A
A61: =Data1!A20 -> 25903 | B61: =IF(ISBLANK(Data1!B20),NA(),Data1!B20) -> 10.4 | C61: =IF(ISBLANK(Data1!E20),NA(),Data1!E20) -> #N/A | D61: =IF(ISBLANK(Data1!AJ20),NA(),Data1!AJ20) -> #N/A | E61: =IF(ISBLANK(Data1!BJ20),NA(),Data1!BJ20) -> 13.7 | F61: =IF(ISBLANK(Data1!BK20),NA(),Data1!BK20) -> 12.2 | H61: =A61 -> 25903 | I61: =IF(ISNA(B61),NA(),B61/$B$58*100) -> 96.296296 | J61: {=IF(ISNA(C61),NA(),C61/INDEX($C$52:$C$282,MATCH(TRUE,INDEX(NOT(ISNA($C$52:$C$282)),0),0))*100)} -> #N/A | K61: {=IF(ISNA(D61),NA(),D61/INDEX($D$52:$D$282,MATCH(TRUE,INDEX(NOT(ISNA($D$52:$D$282)),0),0))*100)} -> #N/A | L61: =IF(ISNA(E61),NA(),E61/$E$58*100) -> 76.536313 | M61: =IF(ISNA(F61),NA(),F61/$F$58*100) -> 103.38983 | O61: =A61 -> 25903 | P61: =IFERROR(IF(OR(ISNA(B61),ISNA(B57)),NA(),B61/B57-1),NA()) -> -0.028037383 | Q61: =IFERROR(IF(OR(ISNA(C61),ISNA(C57)),NA(),C61/C57-1),NA()) -> #N/A | R61: =IFERROR(IF(OR(ISNA(D61),ISNA(D57)),NA(),D61/D57-1),NA()) -> #N/A | S61: =IFERROR(IF(OR(ISNA(E61),ISNA(E57)),NA(),E61/E57-1),NA()) -> #N/A | T61: =IFERROR(IF(OR(ISNA(F61),ISNA(F57)),NA(),F61/F57-1),NA()) -> #N/A
A62: =Data1!A21 -> 25993 | B62: =IF(ISBLANK(Data1!B21),NA(),Data1!B21) -> 10.6 | C62: =IF(ISBLANK(Data1!E21),NA(),Data1!E21) -> #N/A | D62: =IF(ISBLANK(Data1!AJ21),NA(),Data1!AJ21) -> #N/A | E62: =IF(ISBLANK(Data1!BJ21),NA(),Data1!BJ21) -> 12.9 | F62: =IF(ISBLANK(Data1!BK21),NA(),Data1!BK21) -> 12.2 | H62: =A62 -> 25993 | I62: =IF(ISNA(B62),NA(),B62/$B$58*100) -> 98.148148 | J62: {=IF(ISNA(C62),NA(),C62/INDEX($C$52:$C$282,MATCH(TRUE,INDEX(NOT(ISNA($C$52:$C$282)),0),0))*100)} -> #N/A | K62: {=IF(ISNA(D62),NA(),D62/INDEX($D$52:$D$282,MATCH(TRUE,INDEX(NOT(ISNA($D$52:$D$282)),0),0))*100)} -> #N/A | L62: =IF(ISNA(E62),NA(),E62/$E$58*100) -> 72.067039 | M62: =IF(ISNA(F62),NA(),F62/$F$58*100) -> 103.38983 | O62: =A62 -> 25993 | P62: =IFERROR(IF(OR(ISNA(B62),ISNA(B58)),NA(),B62/B58-1),NA()) -> -0.018518519 | Q62: =IFERROR(IF(OR(ISNA(C62),ISNA(C58)),NA(),C62/C58-1),NA()) -> #N/A | R62: =IFERROR(IF(OR(ISNA(D62),ISNA(D58)),NA(),D62/D58-1),NA()) -> #N/A | S62: =IFERROR(IF(OR(ISNA(E62),ISNA(E58)),NA(),E62/E58-1),NA()) -> -0.27932961 | T62: =IFERROR(IF(OR(ISNA(F62),ISNA(F58)),NA(),F62/F58-1),NA()) -> 0.033898305
A63: =Data1!A22 -> 26085 | B63: =IF(ISBLANK(Data1!B22),NA(),Data1!B22) -> 10.7 | C63: =IF(ISBLANK(Data1!E22),NA(),Data1!E22) -> #N/A | D63: =IF(ISBLANK(Data1!AJ22),NA(),Data1!AJ22) -> #N/A | E63: =IF(ISBLANK(Data1!BJ22),NA(),Data1!BJ22) -> 12.7 | F63: =IF(ISBLANK(Data1!BK22),NA(),Data1!BK22) -> 12.2 | H63: =A63 -> 26085 | I63: =IF(ISNA(B63),NA(),B63/$B$58*100) -> 99.074074 | J63: {=IF(ISNA(C63),NA(),C63/INDEX($C$52:$C$282,MATCH(TRUE,INDEX(NOT(ISNA($C$52:$C$282)),0),0))*100)} -> #N/A | K63: {=IF(ISNA(D63),NA(),D63/INDEX($D$52:$D$282,MATCH(TRUE,INDEX(NOT(ISNA($D$52:$D$282)),0),0))*100)} -> #N/A | L63: =IF(ISNA(E63),NA(),E63/$E$58*100) -> 70.949721 | M63: =IF(ISNA(F63),NA(),F63/$F$58*100) -> 103.38983 | O63: =A63 -> 26085 | P63: =IFERROR(IF(OR(ISNA(B63),ISNA(B59)),NA(),B63/B59-1),NA()) -> -0.018348624 | Q63: =IFERROR(IF(OR(ISNA(C63),ISNA(C59)),NA(),C63/C59-1),NA()) -> #N/A | R63: =IFERROR(IF(OR(ISNA(D63),ISNA(D59)),NA(),D63/D59-1),NA()) -> #N/A | S63: =IFERROR(IF(OR(ISNA(E63),ISNA(E59)),NA(),E63/E59-1),NA()) -> -0.18589744 | T63: =IFERROR(IF(OR(ISNA(F63),ISNA(F59)),NA(),F63/F59-1),NA()) -> 0.016666667
A64: =Data1!A23 -> 26177 | B64: =IF(ISBLANK(Data1!B23),NA(),Data1!B23) -> 11 | C64: =IF(ISBLANK(Data1!E23),NA(),Data1!E23) -> #N/A | D64: =IF(ISBLANK(Data1!AJ23),NA(),Data1!AJ23) -> #N/A | E64: =IF(ISBLANK(Data1!BJ23),NA(),Data1!BJ23) -> 13 | F64: =IF(ISBLANK(Data1!BK23),NA(),Data1!BK23) -> 12.4 | H64: =A64 -> 26177 | I64: =IF(ISNA(B64),NA(),B64/$B$58*100) -> 101.85185 | J64: {=IF(ISNA(C64),NA(),C64/INDEX($C$52:$C$282,MATCH(TRUE,INDEX(NOT(ISNA($C$52:$C$282)),0),0))*100)} -> #N/A | K64: {=IF(ISNA(D64),NA(),D64/INDEX($D$52:$D$282,MATCH(TRUE,INDEX(NOT(ISNA($D$52:$D$282)),0),0))*100)} -> #N/A | L64: =IF(ISNA(E64),NA(),E64/$E$58*100) -> 72.625698 | M64: =IF(ISNA(F64),NA(),F64/$F$58*100) -> 105.08475 | O64: =A64 -> 26177 | P64: =IFERROR(IF(OR(ISNA(B64),ISNA(B60)),NA(),B64/B60-1),NA()) -> 0.028037383 | Q64: =IFERROR(IF(OR(ISNA(C64),ISNA(C60)),NA(),C64/C60-1),NA()) -> #N/A | R64: =IFERROR(IF(OR(ISNA(D64),ISNA(D60)),NA(),D64/D60-1),NA()) -> #N/A | S64: =IFERROR(IF(OR(ISNA(E64),ISNA(E60)),NA(),E64/E60-1),NA()) -> -0.11564626 | T64: =IFERROR(IF(OR(ISNA(F64),ISNA(F60)),NA(),F64/F60-1),NA()) -> 0.0081300813
A65: =Data1!A24 -> 26268 | B65: =IF(ISBLANK(Data1!B24),NA(),Data1!B24) -> 10.7 | C65: =IF(ISBLANK(Data1!E24),NA(),Data1!E24) -> #N/A | D65: =IF(ISBLANK(Data1!AJ24),NA(),Data1!AJ24) -> #N/A | E65: =IF(ISBLANK(Data1!BJ24),NA(),Data1!BJ24) -> 12.1 | F65: =IF(ISBLANK(Data1!BK24),NA(),Data1!BK24) -> 12.4 | H65: =A65 -> 26268 | I65: =IF(ISNA(B65),NA(),B65/$B$58*100) -> 99.074074 | J65: {=IF(ISNA(C65),NA(),C65/INDEX($C$52:$C$282,MATCH(TRUE,INDEX(NOT(ISNA($C$52:$C$282)),0),0))*100)} -> #N/A | K65: {=IF(ISNA(D65),NA(),D65/INDEX($D$52:$D$282,MATCH(TRUE,INDEX(NOT(ISNA($D$52:$D$282)),0),0))*100)} -> #N/A | L65: =IF(ISNA(E65),NA(),E65/$E$58*100) -> 67.597765 | M65: =IF(ISNA(F65),NA(),F65/$F$58*100) -> 105.08475 | O65: =A65 -> 26268 | P65: =IFERROR(IF(OR(ISNA(B65),ISNA(B61)),NA(),B65/B61-1),NA()) -> 0.028846154 | Q65: =IFERROR(IF(OR(ISNA(C65),ISNA(C61)),NA(),C65/C61-1),NA()) -> #N/A | R65: =IFERROR(IF(OR(ISNA(D65),ISNA(D61)),NA(),D65/D61-1),NA()) -> #N/A | S65: =IFERROR(IF(OR(ISNA(E65),ISNA(E61)),NA(),E65/E61-1),NA()) -> -0.11678832 | T65: =IFERROR(IF(OR(ISNA(F65),ISNA(F61)),NA(),F65/F61-1),NA()) -> 0.016393443
A66: =Data1!A25 -> 26359 | B66: =IF(ISBLANK(Data1!B25),NA(),Data1!B25) -> 10.8 | C66: =IF(ISBLANK(Data1!E25),NA(),Data1!E25) -> #N/A | D66: =IF(ISBLANK(Data1!AJ25),NA(),Data1!AJ25) -> #N/A | E66: =IF(ISBLANK(Data1!BJ25),NA(),Data1!BJ25) -> 12.1 | F66: =IF(ISBLANK(Data1!BK25),NA(),Data1!BK25) -> 12.7 | H66: =A66 -> 26359 | I66: =IF(ISNA(B66),NA(),B66/$B$58*100) -> 100 | J66: {=IF(ISNA(C66),NA(),C66/INDEX($C$52:$C$282,MATCH(TRUE,INDEX(NOT(ISNA($C$52:$C$282)),0),0))*100)} -> #N/A | K66: {=IF(ISNA(D66),NA(),D66/INDEX($D$52:$D$282,MATCH(TRUE,INDEX(NOT(ISNA($D$52:$D$282)),0),0))*100)} -> #N/A | L66: =IF(ISNA(E66),NA(),E66/$E$58*100) -> 67.597765 | M66: =IF(ISNA(F66),NA(),F66/$F$58*100) -> 107.62712 | O66: =A66 -> 26359 | P66: =IFERROR(IF(OR(ISNA(B66),ISNA(B62)),NA(),B66/B62-1),NA()) -> 0.018867925 | Q66: =IFERROR(IF(OR(ISNA(C66),ISNA(C62)),NA(),C66/C62-1),NA()) -> #N/A | R66: =IFERROR(IF(OR(ISNA(D66),ISNA(D62)),NA(),D66/D62-1),NA()) -> #N/A | S66: =IFERROR(IF(OR(ISNA(E66),ISNA(E62)),NA(),E66/E62-1),NA()) -> -0.062015504 | T66: =IFERROR(IF(OR(ISNA(F66),ISNA(F62)),NA(),F66/F62-1),NA()) -> 0.040983607
A67: =Data1!A26 -> 26451 | B67: =IF(ISBLANK(Data1!B26),NA(),Data1!B26) -> 10.9 | C67: =IF(ISBLANK(Data1!E26),NA(),Data1!E26) -> #N/A | D67: =IF(ISBLANK(Data1!AJ26),NA(),Data1!AJ26) -> #N/A | E67: =IF(ISBLANK(Data1!BJ26),NA(),Data1!BJ26) -> 11.3 | F67: =IF(ISBLANK(Data1!BK26),NA(),Data1!BK26) -> 12.5 | H67: =A67 -> 26451 | I67: =IF(ISNA(B67),NA(),B67/$B$58*100) -> 100.92593 | J67: {=IF(ISNA(C67),NA(),C67/INDEX($C$52:$C$282,MATCH(TRUE,INDEX(NOT(ISNA($C$52:$C$282)),0),0))*100)} -> #N/A | K67: {=IF(ISNA(D67),NA(),D67/INDEX($D$52:$D$282,MATCH(TRUE,INDEX(NOT(ISNA($D$52:$D$282)),0),0))*100)} -> #N/A | L67: =IF(ISNA(E67),NA(),E67/$E$58*100) -> 63.128492 | M67: =IF(ISNA(F67),NA(),F67/$F$58*100) -> 105.9322 | O67: =A67 -> 26451 | P67: =IFERROR(IF(OR(ISNA(B67),ISNA(B63)),NA(),B67/B63-1),NA()) -> 0.018691589 | Q67: =IFERROR(IF(OR(ISNA(C67),ISNA(C63)),NA(),C67/C63-1),NA()) -> #N/A | R67: =IFERROR(IF(OR(ISNA(D67),ISNA(D63)),NA(),D67/D63-1),NA()) -> #N/A | S67: =IFERROR(IF(OR(ISNA(E67),ISNA(E63)),NA(),E67/E63-1),NA()) -> -0.11023622 | T67: =IFERROR(IF(OR(ISNA(F67),ISNA(F63)),NA(),F67/F63-1),NA()) -> 0.024590164
... A282: =Data1!A241 -> 46082 | B282: =IF(ISBLANK(Data1!B241),NA(),Data1!B241) -> 173.4 | C282: =IF(ISBLANK(Data1!E241),NA(),Data1!E241) -> 179.3 | D282: =IF(ISBLANK(Data1!AJ241),NA(),Data1!AJ241) -> 132.6 | E282: =IF(ISBLANK(Data1!BJ241),NA(),Data1!BJ241) -> 187.3 | F282: =IF(ISBLANK(Data1!BK241),NA(),Data1!BK241) -> 152.2 | H282: =A282 -> 46082 | I282: =IF(ISNA(B282),NA(),B282/$B$58*100) -> 1605.5556 | J282: {=IF(ISNA(C282),NA(),C282/INDEX($C$52:$C$282,MATCH(TRUE,INDEX(NOT(ISNA($C$52:$C$282)),0),0))*100)} -> 341.52381 | K282: {=IF(ISNA(D282),NA(),D282/INDEX($D$52:$D$282,MATCH(TRUE,INDEX(NOT(ISNA($D$52:$D$282)),0),0))*100)} -> 209.14826 | L282: =IF(ISNA(E282),NA(),E282/$E$58*100) -> 1046.3687 | M282: =IF(ISNA(F282),NA(),F282/$F$58*100) -> 1289.8305 | O282: =A282 -> 46082 | P282: =IFERROR(IF(OR(ISNA(B282),ISNA(B278)),NA(),B282/B278-1),NA()) -> 0.11583012 | Q282: =IFERROR(IF(OR(ISNA(C282),ISNA(C278)),NA(),C282/C278-1),NA()) -> 0.12343358 | R282: =IFERROR(IF(OR(ISNA(D282),ISNA(D278)),NA(),D282/D278-1),NA()) -> 0.0075987842 | S282: =IFERROR(IF(OR(ISNA(E282),ISNA(E278)),NA(),E282/E278-1),NA()) -> -0.012130802 | T282: =IFERROR(IF(OR(ISNA(F282),ISNA(F278)),NA(),F282/F278-1),NA()) -> -0.025608195
