Workbook
Name A2325806K: Data1!$EC$1:$EC$10,Data1!$EC$11:$EC$294
Name A2325806K_Data: Data1!$EC$11:$EC$294
Name A2325806K_Latest: Data1!$EC$294
Name A2325811C: Data2!$AI$1:$AI$10,Data2!$AI$11:$AI$294
Name A2325811C_Data: Data2!$AI$11:$AI$294
Name A2325811C_Latest: Data2!$AI$294
Name A2325816R: Data2!$GE$1:$GE$10,Data2!$GE$11:$GE$294
Name A2325816R_Data: Data2!$GE$11:$GE$294
Name A2325816R_Latest: Data2!$GE$294
Name A2325821J: Data3!$CK$1:$CK$10,Data3!$CK$11:$CK$294
Name A2325821J_Data: Data3!$CK$11:$CK$294
Name A2325821J_Latest: Data3!$CK$294
Name A2325826V: Data3!$IG$1:$IG$10,Data3!$IG$11:$IG$294
Name A2325826V_Data: Data3!$IG$11:$IG$294
Name A2325826V_Latest: Data3!$IG$294
Name A2325831L: Data4!$EM$1:$EM$10,Data4!$EM$11:$EM$294
Name A2325831L_Data: Data4!$EM$11:$EM$294
Name A2325831L_Latest: Data4!$EM$294
Name A2325836X: Data5!$AS$1:$AS$10,Data5!$AS$139:$AS$294
Name A2325836X_Data: Data5!$AS$139:$AS$294
Name A2325836X_Latest: Data5!$AS$294
Name A2325841T: Data5!$GO$1:$GO$10,Data5!$GO$11:$GO$294
Name A2325841T_Data: Data5!$GO$11:$GO$294
Name A2325841T_Latest: Data5!$GO$294
Name A2325846C: Data6!$CU$1:$CU$10,Data6!$CU$11:$CU$294
Name A2325846C_Data: Data6!$CU$11:$CU$294
Name A2325846C_Latest: Data6!$CU$294
Name A2325851W: Data1!$B$1:$B$10,Data1!$B$107:$B$294
Name A2325851W_Data: Data1!$B$107:$B$294
Name A2325851W_Latest: Data1!$B$294
Name A2325856J: Data1!$EX$1:$EX$10,Data1!$EX$107:$EX$294
Name A2325856J_Data: Data1!$EX$107:$EX$294
Name A2325856J_Latest: Data1!$EX$294
Name A2325861A: Data2!$BD$1:$BD$10,Data2!$BD$107:$BD$294
Name A2325861A_Data: Data2!$BD$107:$BD$294
Name A2325861A_Latest: Data2!$BD$294
Name A2325866L: Data2!$GZ$1:$GZ$10,Data2!$GZ$107:$GZ$294
Name A2325866L_Data: Data2!$GZ$107:$GZ$294
Name A2325866L_Latest: Data2!$GZ$294
Name A2325871F: Data3!$DF$1:$DF$10,Data3!$DF$107:$DF$294
Name A2325871F_Data: Data3!$DF$107:$DF$294
Name A2325871F_Latest: Data3!$DF$294
Name A2325876T: Data4!$L$1:$L$10,Data4!$L$107:$L$294
Name A2325876T_Data: Data4!$L$107:$L$294
Name A2325876T_Latest: Data4!$L$294
Name A2325881K: Data4!$FH$1:$FH$10,Data4!$FH$139:$FH$294
Name A2325881K_Data: Data4!$FH$139:$FH$294
Name A2325881K_Latest: Data4!$FH$294
Name A2325886W: Data5!$BN$1:$BN$10,Data5!$BN$107:$BN$294
Name A2325886W_Data: Data5!$BN$107:$BN$294
Name A2325886W_Latest: Data5!$BN$294
Name A2325891R: Data5!$HJ$1:$HJ$10,Data5!$HJ$107:$HJ$294
Name A2325891R_Data: Data5!$HJ$107:$HJ$294
Name A2325891R_Latest: Data5!$HJ$294
Name A2325896A: Data1!$AP$1:$AP$10,Data1!$AP$107:$AP$294
Name A2325896A_Data: Data1!$AP$107:$AP$294
Name A2325896A_Latest: Data1!$AP$294
Name A2325901J: Data1!$GL$1:$GL$10,Data1!$GL$107:$GL$294
Name A2325901J_Data: Data1!$GL$107:$GL$294
Name A2325901J_Latest: Data1!$GL$294

Sheet Index
B2: Time Series Workbook
B5: 6401.0 Consumer Price Index, Australia
B6: TABLE 9. CPI: Group, Sub-group and Expenditure Class, Index Numbers by Capital City
A8: Related Information: | B8: Summary Publication | C8: Explanatory Notes | D8: Inquiries
A10: Data Item Description | D10: Series Type | E10: Series ID | F10: Series Start | G10: Series End | H10: No. Obs. | I10: Unit | J10: Data Type | K10: Freq. | L10: Collection Month
A12: Index Numbers ; Food and non-alcoholic beverages ; Sydney ; | D12: Original | E12: A2325851W | F12: 26543 | G12: 43617 | H12: 188 | I12: Index Numbers | J12: INDEX | K12: Quarter | L12: 3
A13: Index Numbers ; Bread and cereal products ; Sydney ; | D13: Original | E13: A2326166T | F13: 26543 | G13: 43617 | H13: 188 | I13: Index Numbers | J13: INDEX | K13: Quarter | L13: 3
A14: Index Numbers ; Bread ; Sydney ; | D14: Original | E14: A2327021W | F14: 29465 | G14: 43617 | H14: 156 | I14: Index Numbers | J14: INDEX | K14: Quarter | L14: 3
A15: Index Numbers ; Cakes and biscuits ; Sydney ; | D15: Original | E15: A2327066A | F15: 29465 | G15: 43617 | H15: 156 | I15: Index Numbers | J15: INDEX | K15: Quarter | L15: 3
A16: Index Numbers ; Breakfast cereals ; Sydney ; | D16: Original | E16: A2327111A | F16: 29465 | G16: 43617 | H16: 156 | I16: Index Numbers | J16: INDEX | K16: Quarter | L16: 3
A17: Index Numbers ; Other cereal products ; Sydney ; | D17: Original | E17: A2327156F | F17: 29465 | G17: 43617 | H17: 156 | I17: Index Numbers | J17: INDEX | K17: Quarter | L17: 3
A18: Index Numbers ; Meat and seafoods ; Sydney ; | D18: Original | E18: A2326211T | F18: 26543 | G18: 43617 | H18: 188 | I18: Index Numbers | J18: INDEX | K18: Quarter | L18: 3
A19: Index Numbers ; Beef and veal ; Sydney ; | D19: Original | E19: A2327201F | F19: 26543 | G19: 43617 | H19: 188 | I19: Index Numbers | J19: INDEX | K19: Quarter | L19: 3
A20: Index Numbers ; Pork ; Sydney ; | D20: Original | E20: A3603903T | F20: 29465 | G20: 43617 | H20: 156 | I20: Index Numbers | J20: INDEX | K20: Quarter | L20: 3
A21: Index Numbers ; Lamb and goat ; Sydney ; | D21: Original | E21: A2327246K | F21: 26543 | G21: 43617 | H21: 188 | I21: Index Numbers | J21: INDEX | K21: Quarter | L21: 3
A22: Index Numbers ; Poultry ; Sydney ; | D22: Original | E22: A2327336R | F22: 26543 | G22: 43617 | H22: 188 | I22: Index Numbers | J22: INDEX | K22: Quarter | L22: 3
A23: Index Numbers ; Other meats ; Sydney ; | D23: Original | E23: A2327426V | F23: 29465 | G23: 43617 | H23: 156 | I23: Index Numbers | J23: INDEX | K23: Quarter | L23: 3
... A1379: Index Numbers ; All groups CPI excluding 'volatile items' ; Australia ; | D1379: Original | E1379: A2330841L | F1379: 31747 | G1379: 43617 | H1379: 131 | I1379: Index Numbers | J1379: INDEX | K1379: Quarter | L1379: 3
A1381: © Commonwealth of Australia 2019

Sheet Energy Summary
A1: Energy Price Index — Summary
A2: Source: ABS 6401.0 Consumer Price Index, Table 9. Original series, quarterly, index 2011–12 = 100.
A3: Window: Sep-1989 to Jun-2019 (common window where all three fuel series are available nationally)
A5: 1. Time Series Data | AD5: Chart source helper tables (collapsed group)
B6: Sydney | E6: Melbourne | H6: Brisbane | K6: Adelaide | N6: Perth | Q6: Hobart | T6: Darwin | W6: Canberra | Z6: Australia
A7: Quarter | B7: Electricity | C7: Gas | D7: Auto fuel | E7: Electricity | F7: Gas | G7: Auto fuel | H7: Electricity | I7: Gas | J7: Auto fuel | K7: Electricity | L7: Gas | M7: Auto fuel | N7: Electricity | O7: Gas | P7: Auto fuel | Q7: Electricity | R7: Gas | S7: Auto fuel | T7: Electricity | U7: Gas | V7: Auto fuel | W7: Electricity | X7: Gas | Y7: Auto fuel | Z7: Electricity | AA7: Gas | AB7: Auto fuel | AD7: Quarter | AE7: Sydney | AF7: Melbourne | AG7: Brisbane | AH7: Adelaide | AI7: Perth | AJ7: Hobart | AK7: Darwin | AL7: Canberra | AM7: Australia | AP7: Quarter | AQ7: Sydney | AR7: Melbourne | AS7: Brisbane | AT7: Adelaide | AU7: Perth | AV7: Hobart | AW7: Darwin | AX7: Canberra | AY7: Australia | BA7: Quarter | BB7: Sydney | BC7: Melbourne | BD7: Brisbane | BE7: Adelaide | BF7: Perth | BG7: Hobart | BH7: Darwin | BI7: Canberra | BJ7: Australia
A8: =Data1!A175 -> 32752 | B8: =Data1!BL175 -> 34 | C8: =Data1!BM175 -> 34.9 | D8: =Data1!CR175 -> 36.6 | E8: =Data1!HH175 -> 35.3 | F8: =Data1!HI175 -> 38.9 | G8: =Data1!IN175 -> 38.3 | H8: =Data2!DN175 -> 40.3 | I8: =Data2!DO175 -> 35.4 | J8: =Data2!ET175 -> 35.6 | K8: =Data3!T175 -> 33 | L8: =Data3!U175 -> 34.5 | M8: =Data3!AZ175 -> 39 | N8: =Data3!FP175 -> 51.1 | O8: =Data3!FQ175 -> 34.6 | P8: =Data3!GV175 -> 41.4 | Q8: =Data4!BV175 -> 31.3 | R8: =Data4!BW175 -> 43.9 | S8: =Data4!DB175 -> 45 | T8: =Data4!HR175 -> 54.7 | U8: =Data4!HS175 -> 37.4 | V8: =Data5!H175 -> 40.5 | W8: =Data5!DX175 -> 38 | X8: =Data5!DY175 -> 30 | Y8: =Data5!FD175 -> 37.9 | Z8: =Data6!AD175 -> 36.5 | AA8: =Data6!AE175 -> 36.3 | AB8: =Data6!BJ175 -> 37.9 | AD8: =A8 -> 32752 | AE8: =B8 -> 34 | AF8: =E8 -> 35.3 | AG8: =H8 -> 40.3 | AH8: =K8 -> 33 | AI8: =N8 -> 51.1 | AJ8: =Q8 -> 31.3 | AK8: =T8 -> 54.7 | AL8: =W8 -> 38 | AM8: =Z8 -> 36.5 | AP8: =A8 -> 32752 | AQ8: =C8 -> 34.9 | AR8: =F8 -> 38.9 | AS8: =I8 -> 35.4 | AT8: =L8 -> 34.5 | AU8: =O8 -> 34.6 | AV8: =R8 -> 43.9 | AW8: =U8 -> 37.4 | AX8: =X8 -> 30 | AY8: =AA8 -> 36.3 | BA8: =A8 -> 32752 | BB8: =D8 -> 36.6 | BC8: =G8 -> 38.3 | BD8: =J8 -> 35.6 | BE8: =M8 -> 39 | BF8: =P8 -> 41.4 | BG8: =S8 -> 45 | BH8: =V8 -> 40.5 | BI8: =Y8 -> 37.9 | BJ8: =AB8 -> 37.9
A9: =Data1!A176 -> 32843 | B9: =Data1!BL176 -> 34 | C9: =Data1!BM176 -> 36.2 | D9: =Data1!CR176 -> 39.1 | E9: =Data1!HH176 -> 36.1 | F9: =Data1!HI176 -> 39.9 | G9: =Data1!IN176 -> 40 | H9: =Data2!DN176 -> 40.3 | I9: =Data2!DO176 -> 36.7 | J9: =Data2!ET176 -> 37.6 | K9: =Data3!T176 -> 33 | L9: =Data3!U176 -> 34.5 | M9: =Data3!AZ176 -> 40.4 | N9: =Data3!FP176 -> 51.1 | O9: =Data3!FQ176 -> 34.7 | P9: =Data3!GV176 -> 41.7 | Q9: =Data4!BV176 -> 31.3 | R9: =Data4!BW176 -> 44.3 | S9: =Data4!DB176 -> 44.1 | T9: =Data4!HR176 -> 54.7 | U9: =Data4!HS176 -> 37.7 | V9: =Data5!H176 -> 40 | W9: =Data5!DX176 -> 38.4 | X9: =Data5!DY176 -> 30.2 | Y9: =Data5!FD176 -> 40 | Z9: =Data6!AD176 -> 36.8 | AA9: =Data6!AE176 -> 37 | AB9: =Data6!BJ176 -> 39.6 | AD9: =A9 -> 32843 | AE9: =B9 -> 34 | AF9: =E9 -> 36.1 | AG9: =H9 -> 40.3 | AH9: =K9 -> 33 | AI9: =N9 -> 51.1 | AJ9: =Q9 -> 31.3 | AK9: =T9 -> 54.7 | AL9: =W9 -> 38.4 | AM9: =Z9 -> 36.8 | AP9: =A9 -> 32843 | AQ9: =C9 -> 36.2 | AR9: =F9 -> 39.9 | AS9: =I9 -> 36.7 | AT9: =L9 -> 34.5 | AU9: =O9 -> 34.7 | AV9: =R9 -> 44.3 | AW9: =U9 -> 37.7 | AX9: =X9 -> 30.2 | AY9: =AA9 -> 37 | BA9: =A9 -> 32843 | BB9: =D9 -> 39.1 | BC9: =G9 -> 40 | BD9: =J9 -> 37.6 | BE9: =M9 -> 40.4 | BF9: =P9 -> 41.7 | BG9: =S9 -> 44.1 | BH9: =V9 -> 40 | BI9: =Y9 -> 40 | BJ9: =AB9 -> 39.6
A10: =Data1!A177 -> 32933 | B10: =Data1!BL177 -> 34 | C10: =Data1!BM177 -> 36.4 | D10: =Data1!CR177 -> 42.1 | E10: =Data1!HH177 -> 36.1 | F10: =Data1!HI177 -> 39.9 | G10: =Data1!IN177 -> 42.6 | H10: =Data2!DN177 -> 40.3 | I10: =Data2!DO177 -> 37.1 | J10: =Data2!ET177 -> 39.9 | K10: =Data3!T177 -> 33 | L10: =Data3!U177 -> 36.1 | M10: =Data3!AZ177 -> 42.6 | N10: =Data3!FP177 -> 51.1 | O10: =Data3!FQ177 -> 34.8 | P10: =Data3!GV177 -> 43.6 | Q10: =Data4!BV177 -> 33 | R10: =Data4!BW177 -> 45.6 | S10: =Data4!DB177 -> 45.9 | T10: =Data4!HR177 -> 54.7 | U10: =Data4!HS177 -> 39.8 | V10: =Data5!H177 -> 41.3 | W10: =Data5!DX177 -> 38.4 | X10: =Data5!DY177 -> 30.9 | Y10: =Data5!FD177 -> 43.6 | Z10: =Data6!AD177 -> 36.8 | AA10: =Data6!AE177 -> 37.4 | AB10: =Data6!BJ177 -> 42.2 | AD10: =A10 -> 32933 | AE10: =B10 -> 34 | AF10: =E10 -> 36.1 | AG10: =H10 -> 40.3 | AH10: =K10 -> 33 | AI10: =N10 -> 51.1 | AJ10: =Q10 -> 33 | AK10: =T10 -> 54.7 | AL10: =W10 -> 38.4 | AM10: =Z10 -> 36.8 | AP10: =A10 -> 32933 | AQ10: =C10 -> 36.4 | AR10: =F10 -> 39.9 | AS10: =I10 -> 37.1 | AT10: =L10 -> 36.1 | AU10: =O10 -> 34.8 | AV10: =R10 -> 45.6 | AW10: =U10 -> 39.8 | AX10: =X10 -> 30.9 | AY10: =AA10 -> 37.4 | BA10: =A10 -> 32933 | BB10: =D10 -> 42.1 | BC10: =G10 -> 42.6 | BD10: =J10 -> 39.9 | BE10: =M10 -> 42.6 | BF10: =P10 -> 43.6 | BG10: =S10 -> 45.9 | BH10: =V10 -> 41.3 | BI10: =Y10 -> 43.6 | BJ10: =AB10 -> 42.2
A11: =Data1!A178 -> 33025 | B11: =Data1!BL178 -> 34 | C11: =Data1!BM178 -> 36.6 | D11: =Data1!CR178 -> 42.1 | E11: =Data1!HH178 -> 36.1 | F11: =Data1!HI178 -> 40 | G11: =Data1!IN178 -> 42.6 | H11: =Data2!DN178 -> 40.3 | I11: =Data2!DO178 -> 37.1 | J11: =Data2!ET178 -> 39.8 | K11: =Data3!T178 -> 33 | L11: =Data3!U178 -> 36.3 | M11: =Data3!AZ178 -> 42.9 | N11: =Data3!FP178 -> 51.1 | O11: =Data3!FQ178 -> 34.9 | P11: =Data3!GV178 -> 44 | Q11: =Data4!BV178 -> 33 | R11: =Data4!BW178 -> 46.9 | S11: =Data4!DB178 -> 43.9 | T11: =Data4!HR178 -> 54.7 | U11: =Data4!HS178 -> 40.2 | V11: =Data5!H178 -> 42.1 | W11: =Data5!DX178 -> 38.4 | X11: =Data5!DY178 -> 33.5 | Y11: =Data5!FD178 -> 44.1 | Z11: =Data6!AD178 -> 36.8 | AA11: =Data6!AE178 -> 37.5 | AB11: =Data6!BJ178 -> 42.2 | AD11: =A11 -> 33025 | AE11: =B11 -> 34 | AF11: =E11 -> 36.1 | AG11: =H11 -> 40.3 | AH11: =K11 -> 33 | AI11: =N11 -> 51.1 | AJ11: =Q11 -> 33 | AK11: =T11 -> 54.7 | AL11: =W11 -> 38.4 | AM11: =Z11 -> 36.8 | AP11: =A11 -> 33025 | AQ11: =C11 -> 36.6 | AR11: =F11 -> 40 | AS11: =I11 -> 37.1 | AT11: =L11 -> 36.3 | AU11: =O11 -> 34.9 | AV11: =R11 -> 46.9 | AW11: =U11 -> 40.2 | AX11: =X11 -> 33.5 | AY11: =AA11 -> 37.5 | BA11: =A11 -> 33025 | BB11: =D11 -> 42.1 | BC11: =G11 -> 42.6 | BD11: =J11 -> 39.8 | BE11: =M11 -> 42.9 | BF11: =P11 -> 44 | BG11: =S11 -> 43.9 | BH11: =V11 -> 42.1 | BI11: =Y11 -> 44.1 | BJ11: =AB11 -> 42.2
A12: =Data1!A179 -> 33117 | B12: =Data1!BL179 -> 27.8 | C12: =Data1!BM179 -> 38.2 | D12: =Data1!CR179 -> 45.1 | E12: =Data1!HH179 -> 38.5 | F12: =Data1!HI179 -> 41.7 | G12: =Data1!IN179 -> 44.9 | H12: =Data2!DN179 -> 40.3 | I12: =Data2!DO179 -> 37.1 | J12: =Data2!ET179 -> 41.1 | K12: =Data3!T179 -> 34.1 | L12: =Data3!U179 -> 36.3 | M12: =Data3!AZ179 -> 44.7 | N12: =Data3!FP179 -> 55.1 | O12: =Data3!FQ179 -> 37.1 | P12: =Data3!GV179 -> 45.3 | Q12: =Data4!BV179 -> 35.3 | R12: =Data4!BW179 -> 46.3 | S12: =Data4!DB179 -> 45.6 | T12: =Data4!HR179 -> 54.7 | U12: =Data4!HS179 -> 40.4 | V12: =Data5!H179 -> 43.2 | W12: =Data5!DX179 -> 39.5 | X12: =Data5!DY179 -> 33.6 | Y12: =Data5!FD179 -> 45.8 | Z12: =Data6!AD179 -> 35.5 | AA12: =Data6!AE179 -> 38.9 | AB12: =Data6!BJ179 -> 44.5 | AD12: =A12 -> 33117 | AE12: =B12 -> 27.8 | AF12: =E12 -> 38.5 | AG12: =H12 -> 40.3 | AH12: =K12 -> 34.1 | AI12: =N12 -> 55.1 | AJ12: =Q12 -> 35.3 | AK12: =T12 -> 54.7 | AL12: =W12 -> 39.5 | AM12: =Z12 -> 35.5 | AP12: =A12 -> 33117 | AQ12: =C12 -> 38.2 | AR12: =F12 -> 41.7 | AS12: =I12 -> 37.1 | AT12: =L12 -> 36.3 | AU12: =O12 -> 37.1 | AV12: =R12 -> 46.3 | AW12: =U12 -> 40.4 | AX12: =X12 -> 33.6 | AY12: =AA12 -> 38.9 | BA12: =A12 -> 33117 | BB12: =D12 -> 45.1 | BC12: =G12 -> 44.9 | BD12: =J12 -> 41.1 | BE12: =M12 -> 44.7 | BF12: =P12 -> 45.3 | BG12: =S12 -> 45.6 | BH12: =V12 -> 43.2 | BI12: =Y12 -> 45.8 | BJ12: =AB12 -> 44.5
A13: =Data1!A180 -> 33208 | B13: =Data1!BL180 -> 35.5 | C13: =Data1!BM180 -> 39.1 | D13: =Data1!CR180 -> 53.1 | E13: =Data1!HH180 -> 38.5 | F13: =Data1!HI180 -> 42.3 | G13: =Data1!IN180 -> 55.8 | H13: =Data2!DN180 -> 40.3 | I13: =Data2!DO180 -> 38.8 | J13: =Data2!ET180 -> 49.6 | K13: =Data3!T180 -> 34.1 | L13: =Data3!U180 -> 36.7 | M13: =Data3!AZ180 -> 53.6 | N13: =Data3!FP180 -> 55.1 | O13: =Data3!FQ180 -> 38.3 | P13: =Data3!GV180 -> 54.6 | Q13: =Data4!BV180 -> 36.3 | R13: =Data4!BW180 -> 51.4 | S13: =Data4!DB180 -> 54.3 | T13: =Data4!HR180 -> 54.7 | U13: =Data4!HS180 -> 41.3 | V13: =Data5!H180 -> 52.7 | W13: =Data5!DX180 -> 40 | X13: =Data5!DY180 -> 34.8 | Y13: =Data5!FD180 -> 55.9 | Z13: =Data6!AD180 -> 38.6 | AA13: =Data6!AE180 -> 39.7 | AB13: =Data6!BJ180 -> 53.7 | AD13: =A13 -> 33208 | AE13: =B13 -> 35.5 | AF13: =E13 -> 38.5 | AG13: =H13 -> 40.3 | AH13: =K13 -> 34.1 | AI13: =N13 -> 55.1 | AJ13: =Q13 -> 36.3 | AK13: =T13 -> 54.7 | AL13: =W13 -> 40 | AM13: =Z13 -> 38.6 | AP13: =A13 -> 33208 | AQ13: =C13 -> 39.1 | AR13: =F13 -> 42.3 | AS13: =I13 -> 38.8 | AT13: =L13 -> 36.7 | AU13: =O13 -> 38.3 | AV13: =R13 -> 51.4 | AW13: =U13 -> 41.3 | AX13: =X13 -> 34.8 | AY13: =AA13 -> 39.7 | BA13: =A13 -> 33208 | BB13: =D13 -> 53.1 | BC13: =G13 -> 55.8 | BD13: =J13 -> 49.6 | BE13: =M13 -> 53.6 | BF13: =P13 -> 54.6 | BG13: =S13 -> 54.3 | BH13: =V13 -> 52.7 | BI13: =Y13 -> 55.9 | BJ13: =AB13 -> 53.7
A14: =Data1!A181 -> 33298 | B14: =Data1!BL181 -> 35.5 | C14: =Data1!BM181 -> 40.1 | D14: =Data1!CR181 -> 44.7 | E14: =Data1!HH181 -> 38.5 | F14: =Data1!HI181 -> 42.1 | G14: =Data1!IN181 -> 47.7 | H14: =Data2!DN181 -> 41.5 | I14: =Data2!DO181 -> 40.5 | J14: =Data2!ET181 -> 41.6 | K14: =Data3!T181 -> 34.1 | L14: =Data3!U181 -> 38.5 | M14: =Data3!AZ181 -> 45.1 | N14: =Data3!FP181 -> 55.1 | O14: =Data3!FQ181 -> 38.2 | P14: =Data3!GV181 -> 45.7 | Q14: =Data4!BV181 -> 36.3 | R14: =Data4!BW181 -> 54.9 | S14: =Data4!DB181 -> 46.4 | T14: =Data4!HR181 -> 54.7 | U14: =Data4!HS181 -> 43.2 | V14: =Data5!H181 -> 45.8 | W14: =Data5!DX181 -> 40 | X14: =Data5!DY181 -> 36.1 | Y14: =Data5!FD181 -> 47.9 | Z14: =Data6!AD181 -> 38.7 | AA14: =Data6!AE181 -> 40 | AB14: =Data6!BJ181 -> 45.4 | AD14: =A14 -> 33298 | AE14: =B14 -> 35.5 | AF14: =E14 -> 38.5 | AG14: =H14 -> 41.5 | AH14: =K14 -> 34.1 | AI14: =N14 -> 55.1 | AJ14: =Q14 -> 36.3 | AK14: =T14 -> 54.7 | AL14: =W14 -> 40 | AM14: =Z14 -> 38.7 | AP14: =A14 -> 33298 | AQ14: =C14 -> 40.1 | AR14: =F14 -> 42.1 | AS14: =I14 -> 40.5 | AT14: =L14 -> 38.5 | AU14: =O14 -> 38.2 | AV14: =R14 -> 54.9 | AW14: =U14 -> 43.2 | AX14: =X14 -> 36.1 | AY14: =AA14 -> 40 | BA14: =A14 -> 33298 | BB14: =D14 -> 44.7 | BC14: =G14 -> 47.7 | BD14: =J14 -> 41.6 | BE14: =M14 -> 45.1 | BF14: =P14 -> 45.7 | BG14: =S14 -> 46.4 | BH14: =V14 -> 45.8 | BI14: =Y14 -> 47.9 | BJ14: =AB14 -> 45.4
A15: =Data1!A182 -> 33390 | B15: =Data1!BL182 -> 35.5 | C15: =Data1!BM182 -> 39.1 | D15: =Data1!CR182 -> 41.6 | E15: =Data1!HH182 -> 38.5 | F15: =Data1!HI182 -> 41.8 | G15: =Data1!IN182 -> 45 | H15: =Data2!DN182 -> 41.5 | I15: =Data2!DO182 -> 40.5 | J15: =Data2!ET182 -> 39.2 | K15: =Data3!T182 -> 34.1 | L15: =Data3!U182 -> 38.7 | M15: =Data3!AZ182 -> 42.8 | N15: =Data3!FP182 -> 55.1 | O15: =Data3!FQ182 -> 38.2 | P15: =Data3!GV182 -> 44.7 | Q15: =Data4!BV182 -> 36.3 | R15: =Data4!BW182 -> 52.3 | S15: =Data4!DB182 -> 45.2 | T15: =Data4!HR182 -> 56.5 | U15: =Data4!HS182 -> 42.3 | V15: =Data5!H182 -> 44.2 | W15: =Data5!DX182 -> 40 | X15: =Data5!DY182 -> 36.2 | Y15: =Data5!FD182 -> 45.4 | Z15: =Data6!AD182 -> 38.7 | AA15: =Data6!AE182 -> 39.8 | AB15: =Data6!BJ182 -> 42.9 | AD15: =A15 -> 33390 | AE15: =B15 -> 35.5 | AF15: =E15 -> 38.5 | AG15: =H15 -> 41.5 | AH15: =K15 -> 34.1 | AI15: =N15 -> 55.1 | AJ15: =Q15 -> 36.3 | AK15: =T15 -> 56.5 | AL15: =W15 -> 40 | AM15: =Z15 -> 38.7 | AP15: =A15 -> 33390 | AQ15: =C15 -> 39.1 | AR15: =F15 -> 41.8 | AS15: =I15 -> 40.5 | AT15: =L15 -> 38.7 | AU15: =O15 -> 38.2 | AV15: =R15 -> 52.3 | AW15: =U15 -> 42.3 | AX15: =X15 -> 36.2 | AY15: =AA15 -> 39.8 | BA15: =A15 -> 33390 | BB15: =D15 -> 41.6 | BC15: =G15 -> 45 | BD15: =J15 -> 39.2 | BE15: =M15 -> 42.8 | BF15: =P15 -> 44.7 | BG15: =S15 -> 45.2 | BH15: =V15 -> 44.2 | BI15: =Y15 -> 45.4 | BJ15: =AB15 -> 42.9
A16: =Data1!A183 -> 33482 | B16: =Data1!BL183 -> 36.8 | C16: =Data1!BM183 -> 40 | D16: =Data1!CR183 -> 44.9 | E16: =Data1!HH183 -> 41 | F16: =Data1!HI183 -> 44.1 | G16: =Data1!IN183 -> 47.1 | H16: =Data2!DN183 -> 41.5 | I16: =Data2!DO183 -> 40.5 | J16: =Data2!ET183 -> 41.2 | K16: =Data3!T183 -> 36.1 | L16: =Data3!U183 -> 38.7 | M16: =Data3!AZ183 -> 45.4 | N16: =Data3!FP183 -> 56.2 | O16: =Data3!FQ183 -> 38.6 | P16: =Data3!GV183 -> 45.9 | Q16: =Data4!BV183 -> 37.6 | R16: =Data4!BW183 -> 50.2 | S16: =Data4!DB183 -> 46.9 | T16: =Data4!HR183 -> 58.3 | U16: =Data4!HS183 -> 42.2 | V16: =Data5!H183 -> 45 | W16: =Data5!DX183 -> 41.3 | X16: =Data5!DY183 -> 36 | Y16: =Data5!FD183 -> 47.7 | Z16: =Data6!AD183 -> 40.3 | AA16: =Data6!AE183 -> 41.1 | AB16: =Data6!BJ183 -> 45.3 | AD16: =A16 -> 33482 | AE16: =B16 -> 36.8 | AF16: =E16 -> 41 | AG16: =H16 -> 41.5 | AH16: =K16 -> 36.1 | AI16: =N16 -> 56.2 | AJ16: =Q16 -> 37.6 | AK16: =T16 -> 58.3 | AL16: =W16 -> 41.3 | AM16: =Z16 -> 40.3 | AP16: =A16 -> 33482 | AQ16: =C16 -> 40 | AR16: =F16 -> 44.1 | AS16: =I16 -> 40.5 | AT16: =L16 -> 38.7 | AU16: =O16 -> 38.6 | AV16: =R16 -> 50.2 | AW16: =U16 -> 42.2 | AX16: =X16 -> 36 | AY16: =AA16 -> 41.1 | BA16: =A16 -> 33482 | BB16: =D16 -> 44.9 | BC16: =G16 -> 47.1 | BD16: =J16 -> 41.2 | BE16: =M16 -> 45.4 | BF16: =P16 -> 45.9 | BG16: =S16 -> 46.9 | BH16: =V16 -> 45 | BI16: =Y16 -> 47.7 | BJ16: =AB16 -> 45.3
A17: =Data1!A184 -> 33573 | B17: =Data1!BL184 -> 37.3 | C17: =Data1!BM184 -> 40 | D17: =Data1!CR184 -> 44.6 | E17: =Data1!HH184 -> 41 | F17: =Data1!HI184 -> 44.1 | G17: =Data1!IN184 -> 46.7 | H17: =Data2!DN184 -> 41.5 | I17: =Data2!DO184 -> 40.5 | J17: =Data2!ET184 -> 41.1 | K17: =Data3!T184 -> 36.1 | L17: =Data3!U184 -> 38.6 | M17: =Data3!AZ184 -> 46 | N17: =Data3!FP184 -> 56.2 | O17: =Data3!FQ184 -> 38.6 | P17: =Data3!GV184 -> 45.5 | Q17: =Data4!BV184 -> 38.3 | R17: =Data4!BW184 -> 48.9 | S17: =Data4!DB184 -> 46.4 | T17: =Data4!HR184 -> 58.3 | U17: =Data4!HS184 -> 42.2 | V17: =Data5!H184 -> 44.9 | W17: =Data5!DX184 -> 41.3 | X17: =Data5!DY184 -> 36.2 | Y17: =Data5!FD184 -> 47.9 | Z17: =Data6!AD184 -> 40.4 | AA17: =Data6!AE184 -> 41.1 | AB17: =Data6!BJ184 -> 45.1 | AD17: =A17 -> 33573 | AE17: =B17 -> 37.3 | AF17: =E17 -> 41 | AG17: =H17 -> 41.5 | AH17: =K17 -> 36.1 | AI17: =N17 -> 56.2 | AJ17: =Q17 -> 38.3 | AK17: =T17 -> 58.3 | AL17: =W17 -> 41.3 | AM17: =Z17 -> 40.4 | AP17: =A17 -> 33573 | AQ17: =C17 -> 40 | AR17: =F17 -> 44.1 | AS17: =I17 -> 40.5 | AT17: =L17 -> 38.6 | AU17: =O17 -> 38.6 | AV17: =R17 -> 48.9 | AW17: =U17 -> 42.2 | AX17: =X17 -> 36.2 | AY17: =AA17 -> 41.1 | BA17: =A17 -> 33573 | BB17: =D17 -> 44.6 | BC17: =G17 -> 46.7 | BD17: =J17 -> 41.1 | BE17: =M17 -> 46 | BF17: =P17 -> 45.5 | BG17: =S17 -> 46.4 | BH17: =V17 -> 44.9 | BI17: =Y17 -> 47.9 | BJ17: =AB17 -> 45.1
A18: =Data1!A185 -> 33664 | B18: =Data1!BL185 -> 37.3 | C18: =Data1!BM185 -> 40 | D18: =Data1!CR185 -> 44.3 | E18: =Data1!HH185 -> 41 | F18: =Data1!HI185 -> 44.1 | G18: =Data1!IN185 -> 46.2 | H18: =Data2!DN185 -> 41.9 | I18: =Data2!DO185 -> 40.5 | J18: =Data2!ET185 -> 40.4 | K18: =Data3!T185 -> 36.1 | L18: =Data3!U185 -> 39.8 | M18: =Data3!AZ185 -> 44.7 | N18: =Data3!FP185 -> 56.2 | O18: =Data3!FQ185 -> 38.6 | P18: =Data3!GV185 -> 45.2 | Q18: =Data4!BV185 -> 38.3 | R18: =Data4!BW185 -> 50.1 | S18: =Data4!DB185 -> 45.8 | T18: =Data4!HR185 -> 58.3 | U18: =Data4!HS185 -> 43 | V18: =Data5!H185 -> 44.8 | W18: =Data5!DX185 -> 41.3 | X18: =Data5!DY185 -> 36.2 | Y18: =Data5!FD185 -> 47.4 | Z18: =Data6!AD185 -> 40.5 | AA18: =Data6!AE185 -> 41.3 | AB18: =Data6!BJ185 -> 44.6 | AD18: =A18 -> 33664 | AE18: =B18 -> 37.3 | AF18: =E18 -> 41 | AG18: =H18 -> 41.9 | AH18: =K18 -> 36.1 | AI18: =N18 -> 56.2 | AJ18: =Q18 -> 38.3 | AK18: =T18 -> 58.3 | AL18: =W18 -> 41.3 | AM18: =Z18 -> 40.5 | AP18: =A18 -> 33664 | AQ18: =C18 -> 40 | AR18: =F18 -> 44.1 | AS18: =I18 -> 40.5 | AT18: =L18 -> 39.8 | AU18: =O18 -> 38.6 | AV18: =R18 -> 50.1 | AW18: =U18 -> 43 | AX18: =X18 -> 36.2 | AY18: =AA18 -> 41.3 | BA18: =A18 -> 33664 | BB18: =D18 -> 44.3 | BC18: =G18 -> 46.2 | BD18: =J18 -> 40.4 | BE18: =M18 -> 44.7 | BF18: =P18 -> 45.2 | BG18: =S18 -> 45.8 | BH18: =V18 -> 44.8 | BI18: =Y18 -> 47.4 | BJ18: =AB18 -> 44.6
A19: =Data1!A186 -> 33756 | B19: =Data1!BL186 -> 37.3 | C19: =Data1!BM186 -> 39.9 | D19: =Data1!CR186 -> 44 | E19: =Data1!HH186 -> 41 | F19: =Data1!HI186 -> 44 | G19: =Data1!IN186 -> 46.4 | H19: =Data2!DN186 -> 42.4 | I19: =Data2!DO186 -> 40.5 | J19: =Data2!ET186 -> 40.7 | K19: =Data3!T186 -> 36.1 | L19: =Data3!U186 -> 39.6 | M19: =Data3!AZ186 -> 45.5 | N19: =Data3!FP186 -> 56.2 | O19: =Data3!FQ186 -> 38.3 | P19: =Data3!GV186 -> 45.7 | Q19: =Data4!BV186 -> 38.3 | R19: =Data4!BW186 -> 49.2 | S19: =Data4!DB186 -> 45.5 | T19: =Data4!HR186 -> 58.3 | U19: =Data4!HS186 -> 43.4 | V19: =Data5!H186 -> 45.2 | W19: =Data5!DX186 -> 41.3 | X19: =Data5!DY186 -> 36.2 | Y19: =Data5!FD186 -> 48 | Z19: =Data6!AD186 -> 40.5 | AA19: =Data6!AE186 -> 41.2 | AB19: =Data6!BJ186 -> 44.8 | AD19: =A19 -> 33756 | AE19: =B19 -> 37.3 | AF19: =E19 -> 41 | AG19: =H19 -> 42.4 | AH19: =K19 -> 36.1 | AI19: =N19 -> 56.2 | AJ19: =Q19 -> 38.3 | AK19: =T19 -> 58.3 | AL19: =W19 -> 41.3 | AM19: =Z19 -> 40.5 | AP19: =A19 -> 33756 | AQ19: =C19 -> 39.9 | AR19: =F19 -> 44 | AS19: =I19 -> 40.5 | AT19: =L19 -> 39.6 | AU19: =O19 -> 38.3 | AV19: =R19 -> 49.2 | AW19: =U19 -> 43.4 | AX19: =X19 -> 36.2 | AY19: =AA19 -> 41.2 | BA19: =A19 -> 33756 | BB19: =D19 -> 44 | BC19: =G19 -> 46.4 | BD19: =J19 -> 40.7 | BE19: =M19 -> 45.5 | BF19: =P19 -> 45.7 | BG19: =S19 -> 45.5 | BH19: =V19 -> 45.2 | BI19: =Y19 -> 48 | BJ19: =AB19 -> 44.8
... A127: =Data1!A294 -> 43617 | B127: =Data1!BL294 -> 135.2 | C127: =Data1!BM294 -> 130.3 | D127: =Data1!CR294 -> 104.3 | E127: =Data1!HH294 -> 144.5 | F127: =Data1!HI294 -> 158.7 | G127: =Data1!IN294 -> 104.9 | H127: =Data2!DN294 -> 133.8 | I127: =Data2!DO294 -> 133.7 | J127: =Data2!ET294 -> 102.1 | K127: =Data3!T294 -> 141.9 | L127: =Data3!U294 -> 142.5 | M127: =Data3!AZ294 -> 105 | N127: =Data3!FP294 -> 143.2 | O127: =Data3!FQ294 -> 119.3 | P127: =Data3!GV294 -> 102.4 | Q127: =Data4!BV294 -> 106.8 | R127: =Data4!BW294 -> 124.4 | S127: =Data4!DB294 -> 102.7 | T127: =Data4!HR294 -> 130.3 | U127: =Data4!HS294 -> 109.3 | V127: =Data5!H294 -> 95.1 | W127: =Data5!DX294 -> 138.3 | X127: =Data5!DY294 -> 157.5 | Y127: =Data5!FD294 -> 102.1 | Z127: =Data6!AD294 -> 138.4 | AA127: =Data6!AE294 -> 144 | AB127: =Data6!BJ294 -> 103.8 | AD127: =A127 -> 43617 | AE127: =B127 -> 135.2 | AF127: =E127 -> 144.5 | AG127: =H127 -> 133.8 | AH127: =K127 -> 141.9 | AI127: =N127 -> 143.2 | AJ127: =Q127 -> 106.8 | AK127: =T127 -> 130.3 | AL127: =W127 -> 138.3 | AM127: =Z127 -> 138.4 | AP127: =A127 -> 43617 | AQ127: =C127 -> 130.3 | AR127: =F127 -> 158.7 | AS127: =I127 -> 133.7 | AT127: =L127 -> 142.5 | AU127: =O127 -> 119.3 | AV127: =R127 -> 124.4 | AW127: =U127 -> 109.3 | AX127: =X127 -> 157.5 | AY127: =AA127 -> 144 | BA127: =A127 -> 43617 | BB127: =D127 -> 104.3 | BC127: =G127 -> 104.9 | BD127: =J127 -> 102.1 | BE127: =M127 -> 105 | BF127: =P127 -> 102.4 | BG127: =S127 -> 102.7 | BH127: =V127 -> 95.1 | BI127: =Y127 -> 102.1 | BJ127: =AB127 -> 103.8
A130: 2. Summary Statistics (Sep-1989 to Jun-2019, index 2011–12 = 100)
A132: Electricity
A133: City | B133: Mean | C133: Median | D133: Std Dev | E133: Min | F133: Max | G133: Start (Sep-89) | H133: Latest (Jun-19) | I133: Total % change | J133: Avg annual %
A134: Sydney | B134: =AVERAGE(B$8:B$127) -> 66.723333 | C134: =MEDIAN(B$8:B$127) -> 47.45 | D134: =_xlfn.STDEV.S(B$8:B$127) -> 35.189818 | E134: =MIN(B$8:B$127) -> 27.8 | F134: =MAX(B$8:B$127) -> 140.5 | G134: =B$8 -> 34 | H134: =B$127 -> 135.2 | I134: =(B$127/B$8)-1 -> 2.9764706 | J134: =(B$127/B$8)^(1/(($A$127-$A$8)/365.25))-1 -> 0.047498448
A135: Melbourne | B135: =AVERAGE(E$8:E$127) -> 72.353333 | C135: =MEDIAN(E$8:E$127) -> 55.05 | D135: =_xlfn.STDEV.S(E$8:E$127) -> 35.020136 | E135: =MIN(E$8:E$127) -> 35.3 | F135: =MAX(E$8:E$127) -> 152.7 | G135: =E$8 -> 35.3 | H135: =E$127 -> 144.5 | I135: =(E$127/E$8)-1 -> 3.0934844 | J135: =(E$127/E$8)^(1/(($A$127-$A$8)/365.25))-1 -> 0.048520216
A136: Brisbane | B136: =AVERAGE(H$8:H$127) -> 74.1 | C136: =MEDIAN(H$8:H$127) -> 54.8 | D136: =_xlfn.STDEV.S(H$8:H$127) -> 38.403094 | E136: =MIN(H$8:H$127) -> 40.3 | F136: =MAX(H$8:H$127) -> 151.1 | G136: =H$8 -> 40.3 | H136: =H$127 -> 133.8 | I136: =(H$127/H$8)-1 -> 2.3200993 | J136: =(H$127/H$8)^(1/(($A$127-$A$8)/365.25))-1 -> 0.041165089
A137: Adelaide | B137: =AVERAGE(K$8:K$127) -> 69.184167 | C137: =MEDIAN(K$8:K$127) -> 61.3 | D137: =_xlfn.STDEV.S(K$8:K$127) -> 34.956686 | E137: =MIN(K$8:K$127) -> 33 | F137: =MAX(K$8:K$127) -> 147.4 | G137: =K$8 -> 33 | H137: =K$127 -> 141.9 | I137: =(K$127/K$8)-1 -> 3.3 | J137: =(K$127/K$8)^(1/(($A$127-$A$8)/365.25))-1 -> 0.050256516
A138: Perth | B138: =AVERAGE(N$8:N$127) -> 77.544167 | C138: =MEDIAN(N$8:N$127) -> 63.7 | D138: =_xlfn.STDEV.S(N$8:N$127) -> 27.457282 | E138: =MIN(N$8:N$127) -> 51.1 | F138: =MAX(N$8:N$127) -> 143.2 | G138: =N$8 -> 51.1 | H138: =N$127 -> 143.2 | I138: =(N$127/N$8)-1 -> 1.8023483 | J138: =(N$127/N$8)^(1/(($A$127-$A$8)/365.25))-1 -> 0.03524801
A139: Hobart | B139: =AVERAGE(Q$8:Q$127) -> 66.298333 | C139: =MEDIAN(Q$8:Q$127) -> 57.8 | D139: =_xlfn.STDEV.S(Q$8:Q$127) -> 26.052271 | E139: =MIN(Q$8:Q$127) -> 31.3 | F139: =MAX(Q$8:Q$127) -> 112.7 | G139: =Q$8 -> 31.3 | H139: =Q$127 -> 106.8 | I139: =(Q$127/Q$8)-1 -> 2.4121406 | J139: =(Q$127/Q$8)^(1/(($A$127-$A$8)/365.25))-1 -> 0.042122636
A140: Darwin | B140: =AVERAGE(T$8:T$127) -> 82.725833 | C140: =MEDIAN(T$8:T$127) -> 68.6 | D140: =_xlfn.STDEV.S(T$8:T$127) -> 28.239354 | E140: =MIN(T$8:T$127) -> 54.7 | F140: =MAX(T$8:T$127) -> 137.9 | G140: =T$8 -> 54.7 | H140: =T$127 -> 130.3 | I140: =(T$127/T$8)-1 -> 1.3820841 | J140: =(T$127/T$8)^(1/(($A$127-$A$8)/365.25))-1 -> 0.029608718
A141: Canberra | B141: =AVERAGE(W$8:W$127) -> 73.500833 | C141: =MEDIAN(W$8:W$127) -> 63.5 | D141: =_xlfn.STDEV.S(W$8:W$127) -> 31.168422 | E141: =MIN(W$8:W$127) -> 38 | F141: =MAX(W$8:W$127) -> 140.4 | G141: =W$8 -> 38 | H141: =W$127 -> 138.3 | I141: =(W$127/W$8)-1 -> 2.6394737 | J141: =(W$127/W$8)^(1/(($A$127-$A$8)/365.25))-1 -> 0.0443847
A142: Australia | B142: =AVERAGE(Z$8:Z$127) -> 70.6375 | C142: =MEDIAN(Z$8:Z$127) -> 54.4 | D142: =_xlfn.STDEV.S(Z$8:Z$127) -> 34.330348 | E142: =MIN(Z$8:Z$127) -> 35.5 | F142: =MAX(Z$8:Z$127) -> 141.6 | G142: =Z$8 -> 36.5 | H142: =Z$127 -> 138.4 | I142: =(Z$127/Z$8)-1 -> 2.7917808 | J142: =(Z$127/Z$8)^(1/(($A$127-$A$8)/365.25))-1 -> 0.045825054
A144: Gas and other household fuels
A145: City | B145: Mean | C145: Median | D145: Std Dev | E145: Min | F145: Max | G145: Start (Sep-89) | H145: Latest (Jun-19) | I145: Total % change | J145: Avg annual %
A146: Sydney | B146: =AVERAGE(C$8:C$127) -> 75.134167 | C146: =MEDIAN(C$8:C$127) -> 68.7 | D146: =_xlfn.STDEV.S(C$8:C$127) -> 33.868615 | E146: =MIN(C$8:C$127) -> 34.9 | F146: =MAX(C$8:C$127) -> 140.9 | G146: =C$8 -> 34.9 | H146: =C$127 -> 130.3 | I146: =(C$127/C$8)-1 -> 2.7335244 | J146: =(C$127/C$8)^(1/(($A$127-$A$8)/365.25))-1 -> 0.045280846
A147: Melbourne | B147: =AVERAGE(F$8:F$127) -> 78.556667 | C147: =MEDIAN(F$8:F$127) -> 63.85 | D147: =_xlfn.STDEV.S(F$8:F$127) -> 35.634328 | E147: =MIN(F$8:F$127) -> 38.9 | F147: =MAX(F$8:F$127) -> 163.8 | G147: =F$8 -> 38.9 | H147: =F$127 -> 158.7 | I147: =(F$127/F$8)-1 -> 3.0796915 | J147: =(F$127/F$8)^(1/(($A$127-$A$8)/365.25))-1 -> 0.048401254
A148: Brisbane | B148: =AVERAGE(I$8:I$127) -> 72.4675 | C148: =MEDIAN(I$8:I$127) -> 52.8 | D148: =_xlfn.STDEV.S(I$8:I$127) -> 34.861197 | E148: =MIN(I$8:I$127) -> 35.4 | F148: =MAX(I$8:I$127) -> 135.1 | G148: =I$8 -> 35.4 | H148: =I$127 -> 133.7 | I148: =(I$127/I$8)-1 -> 2.7768362 | J148: =(I$127/I$8)^(1/(($A$127-$A$8)/365.25))-1 -> 0.045686222
A149: Adelaide | B149: =AVERAGE(L$8:L$127) -> 77.159167 | C149: =MEDIAN(L$8:L$127) -> 64.55 | D149: =_xlfn.STDEV.S(L$8:L$127) -> 38.334693 | E149: =MIN(L$8:L$127) -> 34.5 | F149: =MAX(L$8:L$127) -> 150 | G149: =L$8 -> 34.5 | H149: =L$127 -> 142.5 | I149: =(L$127/L$8)-1 -> 3.1304348 | J149: =(L$127/L$8)^(1/(($A$127-$A$8)/365.25))-1 -> 0.048837009
A150: Perth | B150: =AVERAGE(O$8:O$127) -> 66.766667 | C150: =MEDIAN(O$8:O$127) -> 50.35 | D150: =_xlfn.STDEV.S(O$8:O$127) -> 32.84808 | E150: =MIN(O$8:O$127) -> 34.6 | F150: =MAX(O$8:O$127) -> 123.9 | G150: =O$8 -> 34.6 | H150: =O$127 -> 119.3 | I150: =(O$127/O$8)-1 -> 2.4479769 | J150: =(O$127/O$8)^(1/(($A$127-$A$8)/365.25))-1 -> 0.04248872
A151: Hobart | B151: =AVERAGE(R$8:R$127) -> 77.354167 | C151: =MEDIAN(R$8:R$127) -> 73.25 | D151: =_xlfn.STDEV.S(R$8:R$127) -> 25.040813 | E151: =MIN(R$8:R$127) -> 43.9 | F151: =MAX(R$8:R$127) -> 124.8 | G151: =R$8 -> 43.9 | H151: =R$127 -> 124.4 | I151: =(R$127/R$8)-1 -> 1.833713 | J151: =(R$127/R$8)^(1/(($A$127-$A$8)/365.25))-1 -> 0.035635433
A152: Darwin | B152: =AVERAGE(U$8:U$127) -> 75.468333 | C152: =MEDIAN(U$8:U$127) -> 71.7 | D152: =_xlfn.STDEV.S(U$8:U$127) -> 25.236328 | E152: =MIN(U$8:U$127) -> 37.4 | F152: =MAX(U$8:U$127) -> 116.5 | G152: =U$8 -> 37.4 | H152: =U$127 -> 109.3 | I152: =(U$127/U$8)-1 -> 1.9224599 | J152: =(U$127/U$8)^(1/(($A$127-$A$8)/365.25))-1 -> 0.036709611
...

Sheet Data1
B1: Index Numbers ; Food and non-alcoholic beverages ; Sydney ; | C1: Index Numbers ; Bread and cereal products ; Sydney ; | D1: Index Numbers ; Bread ; Sydney ; | E1: Index Numbers ; Cakes and biscuits ; Sydney ; | F1: Index Numbers ; Breakfast cereals ; Sydney ; | G1: Index Numbers ; Other cereal products ; Sydney ; | H1: Index Numbers ; Meat and seafoods ; Sydney ; | I1: Index Numbers ; Beef and veal ; Sydney ; | J1: Index Numbers ; Pork ; Sydney ; | K1: Index Numbers ; Lamb and goat ; Sydney ; | L1: Index Numbers ; Poultry ; Sydney ; | M1: Index Numbers ; Other meats ; Sydney ; | N1: Index Numbers ; Fish and other seafood ; Sydney ; | O1: Index Numbers ; Dairy and related products ; Sydney ; | P1: Index Numbers ; Milk ; Sydney ; | Q1: Index Numbers ; Cheese ; Sydney ; | R1: Index Numbers ; Ice cream and other dairy products ; Sydney ; | S1: Index Numbers ; Fruit and vegetables ; Sydney ; | T1: Index Numbers ; Fruit ; Sydney ; | U1: Index Numbers ; Vegetables ; Sydney ; | V1: Index Numbers ; Food products n.e.c. ; Sydney ; | W1: Index Numbers ; Eggs ; Sydney ; | X1: Index Numbers ; Jams, honey and spreads ; Sydney ; | Y1: Index Numbers ; Food additives and condiments ; Sydney ; | Z1: Index Numbers ; Oils and fats ; Sydney ; | AA1: Index Numbers ; Snacks and confectionery ; Sydney ; | AB1: Index Numbers ; Other food products n.e.c. ; Sydney ; | AC1: Index Numbers ; Non-alcoholic beverages ; Sydney ; | AD1: Index Numbers ; Coffee, tea and cocoa ; Sydney ; | AE1: Index Numbers ; Waters, soft drinks and juices ; Sydney ; | AF1: Index Numbers ; Meals out and take away foods ; Sydney ; | AG1: Index Numbers ; Restaurant meals ; Sydney ; | AH1: Index Numbers ; Take away and fast foods ; Sydney ; | AI1: Index Numbers ; Alcohol and tobacco ; Sydney ; | AJ1: Index Numbers ; Alcoholic beverages ; Sydney ; | AK1: Index Numbers ; Spirits ; Sydney ; | AL1: Index Numbers ; Wine ; Sydney ; | AM1: Index Numbers ; Beer ; Sydney ; | AN1: Index Numbers ; Tobacco ; Sydney ; | AO1: Index Numbers ; Tobacco ; Sydney ; | AP1: Index Numbers ; Clothing and footwear ; Sydney ; | AQ1: Index Numbers ; Garments ; Sydney ; | AR1: Index Numbers ; Garments for men ; Sydney ; | AS1: Index Numbers ; Garments for women ; Sydney ; | AT1: Index Numbers ; Garments for infants and children ; Sydney ; | AU1: Index Numbers ; Footwear ; Sydney ; | AV1: Index Numbers ; Footwear for men ; Sydney ; | AW1: Index Numbers ; Footwear for women ; Sydney ; | AX1: Index Numbers ; Footwear for infants and children ; Sydney ; | AY1: Index Numbers ; Accessories and clothing services ; Sydney ; | AZ1: Index Numbers ; Accessories ; Sydney ; | BA1: Index Numbers ; Cleaning, repair and hire of clothing and footwear ; Sydney ; | BB1: Index Numbers ; Housing ; Sydney ; | BC1: Index Numbers ; Rents ; Sydney ; | BD1: Index Numbers ; Rents ; Sydney ; | BE1: Index Numbers ; New dwelling purchase by owner-occupiers ; Sydney ; | BF1: Index Numbers ; New dwelling purchase by owner-occupiers ; Sydney ; | BG1: Index Numbers ; Other housing ; Sydney ; | BH1: Index Numbers ; Maintenance and repair of the dwelling ; Sydney ; | BI1: Index Numbers ; Property rates and charges ; Sydney ; | BJ1: Index Numbers ; Utilities ; Sydney ; | BK1: Index Numbers ; Water and sewerage ; Sydney ; | BL1: Index Numbers ; Electricity ; Sydney ; | BM1: Index Numbers ; Gas and other household fuels ; Sydney ; | BN1: Index Numbers ; Furnishings, household equipment and services ; Sydney ; | BO1: Index Numbers ; Furniture and furnishings ; Sydney ; | BP1: Index Numbers ; Furniture ; Sydney ; | BQ1: Index Numbers ; Carpets and other floor coverings ; Sydney ; | BR1: Index Numbers ; Household textiles ; Sydney ; | BS1: Index Numbers ; Household textiles ; Sydney ; | BT1: Index Numbers ; Household appliances, utensils and tools ; Sydney ; | BU1: Index Numbers ; Major household appliances ; Sydney ; | BV1: Index Numbers ; Small electric household appliances ; Sydney ; | BW1: Index Numbers ; Glassware, tableware and household utensils ; Sydney ; | BX1: Index Numbers ; Tools and equipment for house and garden ; Sydney ; | BY1: Index Numbers ; Non-durable household products ; Sydney ; | BZ1: Index Numbers ; Cleaning and maintenance products ; Sydney ; | CA1: Index Numbers ; Personal care products ; Sydney ; | CB1: Index Numbers ; Other non-durable household products ; Sydney ; | CC1: Index Numbers ; Domestic and household services ; Sydney ; | CD1: Index Numbers ; Child care ; Sydney ; | CE1: Index Numbers ; Hairdressing and personal grooming services ; Sydney ; | CF1: Index Numbers ; Other household services ; Sydney ; | CG1: Index Numbers ; Health ; Sydney ; | CH1: Index Numbers ; Medical products, appliances and equipment ; Sydney ; | CI1: Index Numbers ; Pharmaceutical products ; Sydney ; | CJ1: Index Numbers ; Therapeutic appliances and equipment ; Sydney ; | CK1: Index Numbers ; Medical, dental and hospital services ; Sydney ; | CL1: Index Numbers ; Medical and hospital services ; Sydney ; | CM1: Index Numbers ; Dental services ; Sydney ; | CN1: Index Numbers ; Transport ; Sydney ; | CO1: Index Numbers ; Private motoring ; Sydney ; | CP1: Index Numbers ; Motor vehicles ; Sydney ; | CQ1: Index Numbers ; Spare parts and accessories for motor vehicles ; Sydney ; | CR1: Index Numbers ; Automotive fuel ; Sydney ; | CS1: Index Numbers ; Maintenance and repair of motor vehicles ; Sydney ; | CT1: Index Numbers ; Other services in respect of motor vehicles ; Sydney ; | CU1: Index Numbers ; Urban transport fares ; Sydney ; | CV1: Index Numbers ; Urban transport fares ; Sydney ; | CW1: Index Numbers ; Communication ; Sydney ; | CX1: Index Numbers ; Communication ; Sydney ; | CY1: Index Numbers ; Postal services ; Sydney ; | CZ1: Index Numbers ; Telecommunication equipment and services ; Sydney ; | DA1: Index Numbers ; Recreation and culture ; Sydney ; | DB1: Index Numbers ; Audio, visual and computing equipment and services ; Sydney ; | DC1: Index Numbers ; Audio, visual and computing equipment ; Sydney ; | DD1: Index Numbers ; Audio, visual and computing media and services ; Sydney ; | DE1: Index Numbers ; Newspapers, books and stationery ; Sydney ; | DF1: Index Numbers ; Books ; Sydney ; | DG1: Index Numbers ; Newspapers, magazines and stationery ; Sydney ; | DH1: Index Numbers ; Holiday travel and accommodation ; Sydney ; | DI1: Index Numbers ; Domestic holiday travel and accommodation ; Sydney ; | DJ1: Index Numbers ; International holiday travel and accommodation ; Sydney ; | DK1: Index Numbers ; Other recreation, sport and culture ; Sydney ; | DL1: Index Numbers ; Equipment for sports, camping and open-air recreation ; Sydney ; | DM1: Index Numbers ; Games, toys and hobbies ; Sydney ; | DN1: Index Numbers ; Pets and related products ; Sydney ; | DO1: Index Numbers ; Veterinary and other services for pets ; Sydney ; | DP1: Index Numbers ; Sports participation ; Sydney ; | DQ1: Index Numbers ; Other recreational, sporting and cultural services ; Sydney ; | DR1: Index Numbers ; Education ; Sydney ; | DS1: Index Numbers ; Education ; Sydney ; | DT1: Index Numbers ; Preschool and primary education ; Sydney ; | DU1: Index Numbers ; Secondary education ; Sydney ; | DV1: Index Numbers ; Tertiary education ; Sydney ; | DW1: Index Numbers ; Insurance and financial services ; Sydney ; | DX1: Index Numbers ; Insurance ; Sydney ; | DY1: Index Numbers ; Insurance ; Sydney ; | DZ1: Index Numbers ; Financial services ; Sydney ; | EA1: Index Numbers ; Deposit and loan facilities (direct charges) ; Sydney ; | EB1: Index Numbers ; Other financial services ; Sydney ; | EC1: Index Numbers ; All groups CPI ; Sydney ; | ED1: Index Numbers ; Tradables ; Sydney ; | EE1: Index Numbers ; Non-tradables ; Sydney ; | EF1: Index Numbers ; All groups, goods component ; Sydney ; | EG1: Index Numbers ; All groups, services component ; Sydney ; | EH1: Index Numbers ; All groups CPI including deposit and loan facilities (indirect charges) ; Sydney ; | EI1: Index Numbers ; All groups CPI excluding Food and non-alcoholic beverages ; Sydney ; | EJ1: Index Numbers ; All groups CPI excluding Alcohol and tobacco ; Sydney ; | EK1: Index Numbers ; All groups CPI excluding Clothing and footwear ; Sydney ; | EL1: Index Numbers ; All groups CPI excluding Housing ; Sydney ; | EM1: Index Numbers ; All groups CPI excluding Furnishings, household equipment and services ; Sydney ; | EN1: Index Numbers ; All groups CPI excluding Health ; Sydney ; | EO1: Index Numbers ; All groups CPI excluding Transport ; Sydney ; | EP1: Index Numbers ; All groups CPI excluding Communication ; Sydney ; | EQ1: Index Numbers ; All groups CPI excluding Recreation and culture ; Sydney ; | ER1: Index Numbers ; All groups CPI excluding Education ; Sydney ; | ES1: Index Numbers ; All groups CPI excluding Insurance and financial services ; Sydney ; | ET1: Index Numbers ; All groups CPI excluding Housing and Insurance and financial services ; Sydney ; | EU1: Index Numbers ; All groups CPI excluding Medical and hospital services ; Sydney ; | EV1: Index Numbers ; All groups CPI excluding food and energy ; Sydney ; | EW1: Index Numbers ; All groups CPI excluding 'volatile items' ; Sydney ; | EX1: Index Numbers ; Food and non-alcoholic beverages ; Melbourne ; | EY1: Index Numbers ; Bread and cereal products ; Melbourne ; | EZ1: Index Numbers ; Bread ; Melbourne ; | FA1: Index Numbers ; Cakes and biscuits ; Melbourne ; | FB1: Index Numbers ; Breakfast cereals ; Melbourne ; | FC1: Index Numbers ; Other cereal products ; Melbourne ; | FD1: Index Numbers ; Meat and seafoods ; Melbourne ; | FE1: Index Numbers ; Beef and veal ; Melbourne ; | FF1: Index Numbers ; Pork ; Melbourne ; | FG1: Index Numbers ; Lamb and goat ; Melbourne ; | FH1: Index Numbers ; Poultry ; Melbourne ; | FI1: Index Numbers ; Other meats ; Melbourne ; | FJ1: Index Numbers ; Fish and other seafood ; Melbourne ; | FK1: Index Numbers ; Dairy and related products ; Melbourne ; | FL1: Index Numbers ; Milk ; Melbourne ; | FM1: Index Numbers ; Cheese ; Melbourne ; | FN1: Index Numbers ; Ice cream and other dairy products ; Melbourne ; | FO1: Index Numbers ; Fruit and vegetables ; Melbourne ; | FP1: Index Numbers ; Fruit ; Melbourne ; | FQ1: Index Numbers ; Vegetables ; Melbourne ; | FR1: Index Numbers ; Food products n.e.c. ; Melbourne ; | FS1: Index Numbers ; Eggs ; Melbourne ; | FT1: Index Numbers ; Jams, honey and spreads ; Melbourne ; | FU1: Index Numbers ; Food additives and condiments ; Melbourne ; | FV1: Index Numbers ; Oils and fats ; Melbourne ; | FW1: Index Numbers ; Snacks and confectionery ; Melbourne ; | FX1: Index Numbers ; Other food products n.e.c. ; Melbourne ; | FY1: Index Numbers ; Non-alcoholic beverages ; Melbourne ; | FZ1: Index Numbers ; Coffee, tea and cocoa ; Melbourne ; | GA1: Index Numbers ; Waters, soft drinks and juices ; Melbourne ; | GB1: Index Numbers ; Meals out and take away foods ; Melbourne ; | GC1: Index Numbers ; Restaurant meals ; Melbourne ; | GD1: Index Numbers ; Take away and fast foods ; Melbourne ; | GE1: Index Numbers ; Alcohol and tobacco ; Melbourne ; | GF1: Index Numbers ; Alcoholic beverages ; Melbourne ; | GG1: Index Numbers ; Spirits ; Melbourne ; | GH1: Index Numbers ; Wine ; Melbourne ; | GI1: Index Numbers ; Beer ; Melbourne ; | GJ1: Index Numbers ; Tobacco ; Melbourne ; | GK1: Index Numbers ; Tobacco ; Melbourne ; | GL1: Index Numbers ; Clothing and footwear ; Melbourne ; | GM1: Index Numbers ; Garments ; Melbourne ; | GN1: Index Numbers ; Garments for men ; Melbourne ; | GO1: Index Numbers ; Garments for women ; Melbourne ; | GP1: Index Numbers ; Garments for infants and children ; Melbourne ; | GQ1: Index Numbers ; Footwear ; Melbourne ; | GR1: Index Numbers ; Footwear for men ; Melbourne ; | GS1: Index Numbers ; Footwear for women ; Melbourne ; | GT1: Index Numbers ; Footwear for infants and children ; Melbourne ; | GU1: Index Numbers ; Accessories and clothing services ; Melbourne ; | GV1: Index Numbers ; Accessories ; Melbourne ; | GW1: Index Numbers ; Cleaning, repair and hire of clothing and footwear ; Melbourne ; | GX1: Index Numbers ; Housing ; Melbourne ; | GY1: Index Numbers ; Rents ; Melbourne ; | GZ1: Index Numbers ; Rents ; Melbourne ; | HA1: Index Numbers ; New dwelling purchase by owner-occupiers ; Melbourne ; | HB1: Index Numbers ; New dwelling purchase by owner-occupiers ; Melbourne ; | HC1: Index Numbers ; Other housing ; Melbourne ; | HD1: Index Numbers ; Maintenance and repair of the dwelling ; Melbourne ; | HE1: Index Numbers ; Property rates and charges ; Melbourne ; | HF1: Index Numbers ; Utilities ; Melbourne ; | HG1: Index Numbers ; Water and sewerage ; Melbourne ; | HH1: Index Numbers ; Electricity ; Melbourne ; | HI1: Index Numbers ; Gas and other household fuels ; Melbourne ; | HJ1: Index Numbers ; Furnishings, household equipment and services ; Melbourne ; | HK1: Index Numbers ; Furniture and furnishings ; Melbourne ; | HL1: Index Numbers ; Furniture ; Melbourne ; | HM1: Index Numbers ; Carpets and other floor coverings ; Melbourne ; | HN1: Index Numbers ; Household textiles ; Melbourne ; | HO1: Index Numbers ; Household textiles ; Melbourne ; | HP1: Index Numbers ; Household appliances, utensils and tools ; Melbourne ; | HQ1: Index Numbers ; Major household appliances ; Melbourne ; | HR1: Index Numbers ; Small electric household appliances ; Melbourne ; | HS1: Index Numbers ; Glassware, tableware and household utensils ; Melbourne ; | HT1: Index Numbers ; Tools and equipment for house and garden ; Melbourne ; | HU1: Index Numbers ; Non-durable household products ; Melbourne ; | HV1: Index Numbers ; Cleaning and maintenance products ; Melbourne ; | HW1: Index Numbers ; Personal care products ; Melbourne ; | HX1: Index Numbers ; Other non-durable household products ; Melbourne ; | HY1: Index Numbers ; Domestic and household services ; Melbourne ; | HZ1: Index Numbers ; Child care ; Melbourne ; | IA1: Index Numbers ; Hairdressing and personal grooming services ; Melbourne ; | IB1: Index Numbers ; Other household services ; Melbourne ; | IC1: Index Numbers ; Health ; Melbourne ; | ID1: Index Numbers ; Medical products, appliances and equipment ; Melbourne ; | IE1: Index Numbers ; Pharmaceutical products ; Melbourne ; | IF1: Index Numbers ; Therapeutic appliances and equipment ; Melbourne ; | IG1: Index Numbers ; Medical, dental and hospital services ; Melbourne ; | IH1: Index Numbers ; Medical and hospital services ; Melbourne ; | II1: Index Numbers ; Dental services ; Melbourne ; | IJ1: Index Numbers ; Transport ; Melbourne ; | IK1: Index Numbers ; Private motoring ; Melbourne ; | IL1: Index Numbers ; Motor vehicles ; Melbourne ; | IM1: Index Numbers ; Spare parts and accessories for motor vehicles ; Melbourne ; | IN1: Index Numbers ; Automotive fuel ; Melbourne ; | IO1: Index Numbers ; Maintenance and repair of motor vehicles ; Melbourne ; | IP1: Index Numbers ; Other services in respect of motor vehicles ; Melbourne ; | IQ1: Index Numbers ; Urban transport fares ; Melbourne ;
A2: Unit | B2: Index Numbers | C2: Index Numbers | D2: Index Numbers | E2: Index Numbers | F2: Index Numbers | G2: Index Numbers | H2: Index Numbers | I2: Index Numbers | J2: Index Numbers | K2: Index Numbers | L2: Index Numbers | M2: Index Numbers | N2: Index Numbers | O2: Index Numbers | P2: Index Numbers | Q2: Index Numbers | R2: Index Numbers | S2: Index Numbers | T2: Index Numbers | U2: Index Numbers | V2: Index Numbers | W2: Index Numbers | X2: Index Numbers | Y2: Index Numbers | Z2: Index Numbers | AA2: Index Numbers | AB2: Index Numbers | AC2: Index Numbers | AD2: Index Numbers | AE2: Index Numbers | AF2: Index Numbers | AG2: Index Numbers | AH2: Index Numbers | AI2: Index Numbers | AJ2: Index Numbers | AK2: Index Numbers | AL2: Index Numbers | AM2: Index Numbers | AN2: Index Numbers | AO2: Index Numbers | AP2: Index Numbers | AQ2: Index Numbers | AR2: Index Numbers | AS2: Index Numbers | AT2: Index Numbers | AU2: Index Numbers | AV2: Index Numbers | AW2: Index Numbers | AX2: Index Numbers | AY2: Index Numbers | AZ2: Index Numbers | BA2: Index Numbers | BB2: Index Numbers | BC2: Index Numbers | BD2: Index Numbers | BE2: Index Numbers | BF2: Index Numbers | BG2: Index Numbers | BH2: Index Numbers | BI2: Index Numbers | BJ2: Index Numbers | BK2: Index Numbers | BL2: Index Numbers | BM2: Index Numbers | BN2: Index Numbers | BO2: Index Numbers | BP2: Index Numbers | BQ2: Index Numbers | BR2: Index Numbers | BS2: Index Numbers | BT2: Index Numbers | BU2: Index Numbers | BV2: Index Numbers | BW2: Index Numbers | BX2: Index Numbers | BY2: Index Numbers | BZ2: Index Numbers | CA2: Index Numbers | CB2: Index Numbers | CC2: Index Numbers | CD2: Index Numbers | CE2: Index Numbers | CF2: Index Numbers | CG2: Index Numbers | CH2: Index Numbers | CI2: Index Numbers | CJ2: Index Numbers | CK2: Index Numbers | CL2: Index Numbers | CM2: Index Numbers | CN2: Index Numbers | CO2: Index Numbers | CP2: Index Numbers | CQ2: Index Numbers | CR2: Index Numbers | CS2: Index Numbers | CT2: Index Numbers | CU2: Index Numbers | CV2: Index Numbers | CW2: Index Numbers | CX2: Index Numbers | CY2: Index Numbers | CZ2: Index Numbers | DA2: Index Numbers | DB2: Index Numbers | DC2: Index Numbers | DD2: Index Numbers | DE2: Index Numbers | DF2: Index Numbers | DG2: Index Numbers | DH2: Index Numbers | DI2: Index Numbers | DJ2: Index Numbers | DK2: Index Numbers | DL2: Index Numbers | DM2: Index Numbers | DN2: Index Numbers | DO2: Index Numbers | DP2: Index Numbers | DQ2: Index Numbers | DR2: Index Numbers | DS2: Index Numbers | DT2: Index Numbers | DU2: Index Numbers | DV2: Index Numbers | DW2: Index Numbers | DX2: Index Numbers | DY2: Index Numbers | DZ2: Index Numbers | EA2: Index Numbers | EB2: Index Numbers | EC2: Index Numbers | ED2: Index Numbers | EE2: Index Numbers | EF2: Index Numbers | EG2: Index Numbers | EH2: Index Numbers | EI2: Index Numbers | EJ2: Index Numbers | EK2: Index Numbers | EL2: Index Numbers | EM2: Index Numbers | EN2: Index Numbers | EO2: Index Numbers | EP2: Index Numbers | EQ2: Index Numbers | ER2: Index Numbers | ES2: Index Numbers | ET2: Index Numbers | EU2: Index Numbers | EV2: Index Numbers | EW2: Index Numbers | EX2: Index Numbers | EY2: Index Numbers | EZ2: Index Numbers | FA2: Index Numbers | FB2: Index Numbers | FC2: Index Numbers | FD2: Index Numbers | FE2: Index Numbers | FF2: Index Numbers | FG2: Index Numbers | FH2: Index Numbers | FI2: Index Numbers | FJ2: Index Numbers | FK2: Index Numbers | FL2: Index Numbers | FM2: Index Numbers | FN2: Index Numbers | FO2: Index Numbers | FP2: Index Numbers | FQ2: Index Numbers | FR2: Index Numbers | FS2: Index Numbers | FT2: Index Numbers | FU2: Index Numbers | FV2: Index Numbers | FW2: Index Numbers | FX2: Index Numbers | FY2: Index Numbers | FZ2: Index Numbers | GA2: Index Numbers | GB2: Index Numbers | GC2: Index Numbers | GD2: Index Numbers | GE2: Index Numbers | GF2: Index Numbers | GG2: Index Numbers | GH2: Index Numbers | GI2: Index Numbers | GJ2: Index Numbers | GK2: Index Numbers | GL2: Index Numbers | GM2: Index Numbers | GN2: Index Numbers | GO2: Index Numbers | GP2: Index Numbers | GQ2: Index Numbers | GR2: Index Numbers | GS2: Index Numbers | GT2: Index Numbers | GU2: Index Numbers | GV2: Index Numbers | GW2: Index Numbers | GX2: Index Numbers | GY2: Index Numbers | GZ2: Index Numbers | HA2: Index Numbers | HB2: Index Numbers | HC2: Index Numbers | HD2: Index Numbers | HE2: Index Numbers | HF2: Index Numbers | HG2: Index Numbers | HH2: Index Numbers | HI2: Index Numbers | HJ2: Index Numbers | HK2: Index Numbers | HL2: Index Numbers | HM2: Index Numbers | HN2: Index Numbers | HO2: Index Numbers | HP2: Index Numbers | HQ2: Index Numbers | HR2: Index Numbers | HS2: Index Numbers | HT2: Index Numbers | HU2: Index Numbers | HV2: Index Numbers | HW2: Index Numbers | HX2: Index Numbers | HY2: Index Numbers | HZ2: Index Numbers | IA2: Index Numbers | IB2: Index Numbers | IC2: Index Numbers | ID2: Index Numbers | IE2: Index Numbers | IF2: Index Numbers | IG2: Index Numbers | IH2: Index Numbers | II2: Index Numbers | IJ2: Index Numbers | IK2: Index Numbers | IL2: Index Numbers | IM2: Index Numbers | IN2: Index Numbers | IO2: Index Numbers | IP2: Index Numbers | IQ2: Index Numbers
A3: Series Type | B3: Original | C3: Original | D3: Original | E3: Original | F3: Original | G3: Original | H3: Original | I3: Original | J3: Original | K3: Original | L3: Original | M3: Original | N3: Original | O3: Original | P3: Original | Q3: Original | R3: Original | S3: Original | T3: Original | U3: Original | V3: Original | W3: Original | X3: Original | Y3: Original | Z3: Original | AA3: Original | AB3: Original | AC3: Original | AD3: Original | AE3: Original | AF3: Original | AG3: Original | AH3: Original | AI3: Original | AJ3: Original | AK3: Original | AL3: Original | AM3: Original | AN3: Original | AO3: Original | AP3: Original | AQ3: Original | AR3: Original | AS3: Original | AT3: Original | AU3: Original | AV3: Original | AW3: Original | AX3: Original | AY3: Original | AZ3: Original | BA3: Original | BB3: Original | BC3: Original | BD3: Original | BE3: Original | BF3: Original | BG3: Original | BH3: Original | BI3: Original | BJ3: Original | BK3: Original | BL3: Original | BM3: Original | BN3: Original | BO3: Original | BP3: Original | BQ3: Original | BR3: Original | BS3: Original | BT3: Original | BU3: Original | BV3: Original | BW3: Original | BX3: Original | BY3: Original | BZ3: Original | CA3: Original | CB3: Original | CC3: Original | CD3: Original | CE3: Original | CF3: Original | CG3: Original | CH3: Original | CI3: Original | CJ3: Original | CK3: Original | CL3: Original | CM3: Original | CN3: Original | CO3: Original | CP3: Original | CQ3: Original | CR3: Original | CS3: Original | CT3: Original | CU3: Original | CV3: Original | CW3: Original | CX3: Original | CY3: Original | CZ3: Original | DA3: Original | DB3: Original | DC3: Original | DD3: Original | DE3: Original | DF3: Original | DG3: Original | DH3: Original | DI3: Original | DJ3: Original | DK3: Original | DL3: Original | DM3: Original | DN3: Original | DO3: Original | DP3: Original | DQ3: Original | DR3: Original | DS3: Original | DT3: Original | DU3: Original | DV3: Original | DW3: Original | DX3: Original | DY3: Original | DZ3: Original | EA3: Original | EB3: Original | EC3: Original | ED3: Original | EE3: Original | EF3: Original | EG3: Original | EH3: Original | EI3: Original | EJ3: Original | EK3: Original | EL3: Original | EM3: Original | EN3: Original | EO3: Original | EP3: Original | EQ3: Original | ER3: Original | ES3: Original | ET3: Original | EU3: Original | EV3: Original | EW3: Original | EX3: Original | EY3: Original | EZ3: Original | FA3: Original | FB3: Original | FC3: Original | FD3: Original | FE3: Original | FF3: Original | FG3: Original | FH3: Original | FI3: Original | FJ3: Original | FK3: Original | FL3: Original | FM3: Original | FN3: Original | FO3: Original | FP3: Original | FQ3: Original | FR3: Original | FS3: Original | FT3: Original | FU3: Original | FV3: Original | FW3: Original | FX3: Original | FY3: Original | FZ3: Original | GA3: Original | GB3: Original | GC3: Original | GD3: Original | GE3: Original | GF3: Original | GG3: Original | GH3: Original | GI3: Original | GJ3: Original | GK3: Original | GL3: Original | GM3: Original | GN3: Original | GO3: Original | GP3: Original | GQ3: Original | GR3: Original | GS3: Original | GT3: Original | GU3: Original | GV3: Original | GW3: Original | GX3: Original | GY3: Original | GZ3: Original | HA3: Original | HB3: Original | HC3: Original | HD3: Original | HE3: Original | HF3: Original | HG3: Original | HH3: Original | HI3: Original | HJ3: Original | HK3: Original | HL3: Original | HM3: Original | HN3: Original | HO3: Original | HP3: Original | HQ3: Original | HR3: Original | HS3: Original | HT3: Original | HU3: Original | HV3: Original | HW3: Original | HX3: Original | HY3: Original | HZ3: Original | IA3: Original | IB3: Original | IC3: Original | ID3: Original | IE3: Original | IF3: Original | IG3: Original | IH3: Original | II3: Original | IJ3: Original | IK3: Original | IL3: Original | IM3: Original | IN3: Original | IO3: Original | IP3: Original | IQ3: Original
A4: Data Type | B4: INDEX | C4: INDEX | D4: INDEX | E4: INDEX | F4: INDEX | G4: INDEX | H4: INDEX | I4: INDEX | J4: INDEX | K4: INDEX | L4: INDEX | M4: INDEX | N4: INDEX | O4: INDEX | P4: INDEX | Q4: INDEX | R4: INDEX | S4: INDEX | T4: INDEX | U4: INDEX | V4: INDEX | W4: INDEX | X4: INDEX | Y4: INDEX | Z4: INDEX | AA4: INDEX | AB4: INDEX | AC4: INDEX | AD4: INDEX | AE4: INDEX | AF4: INDEX | AG4: INDEX | AH4: INDEX | AI4: INDEX | AJ4: INDEX | AK4: INDEX | AL4: INDEX | AM4: INDEX | AN4: INDEX | AO4: INDEX | AP4: INDEX | AQ4: INDEX | AR4: INDEX | AS4: INDEX | AT4: INDEX | AU4: INDEX | AV4: INDEX | AW4: INDEX | AX4: INDEX | AY4: INDEX | AZ4: INDEX | BA4: INDEX | BB4: INDEX | BC4: INDEX | BD4: INDEX | BE4: INDEX | BF4: INDEX | BG4: INDEX | BH4: INDEX | BI4: INDEX | BJ4: INDEX | BK4: INDEX | BL4: INDEX | BM4: INDEX | BN4: INDEX | BO4: INDEX | BP4: INDEX | BQ4: INDEX | BR4: INDEX | BS4: INDEX | BT4: INDEX | BU4: INDEX | BV4: INDEX | BW4: INDEX | BX4: INDEX | BY4: INDEX | BZ4: INDEX | CA4: INDEX | CB4: INDEX | CC4: INDEX | CD4: INDEX | CE4: INDEX | CF4: INDEX | CG4: INDEX | CH4: INDEX | CI4: INDEX | CJ4: INDEX | CK4: INDEX | CL4: INDEX | CM4: INDEX | CN4: INDEX | CO4: INDEX | CP4: INDEX | CQ4: INDEX | CR4: INDEX | CS4: INDEX | CT4: INDEX | CU4: INDEX | CV4: INDEX | CW4: INDEX | CX4: INDEX | CY4: INDEX | CZ4: INDEX | DA4: INDEX | DB4: INDEX | DC4: INDEX | DD4: INDEX | DE4: INDEX | DF4: INDEX | DG4: INDEX | DH4: INDEX | DI4: INDEX | DJ4: INDEX | DK4: INDEX | DL4: INDEX | DM4: INDEX | DN4: INDEX | DO4: INDEX | DP4: INDEX | DQ4: INDEX | DR4: INDEX | DS4: INDEX | DT4: INDEX | DU4: INDEX | DV4: INDEX | DW4: INDEX | DX4: INDEX | DY4: INDEX | DZ4: INDEX | EA4: INDEX | EB4: INDEX | EC4: INDEX | ED4: INDEX | EE4: INDEX | EF4: INDEX | EG4: INDEX | EH4: INDEX | EI4: INDEX | EJ4: INDEX | EK4: INDEX | EL4: INDEX | EM4: INDEX | EN4: INDEX | EO4: INDEX | EP4: INDEX | EQ4: INDEX | ER4: INDEX | ES4: INDEX | ET4: INDEX | EU4: INDEX | EV4: INDEX | EW4: INDEX | EX4: INDEX | EY4: INDEX | EZ4: INDEX | FA4: INDEX | FB4: INDEX | FC4: INDEX | FD4: INDEX | FE4: INDEX | FF4: INDEX | FG4: INDEX | FH4: INDEX | FI4: INDEX | FJ4: INDEX | FK4: INDEX | FL4: INDEX | FM4: INDEX | FN4: INDEX | FO4: INDEX | FP4: INDEX | FQ4: INDEX | FR4: INDEX | FS4: INDEX | FT4: INDEX | FU4: INDEX | FV4: INDEX | FW4: INDEX | FX4: INDEX | FY4: INDEX | FZ4: INDEX | GA4: INDEX | GB4: INDEX | GC4: INDEX | GD4: INDEX | GE4: INDEX | GF4: INDEX | GG4: INDEX | GH4: INDEX | GI4: INDEX | GJ4: INDEX | GK4: INDEX | GL4: INDEX | GM4: INDEX | GN4: INDEX | GO4: INDEX | GP4: INDEX | GQ4: INDEX | GR4: INDEX | GS4: INDEX | GT4: INDEX | GU4: INDEX | GV4: INDEX | GW4: INDEX | GX4: INDEX | GY4: INDEX | GZ4: INDEX | HA4: INDEX | HB4: INDEX | HC4: INDEX | HD4: INDEX | HE4: INDEX | HF4: INDEX | HG4: INDEX | HH4: INDEX | HI4: INDEX | HJ4: INDEX | HK4: INDEX | HL4: INDEX | HM4: INDEX | HN4: INDEX | HO4: INDEX | HP4: INDEX | HQ4: INDEX | HR4: INDEX | HS4: INDEX | HT4: INDEX | HU4: INDEX | HV4: INDEX | HW4: INDEX | HX4: INDEX | HY4: INDEX | HZ4: INDEX | IA4: INDEX | IB4: INDEX | IC4: INDEX | ID4: INDEX | IE4: INDEX | IF4: INDEX | IG4: INDEX | IH4: INDEX | II4: INDEX | IJ4: INDEX | IK4: INDEX | IL4: INDEX | IM4: INDEX | IN4: INDEX | IO4: INDEX | IP4: INDEX | IQ4: INDEX
