Workbook
Name A124792079W: Data1!$D$1:$D$10,Data1!$D$11:$D$165
Name A124792079W_Data: Data1!$D$11:$D$165
Name A124792079W_Latest: Data1!$D$165
Name A124792081J: Data1!$W$1:$W$10,Data1!$W$11:$W$165
Name A124792081J_Data: Data1!$W$11:$W$165
Name A124792081J_Latest: Data1!$W$165
Name A124792083L: Data1!$AP$1:$AP$10,Data1!$AP$11:$AP$165
Name A124792083L_Data: Data1!$AP$11:$AP$165
Name A124792083L_Latest: Data1!$AP$165
Name A124792377V: Data1!$B$1:$B$10,Data1!$B$11:$B$165
Name A124792377V_Data: Data1!$B$11:$B$165
Name A124792377V_Latest: Data1!$B$165
Name A124792395X: Data1!$U$1:$U$10,Data1!$U$11:$U$165
Name A124792395X_Data: Data1!$U$11:$U$165
Name A124792395X_Latest: Data1!$U$165
Name A124792413T: Data1!$AN$1:$AN$10,Data1!$AN$11:$AN$165
Name A124792413T_Data: Data1!$AN$11:$AN$165
Name A124792413T_Latest: Data1!$AN$165
Name A3517168V: Data1!$C$1:$C$10,Data1!$C$11:$C$165
Name A3517168V_Data: Data1!$C$11:$C$165
Name A3517168V_Latest: Data1!$C$165
Name A3517171J: Data1!$E$1:$E$10,Data1!$E$11:$E$165
Name A3517171J_Data: Data1!$E$11:$E$165
Name A3517171J_Latest: Data1!$E$165
Name A3517174R: Data1!$F$1:$F$10,Data1!$F$11:$F$165
Name A3517174R_Data: Data1!$F$11:$F$165
Name A3517174R_Latest: Data1!$F$165
Name A3517177W: Data1!$G$1:$G$10,Data1!$G$11:$G$165
Name A3517177W_Data: Data1!$G$11:$G$165
Name A3517177W_Latest: Data1!$G$165
Name A3517180K: Data1!$H$1:$H$10,Data1!$H$11:$H$165
Name A3517180K_Data: Data1!$H$11:$H$165
Name A3517180K_Latest: Data1!$H$165
Name A3517183T: Data1!$I$1:$I$10,Data1!$I$11:$I$165
Name A3517183T_Data: Data1!$I$11:$I$165
Name A3517183T_Latest: Data1!$I$165
Name A3517186X: Data1!$K$1:$K$10,Data1!$K$11:$K$165
Name A3517186X_Data: Data1!$K$11:$K$165
Name A3517186X_Latest: Data1!$K$165
Name A3517189F: Data1!$L$1:$L$10,Data1!$L$11:$L$165
Name A3517189F_Data: Data1!$L$11:$L$165
Name A3517189F_Latest: Data1!$L$165
Name A3517192V: Data1!$M$1:$M$10,Data1!$M$11:$M$165
Name A3517192V_Data: Data1!$M$11:$M$165
Name A3517192V_Latest: Data1!$M$165
Name A3517195A: Data1!$N$1:$N$10,Data1!$N$11:$N$165
Name A3517195A_Data: Data1!$N$11:$N$165
Name A3517195A_Latest: Data1!$N$165
Name A3517198J: Data1!$O$1:$O$10,Data1!$O$11:$O$165
Name A3517198J_Data: Data1!$O$11:$O$165
Name A3517198J_Latest: Data1!$O$165
Name A3517210L: Data1!$V$1:$V$10,Data1!$V$11:$V$165
Name A3517210L_Data: Data1!$V$11:$V$165
Name A3517210L_Latest: Data1!$V$165
Name A3517213V: Data1!$X$1:$X$10,Data1!$X$11:$X$165
Name A3517213V_Data: Data1!$X$11:$X$165
Name A3517213V_Latest: Data1!$X$165
Name A3517216A: Data1!$Y$1:$Y$10,Data1!$Y$11:$Y$165
Name A3517216A_Data: Data1!$Y$11:$Y$165
Name A3517216A_Latest: Data1!$Y$165

Sheet Index
B2: Time Series Workbook
B5: 5625.0 Private New Capital Expenditure and Expected Expenditure, Australia
B6: Table 1. Actual Expenditure, by Type of Asset and Industry, Original - Current Prices $m
D8: Enquiries
A10: Data Item Description | D10: Series Type | E10: Series ID | F10: Series Start | G10: Series End | H10: No. Obs. | I10: Unit | J10: Data Type | K10: Freq. | L10: Collection Month
A12: Actual Expenditure ; Total (State) ; Buildings and Structures ; Current Price ; Total, including Education and Health ; | D12: Original | E12: A124792377V | F12: 31929 | G12: 45992 | H12: 155 | I12: $ Millions | J12: FLOW | K12: Quarter | L12: 3
A13: Actual Expenditure ; Total (State) ; Buildings and Structures ; Current Price ; Mining ; | D13: Original | E13: A3517168V | F13: 31929 | G13: 45992 | H13: 155 | I13: $ Millions | J13: FLOW | K13: Quarter | L13: 3
A14: Actual Expenditure ; Total (State) ; Buildings and Structures ; Current Price ; Non-Mining, including Education and Health ; | D14: Original | E14: A124792079W | F14: 31929 | G14: 45992 | H14: 155 | I14: $ Millions | J14: FLOW | K14: Quarter | L14: 3
A15: Actual Expenditure ; Total (State) ; Buildings and Structures ; Current Price ; Manufacturing ; | D15: Original | E15: A3517171J | F15: 31929 | G15: 45992 | H15: 155 | I15: $ Millions | J15: FLOW | K15: Quarter | L15: 3
A16: Actual Expenditure ; Total (State) ; Buildings and Structures ; Current Price ; Electricity, Gas, Water and Waste Services ; | D16: Original | E16: A3517174R | F16: 31929 | G16: 45992 | H16: 155 | I16: $ Millions | J16: FLOW | K16: Quarter | L16: 3
A17: Actual Expenditure ; Total (State) ; Buildings and Structures ; Current Price ; Construction ; | D17: Original | E17: A3517177W | F17: 31929 | G17: 45992 | H17: 155 | I17: $ Millions | J17: FLOW | K17: Quarter | L17: 3
A18: Actual Expenditure ; Total (State) ; Buildings and Structures ; Current Price ; Wholesale Trade ; | D18: Original | E18: A3517180K | F18: 31929 | G18: 45992 | H18: 155 | I18: $ Millions | J18: FLOW | K18: Quarter | L18: 3
A19: Actual Expenditure ; Total (State) ; Buildings and Structures ; Current Price ; Retail Trade ; | D19: Original | E19: A3517183T | F19: 31929 | G19: 45992 | H19: 155 | I19: $ Millions | J19: FLOW | K19: Quarter | L19: 3
A20: Actual Expenditure ; Total (State) ; Buildings and Structures ; Current Price ; Accommodation and Food Services ; | D20: Original | E20: A83728707W | F20: 31929 | G20: 45992 | H20: 155 | I20: $ Millions | J20: FLOW | K20: Quarter | L20: 3
A21: Actual Expenditure ; Total (State) ; Buildings and Structures ; Current Price ; Transport, Postal and Warehousing ; | D21: Original | E21: A3517186X | F21: 31929 | G21: 45992 | H21: 155 | I21: $ Millions | J21: FLOW | K21: Quarter | L21: 3
A22: Actual Expenditure ; Total (State) ; Buildings and Structures ; Current Price ; Information Media and Telecommunications ; | D22: Original | E22: A3517189F | F22: 31929 | G22: 45992 | H22: 155 | I22: $ Millions | J22: FLOW | K22: Quarter | L22: 3
A23: Actual Expenditure ; Total (State) ; Buildings and Structures ; Current Price ; Financial and Insurance Services ; | D23: Original | E23: A3517192V | F23: 31929 | G23: 45992 | H23: 155 | I23: $ Millions | J23: FLOW | K23: Quarter | L23: 3
... A68: Actual Expenditure ; Total (State) ; Total (Type of Asset - Detailed Level) ; Current Price ; Other Services ; | D68: Original | E68: A83728718C | F68: 31929 | G68: 45992 | H68: 155 | I68: $ Millions | J68: FLOW | K68: Quarter | L68: 3
A70: © Commonwealth of Australia 2026

Sheet Data1
B1: Actual Expenditure ; Total (State) ; Buildings and Structures ; Current Price ; Total, including Education and Health ; | C1: Actual Expenditure ; Total (State) ; Buildings and Structures ; Current Price ; Mining ; | D1: Actual Expenditure ; Total (State) ; Buildings and Structures ; Current Price ; Non-Mining, including Education and Health ; | E1: Actual Expenditure ; Total (State) ; Buildings and Structures ; Current Price ; Manufacturing ; | F1: Actual Expenditure ; Total (State) ; Buildings and Structures ; Current Price ; Electricity, Gas, Water and Waste Services ; | G1: Actual Expenditure ; Total (State) ; Buildings and Structures ; Current Price ; Construction ; | H1: Actual Expenditure ; Total (State) ; Buildings and Structures ; Current Price ; Wholesale Trade ; | I1: Actual Expenditure ; Total (State) ; Buildings and Structures ; Current Price ; Retail Trade ; | J1: Actual Expenditure ; Total (State) ; Buildings and Structures ; Current Price ; Accommodation and Food Services ; | K1: Actual Expenditure ; Total (State) ; Buildings and Structures ; Current Price ; Transport, Postal and Warehousing ; | L1: Actual Expenditure ; Total (State) ; Buildings and Structures ; Current Price ; Information Media and Telecommunications ; | M1: Actual Expenditure ; Total (State) ; Buildings and Structures ; Current Price ; Financial and Insurance Services ; | N1: Actual Expenditure ; Total (State) ; Buildings and Structures ; Current Price ; Rental, Hiring and Real Estate Services ; | O1: Actual Expenditure ; Total (State) ; Buildings and Structures ; Current Price ; Professional, Scientific and Technical Services ; | P1: Actual Expenditure ; Total (State) ; Buildings and Structures ; Current Price ; Administrative and Support Services ; | Q1: Actual Expenditure ; Total (State) ; Buildings and Structures ; Current Price ; Education and Training ; | R1: Actual Expenditure ; Total (State) ; Buildings and Structures ; Current Price ; Health Care and Social Assistance ; | S1: Actual Expenditure ; Total (State) ; Buildings and Structures ; Current Price ; Arts and Recreation Services ; | T1: Actual Expenditure ; Total (State) ; Buildings and Structures ; Current Price ; Other Services ; | U1: Actual Expenditure ; Total (State) ; Equipment, Plant and Machinery ; Current Price ; Total, including Education and Health ; | V1: Actual Expenditure ; Total (State) ; Equipment, Plant and Machinery ; Current Price ; Mining ; | W1: Actual Expenditure ; Total (State) ; Equipment, Plant and Machinery ; Current Price ; Non-Mining, including Education and Health ; | X1: Actual Expenditure ; Total (State) ; Equipment, Plant and Machinery ; Current Price ; Manufacturing ; | Y1: Actual Expenditure ; Total (State) ; Equipment, Plant and Machinery ; Current Price ; Electricity, Gas, Water and Waste Services ; | Z1: Actual Expenditure ; Total (State) ; Equipment, Plant and Machinery ; Current Price ; Construction ; | AA1: Actual Expenditure ; Total (State) ; Equipment, Plant and Machinery ; Current Price ; Wholesale Trade ; | AB1: Actual Expenditure ; Total (State) ; Equipment, Plant and Machinery ; Current Price ; Retail Trade ; | AC1: Actual Expenditure ; Total (State) ; Equipment, Plant and Machinery ; Current Price ; Accommodation and Food Services ; | AD1: Actual Expenditure ; Total (State) ; Equipment, Plant and Machinery ; Current Price ; Transport, Postal and Warehousing ; | AE1: Actual Expenditure ; Total (State) ; Equipment, Plant and Machinery ; Current Price ; Information Media and Telecommunications ; | AF1: Actual Expenditure ; Total (State) ; Equipment, Plant and Machinery ; Current Price ; Financial and Insurance Services ; | AG1: Actual Expenditure ; Total (State) ; Equipment, Plant and Machinery ; Current Price ; Rental, Hiring and Real Estate Services ; | AH1: Actual Expenditure ; Total (State) ; Equipment, Plant and Machinery ; Current Price ; Professional, Scientific and Technical Services ; | AI1: Actual Expenditure ; Total (State) ; Equipment, Plant and Machinery ; Current Price ; Administrative and Support Services ; | AJ1: Actual Expenditure ; Total (State) ; Equipment, Plant and Machinery ; Current Price ; Education and Training ; | AK1: Actual Expenditure ; Total (State) ; Equipment, Plant and Machinery ; Current Price ; Health Care and Social Assistance ; | AL1: Actual Expenditure ; Total (State) ; Equipment, Plant and Machinery ; Current Price ; Arts and Recreation Services ; | AM1: Actual Expenditure ; Total (State) ; Equipment, Plant and Machinery ; Current Price ; Other Services ; | AN1: Actual Expenditure ; Total (State) ; Total (Type of Asset - Detailed Level) ; Current Price ; Total, including Education and Health ; | AO1: Actual Expenditure ; Total (State) ; Total (Type of Asset - Detailed Level) ; Current Price ; Mining ; | AP1: Actual Expenditure ; Total (State) ; Total (Type of Asset - Detailed Level) ; Current Price ; Non-Mining, including Education and Health ; | AQ1: Actual Expenditure ; Total (State) ; Total (Type of Asset - Detailed Level) ; Current Price ; Manufacturing ; | AR1: Actual Expenditure ; Total (State) ; Total (Type of Asset - Detailed Level) ; Current Price ; Electricity, Gas, Water and Waste Services ; | AS1: Actual Expenditure ; Total (State) ; Total (Type of Asset - Detailed Level) ; Current Price ; Construction ; | AT1: Actual Expenditure ; Total (State) ; Total (Type of Asset - Detailed Level) ; Current Price ; Wholesale Trade ; | AU1: Actual Expenditure ; Total (State) ; Total (Type of Asset - Detailed Level) ; Current Price ; Retail Trade ; | AV1: Actual Expenditure ; Total (State) ; Total (Type of Asset - Detailed Level) ; Current Price ; Accommodation and Food Services ; | AW1: Actual Expenditure ; Total (State) ; Total (Type of Asset - Detailed Level) ; Current Price ; Transport, Postal and Warehousing ; | AX1: Actual Expenditure ; Total (State) ; Total (Type of Asset - Detailed Level) ; Current Price ; Information Media and Telecommunications ; | AY1: Actual Expenditure ; Total (State) ; Total (Type of Asset - Detailed Level) ; Current Price ; Financial and Insurance Services ; | AZ1: Actual Expenditure ; Total (State) ; Total (Type of Asset - Detailed Level) ; Current Price ; Rental, Hiring and Real Estate Services ; | BA1: Actual Expenditure ; Total (State) ; Total (Type of Asset - Detailed Level) ; Current Price ; Professional, Scientific and Technical Services ; | BB1: Actual Expenditure ; Total (State) ; Total (Type of Asset - Detailed Level) ; Current Price ; Administrative and Support Services ; | BC1: Actual Expenditure ; Total (State) ; Total (Type of Asset - Detailed Level) ; Current Price ; Education and Training ; | BD1: Actual Expenditure ; Total (State) ; Total (Type of Asset - Detailed Level) ; Current Price ; Health Care and Social Assistance ; | BE1: Actual Expenditure ; Total (State) ; Total (Type of Asset - Detailed Level) ; Current Price ; Arts and Recreation Services ; | BF1: Actual Expenditure ; Total (State) ; Total (Type of Asset - Detailed Level) ; Current Price ; Other Services ;
A2: Unit | B2: $ Millions | C2: $ Millions | D2: $ Millions | E2: $ Millions | F2: $ Millions | G2: $ Millions | H2: $ Millions | I2: $ Millions | J2: $ Millions | K2: $ Millions | L2: $ Millions | M2: $ Millions | N2: $ Millions | O2: $ Millions | P2: $ Millions | Q2: $ Millions | R2: $ Millions | S2: $ Millions | T2: $ Millions | U2: $ Millions | V2: $ Millions | W2: $ Millions | X2: $ Millions | Y2: $ Millions | Z2: $ Millions | AA2: $ Millions | AB2: $ Millions | AC2: $ Millions | AD2: $ Millions | AE2: $ Millions | AF2: $ Millions | AG2: $ Millions | AH2: $ Millions | AI2: $ Millions | AJ2: $ Millions | AK2: $ Millions | AL2: $ Millions | AM2: $ Millions | AN2: $ Millions | AO2: $ Millions | AP2: $ Millions | AQ2: $ Millions | AR2: $ Millions | AS2: $ Millions | AT2: $ Millions | AU2: $ Millions | AV2: $ Millions | AW2: $ Millions | AX2: $ Millions | AY2: $ Millions | AZ2: $ Millions | BA2: $ Millions | BB2: $ Millions | BC2: $ Millions | BD2: $ Millions | BE2: $ Millions | BF2: $ Millions
A3: Series Type | B3: Original | C3: Original | D3: Original | E3: Original | F3: Original | G3: Original | H3: Original | I3: Original | J3: Original | K3: Original | L3: Original | M3: Original | N3: Original | O3: Original | P3: Original | Q3: Original | R3: Original | S3: Original | T3: Original | U3: Original | V3: Original | W3: Original | X3: Original | Y3: Original | Z3: Original | AA3: Original | AB3: Original | AC3: Original | AD3: Original | AE3: Original | AF3: Original | AG3: Original | AH3: Original | AI3: Original | AJ3: Original | AK3: Original | AL3: Original | AM3: Original | AN3: Original | AO3: Original | AP3: Original | AQ3: Original | AR3: Original | AS3: Original | AT3: Original | AU3: Original | AV3: Original | AW3: Original | AX3: Original | AY3: Original | AZ3: Original | BA3: Original | BB3: Original | BC3: Original | BD3: Original | BE3: Original | BF3: Original
A4: Data Type | B4: FLOW | C4: FLOW | D4: FLOW | E4: FLOW | F4: FLOW | G4: FLOW | H4: FLOW | I4: FLOW | J4: FLOW | K4: FLOW | L4: FLOW | M4: FLOW | N4: FLOW | O4: FLOW | P4: FLOW | Q4: FLOW | R4: FLOW | S4: FLOW | T4: FLOW | U4: FLOW | V4: FLOW | W4: FLOW | X4: FLOW | Y4: FLOW | Z4: FLOW | AA4: FLOW | AB4: FLOW | AC4: FLOW | AD4: FLOW | AE4: FLOW | AF4: FLOW | AG4: FLOW | AH4: FLOW | AI4: FLOW | AJ4: FLOW | AK4: FLOW | AL4: FLOW | AM4: FLOW | AN4: FLOW | AO4: FLOW | AP4: FLOW | AQ4: FLOW | AR4: FLOW | AS4: FLOW | AT4: FLOW | AU4: FLOW | AV4: FLOW | AW4: FLOW | AX4: FLOW | AY4: FLOW | AZ4: FLOW | BA4: FLOW | BB4: FLOW | BC4: FLOW | BD4: FLOW | BE4: FLOW | BF4: FLOW
A5: Frequency | B5: Quarter | C5: Quarter | D5: Quarter | E5: Quarter | F5: Quarter | G5: Quarter | H5: Quarter | I5: Quarter | J5: Quarter | K5: Quarter | L5: Quarter | M5: Quarter | N5: Quarter | O5: Quarter | P5: Quarter | Q5: Quarter | R5: Quarter | S5: Quarter | T5: Quarter | U5: Quarter | V5: Quarter | W5: Quarter | X5: Quarter | Y5: Quarter | Z5: Quarter | AA5: Quarter | AB5: Quarter | AC5: Quarter | AD5: Quarter | AE5: Quarter | AF5: Quarter | AG5: Quarter | AH5: Quarter | AI5: Quarter | AJ5: Quarter | AK5: Quarter | AL5: Quarter | AM5: Quarter | AN5: Quarter | AO5: Quarter | AP5: Quarter | AQ5: Quarter | AR5: Quarter | AS5: Quarter | AT5: Quarter | AU5: Quarter | AV5: Quarter | AW5: Quarter | AX5: Quarter | AY5: Quarter | AZ5: Quarter | BA5: Quarter | BB5: Quarter | BC5: Quarter | BD5: Quarter | BE5: Quarter | BF5: Quarter
A6: Collection Month | B6: 3 | C6: 3 | D6: 3 | E6: 3 | F6: 3 | G6: 3 | H6: 3 | I6: 3 | J6: 3 | K6: 3 | L6: 3 | M6: 3 | N6: 3 | O6: 3 | P6: 3 | Q6: 3 | R6: 3 | S6: 3 | T6: 3 | U6: 3 | V6: 3 | W6: 3 | X6: 3 | Y6: 3 | Z6: 3 | AA6: 3 | AB6: 3 | AC6: 3 | AD6: 3 | AE6: 3 | AF6: 3 | AG6: 3 | AH6: 3 | AI6: 3 | AJ6: 3 | AK6: 3 | AL6: 3 | AM6: 3 | AN6: 3 | AO6: 3 | AP6: 3 | AQ6: 3 | AR6: 3 | AS6: 3 | AT6: 3 | AU6: 3 | AV6: 3 | AW6: 3 | AX6: 3 | AY6: 3 | AZ6: 3 | BA6: 3 | BB6: 3 | BC6: 3 | BD6: 3 | BE6: 3 | BF6: 3
A7: Series Start | B7: 31929 | C7: 31929 | D7: 31929 | E7: 31929 | F7: 31929 | G7: 31929 | H7: 31929 | I7: 31929 | J7: 31929 | K7: 31929 | L7: 31929 | M7: 31929 | N7: 31929 | O7: 31929 | P7: 31929 | Q7: 42979 | R7: 42979 | S7: 31929 | T7: 31929 | U7: 31929 | V7: 31929 | W7: 31929 | X7: 31929 | Y7: 31929 | Z7: 31929 | AA7: 31929 | AB7: 31929 | AC7: 31929 | AD7: 31929 | AE7: 31929 | AF7: 31929 | AG7: 31929 | AH7: 31929 | AI7: 31929 | AJ7: 42979 | AK7: 42979 | AL7: 31929 | AM7: 31929 | AN7: 31929 | AO7: 31929 | AP7: 31929 | AQ7: 31929 | AR7: 31929 | AS7: 31929 | AT7: 31929 | AU7: 31929 | AV7: 31929 | AW7: 31929 | AX7: 31929 | AY7: 31929 | AZ7: 31929 | BA7: 31929 | BB7: 31929 | BC7: 42979 | BD7: 42979 | BE7: 31929 | BF7: 31929
A8: Series End | B8: 45992 | C8: 45992 | D8: 45992 | E8: 45992 | F8: 45992 | G8: 45992 | H8: 45992 | I8: 45992 | J8: 45992 | K8: 45992 | L8: 45992 | M8: 45992 | N8: 45992 | O8: 45992 | P8: 45992 | Q8: 45992 | R8: 45992 | S8: 45992 | T8: 45992 | U8: 45992 | V8: 45992 | W8: 45992 | X8: 45992 | Y8: 45992 | Z8: 45992 | AA8: 45992 | AB8: 45992 | AC8: 45992 | AD8: 45992 | AE8: 45992 | AF8: 45992 | AG8: 45992 | AH8: 45992 | AI8: 45992 | AJ8: 45992 | AK8: 45992 | AL8: 45992 | AM8: 45992 | AN8: 45992 | AO8: 45992 | AP8: 45992 | AQ8: 45992 | AR8: 45992 | AS8: 45992 | AT8: 45992 | AU8: 45992 | AV8: 45992 | AW8: 45992 | AX8: 45992 | AY8: 45992 | AZ8: 45992 | BA8: 45992 | BB8: 45992 | BC8: 45992 | BD8: 45992 | BE8: 45992 | BF8: 45992
A9: No. Obs | B9: 155 | C9: 155 | D9: 155 | E9: 155 | F9: 155 | G9: 155 | H9: 155 | I9: 155 | J9: 155 | K9: 155 | L9: 155 | M9: 155 | N9: 155 | O9: 155 | P9: 155 | Q9: 34 | R9: 34 | S9: 155 | T9: 155 | U9: 155 | V9: 155 | W9: 155 | X9: 155 | Y9: 155 | Z9: 155 | AA9: 155 | AB9: 155 | AC9: 155 | AD9: 155 | AE9: 155 | AF9: 155 | AG9: 155 | AH9: 155 | AI9: 155 | AJ9: 34 | AK9: 34 | AL9: 155 | AM9: 155 | AN9: 155 | AO9: 155 | AP9: 155 | AQ9: 155 | AR9: 155 | AS9: 155 | AT9: 155 | AU9: 155 | AV9: 155 | AW9: 155 | AX9: 155 | AY9: 155 | AZ9: 155 | BA9: 155 | BB9: 155 | BC9: 34 | BD9: 34 | BE9: 155 | BF9: 155
A10: Series ID | B10: A124792377V | C10: A3517168V | D10: A124792079W | E10: A3517171J | F10: A3517174R | G10: A3517177W | H10: A3517180K | I10: A3517183T | J10: A83728707W | K10: A3517186X | L10: A3517189F | M10: A3517192V | N10: A3517195A | O10: A3517198J | P10: A83728710K | Q10: A85301896V | R10: A85301921K | S10: A83728713T | T10: A83728716X | U10: A124792395X | V10: A3517210L | W10: A124792081J | X10: A3517213V | Y10: A3517216A | Z10: A3517219J | AA10: A3517222W | AB10: A3517225C | AC10: A83728708X | AD10: A3517228K | AE10: A3517231X | AF10: A3517234F | AG10: A3517237L | AH10: A3517240A | AI10: A83728711L | AJ10: A85301942W | AK10: A85301930L | AL10: A83728714V | AM10: A83728717A | AN10: A124792413T | AO10: A3517252K | AP10: A124792083L | AQ10: A3517255T | AR10: A3517258X | AS10: A3517261L | AT10: A3517264V | AU10: A3517267A | AV10: A83728709A | AW10: A3517270R | AX10: A3517273W | AY10: A3517276C | AZ10: A3517279K | BA10: A3517282X | BB10: A83728712R | BC10: A85301951X | BD10: A85301904J | BE10: A83728715W | BF10: A83728718C
A11: 31929 | B11: 2489 | C11: 421 | D11: 2068 | E11: 175 | F11: 16 | G11: 138 | H11: 58 | I11: 86 | J11: 274 | K11: 62 | L11: 54 | M11: 237 | N11: 582 | O11: 28 | P11: 9 | S11: 33 | T11: 5 | U11: 4735 | V11: 578 | W11: 4157 | X11: 1517 | Y11: 5 | Z11: 147 | AA11: 410 | AB11: 308 | AC11: 110 | AD11: 458 | AE11: 80 | AF11: 272 | AG11: 278 | AH11: 187 | AI11: 62 | AL11: 31 | AM11: 56 | AN11: 7225 | AO11: 1000 | AP11: 6225 | AQ11: 1692 | AR11: 21 | AS11: 286 | AT11: 468 | AU11: 395 | AV11: 384 | AW11: 519 | AX11: 134 | AY11: 509 | AZ11: 861 | BA11: 215 | BB11: 72 | BE11: 64 | BF11: 62
A12: 32021 | B12: 2708 | C12: 514 | D12: 2195 | E12: 212 | F12: 12 | G12: 132 | H12: 63 | I12: 77 | J12: 203 | K12: 93 | L12: 36 | M12: 294 | N12: 640 | O12: 52 | P12: 18 | S12: 36 | T12: 4 | U12: 4385 | V12: 495 | W12: 3890 | X12: 1442 | Y12: 5 | Z12: 273 | AA12: 299 | AB12: 290 | AC12: 124 | AD12: 308 | AE12: 93 | AF12: 330 | AG12: 244 | AH12: 159 | AI12: 47 | AL12: 15 | AM12: 43 | AN12: 7094 | AO12: 1009 | AP12: 6084 | AQ12: 1654 | AR12: 17 | AS12: 404 | AT12: 362 | AU12: 368 | AV12: 327 | AW12: 401 | AX12: 129 | AY12: 624 | AZ12: 884 | BA12: 210 | BB12: 65 | BE12: 51 | BF12: 47
A13: 32112 | B13: 3393 | C13: 382 | D13: 3011 | E13: 226 | F13: 15 | G13: 196 | H13: 107 | I13: 129 | J13: 282 | K13: 52 | L13: 28 | M13: 416 | N13: 1002 | O13: 38 | P13: 12 | S13: 42 | T13: 12 | U13: 5169 | V13: 735 | W13: 4434 | X13: 1425 | Y13: 6 | Z13: 171 | AA13: 396 | AB13: 329 | AC13: 207 | AD13: 402 | AE13: 120 | AF13: 386 | AG13: 346 | AH13: 220 | AI13: 67 | AL13: 21 | AM13: 69 | AN13: 8562 | AO13: 1117 | AP13: 7445 | AQ13: 1651 | AR13: 21 | AS13: 367 | AT13: 503 | AU13: 458 | AV13: 489 | AW13: 454 | AX13: 148 | AY13: 802 | AZ13: 1348 | BA13: 259 | BB13: 79 | BE13: 63 | BF13: 81
A14: 32203 | B14: 2634 | C14: 383 | D14: 2251 | E14: 241 | F14: 13 | G14: 130 | H14: 49 | I14: 43 | J14: 247 | K14: 67 | L14: 6 | M14: 204 | N14: 796 | O14: 38 | P14: 12 | S14: 72 | T14: 5 | U14: 4389 | V14: 550 | W14: 3839 | X14: 1292 | Y14: 4 | Z14: 182 | AA14: 291 | AB14: 218 | AC14: 116 | AD14: 316 | AE14: 130 | AF14: 327 | AG14: 244 | AH14: 331 | AI14: 86 | AL14: 33 | AM14: 41 | AN14: 7023 | AO14: 934 | AP14: 6090 | AQ14: 1533 | AR14: 17 | AS14: 312 | AT14: 340 | AU14: 262 | AV14: 363 | AW14: 383 | AX14: 136 | AY14: 531 | AZ14: 1041 | BA14: 368 | BB14: 99 | BE14: 105 | BF14: 46
A15: 32295 | B15: 3532 | C15: 397 | D15: 3136 | E15: 255 | F15: 15 | G15: 165 | H15: 116 | I15: 57 | J15: 378 | K15: 70 | L15: 16 | M15: 325 | N15: 1139 | O15: 66 | P15: 22 | S15: 37 | T15: 6 | U15: 5500 | V15: 579 | W15: 4921 | X15: 1689 | Y15: 9 | Z15: 223 | AA15: 424 | AB15: 290 | AC15: 144 | AD15: 400 | AE15: 118 | AF15: 378 | AG15: 476 | AH15: 274 | AI15: 80 | AL15: 40 | AM15: 88 | AN15: 9032 | AO15: 976 | AP15: 8056 | AQ15: 1944 | AR15: 24 | AS15: 388 | AT15: 539 | AU15: 347 | AV15: 522 | AW15: 470 | AX15: 133 | AY15: 703 | AZ15: 1615 | BA15: 340 | BB15: 102 | BE15: 76 | BF15: 94
A16: 32387 | B16: 3236 | C16: 362 | D16: 2875 | E16: 259 | F16: 11 | G16: 105 | H16: 133 | I16: 66 | J16: 261 | K16: 59 | L16: 19 | M16: 338 | N16: 1114 | O16: 34 | P16: 10 | S16: 27 | T16: 13 | U16: 4514 | V16: 576 | W16: 3938 | X16: 1306 | Y16: 9 | Z16: 197 | AA16: 352 | AB16: 279 | AC16: 137 | AD16: 373 | AE16: 97 | AF16: 355 | AG16: 216 | AH16: 239 | AI16: 72 | AL16: 15 | AM16: 57 | AN16: 7750 | AO16: 937 | AP16: 6813 | AQ16: 1565 | AR16: 20 | AS16: 301 | AT16: 485 | AU16: 345 | AV16: 397 | AW16: 432 | AX16: 116 | AY16: 693 | AZ16: 1329 | BA16: 274 | BB16: 82 | BE16: 42 | BF16: 70
A17: 32478 | B17: 3984 | C17: 378 | D17: 3606 | E17: 308 | F17: 11 | G17: 233 | H17: 164 | I17: 108 | J17: 343 | K17: 58 | L17: 26 | M17: 331 | N17: 1369 | O17: 59 | P17: 19 | S17: 32 | T17: 7 | U17: 5904 | V17: 749 | W17: 5155 | X17: 1666 | Y17: 7 | Z17: 270 | AA17: 514 | AB17: 317 | AC17: 135 | AD17: 705 | AE17: 112 | AF17: 410 | AG17: 297 | AH17: 260 | AI17: 79 | AL17: 13 | AM17: 62 | AN17: 9888 | AO17: 1127 | AP17: 8761 | AQ17: 1973 | AR17: 18 | AS17: 503 | AT17: 677 | AU17: 425 | AV17: 478 | AW17: 762 | AX17: 137 | AY17: 741 | AZ17: 1667 | BA17: 319 | BB17: 98 | BE17: 45 | BF17: 68
A18: 32568 | B18: 3252 | C18: 409 | D18: 2843 | E18: 295 | F18: 11 | G18: 88 | H18: 131 | I18: 54 | J18: 253 | K18: 67 | L18: 10 | M18: 260 | N18: 1151 | O18: 45 | P18: 15 | S18: 45 | T18: 3 | U18: 5179 | V18: 549 | W18: 4630 | X18: 1416 | Y18: 6 | Z18: 307 | AA18: 381 | AB18: 209 | AC18: 112 | AD18: 521 | AE18: 75 | AF18: 512 | AG18: 228 | AH18: 376 | AI18: 103 | AL18: 8 | AM18: 89 | AN18: 8430 | AO18: 958 | AP18: 7473 | AQ18: 1711 | AR18: 17 | AS18: 395 | AT18: 512 | AU18: 264 | AV18: 365 | AW18: 587 | AX18: 85 | AY18: 772 | AZ18: 1379 | BA18: 422 | BB18: 118 | BE18: 54 | BF18: 92
A19: 32660 | B19: 4345 | C19: 372 | D19: 3973 | E19: 367 | F19: 14 | G19: 149 | H19: 151 | I19: 87 | J19: 389 | K19: 99 | L19: 25 | M19: 442 | N19: 1543 | O19: 62 | P19: 20 | S19: 27 | T19: 9 | U19: 6160 | V19: 633 | W19: 5527 | X19: 1708 | Y19: 3 | Z19: 386 | AA19: 487 | AB19: 312 | AC19: 141 | AD19: 594 | AE19: 103 | AF19: 396 | AG19: 323 | AH19: 496 | AI19: 136 | AL19: 14 | AM19: 87 | AN19: 10505 | AO19: 1006 | AP19: 9499 | AQ19: 2075 | AR19: 17 | AS19: 535 | AT19: 638 | AU19: 400 | AV19: 531 | AW19: 693 | AX19: 128 | AY19: 837 | AZ19: 1866 | BA19: 559 | BB19: 156 | BE19: 41 | BF19: 96
A20: 32752 | B20: 3849 | C20: 500 | D20: 3349 | E20: 298 | F20: 8 | G20: 158 | H20: 120 | I20: 98 | J20: 273 | K20: 66 | L20: 29 | M20: 358 | N20: 1274 | O20: 91 | P20: 32 | S20: 31 | T20: 14 | U20: 5617 | V20: 546 | W20: 5070 | X20: 1555 | Y20: 26 | Z20: 226 | AA20: 456 | AB20: 332 | AC20: 101 | AD20: 664 | AE20: 73 | AF20: 374 | AG20: 359 | AH20: 390 | AI20: 106 | AL20: 7 | AM20: 89 | AN20: 9466 | AO20: 1046 | AP20: 8420 | AQ20: 1853 | AR20: 34 | AS20: 384 | AT20: 575 | AU20: 430 | AV20: 374 | AW20: 730 | AX20: 102 | AY20: 732 | AZ20: 1634 | BA20: 482 | BB20: 138 | BE20: 38 | BF20: 103
A21: 32843 | B21: 4436 | C21: 473 | D21: 3963 | E21: 361 | F21: 8 | G21: 245 | H21: 186 | I21: 111 | J21: 292 | K21: 90 | L21: 37 | M21: 425 | N21: 1453 | O21: 87 | P21: 30 | S21: 33 | T21: 16 | U21: 5940 | V21: 651 | W21: 5290 | X21: 1835 | Y21: 27 | Z21: 334 | AA21: 490 | AB21: 286 | AC21: 123 | AD21: 416 | AE21: 56 | AF21: 402 | AG21: 363 | AH21: 435 | AI21: 116 | AL21: 8 | AM21: 90 | AN21: 10376 | AO21: 1124 | AP21: 9252 | AQ21: 2197 | AR21: 35 | AS21: 579 | AT21: 676 | AU21: 397 | AV21: 415 | AW21: 506 | AX21: 93 | AY21: 827 | AZ21: 1816 | BA21: 523 | BB21: 146 | BE21: 42 | BF21: 106
A22: 32933 | B22: 3581 | C22: 412 | D22: 3169 | E22: 307 | F22: 14 | G22: 74 | H22: 109 | I22: 49 | J22: 201 | K22: 104 | L22: 31 | M22: 390 | N22: 1247 | O22: 102 | P22: 36 | S22: 30 | T22: 7 | U22: 4871 | V22: 484 | W22: 4387 | X22: 1522 | Y22: 8 | Z22: 242 | AA22: 371 | AB22: 241 | AC22: 113 | AD22: 279 | AE22: 63 | AF22: 370 | AG22: 408 | AH22: 350 | AI22: 95 | AL22: 7 | AM22: 63 | AN22: 8452 | AO22: 896 | AP22: 7557 | AQ22: 1830 | AR22: 22 | AS22: 316 | AT22: 479 | AU22: 290 | AV22: 315 | AW22: 383 | AX22: 95 | AY22: 760 | AZ22: 1655 | BA22: 452 | BB22: 131 | BE22: 37 | BF22: 70
... A88: 38961 | B88: 8931 | C88: 3720 | D88: 5211 | E88: 1068 | F88: 445 | G88: 47 | H88: 85 | I88: 231 | J88: 346 | K88: 755 | L88: 265 | M88: 140 | N88: 935 | O88: 35 | P88: 33 | S88: 126 | T88: 23 | U88: 12323 | V88: 1225 | W88: 11097 | X88: 1953 | Y88: 253 | Z88: 716 | AA88: 608 | AB88: 722 | AC88: 408 | AD88: 1556 | AE88: 393 | AF88: 721 | AG88: 1569 | AH88: 720 | AI88: 212 | AL88: 154 | AM88: 297 | AN88: 21254 | AO88: 4946 | AP88: 16308 | AQ88: 3020 | AR88: 698 | AS88: 763 | AT88: 693 | AU88: 953 | AV88: 754 | AW88: 2311 | AX88: 658 | AY88: 862 | AZ88: 2504 | BA88: 755 | BB88: 246 | BE88: 280 | BF88: 320
A89: 39052 | B89: 9754 | C89: 4329 | D89: 5425 | E89: 1103 | F89: 536 | G89: 56 | H89: 146 | I89: 261 | K89: 690 | M89: 191 | N89: 905 | S89: 85 | T89: 45 | U89: 13760 | V89: 1911 | W89: 11849 | X89: 2284 | Y89: 305 | Z89: 656 | AA89: 655 | AB89: 859 | AD89: 1322 | AF89: 823 | AG89: 1819 | AL89: 143 | AM89: 301 | AN89: 23513 | AO89: 6239 | AP89: 17274 | AQ89: 3387 | AR89: 842 | AS89: 713 | AT89: 801 | AU89: 1120 | AV89: 865 | AW89: 2012 | AX89: 637 | AY89: 1014 | AZ89: 2724 | BA89: 780 | BB89: 248 | BE89: 228 | BF89: 346
A90: 39142 | B90: 9796 | C90: 4046 | D90: 5749 | E90: 818 | F90: 438 | G90: 55 | H90: 94 | I90: 170 | K90: 557 | M90: 148 | N90: 1164 | S90: 41 | T90: 13 | U90: 12205 | V90: 1445 | W90: 10760 | X90: 1979 | Y90: 264 | Z90: 756 | AA90: 563 | AB90: 784 | AD90: 1289 | AF90: 679 | AG90: 1470 | AL90: 94 | AM90: 157 | AN90: 22001 | AO90: 5491 | AP90: 16509 | AQ90: 2798 | AR90: 703 | AS90: 811 | AT90: 658 | AU90: 954 | AV90: 619 | AW90: 1846 | AX90: 1663 | AY90: 827 | AZ90: 2634 | BA90: 778 | BB90: 328 | BE90: 135 | BF90: 170
A91: 39234 | B91: 12614 | C91: 4958 | D91: 7656 | E91: 750 | F91: 691 | G91: 35 | H91: 102 | I91: 146 | J91: 354 | K91: 647 | L91: 1677 | M91: 120 | N91: 1839 | O91: 29 | P91: 24 | S91: 73 | T91: 41 | U91: 14805 | V91: 1987 | W91: 12818 | X91: 2151 | Y91: 196 | Z91: 1031 | AA91: 728 | AB91: 917 | AC91: 420 | AD91: 1731 | AE91: 625 | AF91: 780 | AG91: 1671 | AH91: 976 | AI91: 340 | AL91: 129 | AM91: 171 | AN91: 27419 | AO91: 6945 | AP91: 20474 | AQ91: 2901 | AR91: 887 | AS91: 1065 | AT91: 830 | AU91: 1064 | AV91: 774 | AW91: 2378 | AX91: 2302 | AY91: 900 | AZ91: 3510 | BA91: 1005 | BB91: 364 | BE91: 203 | BF91: 212
A92: 39326 | B92: 10593 | C92: 4438 | D92: 6155 | E92: 848 | F92: 582 | G92: 27 | H92: 142 | I92: 199 | J92: 376 | K92: 639 | L92: 901 | M92: 152 | N92: 1049 | O92: 82 | P92: 13 | S92: 99 | T92: 178 | U92: 12925 | V92: 1728 | W92: 11197 | X92: 1989 | Y92: 196 | Z92: 906 | AA92: 663 | AB92: 961 | AC92: 352 | AD92: 1273 | AE92: 385 | AF92: 646 | AG92: 1622 | AH92: 634 | AI92: 330 | AL92: 217 | AM92: 202 | AN92: 23518 | AO92: 6166 | AP92: 17352 | AQ92: 2837 | AR92: 778 | AS92: 933 | AT92: 805 | AU92: 1160 | AV92: 728 | AW92: 1912 | AX92: 1286 | AY92: 799 | AZ92: 2672 | BA92: 716 | BB92: 343 | BE92: 316 | BF92: 380
A93: 39417 | B93: 13133 | C93: 5441 | D93: 7692 | E93: 959 | F93: 752 | G93: 37 | H93: 184 | I93: 264 | K93: 681 | M93: 157 | N93: 1632 | O93: 98 | U93: 14727 | V93: 2093 | W93: 12634 | X93: 2379 | Y93: 290 | Z93: 1038 | AA93: 764 | AB93: 1000 | AD93: 1432 | AF93: 744 | AG93: 1766 | AH93: 839 | AN93: 27860 | AO93: 7534 | AP93: 20326 | AQ93: 3338 | AR93: 1042 | AS93: 1074 | AT93: 948 | AU93: 1264 | AV93: 929 | AW93: 2114 | AX93: 1504 | AY93: 901 | AZ93: 3399 | BA93: 936 | BB93: 312 | BE93: 196 | BF93: 358
A94: 39508 | B94: 11157 | C94: 4832 | D94: 6325 | E94: 977 | F94: 710 | G94: 53 | H94: 112 | I94: 159 | K94: 568 | M94: 120 | N94: 1149 | O94: 80 | S94: 55 | T94: 135 | U94: 12035 | V94: 1890 | W94: 10145 | X94: 1932 | Y94: 268 | Z94: 824 | AA94: 588 | AB94: 621 | AD94: 1372 | AF94: 547 | AG94: 1218 | AH94: 755 | AL94: 81 | AM94: 162 | AN94: 23192 | AO94: 6722 | AP94: 16470 | AQ94: 2909 | AR94: 978 | AS94: 877 | AT94: 700 | AU94: 780 | AV94: 644 | AW94: 1939 | AX94: 1504 | AY94: 667 | AZ94: 2367 | BA94: 836 | BB94: 229 | BE94: 136 | BF94: 297
A95: 39600 | B95: 13274 | C95: 5978 | D95: 7296 | E95: 983 | F95: 568 | G95: 67 | H95: 178 | I95: 213 | K95: 673 | M95: 227 | N95: 1644 | O95: 61 | S95: 94 | T95: 42 | U95: 16324 | V95: 2801 | W95: 13523 | X95: 2273 | Y95: 458 | Z95: 1128 | AA95: 765 | AB95: 1106 | AD95: 2087 | AF95: 663 | AG95: 1515 | AH95: 828 | AL95: 105 | AM95: 195 | AN95: 29597 | AO95: 8779 | AP95: 20819 | AQ95: 3256 | AR95: 1026 | AS95: 1195 | AT95: 943 | AU95: 1319 | AV95: 624 | AW95: 2760 | AX95: 2026 | AY95: 891 | AZ95: 3159 | BA95: 889 | BB95: 262 | BE95: 200 | BF95: 237
A96: 39692 | B96: 13412 | C96: 6331 | D96: 7081 | E96: 961 | F96: 735 | G96: 27 | H96: 112 | I96: 193 | J96: 410 | K96: 948 | L96: 883 | M96: 260 | N96: 1356 | O96: 47 | P96: 21 | S96: 76 | T96: 51 | U96: 14286 | V96: 2241 | W96: 12045 | X96: 1975 | Y96: 232 | Z96: 688 | AA96: 797 | AB96: 912 | AC96: 283 | AD96: 1777 | AE96: 699 | AF96: 676 | AG96: 1935 | AH96: 659 | AI96: 232 | AL96: 95 | AM96: 189 | AN96: 27698 | AO96: 8572 | AP96: 19126 | AQ96: 2936 | AR96: 967 | AS96: 715 | AT96: 910 | AU96: 1105 | AV96: 693 | AW96: 2725 | AX96: 1583 | AY96: 936 | AZ96: 3291 | BA96: 706 | BB96: 253 | BE96: 171 | BF96: 240
A97: 39783 | B97: 17500 | C97: 8121 | D97: 9379 | E97: 1264 | F97: 1223 | G97: 85 | H97: 249 | I97: 361 | J97: 266 | K97: 1340 | L97: 1074 | M97: 240 | N97: 1558 | O97: 79 | P97: 172 | S97: 133 | T97: 8 | U97: 16769 | V97: 2921 | W97: 13848 | X97: 2347 | Y97: 439 | Z97: 787 | AA97: 849 | AB97: 1150 | AC97: 406 | AD97: 2463 | AE97: 444 | AF97: 754 | AG97: 1669 | AH97: 936 | AI97: 234 | AL97: 130 | AM97: 215 | AN97: 34269 | AO97: 11042 | AP97: 23227 | AQ97: 3612 | AR97: 1662 | AS97: 872 | AT97: 1098 | AU97: 1510 | AV97: 673 | AW97: 3803 | AX97: 1518 | AY97: 994 | AZ97: 3228 | BA97: 1016 | BB97: 406 | BE97: 264 | BF97: 223
A98: 39873 | B98: 13585 | C98: 6807 | D98: 6778 | E98: 1035 | F98: 955 | G98: 52 | H98: 120 | I98: 141 | J98: 144 | K98: 1133 | L98: 983 | M98: 155 | N98: 901 | O98: 56 | P98: 37 | S98: 102 | T98: 26 | U98: 13291 | V98: 2284 | W98: 11008 | X98: 1820 | Y98: 263 | Z98: 1064 | AA98: 704 | AB98: 824 | AC98: 502 | AD98: 1816 | AE98: 464 | AF98: 604 | AG98: 1173 | AH98: 516 | AI98: 134 | AL98: 114 | AM98: 190 | AN98: 26876 | AO98: 9090 | AP98: 17786 | AQ98: 2855 | AR98: 1218 | AS98: 1116 | AT98: 825 | AU98: 965 | AV98: 646 | AW98: 2949 | AX98: 1447 | AY98: 759 | AZ98: 2074 | BA98: 572 | BB98: 171 | BE98: 216 | BF98: 216
A99: 39965 | B99: 15623 | C99: 6831 | D99: 8792 | E99: 1073 | F99: 1377 | G99: 78 | H99: 143 | I99: 232 | J99: 427 | K99: 1298 | L99: 1272 | M99: 166 | N99: 1155 | O99: 55 | P99: 57 | S99: 123 | T99: 76 | U99: 17104 | V99: 2442 | W99: 14662 | X99: 2206 | Y99: 332 | Z99: 1315 | AA99: 903 | AB99: 1270 | AC99: 663 | AD99: 2274 | AE99: 512 | AF99: 610 | AG99: 1333 | AH99: 1034 | AI99: 484 | AL99: 174 | AM99: 442 | AN99: 32727 | AO99: 9273 | AP99: 23454 | AQ99: 3279 | AR99: 1710 | AS99: 1393 | AT99: 1046 | AU99: 1502 | AV99: 1090 | AW99: 3572 | AX99: 1784 | AY99: 776 | AZ99: 2487 | BA99: 1090 | BB99: 541 | BE99: 297 | BF99: 518
A100: 40057 | B100: 12784 | C100: 6044 | D100: 6740 | E100: 936 | F100: 932 | G100: 47 | H100: 128 | I100: 262 | J100: 312 | K100: 1016 | L100: 893 | M100: 104 | N100: 804 | O100: 112 | P100: 69 | S100: 100 | T100: 77 | U100: 13738 | V100: 1916 | W100: 11821 | X100: 1679 | Y100: 311 | Z100: 1019 | AA100: 638 | AB100: 910 | AC100: 399 | AD100: 2035 | AE100: 382 | AF100: 506 | AG100: 1594 | AH100: 741 | AI100: 263 | AL100: 176 | AM100: 264 | AN100: 26522 | AO100: 7961 | AP100: 18561 | AQ100: 2615 | AR100: 1243 | AS100: 1066 | AT100: 766 | AU100: 1172 | AV100: 711 | AW100: 3051 | AX100: 1275 | AY100: 611 | AZ100: 2399 | BA100: 853 | BB100: 332 | BE100: 276 | BF100: 341
A101: 40148 | B101: 14818 | C101: 6792 | D101: 8026 | E101: 1186 | F101: 1184 | G101: 70 | H101: 142 | I101: 254 | J101: 476 | K101: 996 | L101: 849 | M101: 178 | N101: 1224 | O101: 119 | P101: 18 | S101: 97 | T101: 117 | U101: 17534 | V101: 2534 | W101: 15000 | X101: 2226 | Y101: 365 | Z101: 1562 | AA101: 951 | AB101: 1095 | AC101: 476 | AD101: 2430 | AE101: 446 | AF101: 564 | AG101: 1910 | AH101: 1012 | AI101: 381 | AL101: 130 | AM101: 314 | AN101: 32352 | AO101: 9326 | AP101: 23027 | AQ101: 3412 | AR101: 1549 | AS101: 1632 | AT101: 1093 | AU101: 1349 | AV101: 952 | AW101: 3426 | AX101: 1295 | AY101: 742 | AZ101: 3135 | BA101: 1130 | BB101: 399 | BE101: 227 | BF101: 431
A102: 40238 | B102: 13055 | C102: 6189 | D102: 6867 | E102: 804 | F102: 928 | G102: 46 | H102: 57 | I102: 156 | J102: 219 | K102: 843 | N102: 1484 | O102: 161 | P102: 52 | S102: 64 | T102: 117 | U102: 12633 | V102: 1900 | W102: 10733 | X102: 1649 | Y102: 255 | Z102: 1513 | AA102: 710 | AB102: 661 | AC102: 322 | AD102: 1459 | AG102: 1252 | AH102: 673 | AI102: 166 | AL102: 165 | AM102: 172 | AN102: 25688 | AO102: 8088 | AP102: 17600 | AQ102: 2453 | AR102: 1183 | AS102: 1558 | AT102: 767 | AU102: 817 | AV102: 541 | AW102: 2302 | AX102: 1194 | AY102: 680 | AZ102: 2736 | BA102: 834 | BB102: 218 | BE102: 229 | BF102: 289
A103: 40330 | B103: 15429 | C103: 7449 | D103: 7980 | E103: 1119 | F103: 1405 | G103: 78 | H103: 109 | I103: 156 | J103: 277 | K103: 879 | N103: 1379 | O103: 195 | P103: 42 | S103: 99 | T103: 155 | U103: 15077 | V103: 2361 | W103: 12717 | X103: 2144 | Y103: 347 | Z103: 1788 | AA103: 607 | AB103: 942 | AC103: 433 | AD103: 1515 | AG103: 1714 | AH103: 709 | AI103: 257 | AL103: 176 | AM103: 177 | AN103: 30507 | AO103: 9810 | AP103: 20697 | AQ103: 3263 | AR103: 1752 | AS103: 1866 | AT103: 716 | AU103: 1098 | AV103: 710 | AW103: 2393 | AX103: 1259 | AY103: 676 | AZ103: 3093 | BA103: 904 | BB103: 299 | BE103: 275 | BF103: 333
A104: 40422 | B104: 16154 | C104: 8350 | D104: 7804 | E104: 950 | F104: 1308 | G104: 59 | H104: 113 | I104: 362 | J104: 289 | K104: 885 | N104: 1444 | O104: 160 | P104: 33 | S104: 110 | T104: 91 | U104: 12447 | V104: 2070 | W104: 10377 | X104: 1748 | Y104: 269 | Z104: 1045 | AA104: 640 | AB104: 685 | AC104: 319 | AD104: 1049 | AG104: 1723 | AH104: 640 | AI104: 237 | AL104: 163 | AM104: 177 | AN104: 28601 | AO104: 10420 | AP104: 18181 | AQ104: 2699 | AR104: 1577 | AS104: 1103 | AT104: 753 | AU104: 1047 | AV104: 608 | AW104: 1934 | AX104: 1097 | AY104: 700 | AZ104: 3167 | BA104: 799 | BB104: 270 | BE104: 272 | BF104: 268
A105: 40513 | B105: 17859 | C105: 8972 | D105: 8887 | E105: 1351 | F105: 1221 | G105: 83 | H105: 167 | I105: 316 | J105: 330 | K105: 1157 | N105: 1552 | O105: 336 | P105: 25 | S105: 125 | T105: 150 | U105: 15741 | V105: 2572 | W105: 13170 | X105: 2054 | Y105: 510 | Z105: 1383 | AA105: 792 | AB105: 868 | AC105: 543 | AD105: 2157 | AG105: 1423 | AH105: 720 | AI105: 257 | AL105: 104 | AM105: 227 | AN105: 33600 | AO105: 11543 | AP105: 22057 | AQ105: 3405 | AR105: 1730 | AS105: 1466 | AT105: 960 | AU105: 1184 | AV105: 873 | AW105: 3313 | AX105: 1181 | AY105: 806 | AZ105: 2974 | BA105: 1056 | BB105: 282 | BE105: 229 | BF105: 377
...

Sheet Energy Utilities
B2: Energy Utilities — Private New Capital Expenditure
B3: ANZSIC division: Electricity, Gas, Water and Waste Services. Source: ABS 5625.0, Table 1 (Original, Current Prices, $m).
B5: Summary statistics ($m, quarterly observations) | H5: Quarter | I5: Buildings & Structures | J5: Equipment, Plant & Machinery | K5: Total Capex
B6: Metric | C6: Buildings & Structures | D6: Equipment, Plant & Machinery | E6: Total Capex | H6: =Data1!A11 -> 31929 | I6: =Data1!F11 -> 16 | J6: =Data1!Y11 -> 5 | K6: =Data1!AR11 -> 21
B7: Series ID | C7: =Data1!F10 -> A3517174R | D7: =Data1!Y10 -> A3517216A | E7: =Data1!AR10 -> A3517258X | H7: =Data1!A12 -> 32021 | I7: =Data1!F12 -> 12 | J7: =Data1!Y12 -> 5 | K7: =Data1!AR12 -> 17
B8: Observations | C8: =COUNT(Data1!F11:F165) -> 155 | D8: =COUNT(Data1!Y11:Y165) -> 155 | E8: =COUNT(Data1!AR11:AR165) -> 155 | H8: =Data1!A13 -> 32112 | I8: =Data1!F13 -> 15 | J8: =Data1!Y13 -> 6 | K8: =Data1!AR13 -> 21
B9: Start | C9: =Data1!F7 -> 31929 | D9: =Data1!Y7 -> 31929 | E9: =Data1!AR7 -> 31929 | H9: =Data1!A14 -> 32203 | I9: =Data1!F14 -> 13 | J9: =Data1!Y14 -> 4 | K9: =Data1!AR14 -> 17
B10: End | C10: =Data1!F8 -> 45992 | D10: =Data1!Y8 -> 45992 | E10: =Data1!AR8 -> 45992 | H10: =Data1!A15 -> 32295 | I10: =Data1!F15 -> 15 | J10: =Data1!Y15 -> 9 | K10: =Data1!AR15 -> 24
B11: Mean | C11: =AVERAGE(Data1!F11:F165) -> 860.85806 | D11: =AVERAGE(Data1!Y11:Y165) -> 268.14194 | E11: =AVERAGE(Data1!AR11:AR165) -> 1129.0323 | H11: =Data1!A16 -> 32387 | I11: =Data1!F16 -> 11 | J11: =Data1!Y16 -> 9 | K11: =Data1!AR16 -> 20
B12: Median | C12: =MEDIAN(Data1!F11:F165) -> 438 | D12: =MEDIAN(Data1!Y11:Y165) -> 273 | E12: =MEDIAN(Data1!AR11:AR165) -> 703 | H12: =Data1!A17 -> 32478 | I12: =Data1!F17 -> 11 | J12: =Data1!Y17 -> 7 | K12: =Data1!AR17 -> 18
B13: Std. Deviation | C13: =_xlfn.STDEV.S(Data1!F11:F165) -> 1046.9044 | D13: =_xlfn.STDEV.S(Data1!Y11:Y165) -> 182.59061 | E13: =_xlfn.STDEV.S(Data1!AR11:AR165) -> 1160.7251 | H13: =Data1!A18 -> 32568 | I13: =Data1!F18 -> 11 | J13: =Data1!Y18 -> 6 | K13: =Data1!AR18 -> 17
B14: Min | C14: =MIN(Data1!F11:F165) -> 5 | D14: =MIN(Data1!Y11:Y165) -> 1 | E14: =MIN(Data1!AR11:AR165) -> 13 | H14: =Data1!A19 -> 32660 | I14: =Data1!F19 -> 14 | J14: =Data1!Y19 -> 3 | K14: =Data1!AR19 -> 17
B15: Max | C15: =MAX(Data1!F11:F165) -> 4739 | D15: =MAX(Data1!Y11:Y165) -> 664 | E15: =MAX(Data1!AR11:AR165) -> 5283 | H15: =Data1!A20 -> 32752 | I15: =Data1!F20 -> 8 | J15: =Data1!Y20 -> 26 | K15: =Data1!AR20 -> 34
B16: 25th percentile | C16: =_xlfn.PERCENTILE.INC(Data1!F11:F165,0.25) -> 54 | D16: =_xlfn.PERCENTILE.INC(Data1!Y11:Y165,0.25) -> 127.5 | E16: =_xlfn.PERCENTILE.INC(Data1!AR11:AR165,0.25) -> 183.5 | H16: =Data1!A21 -> 32843 | I16: =Data1!F21 -> 8 | J16: =Data1!Y21 -> 27 | K16: =Data1!AR21 -> 35
B17: 75th percentile | C17: =_xlfn.PERCENTILE.INC(Data1!F11:F165,0.75) -> 1202.5 | D17: =_xlfn.PERCENTILE.INC(Data1!Y11:Y165,0.75) -> 392 | E17: =_xlfn.PERCENTILE.INC(Data1!AR11:AR165,0.75) -> 1578 | H17: =Data1!A22 -> 32933 | I17: =Data1!F22 -> 14 | J17: =Data1!Y22 -> 8 | K17: =Data1!AR22 -> 22
B18: Latest quarter | C18: {=INDEX(Data1!F11:F165,COUNT(Data1!F11:F165))} -> 4739 | D18: {=INDEX(Data1!Y11:Y165,COUNT(Data1!Y11:Y165))} -> 544 | E18: {=INDEX(Data1!AR11:AR165,COUNT(Data1!AR11:AR165))} -> 5283 | H18: =Data1!A23 -> 33025 | I18: =Data1!F23 -> 23 | J18: =Data1!Y23 -> 7 | K18: =Data1!AR23 -> 31
B19: Sum (total period) | C19: =SUM(Data1!F11:F165) -> 133433 | D19: =SUM(Data1!Y11:Y165) -> 41562 | E19: =SUM(Data1!AR11:AR165) -> 175000 | H19: =Data1!A24 -> 33117 | I19: =Data1!F24 -> 9 | J19: =Data1!Y24 -> 7 | K19: =Data1!AR24 -> 17
H20: =Data1!A25 -> 33208 | I20: =Data1!F25 -> 8 | J20: =Data1!Y25 -> 5 | K20: =Data1!AR25 -> 14
B21: Annual totals by calendar year ($m) | H21: =Data1!A26 -> 33298 | I21: =Data1!F26 -> 11 | J21: =Data1!Y26 -> 3 | K21: =Data1!AR26 -> 14
B22: Year | C22: Buildings & Structures | D22: Equipment, Plant & Machinery | E22: Total Capex | H22: =Data1!A27 -> 33390 | I22: =Data1!F27 -> 7 | J22: =Data1!Y27 -> 11 | K22: =Data1!AR27 -> 18
B23: 1988 | C23: =SUMIFS(Data1!F$11:F$165,Data1!$A$11:$A$165,">="&DATE($B23,1,1),Data1!$A$11:$A$165,"<="&DATE($B23,12,31)) -> 50 | D23: =SUMIFS(Data1!Y$11:Y$165,Data1!$A$11:$A$165,">="&DATE($B23,1,1),Data1!$A$11:$A$165,"<="&DATE($B23,12,31)) -> 29 | E23: =SUMIFS(Data1!AR$11:AR$165,Data1!$A$11:$A$165,">="&DATE($B23,1,1),Data1!$A$11:$A$165,"<="&DATE($B23,12,31)) -> 79 | H23: =Data1!A28 -> 33482 | I23: =Data1!F28 -> 7 | J23: =Data1!Y28 -> 8 | K23: =Data1!AR28 -> 15
B24: 1989 | C24: =SUMIFS(Data1!F$11:F$165,Data1!$A$11:$A$165,">="&DATE($B24,1,1),Data1!$A$11:$A$165,"<="&DATE($B24,12,31)) -> 41 | D24: =SUMIFS(Data1!Y$11:Y$165,Data1!$A$11:$A$165,">="&DATE($B24,1,1),Data1!$A$11:$A$165,"<="&DATE($B24,12,31)) -> 62 | E24: =SUMIFS(Data1!AR$11:AR$165,Data1!$A$11:$A$165,">="&DATE($B24,1,1),Data1!$A$11:$A$165,"<="&DATE($B24,12,31)) -> 103 | H24: =Data1!A29 -> 33573 | I24: =Data1!F29 -> 8 | J24: =Data1!Y29 -> 12 | K24: =Data1!AR29 -> 19
B25: 1990 | C25: =SUMIFS(Data1!F$11:F$165,Data1!$A$11:$A$165,">="&DATE($B25,1,1),Data1!$A$11:$A$165,"<="&DATE($B25,12,31)) -> 54 | D25: =SUMIFS(Data1!Y$11:Y$165,Data1!$A$11:$A$165,">="&DATE($B25,1,1),Data1!$A$11:$A$165,"<="&DATE($B25,12,31)) -> 27 | E25: =SUMIFS(Data1!AR$11:AR$165,Data1!$A$11:$A$165,">="&DATE($B25,1,1),Data1!$A$11:$A$165,"<="&DATE($B25,12,31)) -> 84 | H25: =Data1!A30 -> 33664 | I25: =Data1!F30 -> 5 | J25: =Data1!Y30 -> 10 | K25: =Data1!AR30 -> 15
B26: 1991 | C26: =SUMIFS(Data1!F$11:F$165,Data1!$A$11:$A$165,">="&DATE($B26,1,1),Data1!$A$11:$A$165,"<="&DATE($B26,12,31)) -> 33 | D26: =SUMIFS(Data1!Y$11:Y$165,Data1!$A$11:$A$165,">="&DATE($B26,1,1),Data1!$A$11:$A$165,"<="&DATE($B26,12,31)) -> 34 | E26: =SUMIFS(Data1!AR$11:AR$165,Data1!$A$11:$A$165,">="&DATE($B26,1,1),Data1!$A$11:$A$165,"<="&DATE($B26,12,31)) -> 66 | H26: =Data1!A31 -> 33756 | I26: =Data1!F31 -> 10 | J26: =Data1!Y31 -> 6 | K26: =Data1!AR31 -> 16
B27: 1992 | C27: =SUMIFS(Data1!F$11:F$165,Data1!$A$11:$A$165,">="&DATE($B27,1,1),Data1!$A$11:$A$165,"<="&DATE($B27,12,31)) -> 40 | D27: =SUMIFS(Data1!Y$11:Y$165,Data1!$A$11:$A$165,">="&DATE($B27,1,1),Data1!$A$11:$A$165,"<="&DATE($B27,12,31)) -> 27 | E27: =SUMIFS(Data1!AR$11:AR$165,Data1!$A$11:$A$165,">="&DATE($B27,1,1),Data1!$A$11:$A$165,"<="&DATE($B27,12,31)) -> 67 | H27: =Data1!A32 -> 33848 | I27: =Data1!F32 -> 10 | J27: =Data1!Y32 -> 5 | K27: =Data1!AR32 -> 15
B28: 1993 | C28: =SUMIFS(Data1!F$11:F$165,Data1!$A$11:$A$165,">="&DATE($B28,1,1),Data1!$A$11:$A$165,"<="&DATE($B28,12,31)) -> 42 | D28: =SUMIFS(Data1!Y$11:Y$165,Data1!$A$11:$A$165,">="&DATE($B28,1,1),Data1!$A$11:$A$165,"<="&DATE($B28,12,31)) -> 28 | E28: =SUMIFS(Data1!AR$11:AR$165,Data1!$A$11:$A$165,">="&DATE($B28,1,1),Data1!$A$11:$A$165,"<="&DATE($B28,12,31)) -> 70 | H28: =Data1!A33 -> 33939 | I28: =Data1!F33 -> 15 | J28: =Data1!Y33 -> 6 | K28: =Data1!AR33 -> 21
B29: 1994 | C29: =SUMIFS(Data1!F$11:F$165,Data1!$A$11:$A$165,">="&DATE($B29,1,1),Data1!$A$11:$A$165,"<="&DATE($B29,12,31)) -> 67 | D29: =SUMIFS(Data1!Y$11:Y$165,Data1!$A$11:$A$165,">="&DATE($B29,1,1),Data1!$A$11:$A$165,"<="&DATE($B29,12,31)) -> 25 | E29: =SUMIFS(Data1!AR$11:AR$165,Data1!$A$11:$A$165,">="&DATE($B29,1,1),Data1!$A$11:$A$165,"<="&DATE($B29,12,31)) -> 92 | H29: =Data1!A34 -> 34029 | I29: =Data1!F34 -> 13 | J29: =Data1!Y34 -> 5 | K29: =Data1!AR34 -> 18
B30: 1995 | C30: =SUMIFS(Data1!F$11:F$165,Data1!$A$11:$A$165,">="&DATE($B30,1,1),Data1!$A$11:$A$165,"<="&DATE($B30,12,31)) -> 123 | D30: =SUMIFS(Data1!Y$11:Y$165,Data1!$A$11:$A$165,">="&DATE($B30,1,1),Data1!$A$11:$A$165,"<="&DATE($B30,12,31)) -> 93 | E30: =SUMIFS(Data1!AR$11:AR$165,Data1!$A$11:$A$165,">="&DATE($B30,1,1),Data1!$A$11:$A$165,"<="&DATE($B30,12,31)) -> 217 | H30: =Data1!A35 -> 34121 | I30: =Data1!F35 -> 6 | J30: =Data1!Y35 -> 7 | K30: =Data1!AR35 -> 13
B31: 1996 | C31: =SUMIFS(Data1!F$11:F$165,Data1!$A$11:$A$165,">="&DATE($B31,1,1),Data1!$A$11:$A$165,"<="&DATE($B31,12,31)) -> 240 | D31: =SUMIFS(Data1!Y$11:Y$165,Data1!$A$11:$A$165,">="&DATE($B31,1,1),Data1!$A$11:$A$165,"<="&DATE($B31,12,31)) -> 510 | E31: =SUMIFS(Data1!AR$11:AR$165,Data1!$A$11:$A$165,">="&DATE($B31,1,1),Data1!$A$11:$A$165,"<="&DATE($B31,12,31)) -> 751 | H31: =Data1!A36 -> 34213 | I31: =Data1!F36 -> 13 | J31: =Data1!Y36 -> 6 | K31: =Data1!AR36 -> 19
B32: 1997 | C32: =SUMIFS(Data1!F$11:F$165,Data1!$A$11:$A$165,">="&DATE($B32,1,1),Data1!$A$11:$A$165,"<="&DATE($B32,12,31)) -> 226 | D32: =SUMIFS(Data1!Y$11:Y$165,Data1!$A$11:$A$165,">="&DATE($B32,1,1),Data1!$A$11:$A$165,"<="&DATE($B32,12,31)) -> 565 | E32: =SUMIFS(Data1!AR$11:AR$165,Data1!$A$11:$A$165,">="&DATE($B32,1,1),Data1!$A$11:$A$165,"<="&DATE($B32,12,31)) -> 790 | H32: =Data1!A37 -> 34304 | I32: =Data1!F37 -> 10 | J32: =Data1!Y37 -> 10 | K32: =Data1!AR37 -> 20
B33: 1998 | C33: =SUMIFS(Data1!F$11:F$165,Data1!$A$11:$A$165,">="&DATE($B33,1,1),Data1!$A$11:$A$165,"<="&DATE($B33,12,31)) -> 239 | D33: =SUMIFS(Data1!Y$11:Y$165,Data1!$A$11:$A$165,">="&DATE($B33,1,1),Data1!$A$11:$A$165,"<="&DATE($B33,12,31)) -> 623 | E33: =SUMIFS(Data1!AR$11:AR$165,Data1!$A$11:$A$165,">="&DATE($B33,1,1),Data1!$A$11:$A$165,"<="&DATE($B33,12,31)) -> 863 | H33: =Data1!A38 -> 34394 | I33: =Data1!F38 -> 8 | J33: =Data1!Y38 -> 7 | K33: =Data1!AR38 -> 15
B34: 1999 | C34: =SUMIFS(Data1!F$11:F$165,Data1!$A$11:$A$165,">="&DATE($B34,1,1),Data1!$A$11:$A$165,"<="&DATE($B34,12,31)) -> 432 | D34: =SUMIFS(Data1!Y$11:Y$165,Data1!$A$11:$A$165,">="&DATE($B34,1,1),Data1!$A$11:$A$165,"<="&DATE($B34,12,31)) -> 1057 | E34: =SUMIFS(Data1!AR$11:AR$165,Data1!$A$11:$A$165,">="&DATE($B34,1,1),Data1!$A$11:$A$165,"<="&DATE($B34,12,31)) -> 1490 | H34: =Data1!A39 -> 34486 | I34: =Data1!F39 -> 12 | J34: =Data1!Y39 -> 13 | K34: =Data1!AR39 -> 25
... B59: 2024 | C59: =SUMIFS(Data1!F$11:F$165,Data1!$A$11:$A$165,">="&DATE($B59,1,1),Data1!$A$11:$A$165,"<="&DATE($B59,12,31)) -> 14037 | D59: =SUMIFS(Data1!Y$11:Y$165,Data1!$A$11:$A$165,">="&DATE($B59,1,1),Data1!$A$11:$A$165,"<="&DATE($B59,12,31)) -> 1856 | E59: =SUMIFS(Data1!AR$11:AR$165,Data1!$A$11:$A$165,">="&DATE($B59,1,1),Data1!$A$11:$A$165,"<="&DATE($B59,12,31)) -> 15893 | H59: =Data1!A64 -> 36770 | I59: =Data1!F64 -> 92 | J59: =Data1!Y64 -> 310 | K59: =Data1!AR64 -> 402
B60: 2025 | C60: =SUMIFS(Data1!F$11:F$165,Data1!$A$11:$A$165,">="&DATE($B60,1,1),Data1!$A$11:$A$165,"<="&DATE($B60,12,31)) -> 15784 | D60: =SUMIFS(Data1!Y$11:Y$165,Data1!$A$11:$A$165,">="&DATE($B60,1,1),Data1!$A$11:$A$165,"<="&DATE($B60,12,31)) -> 1870 | E60: =SUMIFS(Data1!AR$11:AR$165,Data1!$A$11:$A$165,">="&DATE($B60,1,1),Data1!$A$11:$A$165,"<="&DATE($B60,12,31)) -> 17655 | F60: partial year (3 quarters) | H60: =Data1!A65 -> 36861 | I60: =Data1!F65 -> 115 | J60: =Data1!Y65 -> 227 | K60: =Data1!AR65 -> 343
H61: =Data1!A66 -> 36951 | I61: =Data1!F66 -> 95 | J61: =Data1!Y66 -> 261 | K61: =Data1!AR66 -> 356
H62: =Data1!A67 -> 37043 | I62: =Data1!F67 -> 99 | J62: =Data1!Y67 -> 310 | K62: =Data1!AR67 -> 409
H63: =Data1!A68 -> 37135 | I63: =Data1!F68 -> 143 | J63: =Data1!Y68 -> 344 | K63: =Data1!AR68 -> 488
H64: =Data1!A69 -> 37226 | I64: =Data1!F69 -> 206 | J64: =Data1!Y69 -> 529 | K64: =Data1!AR69 -> 735
H65: =Data1!A70 -> 37316 | I65: =Data1!F70 -> 228 | J65: =Data1!Y70 -> 300 | K65: =Data1!AR70 -> 528
H66: =Data1!A71 -> 37408 | I66: =Data1!F71 -> 270 | J66: =Data1!Y71 -> 343 | K66: =Data1!AR71 -> 613
...

Sheet Enquiries
B2: Time Series Workbook
B5: 5625.0 Private New Capital Expenditure and Expected Expenditure, Australia
B6: Table 1. Actual Expenditure, by Type of Asset and Industry, Original - Current Prices $m
B10: E N Q U I R I E S
B11: For further information about this and related statistics visit www.abs.gov.au/about/contact-us. The
B12: ABS Privacy Policy outlines how the ABS will handle any personal information that you provide to us.
