Workbook
Name A2325846C: Data1!$B$1:$B$10,Data1!$B$11:$B$320
Name A2325846C_Data: Data1!$B$11:$B$320
Name A2325846C_Latest: Data1!$B$320
Name A2325850V: Data1!$ED$1:$ED$10,Data1!$ED$12:$ED$320
Name A2325850V_Data: Data1!$ED$12:$ED$320
Name A2325850V_Latest: Data1!$ED$320
Name A2325891R: Data1!$C$1:$C$10,Data1!$C$107:$C$320
Name A2325891R_Data: Data1!$C$107:$C$320
Name A2325891R_Latest: Data1!$C$320
Name A2325895X: Data1!$EE$1:$EE$10,Data1!$EE$108:$EE$320
Name A2325895X_Data: Data1!$EE$108:$EE$320
Name A2325895X_Latest: Data1!$EE$320
Name A2325936J: Data1!$AQ$1:$AQ$10,Data1!$AQ$107:$AQ$320
Name A2325936J_Data: Data1!$AQ$107:$AQ$320
Name A2325936J_Latest: Data1!$AQ$320
Name A2325940X: Data1!$FS$1:$FS$10,Data1!$FS$108:$FS$320
Name A2325940X_Data: Data1!$FS$108:$FS$320
Name A2325940X_Latest: Data1!$FS$320
Name A2325981V: Data1!$BC$1:$BC$10,Data1!$BC$107:$BC$320
Name A2325981V_Data: Data1!$BC$107:$BC$320
Name A2325981V_Latest: Data1!$BC$320
Name A2325985C: Data1!$GE$1:$GE$10,Data1!$GE$108:$GE$320
Name A2325985C_Data: Data1!$GE$108:$GE$320
Name A2325985C_Latest: Data1!$GE$320
Name A2326026R: Data1!$BO$1:$BO$10,Data1!$BO$107:$BO$320
Name A2326026R_Data: Data1!$BO$107:$BO$320
Name A2326026R_Latest: Data1!$BO$320
Name A2326030F: Data1!$GQ$1:$GQ$10,Data1!$GQ$108:$GQ$320
Name A2326030F_Data: Data1!$GQ$108:$GQ$320
Name A2326030F_Latest: Data1!$GQ$320
Name A2326071A: Data1!$CO$1:$CO$10,Data1!$CO$107:$CO$320
Name A2326071A_Data: Data1!$CO$107:$CO$320
Name A2326071A_Latest: Data1!$CO$320
Name A2326075K: Data1!$HQ$1:$HQ$10,Data1!$HQ$108:$HQ$320
Name A2326075K_Data: Data1!$HQ$108:$HQ$320
Name A2326075K_Latest: Data1!$HQ$320
Name A2326116V: Data1!$AJ$1:$AJ$10,Data1!$AJ$107:$AJ$320
Name A2326116V_Data: Data1!$AJ$107:$AJ$320
Name A2326116V_Latest: Data1!$AJ$320
Name A2326120K: Data1!$FL$1:$FL$10,Data1!$FL$108:$FL$320
Name A2326120K_Data: Data1!$FL$108:$FL$320
Name A2326120K_Latest: Data1!$FL$320
Name A2326161F: Data1!$P$1:$P$10,Data1!$P$107:$P$320
Name A2326161F_Data: Data1!$P$107:$P$320
Name A2326161F_Latest: Data1!$P$320
Name A2326165R: Data1!$ER$1:$ER$10,Data1!$ER$108:$ER$320
Name A2326165R_Data: Data1!$ER$108:$ER$320
Name A2326165R_Latest: Data1!$ER$320
Name A2326206X: Data1!$D$1:$D$10,Data1!$D$107:$D$320
Name A2326206X_Data: Data1!$D$107:$D$320
Name A2326206X_Latest: Data1!$D$320
Name A2326210R: Data1!$EF$1:$EF$10,Data1!$EF$108:$EF$320
Name A2326210R_Data: Data1!$EF$108:$EF$320
Name A2326210R_Latest: Data1!$EF$320
Name A2326251K: Data1!$I$1:$I$10,Data1!$I$107:$I$320
Name A2326251K_Data: Data1!$I$107:$I$320
Name A2326251K_Latest: Data1!$I$320
Name A2326255V: Data1!$EK$1:$EK$10,Data1!$EK$108:$EK$320
Name A2326255V_Data: Data1!$EK$108:$EK$320
Name A2326255V_Latest: Data1!$EK$320

Sheet Index
B2: Time Series Workbook
B5: 6401.0 Consumer Price Index, Australia
B6: TABLE 18. CPI: Quarterly Group, Sub-group and Expenditure Class, Weighted Average of Eight Capital Cities
D8: Enquiries
A10: Data Item Description | D10: Series Type | E10: Series ID | F10: Series Start | G10: Series End | H10: No. Obs. | I10: Unit | J10: Data Type | K10: Freq. | L10: Collection Month
A12: Index Numbers ; All groups CPI ; Australia ; | D12: Original | E12: A2325846C | F12: 17777 | G12: 45992 | H12: 310 | I12: Index Numbers | J12: INDEX | K12: Quarter | L12: 3
A13: Index Numbers ; Food and non-alcoholic beverages ; Australia ; | D13: Original | E13: A2325891R | F13: 26543 | G13: 45992 | H13: 214 | I13: Index Numbers | J13: INDEX | K13: Quarter | L13: 3
A14: Index Numbers ; Bread and cereal products ; Australia ; | D14: Original | E14: A2326206X | F14: 26543 | G14: 45992 | H14: 214 | I14: Index Numbers | J14: INDEX | K14: Quarter | L14: 3
A15: Index Numbers ; Bread ; Australia ; | D15: Original | E15: A2327061R | F15: 29465 | G15: 45992 | H15: 182 | I15: Index Numbers | J15: INDEX | K15: Quarter | L15: 3
A16: Index Numbers ; Cakes and biscuits ; Australia ; | D16: Original | E16: A2327106J | F16: 29465 | G16: 45992 | H16: 182 | I16: Index Numbers | J16: INDEX | K16: Quarter | L16: 3
A17: Index Numbers ; Breakfast cereals ; Australia ; | D17: Original | E17: A2327151V | F17: 29465 | G17: 45992 | H17: 182 | I17: Index Numbers | J17: INDEX | K17: Quarter | L17: 3
A18: Index Numbers ; Other cereal products ; Australia ; | D18: Original | E18: A2327196X | F18: 29465 | G18: 45992 | H18: 182 | I18: Index Numbers | J18: INDEX | K18: Quarter | L18: 3
A19: Index Numbers ; Meat and seafoods ; Australia ; | D19: Original | E19: A2326251K | F19: 26543 | G19: 45992 | H19: 214 | I19: Index Numbers | J19: INDEX | K19: Quarter | L19: 3
A20: Index Numbers ; Beef and veal ; Australia ; | D20: Original | E20: A2327241X | F20: 26543 | G20: 45992 | H20: 214 | I20: Index Numbers | J20: INDEX | K20: Quarter | L20: 3
A21: Index Numbers ; Pork ; Australia ; | D21: Original | E21: A3604358R | F21: 29465 | G21: 45992 | H21: 182 | I21: Index Numbers | J21: INDEX | K21: Quarter | L21: 3
A22: Index Numbers ; Lamb and goat ; Australia ; | D22: Original | E22: A2327286C | F22: 26543 | G22: 45992 | H22: 214 | I22: Index Numbers | J22: INDEX | K22: Quarter | L22: 3
A23: Index Numbers ; Poultry ; Australia ; | D23: Original | E23: A2327376J | F23: 26543 | G23: 45992 | H23: 214 | I23: Index Numbers | J23: INDEX | K23: Quarter | L23: 3
... A407: Contribution to Total CPI ; Other financial services ; Australia ; | D407: Original | E407: A3603555J | F407: 45992 | G407: 45992 | H407: 1 | I407: Index Points | J407: INDEX | K407: Quarter | L407: 3
A409: © Commonwealth of Australia 2026

Sheet Energy Prices
A1: Energy Prices in Australia — Growth Over Time
A2: Source: ABS 6401.0 Consumer Price Index, Australia — Table 18 (Weighted Average of Eight Capital Cities). Reference period: Sep 2025 = 100.0.
A3: Series: Electricity (A2328141J, from Sep 1980) and Gas & other household fuels (A2331921F, from Sep 1989). All Groups CPI (A2325846C) shown as a reference.
A5: Headline growth rates | F5: Quarterly index values (Sep 2025 = 100) | N5: Annual snapshot (September quarter each year)
A7: Period | B7: Electricity | C7: Gas & household fuels | D7: All Groups CPI | F7: Quarter | G7: All Groups CPI | H7: Electricity | I7: Gas & household fuels | J7: Electricity YoY % | K7: Gas YoY % | L7: CPI YoY % | N7: Year | O7: Electricity index | P7: Gas index | Q7: CPI index | R7: Electricity annual % | S7: Gas annual % | T7: CPI annual % | V7: Quarter | W7: Electricity YoY % | X7: Gas YoY % | Y7: CPI YoY %
A8: Latest year (Sep 2024 → Sep 2025) | B8: =Data1!BM320/Data1!BM316-1 -> 0.25575174 | C8: =Data1!BN320/Data1!BN316-1 -> 0.045859873 | D8: =Data1!B320/Data1!B316-1 -> 0.036256585 | F8: =Data1!A139 -> 29465 | G8: =Data1!B139 -> 18.48 | H8: =Data1!BM139 -> 10.46 | I8: =IF(ISBLANK(Data1!BN139),NA(),Data1!BN139) -> #N/A | J8: =IFERROR(Data1!BM139/Data1!BM135-1,NA()) -> #N/A | K8: =IFERROR(IF(OR(ISBLANK(Data1!BN139),ISBLANK(Data1!BN135)),NA(),Data1!BN139/Data1!BN135-1),NA()) -> #N/A | L8: =IFERROR(Data1!B139/Data1!B135-1,NA()) -> 0.10131108 | N8: 1980 | O8: {=INDEX(Data1!BM:BM,140+($N8-1980)*4)} -> 10.53 | P8: {=IF($N8<1989,NA(),INDEX(Data1!BN:BN,140+($N8-1980)*4))} -> #N/A | Q8: {=INDEX(Data1!B:B,140+($N8-1980)*4)} -> 18.87 | V8: =F8 -> 29465 | W8: =J8 -> #N/A | X8: =K8 -> #N/A | Y8: =L8 -> 0.10131108
A9: Last 5 years (Sep 2020 → Sep 2025) — cumulative | B9: =Data1!BM320/Data1!BM300-1 -> 0.15402581 | C9: =Data1!BN320/Data1!BN300-1 -> 0.49317975 | D9: =Data1!B320/Data1!B300-1 -> 0.23243243 | F9: =Data1!A140 -> 29556 | G9: =Data1!B140 -> 18.87 | H9: =Data1!BM140 -> 10.53 | I9: =IF(ISBLANK(Data1!BN140),NA(),Data1!BN140) -> #N/A | J9: =IFERROR(Data1!BM140/Data1!BM136-1,NA()) -> #N/A | K9: =IFERROR(IF(OR(ISBLANK(Data1!BN140),ISBLANK(Data1!BN136)),NA(),Data1!BN140/Data1!BN136-1),NA()) -> #N/A | L9: =IFERROR(Data1!B140/Data1!B136-1,NA()) -> 0.092013889 | N9: =N8+1 -> 1981 | O9: {=INDEX(Data1!BM:BM,140+($N9-1980)*4)} -> 12.31 | P9: {=IF($N9<1989,NA(),INDEX(Data1!BN:BN,140+($N9-1980)*4))} -> #N/A | Q9: {=INDEX(Data1!B:B,140+($N9-1980)*4)} -> 20.99 | R9: =IFERROR(O9/O8-1,NA()) -> 0.16904084 | S9: =IFERROR(IF(OR(ISNA(P9),ISNA(P8)),NA(),P9/P8-1),NA()) -> #N/A | T9: =IFERROR(Q9/Q8-1,NA()) -> 0.11234764 | V9: =F9 -> 29556 | W9: =J9 -> #N/A | X9: =K9 -> #N/A | Y9: =L9 -> 0.092013889
A10: Last 5 years — annualised (CAGR) | B10: =(Data1!BM320/Data1!BM300)^(1/5)-1 -> 0.029065704 | C10: =(Data1!BN320/Data1!BN300)^(1/5)-1 -> 0.08348379 | D10: =(Data1!B320/Data1!B300)^(1/5)-1 -> 0.042683794 | F10: =Data1!A141 -> 29646 | G10: =Data1!B141 -> 19.33 | H10: =Data1!BM141 -> 11.47 | I10: =IF(ISBLANK(Data1!BN141),NA(),Data1!BN141) -> #N/A | J10: =IFERROR(Data1!BM141/Data1!BM137-1,NA()) -> #N/A | K10: =IFERROR(IF(OR(ISBLANK(Data1!BN141),ISBLANK(Data1!BN137)),NA(),Data1!BN141/Data1!BN137-1),NA()) -> #N/A | L10: =IFERROR(Data1!B141/Data1!B137-1,NA()) -> 0.093944539 | N10: =N9+1 -> 1982 | O10: {=INDEX(Data1!BM:BM,140+($N10-1980)*4)} -> 16.53 | P10: {=IF($N10<1989,NA(),INDEX(Data1!BN:BN,140+($N10-1980)*4))} -> #N/A | Q10: {=INDEX(Data1!B:B,140+($N10-1980)*4)} -> 23.31 | R10: =IFERROR(O10/O9-1,NA()) -> 0.34281072 | S10: =IFERROR(IF(OR(ISNA(P10),ISNA(P9)),NA(),P10/P9-1),NA()) -> #N/A | T10: =IFERROR(Q10/Q9-1,NA()) -> 0.11052882 | V10: =F10 -> 29646 | W10: =J10 -> #N/A | X10: =K10 -> #N/A | Y10: =L10 -> 0.093944539
A11: Last 10 years (Sep 2015 → Sep 2025) — cumulative | B11: =Data1!BM320/Data1!BM280-1 -> 0.21213686 | C11: =Data1!BN320/Data1!BN280-1 -> 0.67209776 | D11: =Data1!B320/Data1!B280-1 -> 0.33280191 | F11: =Data1!A142 -> 29738 | G11: =Data1!B142 -> 19.76 | H11: =Data1!BM142 -> 11.57 | I11: =IF(ISBLANK(Data1!BN142),NA(),Data1!BN142) -> #N/A | J11: =IFERROR(Data1!BM142/Data1!BM138-1,NA()) -> #N/A | K11: =IFERROR(IF(OR(ISBLANK(Data1!BN142),ISBLANK(Data1!BN138)),NA(),Data1!BN142/Data1!BN138-1),NA()) -> #N/A | L11: =IFERROR(Data1!B142/Data1!B138-1,NA()) -> 0.087506879 | N11: =N10+1 -> 1983 | O11: {=INDEX(Data1!BM:BM,140+($N11-1980)*4)} -> 17.88 | P11: {=IF($N11<1989,NA(),INDEX(Data1!BN:BN,140+($N11-1980)*4))} -> #N/A | Q11: {=INDEX(Data1!B:B,140+($N11-1980)*4)} -> 25.32 | R11: =IFERROR(O11/O10-1,NA()) -> 0.081669691 | S11: =IFERROR(IF(OR(ISNA(P11),ISNA(P10)),NA(),P11/P10-1),NA()) -> #N/A | T11: =IFERROR(Q11/Q10-1,NA()) -> 0.086229086 | V11: =F11 -> 29738 | W11: =J11 -> #N/A | X11: =K11 -> #N/A | Y11: =L11 -> 0.087506879
A12: Last 10 years — annualised (CAGR) | B12: =(Data1!BM320/Data1!BM280)^(1/10)-1 -> 0.019424732 | C12: =(Data1!BN320/Data1!BN280)^(1/10)-1 -> 0.052752221 | D12: =(Data1!B320/Data1!B280)^(1/10)-1 -> 0.029144982 | F12: =Data1!A143 -> 29830 | G12: =Data1!B143 -> 20.14 | H12: =Data1!BM143 -> 12.05 | I12: =IF(ISBLANK(Data1!BN143),NA(),Data1!BN143) -> #N/A | J12: =IFERROR(Data1!BM143/Data1!BM139-1,NA()) -> 0.15200765 | K12: =IFERROR(IF(OR(ISBLANK(Data1!BN143),ISBLANK(Data1!BN139)),NA(),Data1!BN143/Data1!BN139-1),NA()) -> #N/A | L12: =IFERROR(Data1!B143/Data1!B139-1,NA()) -> 0.08982684 | N12: =N11+1 -> 1984 | O12: {=INDEX(Data1!BM:BM,140+($N12-1980)*4)} -> 18.39 | P12: {=IF($N12<1989,NA(),INDEX(Data1!BN:BN,140+($N12-1980)*4))} -> #N/A | Q12: {=INDEX(Data1!B:B,140+($N12-1980)*4)} -> 25.98 | R12: =IFERROR(O12/O11-1,NA()) -> 0.02852349 | S12: =IFERROR(IF(OR(ISNA(P12),ISNA(P11)),NA(),P12/P11-1),NA()) -> #N/A | T12: =IFERROR(Q12/Q11-1,NA()) -> 0.026066351 | V12: =F12 -> 29830 | W12: =J12 -> 0.15200765 | X12: =K12 -> #N/A | Y12: =L12 -> 0.08982684
A13: Last 20 years (Sep 2005 → Sep 2025) — cumulative | B13: =Data1!BM320/Data1!BM240-1 -> 1.5359265 | C13: =Data1!BN320/Data1!BN240-1 -> 2.1893817 | D13: =Data1!B320/Data1!B240-1 -> 0.7231192 | F13: =Data1!A144 -> 29921 | G13: =Data1!B144 -> 20.99 | H13: =Data1!BM144 -> 12.31 | I13: =IF(ISBLANK(Data1!BN144),NA(),Data1!BN144) -> #N/A | J13: =IFERROR(Data1!BM144/Data1!BM140-1,NA()) -> 0.16904084 | K13: =IFERROR(IF(OR(ISBLANK(Data1!BN144),ISBLANK(Data1!BN140)),NA(),Data1!BN144/Data1!BN140-1),NA()) -> #N/A | L13: =IFERROR(Data1!B144/Data1!B140-1,NA()) -> 0.11234764 | N13: =N12+1 -> 1985 | O13: {=INDEX(Data1!BM:BM,140+($N13-1980)*4)} -> 19.54 | P13: {=IF($N13<1989,NA(),INDEX(Data1!BN:BN,140+($N13-1980)*4))} -> #N/A | Q13: {=INDEX(Data1!B:B,140+($N13-1980)*4)} -> 28.11 | R13: =IFERROR(O13/O12-1,NA()) -> 0.062533986 | S13: =IFERROR(IF(OR(ISNA(P13),ISNA(P12)),NA(),P13/P12-1),NA()) -> #N/A | T13: =IFERROR(Q13/Q12-1,NA()) -> 0.081986143 | V13: =F13 -> 29921 | W13: =J13 -> 0.16904084 | X13: =K13 -> #N/A | Y13: =L13 -> 0.11234764
A14: Last 20 years — annualised (CAGR) | B14: =(Data1!BM320/Data1!BM240)^(1/20)-1 -> 0.047627363 | C14: =(Data1!BN320/Data1!BN240)^(1/20)-1 -> 0.059705833 | D14: =(Data1!B320/Data1!B240)^(1/20)-1 -> 0.027580292 | F14: =Data1!A145 -> 30011 | G14: =Data1!B145 -> 21.38 | H14: =Data1!BM145 -> 13.42 | I14: =IF(ISBLANK(Data1!BN145),NA(),Data1!BN145) -> #N/A | J14: =IFERROR(Data1!BM145/Data1!BM141-1,NA()) -> 0.17000872 | K14: =IFERROR(IF(OR(ISBLANK(Data1!BN145),ISBLANK(Data1!BN141)),NA(),Data1!BN145/Data1!BN141-1),NA()) -> #N/A | L14: =IFERROR(Data1!B145/Data1!B141-1,NA()) -> 0.10605277 | N14: =N13+1 -> 1986 | O14: {=INDEX(Data1!BM:BM,140+($N14-1980)*4)} -> 20.75 | P14: {=IF($N14<1989,NA(),INDEX(Data1!BN:BN,140+($N14-1980)*4))} -> #N/A | Q14: {=INDEX(Data1!B:B,140+($N14-1980)*4)} -> 30.85 | R14: =IFERROR(O14/O13-1,NA()) -> 0.061924258 | S14: =IFERROR(IF(OR(ISNA(P14),ISNA(P13)),NA(),P14/P13-1),NA()) -> #N/A | T14: =IFERROR(Q14/Q13-1,NA()) -> 0.097474208 | V14: =F14 -> 30011 | W14: =J14 -> 0.17000872 | X14: =K14 -> #N/A | Y14: =L14 -> 0.10605277
A15: Since series start — cumulative | B15: =Data1!BM320/Data1!BM139-1 -> 7.9751434 | C15: =Data1!BN320/Data1!BN175-1 -> 4.8330373 | D15: =Data1!B320/Data1!B139-1 -> 4.4285714 | F15: =Data1!A146 -> 30103 | G15: =Data1!B146 -> 21.88 | H15: =Data1!BM146 -> 14.07 | I15: =IF(ISBLANK(Data1!BN146),NA(),Data1!BN146) -> #N/A | J15: =IFERROR(Data1!BM146/Data1!BM142-1,NA()) -> 0.21607606 | K15: =IFERROR(IF(OR(ISBLANK(Data1!BN146),ISBLANK(Data1!BN142)),NA(),Data1!BN146/Data1!BN142-1),NA()) -> #N/A | L15: =IFERROR(Data1!B146/Data1!B142-1,NA()) -> 0.10728745 | N15: =N14+1 -> 1987 | O15: {=INDEX(Data1!BM:BM,140+($N15-1980)*4)} -> 22.07 | P15: {=IF($N15<1989,NA(),INDEX(Data1!BN:BN,140+($N15-1980)*4))} -> #N/A | Q15: {=INDEX(Data1!B:B,140+($N15-1980)*4)} -> 33.05 | R15: =IFERROR(O15/O14-1,NA()) -> 0.063614458 | S15: =IFERROR(IF(OR(ISNA(P15),ISNA(P14)),NA(),P15/P14-1),NA()) -> #N/A | T15: =IFERROR(Q15/Q14-1,NA()) -> 0.071312804 | V15: =F15 -> 30103 | W15: =J15 -> 0.21607606 | X15: =K15 -> #N/A | Y15: =L15 -> 0.10728745
A16: Since series start — annualised (CAGR) | B16: =(Data1!BM320/Data1!BM139)^(1/((2025-1980)))-1 -> 0.049974369 | C16: =(Data1!BN320/Data1!BN175)^(1/((2025-1989)))-1 -> 0.050206868 | D16: =(Data1!B320/Data1!B139)^(1/((2025-1980)))-1 -> 0.038308348 | F16: =Data1!A147 -> 30195 | G16: =Data1!B147 -> 22.65 | H16: =Data1!BM147 -> 15.45 | I16: =IF(ISBLANK(Data1!BN147),NA(),Data1!BN147) -> #N/A | J16: =IFERROR(Data1!BM147/Data1!BM143-1,NA()) -> 0.28215768 | K16: =IFERROR(IF(OR(ISBLANK(Data1!BN147),ISBLANK(Data1!BN143)),NA(),Data1!BN147/Data1!BN143-1),NA()) -> #N/A | L16: =IFERROR(Data1!B147/Data1!B143-1,NA()) -> 0.12462761 | N16: =N15+1 -> 1988 | O16: {=INDEX(Data1!BM:BM,140+($N16-1980)*4)} -> 23.23 | P16: {=IF($N16<1989,NA(),INDEX(Data1!BN:BN,140+($N16-1980)*4))} -> #N/A | Q16: {=INDEX(Data1!B:B,140+($N16-1980)*4)} -> 35.57 | R16: =IFERROR(O16/O15-1,NA()) -> 0.052560036 | S16: =IFERROR(IF(OR(ISNA(P16),ISNA(P15)),NA(),P16/P15-1),NA()) -> #N/A | T16: =IFERROR(Q16/Q15-1,NA()) -> 0.076248109 | V16: =F16 -> 30195 | W16: =J16 -> 0.28215768 | X16: =K16 -> #N/A | Y16: =L16 -> 0.12462761
F17: =Data1!A148 -> 30286 | G17: =Data1!B148 -> 23.31 | H17: =Data1!BM148 -> 16.53 | I17: =IF(ISBLANK(Data1!BN148),NA(),Data1!BN148) -> #N/A | J17: =IFERROR(Data1!BM148/Data1!BM144-1,NA()) -> 0.34281072 | K17: =IFERROR(IF(OR(ISBLANK(Data1!BN148),ISBLANK(Data1!BN144)),NA(),Data1!BN148/Data1!BN144-1),NA()) -> #N/A | L17: =IFERROR(Data1!B148/Data1!B144-1,NA()) -> 0.11052882 | N17: =N16+1 -> 1989 | O17: {=INDEX(Data1!BM:BM,140+($N17-1980)*4)} -> 24.12 | P17: {=IF($N17<1989,NA(),INDEX(Data1!BN:BN,140+($N17-1980)*4))} -> 17.24 | Q17: {=INDEX(Data1!B:B,140+($N17-1980)*4)} -> 38.35 | R17: =IFERROR(O17/O16-1,NA()) -> 0.038312527 | S17: =IFERROR(IF(OR(ISNA(P17),ISNA(P16)),NA(),P17/P16-1),NA()) -> #N/A | T17: =IFERROR(Q17/Q16-1,NA()) -> 0.078155749 | V17: =F17 -> 30286 | W17: =J17 -> 0.34281072 | X17: =K17 -> #N/A | Y17: =L17 -> 0.11052882
F18: =Data1!A149 -> 30376 | G18: =Data1!B149 -> 23.81 | H18: =Data1!BM149 -> 16.63 | I18: =IF(ISBLANK(Data1!BN149),NA(),Data1!BN149) -> #N/A | J18: =IFERROR(Data1!BM149/Data1!BM145-1,NA()) -> 0.23919523 | K18: =IFERROR(IF(OR(ISBLANK(Data1!BN149),ISBLANK(Data1!BN145)),NA(),Data1!BN149/Data1!BN145-1),NA()) -> #N/A | L18: =IFERROR(Data1!B149/Data1!B145-1,NA()) -> 0.11365762 | N18: =N17+1 -> 1990 | O18: {=INDEX(Data1!BM:BM,140+($N18-1980)*4)} -> 25.3 | P18: {=IF($N18<1989,NA(),INDEX(Data1!BN:BN,140+($N18-1980)*4))} -> 18.46 | Q18: {=INDEX(Data1!B:B,140+($N18-1980)*4)} -> 40.98 | R18: =IFERROR(O18/O17-1,NA()) -> 0.048922056 | S18: =IFERROR(IF(OR(ISNA(P18),ISNA(P17)),NA(),P18/P17-1),NA()) -> 0.070765661 | T18: =IFERROR(Q18/Q17-1,NA()) -> 0.068578879 | V18: =F18 -> 30376 | W18: =J18 -> 0.23919523 | X18: =K18 -> #N/A | Y18: =L18 -> 0.11365762
A19: Annualised growth by decade (CAGR) | F19: =Data1!A150 -> 30468 | G19: =Data1!B150 -> 24.32 | H19: =Data1!BM150 -> 16.6 | I19: =IF(ISBLANK(Data1!BN150),NA(),Data1!BN150) -> #N/A | J19: =IFERROR(Data1!BM150/Data1!BM146-1,NA()) -> 0.17981521 | K19: =IFERROR(IF(OR(ISBLANK(Data1!BN150),ISBLANK(Data1!BN146)),NA(),Data1!BN150/Data1!BN146-1),NA()) -> #N/A | L19: =IFERROR(Data1!B150/Data1!B146-1,NA()) -> 0.11151737 | N19: =N18+1 -> 1991 | O19: {=INDEX(Data1!BM:BM,140+($N19-1980)*4)} -> 26.53 | P19: {=IF($N19<1989,NA(),INDEX(Data1!BN:BN,140+($N19-1980)*4))} -> 19.15 | Q19: {=INDEX(Data1!B:B,140+($N19-1980)*4)} -> 41.6 | R19: =IFERROR(O19/O18-1,NA()) -> 0.048616601 | S19: =IFERROR(IF(OR(ISNA(P19),ISNA(P18)),NA(),P19/P18-1),NA()) -> 0.037378115 | T19: =IFERROR(Q19/Q18-1,NA()) -> 0.015129331 | V19: =F19 -> 30468 | W19: =J19 -> 0.17981521 | X19: =K19 -> #N/A | Y19: =L19 -> 0.11151737
F20: =Data1!A151 -> 30560 | G20: =Data1!B151 -> 24.74 | H20: =Data1!BM151 -> 17.11 | I20: =IF(ISBLANK(Data1!BN151),NA(),Data1!BN151) -> #N/A | J20: =IFERROR(Data1!BM151/Data1!BM147-1,NA()) -> 0.10744337 | K20: =IFERROR(IF(OR(ISBLANK(Data1!BN151),ISBLANK(Data1!BN147)),NA(),Data1!BN151/Data1!BN147-1),NA()) -> #N/A | L20: =IFERROR(Data1!B151/Data1!B147-1,NA()) -> 0.092273731 | N20: =N19+1 -> 1992 | O20: {=INDEX(Data1!BM:BM,140+($N20-1980)*4)} -> 27.64 | P20: {=IF($N20<1989,NA(),INDEX(Data1!BN:BN,140+($N20-1980)*4))} -> 19.83 | Q20: {=INDEX(Data1!B:B,140+($N20-1980)*4)} -> 41.71 | R20: =IFERROR(O20/O19-1,NA()) -> 0.041839427 | S20: =IFERROR(IF(OR(ISNA(P20),ISNA(P19)),NA(),P20/P19-1),NA()) -> 0.035509138 | T20: =IFERROR(Q20/Q19-1,NA()) -> 0.0026442308 | V20: =F20 -> 30560 | W20: =J20 -> 0.10744337 | X20: =K20 -> #N/A | Y20: =L20 -> 0.092273731
A21: Decade | B21: Electricity | C21: Gas & household fuels | D21: All Groups CPI | F21: =Data1!A152 -> 30651 | G21: =Data1!B152 -> 25.32 | H21: =Data1!BM152 -> 17.88 | I21: =IF(ISBLANK(Data1!BN152),NA(),Data1!BN152) -> #N/A | J21: =IFERROR(Data1!BM152/Data1!BM148-1,NA()) -> 0.081669691 | K21: =IFERROR(IF(OR(ISBLANK(Data1!BN152),ISBLANK(Data1!BN148)),NA(),Data1!BN152/Data1!BN148-1),NA()) -> #N/A | L21: =IFERROR(Data1!B152/Data1!B148-1,NA()) -> 0.086229086 | N21: =N20+1 -> 1993 | O21: {=INDEX(Data1!BM:BM,140+($N21-1980)*4)} -> 28.24 | P21: {=IF($N21<1989,NA(),INDEX(Data1!BN:BN,140+($N21-1980)*4))} -> 20.62 | Q21: {=INDEX(Data1!B:B,140+($N21-1980)*4)} -> 42.53 | R21: =IFERROR(O21/O20-1,NA()) -> 0.02170767 | S21: =IFERROR(IF(OR(ISNA(P21),ISNA(P20)),NA(),P21/P20-1),NA()) -> 0.039838628 | T21: =IFERROR(Q21/Q20-1,NA()) -> 0.019659554 | V21: =F21 -> 30651 | W21: =J21 -> 0.081669691 | X21: =K21 -> #N/A | Y21: =L21 -> 0.086229086
A22: 1980s (1980–1990) | B22: =(VLOOKUP(1990,$N$8:$Q$53,2,FALSE)/VLOOKUP(1980,$N$8:$Q$53,2,FALSE))^(1/10)-1 -> 0.091614297 | C22: n/a | D22: =(VLOOKUP(1990,$N$8:$Q$53,4,FALSE)/VLOOKUP(1980,$N$8:$Q$53,4,FALSE))^(1/10)-1 -> 0.080637428 | F22: =Data1!A153 -> 30742 | G22: =Data1!B153 -> 25.21 | H22: =Data1!BM153 -> 17.66 | I22: =IF(ISBLANK(Data1!BN153),NA(),Data1!BN153) -> #N/A | J22: =IFERROR(Data1!BM153/Data1!BM149-1,NA()) -> 0.06193626 | K22: =IFERROR(IF(OR(ISBLANK(Data1!BN153),ISBLANK(Data1!BN149)),NA(),Data1!BN153/Data1!BN149-1),NA()) -> #N/A | L22: =IFERROR(Data1!B153/Data1!B149-1,NA()) -> 0.058798824 | N22: =N21+1 -> 1994 | O22: {=INDEX(Data1!BM:BM,140+($N22-1980)*4)} -> 28.26 | P22: {=IF($N22<1989,NA(),INDEX(Data1!BN:BN,140+($N22-1980)*4))} -> 21.1 | Q22: {=INDEX(Data1!B:B,140+($N22-1980)*4)} -> 43.61 | R22: =IFERROR(O22/O21-1,NA()) -> 0.0007082153 | S22: =IFERROR(IF(OR(ISNA(P22),ISNA(P21)),NA(),P22/P21-1),NA()) -> 0.023278371 | T22: =IFERROR(Q22/Q21-1,NA()) -> 0.02539384 | V22: =F22 -> 30742 | W22: =J22 -> 0.06193626 | X22: =K22 -> #N/A | Y22: =L22 -> 0.058798824
A23: 1990s (1990–2000) | B23: =(VLOOKUP(2000,$N$8:$Q$53,2,FALSE)/VLOOKUP(1990,$N$8:$Q$53,2,FALSE))^(1/10)-1 -> 0.021835326 | C23: =(VLOOKUP(2000,$N$8:$Q$53,3,FALSE)/VLOOKUP(1990,$N$8:$Q$53,3,FALSE))^(1/10)-1 -> 0.027104331 | D23: =(VLOOKUP(2000,$N$8:$Q$53,4,FALSE)/VLOOKUP(1990,$N$8:$Q$53,4,FALSE))^(1/10)-1 -> 0.021633125 | F23: =Data1!A154 -> 30834 | G23: =Data1!B154 -> 25.28 | H23: =Data1!BM154 -> 17.33 | I23: =IF(ISBLANK(Data1!BN154),NA(),Data1!BN154) -> #N/A | J23: =IFERROR(Data1!BM154/Data1!BM150-1,NA()) -> 0.043975904 | K23: =IFERROR(IF(OR(ISBLANK(Data1!BN154),ISBLANK(Data1!BN150)),NA(),Data1!BN154/Data1!BN150-1),NA()) -> #N/A | L23: =IFERROR(Data1!B154/Data1!B150-1,NA()) -> 0.039473684 | N23: =N22+1 -> 1995 | O23: {=INDEX(Data1!BM:BM,140+($N23-1980)*4)} -> 28.34 | P23: {=IF($N23<1989,NA(),INDEX(Data1!BN:BN,140+($N23-1980)*4))} -> 21.48 | Q23: {=INDEX(Data1!B:B,140+($N23-1980)*4)} -> 45.81 | R23: =IFERROR(O23/O22-1,NA()) -> 0.0028308563 | S23: =IFERROR(IF(OR(ISNA(P23),ISNA(P22)),NA(),P23/P22-1),NA()) -> 0.018009479 | T23: =IFERROR(Q23/Q22-1,NA()) -> 0.050447145 | V23: =F23 -> 30834 | W23: =J23 -> 0.043975904 | X23: =K23 -> #N/A | Y23: =L23 -> 0.039473684
A24: 2000s (2000–2010) | B24: =(VLOOKUP(2010,$N$8:$Q$53,2,FALSE)/VLOOKUP(2000,$N$8:$Q$53,2,FALSE))^(1/10)-1 -> 0.062991676 | C24: =(VLOOKUP(2010,$N$8:$Q$53,3,FALSE)/VLOOKUP(2000,$N$8:$Q$53,3,FALSE))^(1/10)-1 -> 0.05966764 | D24: =(VLOOKUP(2010,$N$8:$Q$53,4,FALSE)/VLOOKUP(2000,$N$8:$Q$53,4,FALSE))^(1/10)-1 -> 0.028545539 | F24: =Data1!A155 -> 30926 | G24: =Data1!B155 -> 25.59 | H24: =Data1!BM155 -> 17.9 | I24: =IF(ISBLANK(Data1!BN155),NA(),Data1!BN155) -> #N/A | J24: =IFERROR(Data1!BM155/Data1!BM151-1,NA()) -> 0.046171829 | K24: =IFERROR(IF(OR(ISBLANK(Data1!BN155),ISBLANK(Data1!BN151)),NA(),Data1!BN155/Data1!BN151-1),NA()) -> #N/A | L24: =IFERROR(Data1!B155/Data1!B151-1,NA()) -> 0.034357316 | N24: =N23+1 -> 1996 | O24: {=INDEX(Data1!BM:BM,140+($N24-1980)*4)} -> 28.7 | P24: {=IF($N24<1989,NA(),INDEX(Data1!BN:BN,140+($N24-1980)*4))} -> 21.95 | Q24: {=INDEX(Data1!B:B,140+($N24-1980)*4)} -> 46.51 | R24: =IFERROR(O24/O23-1,NA()) -> 0.012702893 | S24: =IFERROR(IF(OR(ISNA(P24),ISNA(P23)),NA(),P24/P23-1),NA()) -> 0.021880819 | T24: =IFERROR(Q24/Q23-1,NA()) -> 0.015280506 | V24: =F24 -> 30926 | W24: =J24 -> 0.046171829 | X24: =K24 -> #N/A | Y24: =L24 -> 0.034357316
A25: 2010s (2010–2020) | B25: =(VLOOKUP(2020,$N$8:$Q$53,2,FALSE)/VLOOKUP(2010,$N$8:$Q$53,2,FALSE))^(1/10)-1 -> 0.034696374 | C25: =(VLOOKUP(2020,$N$8:$Q$53,3,FALSE)/VLOOKUP(2010,$N$8:$Q$53,3,FALSE))^(1/10)-1 -> 0.043599419 | D25: =(VLOOKUP(2020,$N$8:$Q$53,4,FALSE)/VLOOKUP(2010,$N$8:$Q$53,4,FALSE))^(1/10)-1 -> 0.019264162 | F25: =Data1!A156 -> 31017 | G25: =Data1!B156 -> 25.98 | H25: =Data1!BM156 -> 18.39 | I25: =IF(ISBLANK(Data1!BN156),NA(),Data1!BN156) -> #N/A | J25: =IFERROR(Data1!BM156/Data1!BM152-1,NA()) -> 0.02852349 | K25: =IFERROR(IF(OR(ISBLANK(Data1!BN156),ISBLANK(Data1!BN152)),NA(),Data1!BN156/Data1!BN152-1),NA()) -> #N/A | L25: =IFERROR(Data1!B156/Data1!B152-1,NA()) -> 0.026066351 | N25: =N24+1 -> 1997 | O25: {=INDEX(Data1!BM:BM,140+($N25-1980)*4)} -> 28.94 | P25: {=IF($N25<1989,NA(),INDEX(Data1!BN:BN,140+($N25-1980)*4))} -> 22.36 | Q25: {=INDEX(Data1!B:B,140+($N25-1980)*4)} -> 46.39 | R25: =IFERROR(O25/O24-1,NA()) -> 0.0083623693 | S25: =IFERROR(IF(OR(ISNA(P25),ISNA(P24)),NA(),P25/P24-1),NA()) -> 0.018678815 | T25: =IFERROR(Q25/Q24-1,NA()) -> -0.0025800903 | V25: =F25 -> 31017 | W25: =J25 -> 0.02852349 | X25: =K25 -> #N/A | Y25: =L25 -> 0.026066351
A26: 2020s so far (2020–2025) | B26: =(VLOOKUP(2025,$N$8:$Q$53,2,FALSE)/VLOOKUP(2020,$N$8:$Q$53,2,FALSE))^(1/5)-1 -> 0.029065704 | C26: =(VLOOKUP(2025,$N$8:$Q$53,3,FALSE)/VLOOKUP(2020,$N$8:$Q$53,3,FALSE))^(1/5)-1 -> 0.08348379 | D26: =(VLOOKUP(2025,$N$8:$Q$53,4,FALSE)/VLOOKUP(2020,$N$8:$Q$53,4,FALSE))^(1/5)-1 -> 0.042683794 | F26: =Data1!A157 -> 31107 | G26: =Data1!B157 -> 26.33 | H26: =Data1!BM157 -> 18.96 | I26: =IF(ISBLANK(Data1!BN157),NA(),Data1!BN157) -> #N/A | J26: =IFERROR(Data1!BM157/Data1!BM153-1,NA()) -> 0.073612684 | K26: =IFERROR(IF(OR(ISBLANK(Data1!BN157),ISBLANK(Data1!BN153)),NA(),Data1!BN157/Data1!BN153-1),NA()) -> #N/A | L26: =IFERROR(Data1!B157/Data1!B153-1,NA()) -> 0.044426815 | N26: =N25+1 -> 1998 | O26: {=INDEX(Data1!BM:BM,140+($N26-1980)*4)} -> 27.95 | P26: {=IF($N26<1989,NA(),INDEX(Data1!BN:BN,140+($N26-1980)*4))} -> 22.36 | Q26: {=INDEX(Data1!B:B,140+($N26-1980)*4)} -> 47.11 | R26: =IFERROR(O26/O25-1,NA()) -> -0.034208708 | S26: =IFERROR(IF(OR(ISNA(P26),ISNA(P25)),NA(),P26/P25-1),NA()) -> 0 | T26: =IFERROR(Q26/Q25-1,NA()) -> 0.015520586 | V26: =F26 -> 31107 | W26: =J26 -> 0.073612684 | X26: =K26 -> #N/A | Y26: =L26 -> 0.044426815
F27: =Data1!A158 -> 31199 | G27: =Data1!B158 -> 26.95 | H27: =Data1!BM158 -> 19.04 | I27: =IF(ISBLANK(Data1!BN158),NA(),Data1!BN158) -> #N/A | J27: =IFERROR(Data1!BM158/Data1!BM154-1,NA()) -> 0.098672822 | K27: =IFERROR(IF(OR(ISBLANK(Data1!BN158),ISBLANK(Data1!BN154)),NA(),Data1!BN158/Data1!BN154-1),NA()) -> #N/A | L27: =IFERROR(Data1!B158/Data1!B154-1,NA()) -> 0.066060127 | N27: =N26+1 -> 1999 | O27: {=INDEX(Data1!BM:BM,140+($N27-1980)*4)} -> 28.26 | P27: {=IF($N27<1989,NA(),INDEX(Data1!BN:BN,140+($N27-1980)*4))} -> 21.9 | Q27: {=INDEX(Data1!B:B,140+($N27-1980)*4)} -> 47.97 | R27: =IFERROR(O27/O26-1,NA()) -> 0.011091234 | S27: =IFERROR(IF(OR(ISNA(P27),ISNA(P26)),NA(),P27/P26-1),NA()) -> -0.020572451 | T27: =IFERROR(Q27/Q26-1,NA()) -> 0.018255148 | V27: =F27 -> 31199 | W27: =J27 -> 0.098672822 | X27: =K27 -> #N/A | Y27: =L27 -> 0.066060127
F28: =Data1!A159 -> 31291 | G28: =Data1!B159 -> 27.56 | H28: =Data1!BM159 -> 19.37 | I28: =IF(ISBLANK(Data1!BN159),NA(),Data1!BN159) -> #N/A | J28: =IFERROR(Data1!BM159/Data1!BM155-1,NA()) -> 0.082122905 | K28: =IFERROR(IF(OR(ISBLANK(Data1!BN159),ISBLANK(Data1!BN155)),NA(),Data1!BN159/Data1!BN155-1),NA()) -> #N/A | L28: =IFERROR(Data1!B159/Data1!B155-1,NA()) -> 0.076983197 | N28: =N27+1 -> 2000 | O28: {=INDEX(Data1!BM:BM,140+($N28-1980)*4)} -> 31.4 | P28: {=IF($N28<1989,NA(),INDEX(Data1!BN:BN,140+($N28-1980)*4))} -> 24.12 | Q28: {=INDEX(Data1!B:B,140+($N28-1980)*4)} -> 50.76 | R28: =IFERROR(O28/O27-1,NA()) -> 0.11111111 | S28: =IFERROR(IF(OR(ISNA(P28),ISNA(P27)),NA(),P28/P27-1),NA()) -> 0.10136986 | T28: =IFERROR(Q28/Q27-1,NA()) -> 0.058161351 | V28: =F28 -> 31291 | W28: =J28 -> 0.082122905 | X28: =K28 -> #N/A | Y28: =L28 -> 0.076983197
F29: =Data1!A160 -> 31382 | G29: =Data1!B160 -> 28.11 | H29: =Data1!BM160 -> 19.54 | I29: =IF(ISBLANK(Data1!BN160),NA(),Data1!BN160) -> #N/A | J29: =IFERROR(Data1!BM160/Data1!BM156-1,NA()) -> 0.062533986 | K29: =IFERROR(IF(OR(ISBLANK(Data1!BN160),ISBLANK(Data1!BN156)),NA(),Data1!BN160/Data1!BN156-1),NA()) -> #N/A | L29: =IFERROR(Data1!B160/Data1!B156-1,NA()) -> 0.081986143 | N29: =N28+1 -> 2001 | O29: {=INDEX(Data1!BM:BM,140+($N29-1980)*4)} -> 32.5 | P29: {=IF($N29<1989,NA(),INDEX(Data1!BN:BN,140+($N29-1980)*4))} -> 24.41 | Q29: {=INDEX(Data1!B:B,140+($N29-1980)*4)} -> 52.35 | R29: =IFERROR(O29/O28-1,NA()) -> 0.035031847 | S29: =IFERROR(IF(OR(ISNA(P29),ISNA(P28)),NA(),P29/P28-1),NA()) -> 0.012023217 | T29: =IFERROR(Q29/Q28-1,NA()) -> 0.031323877 | V29: =F29 -> 31382 | W29: =J29 -> 0.062533986 | X29: =K29 -> #N/A | Y29: =L29 -> 0.081986143
F30: =Data1!A161 -> 31472 | G30: =Data1!B161 -> 28.76 | H30: =Data1!BM161 -> 20 | I30: =IF(ISBLANK(Data1!BN161),NA(),Data1!BN161) -> #N/A | J30: =IFERROR(Data1!BM161/Data1!BM157-1,NA()) -> 0.054852321 | K30: =IFERROR(IF(OR(ISBLANK(Data1!BN161),ISBLANK(Data1!BN157)),NA(),Data1!BN161/Data1!BN157-1),NA()) -> #N/A | L30: =IFERROR(Data1!B161/Data1!B157-1,NA()) -> 0.092290163 | N30: =N29+1 -> 2002 | O30: {=INDEX(Data1!BM:BM,140+($N30-1980)*4)} -> 33.36 | P30: {=IF($N30<1989,NA(),INDEX(Data1!BN:BN,140+($N30-1980)*4))} -> 25.81 | Q30: {=INDEX(Data1!B:B,140+($N30-1980)*4)} -> 53.92 | R30: =IFERROR(O30/O29-1,NA()) -> 0.026461538 | S30: =IFERROR(IF(OR(ISNA(P30),ISNA(P29)),NA(),P30/P29-1),NA()) -> 0.057353544 | T30: =IFERROR(Q30/Q29-1,NA()) -> 0.029990449 | V30: =F30 -> 31472 | W30: =J30 -> 0.054852321 | X30: =K30 -> #N/A | Y30: =L30 -> 0.092290163
F31: =Data1!A162 -> 31564 | G31: =Data1!B162 -> 29.23 | H31: =Data1!BM162 -> 20.12 | I31: =IF(ISBLANK(Data1!BN162),NA(),Data1!BN162) -> #N/A | J31: =IFERROR(Data1!BM162/Data1!BM158-1,NA()) -> 0.056722689 | K31: =IFERROR(IF(OR(ISBLANK(Data1!BN162),ISBLANK(Data1!BN158)),NA(),Data1!BN162/Data1!BN158-1),NA()) -> #N/A | L31: =IFERROR(Data1!B162/Data1!B158-1,NA()) -> 0.084601113 | N31: =N30+1 -> 2003 | O31: {=INDEX(Data1!BM:BM,140+($N31-1980)*4)} -> 35.07 | P31: {=IF($N31<1989,NA(),INDEX(Data1!BN:BN,140+($N31-1980)*4))} -> 27.66 | Q31: {=INDEX(Data1!B:B,140+($N31-1980)*4)} -> 55.22 | R31: =IFERROR(O31/O30-1,NA()) -> 0.051258993 | S31: =IFERROR(IF(OR(ISNA(P31),ISNA(P30)),NA(),P31/P30-1),NA()) -> 0.071677644 | T31: =IFERROR(Q31/Q30-1,NA()) -> 0.024109792 | V31: =F31 -> 31564 | W31: =J31 -> 0.056722689 | X31: =K31 -> #N/A | Y31: =L31 -> 0.084601113
F32: =Data1!A163 -> 31656 | G32: =Data1!B163 -> 30 | H32: =Data1!BM163 -> 20.46 | I32: =IF(ISBLANK(Data1!BN163),NA(),Data1!BN163) -> #N/A | J32: =IFERROR(Data1!BM163/Data1!BM159-1,NA()) -> 0.056272586 | K32: =IFERROR(IF(OR(ISBLANK(Data1!BN163),ISBLANK(Data1!BN159)),NA(),Data1!BN163/Data1!BN159-1),NA()) -> #N/A | L32: =IFERROR(Data1!B163/Data1!B159-1,NA()) -> 0.088534107 | N32: =N31+1 -> 2004 | O32: {=INDEX(Data1!BM:BM,140+($N32-1980)*4)} -> 36.04 | P32: {=IF($N32<1989,NA(),INDEX(Data1!BN:BN,140+($N32-1980)*4))} -> 29.43 | Q32: {=INDEX(Data1!B:B,140+($N32-1980)*4)} -> 56.63 | R32: =IFERROR(O32/O31-1,NA()) -> 0.027658968 | S32: =IFERROR(IF(OR(ISNA(P32),ISNA(P31)),NA(),P32/P31-1),NA()) -> 0.063991323 | T32: =IFERROR(Q32/Q31-1,NA()) -> 0.025534227 | V32: =F32 -> 31656 | W32: =J32 -> 0.056272586 | X32: =K32 -> #N/A | Y32: =L32 -> 0.088534107
F33: =Data1!A164 -> 31747 | G33: =Data1!B164 -> 30.85 | H33: =Data1!BM164 -> 20.75 | I33: =IF(ISBLANK(Data1!BN164),NA(),Data1!BN164) -> #N/A | J33: =IFERROR(Data1!BM164/Data1!BM160-1,NA()) -> 0.061924258 | K33: =IFERROR(IF(OR(ISBLANK(Data1!BN164),ISBLANK(Data1!BN160)),NA(),Data1!BN164/Data1!BN160-1),NA()) -> #N/A | L33: =IFERROR(Data1!B164/Data1!B160-1,NA()) -> 0.097474208 | N33: =N32+1 -> 2005 | O33: {=INDEX(Data1!BM:BM,140+($N33-1980)*4)} -> 37.02 | P33: {=IF($N33<1989,NA(),INDEX(Data1!BN:BN,140+($N33-1980)*4))} -> 30.89 | Q33: {=INDEX(Data1!B:B,140+($N33-1980)*4)} -> 58.22 | R33: =IFERROR(O33/O32-1,NA()) -> 0.027192009 | S33: =IFERROR(IF(OR(ISNA(P33),ISNA(P32)),NA(),P33/P32-1),NA()) -> 0.049609242 | T33: =IFERROR(Q33/Q32-1,NA()) -> 0.028076991 | V33: =F33 -> 31747 | W33: =J33 -> 0.061924258 | X33: =K33 -> #N/A | Y33: =L33 -> 0.097474208
F34: =Data1!A165 -> 31837 | G34: =Data1!B165 -> 31.47 | H34: =Data1!BM165 -> 20.87 | I34: =IF(ISBLANK(Data1!BN165),NA(),Data1!BN165) -> #N/A | J34: =IFERROR(Data1!BM165/Data1!BM161-1,NA()) -> 0.0435 | K34: =IFERROR(IF(OR(ISBLANK(Data1!BN165),ISBLANK(Data1!BN161)),NA(),Data1!BN165/Data1!BN161-1),NA()) -> #N/A | L34: =IFERROR(Data1!B165/Data1!B161-1,NA()) -> 0.094228095 | N34: =N33+1 -> 2006 | O34: {=INDEX(Data1!BM:BM,140+($N34-1980)*4)} -> 38.13 | P34: {=IF($N34<1989,NA(),INDEX(Data1!BN:BN,140+($N34-1980)*4))} -> 32.33 | Q34: {=INDEX(Data1!B:B,140+($N34-1980)*4)} -> 60.11 | R34: =IFERROR(O34/O33-1,NA()) -> 0.029983793 | S34: =IFERROR(IF(OR(ISNA(P34),ISNA(P33)),NA(),P34/P33-1),NA()) -> 0.046617028 | T34: =IFERROR(Q34/Q33-1,NA()) -> 0.032463071 | V34: =F34 -> 31837 | W34: =J34 -> 0.0435 | X34: =K34 -> #N/A | Y34: =L34 -> 0.094228095
F35: =Data1!A166 -> 31929 | G35: =Data1!B166 -> 31.93 | H35: =Data1!BM166 -> 20.92 | I35: =IF(ISBLANK(Data1!BN166),NA(),Data1!BN166) -> #N/A | J35: =IFERROR(Data1!BM166/Data1!BM162-1,NA()) -> 0.039761431 | K35: =IFERROR(IF(OR(ISBLANK(Data1!BN166),ISBLANK(Data1!BN162)),NA(),Data1!BN166/Data1!BN162-1),NA()) -> #N/A | L35: =IFERROR(Data1!B166/Data1!B162-1,NA()) -> 0.092370852 | N35: =N34+1 -> 2007 | O35: {=INDEX(Data1!BM:BM,140+($N35-1980)*4)} -> 40.32 | P35: {=IF($N35<1989,NA(),INDEX(Data1!BN:BN,140+($N35-1980)*4))} -> 33.65 | Q35: {=INDEX(Data1!B:B,140+($N35-1980)*4)} -> 61.89 | R35: =IFERROR(O35/O34-1,NA()) -> 0.05743509 | S35: =IFERROR(IF(OR(ISNA(P35),ISNA(P34)),NA(),P35/P34-1),NA()) -> 0.040828951 | T35: =IFERROR(Q35/Q34-1,NA()) -> 0.029612377 | V35: =F35 -> 31929 | W35: =J35 -> 0.039761431 | X35: =K35 -> #N/A | Y35: =L35 -> 0.092370852
F36: =Data1!A167 -> 32021 | G36: =Data1!B167 -> 32.47 | H36: =Data1!BM167 -> 21.9 | I36: =IF(ISBLANK(Data1!BN167),NA(),Data1!BN167) -> #N/A | J36: =IFERROR(Data1!BM167/Data1!BM163-1,NA()) -> 0.070381232 | K36: =IFERROR(IF(OR(ISBLANK(Data1!BN167),ISBLANK(Data1!BN163)),NA(),Data1!BN167/Data1!BN163-1),NA()) -> #N/A | L36: =IFERROR(Data1!B167/Data1!B163-1,NA()) -> 0.082333333 | N36: =N35+1 -> 2008 | O36: {=INDEX(Data1!BM:BM,140+($N36-1980)*4)} -> 44.42 | P36: {=IF($N36<1989,NA(),INDEX(Data1!BN:BN,140+($N36-1980)*4))} -> 36.88 | Q36: {=INDEX(Data1!B:B,140+($N36-1980)*4)} -> 64.16 | R36: =IFERROR(O36/O35-1,NA()) -> 0.10168651 | S36: =IFERROR(IF(OR(ISNA(P36),ISNA(P35)),NA(),P36/P35-1),NA()) -> 0.095988113 | T36: =IFERROR(Q36/Q35-1,NA()) -> 0.036677977 | V36: =F36 -> 32021 | W36: =J36 -> 0.070381232 | X36: =K36 -> #N/A | Y36: =L36 -> 0.082333333
F37: =Data1!A168 -> 32112 | G37: =Data1!B168 -> 33.05 | H37: =Data1!BM168 -> 22.07 | I37: =IF(ISBLANK(Data1!BN168),NA(),Data1!BN168) -> #N/A | J37: =IFERROR(Data1!BM168/Data1!BM164-1,NA()) -> 0.063614458 | K37: =IFERROR(IF(OR(ISBLANK(Data1!BN168),ISBLANK(Data1!BN164)),NA(),Data1!BN168/Data1!BN164-1),NA()) -> #N/A | L37: =IFERROR(Data1!B168/Data1!B164-1,NA()) -> 0.071312804 | N37: =N36+1 -> 2009 | O37: {=INDEX(Data1!BM:BM,140+($N37-1980)*4)} -> 51.39 | P37: {=IF($N37<1989,NA(),INDEX(Data1!BN:BN,140+($N37-1980)*4))} -> 40.21 | Q37: {=INDEX(Data1!B:B,140+($N37-1980)*4)} -> 65.51 | R37: =IFERROR(O37/O36-1,NA()) -> 0.1569113 | S37: =IFERROR(IF(OR(ISNA(P37),ISNA(P36)),NA(),P37/P36-1),NA()) -> 0.090292842 | T37: =IFERROR(Q37/Q36-1,NA()) -> 0.021041147 | V37: =F37 -> 32112 | W37: =J37 -> 0.063614458 | X37: =K37 -> #N/A | Y37: =L37 -> 0.071312804
F38: =Data1!A169 -> 32203 | G38: =Data1!B169 -> 33.63 | H38: =Data1!BM169 -> 22.14 | I38: =IF(ISBLANK(Data1!BN169),NA(),Data1!BN169) -> #N/A | J38: =IFERROR(Data1!BM169/Data1!BM165-1,NA()) -> 0.060852899 | K38: =IFERROR(IF(OR(ISBLANK(Data1!BN169),ISBLANK(Data1!BN165)),NA(),Data1!BN169/Data1!BN165-1),NA()) -> #N/A | L38: =IFERROR(Data1!B169/Data1!B165-1,NA()) -> 0.068636797 | N38: =N37+1 -> 2010 | O38: {=INDEX(Data1!BM:BM,140+($N38-1980)*4)} -> 57.84 | P38: {=IF($N38<1989,NA(),INDEX(Data1!BN:BN,140+($N38-1980)*4))} -> 43.06 | Q38: {=INDEX(Data1!B:B,140+($N38-1980)*4)} -> 67.26 | R38: =IFERROR(O38/O37-1,NA()) -> 0.1255108 | S38: =IFERROR(IF(OR(ISNA(P38),ISNA(P37)),NA(),P38/P37-1),NA()) -> 0.070877891 | T38: =IFERROR(Q38/Q37-1,NA()) -> 0.026713479 | V38: =F38 -> 32203 | W38: =J38 -> 0.060852899 | X38: =K38 -> #N/A | Y38: =L38 -> 0.068636797
... F53: =Data1!A184 -> 33573 | G53: =Data1!B184 -> 41.6 | H53: =Data1!BM184 -> 26.53 | I53: =IF(ISBLANK(Data1!BN184),NA(),Data1!BN184) -> 19.15 | J53: =IFERROR(Data1!BM184/Data1!BM180-1,NA()) -> 0.048616601 | K53: =IFERROR(IF(OR(ISBLANK(Data1!BN184),ISBLANK(Data1!BN180)),NA(),Data1!BN184/Data1!BN180-1),NA()) -> 0.037378115 | L53: =IFERROR(Data1!B184/Data1!B180-1,NA()) -> 0.015129331 | N53: =N52+1 -> 2025 | O53: {=INDEX(Data1!BM:BM,140+($N53-1980)*4)} -> 93.88 | P53: {=IF($N53<1989,NA(),INDEX(Data1!BN:BN,140+($N53-1980)*4))} -> 98.52 | Q53: {=INDEX(Data1!B:B,140+($N53-1980)*4)} -> 100.32 | R53: =IFERROR(O53/O52-1,NA()) -> 0.25575174 | S53: =IFERROR(IF(OR(ISNA(P53),ISNA(P52)),NA(),P53/P52-1),NA()) -> 0.045859873 | T53: =IFERROR(Q53/Q52-1,NA()) -> 0.036256585 | V53: =F53 -> 33573 | W53: =J53 -> 0.048616601 | X53: =K53 -> 0.037378115 | Y53: =L53 -> 0.015129331
F54: =Data1!A185 -> 33664 | G54: =Data1!B185 -> 41.6 | H54: =Data1!BM185 -> 26.55 | I54: =IF(ISBLANK(Data1!BN185),NA(),Data1!BN185) -> 19.24 | J54: =IFERROR(Data1!BM185/Data1!BM181-1,NA()) -> 0.046511628 | K54: =IFERROR(IF(OR(ISBLANK(Data1!BN185),ISBLANK(Data1!BN181)),NA(),Data1!BN185/Data1!BN181-1),NA()) -> 0.032188841 | L54: =IFERROR(Data1!B185/Data1!B181-1,NA()) -> 0.017114914 | V54: =F54 -> 33664 | W54: =J54 -> 0.046511628 | X54: =K54 -> 0.032188841 | Y54: =L54 -> 0.017114914
F55: =Data1!A186 -> 33756 | G55: =Data1!B186 -> 41.48 | H55: =Data1!BM186 -> 26.58 | I55: =IF(ISBLANK(Data1!BN186),NA(),Data1!BN186) -> 19.19 | J55: =IFERROR(Data1!BM186/Data1!BM182-1,NA()) -> 0.046456693 | K55: =IFERROR(IF(OR(ISBLANK(Data1!BN186),ISBLANK(Data1!BN182)),NA(),Data1!BN186/Data1!BN182-1),NA()) -> 0.035617917 | L55: =IFERROR(Data1!B186/Data1!B182-1,NA()) -> 0.012201074 | V55: =F55 -> 33756 | W55: =J55 -> 0.046456693 | X55: =K55 -> 0.035617917 | Y55: =L55 -> 0.012201074
F56: =Data1!A187 -> 33848 | G56: =Data1!B187 -> 41.52 | H56: =Data1!BM187 -> 27.13 | I56: =IF(ISBLANK(Data1!BN187),NA(),Data1!BN187) -> 19.27 | J56: =IFERROR(Data1!BM187/Data1!BM183-1,NA()) -> 0.027262401 | K56: =IFERROR(IF(OR(ISBLANK(Data1!BN187),ISBLANK(Data1!BN183)),NA(),Data1!BN187/Data1!BN183-1),NA()) -> 0.0062663185 | L56: =IFERROR(Data1!B187/Data1!B183-1,NA()) -> 0.007522446 | V56: =F56 -> 33848 | W56: =J56 -> 0.027262401 | X56: =K56 -> 0.0062663185 | Y56: =L56 -> 0.007522446
...

Sheet Data1
B1: Index Numbers ; All groups CPI ; Australia ; | C1: Index Numbers ; Food and non-alcoholic beverages ; Australia ; | D1: Index Numbers ; Bread and cereal products ; Australia ; | E1: Index Numbers ; Bread ; Australia ; | F1: Index Numbers ; Cakes and biscuits ; Australia ; | G1: Index Numbers ; Breakfast cereals ; Australia ; | H1: Index Numbers ; Other cereal products ; Australia ; | I1: Index Numbers ; Meat and seafoods ; Australia ; | J1: Index Numbers ; Beef and veal ; Australia ; | K1: Index Numbers ; Pork ; Australia ; | L1: Index Numbers ; Lamb and goat ; Australia ; | M1: Index Numbers ; Poultry ; Australia ; | N1: Index Numbers ; Other meats ; Australia ; | O1: Index Numbers ; Fish and other seafood ; Australia ; | P1: Index Numbers ; Dairy and related products ; Australia ; | Q1: Index Numbers ; Milk ; Australia ; | R1: Index Numbers ; Cheese ; Australia ; | S1: Index Numbers ; Ice cream and other dairy products ; Australia ; | T1: Index Numbers ; Fruit and vegetables ; Australia ; | U1: Index Numbers ; Fruit ; Australia ; | V1: Index Numbers ; Vegetables ; Australia ; | W1: Index Numbers ; Food products n.e.c. ; Australia ; | X1: Index Numbers ; Eggs ; Australia ; | Y1: Index Numbers ; Jams, honey and spreads ; Australia ; | Z1: Index Numbers ; Food additives and condiments ; Australia ; | AA1: Index Numbers ; Oils and fats ; Australia ; | AB1: Index Numbers ; Snacks and confectionery ; Australia ; | AC1: Index Numbers ; Other food products n.e.c. ; Australia ; | AD1: Index Numbers ; Non-alcoholic beverages ; Australia ; | AE1: Index Numbers ; Coffee, tea and cocoa ; Australia ; | AF1: Index Numbers ; Waters, soft drinks and juices ; Australia ; | AG1: Index Numbers ; Meals out and take away foods ; Australia ; | AH1: Index Numbers ; Restaurant meals ; Australia ; | AI1: Index Numbers ; Take away and fast foods ; Australia ; | AJ1: Index Numbers ; Alcohol and tobacco ; Australia ; | AK1: Index Numbers ; Alcoholic beverages ; Australia ; | AL1: Index Numbers ; Spirits ; Australia ; | AM1: Index Numbers ; Wine ; Australia ; | AN1: Index Numbers ; Beer ; Australia ; | AO1: Index Numbers ; Tobacco ; Australia ; | AP1: Index Numbers ; Tobacco ; Australia ; | AQ1: Index Numbers ; Clothing and footwear ; Australia ; | AR1: Index Numbers ; Garments ; Australia ; | AS1: Index Numbers ; Garments for men ; Australia ; | AT1: Index Numbers ; Garments for women ; Australia ; | AU1: Index Numbers ; Garments for infants and children ; Australia ; | AV1: Index Numbers ; Footwear ; Australia ; | AW1: Index Numbers ; Footwear for men ; Australia ; | AX1: Index Numbers ; Footwear for women ; Australia ; | AY1: Index Numbers ; Footwear for infants and children ; Australia ; | AZ1: Index Numbers ; Accessories and clothing services ; Australia ; | BA1: Index Numbers ; Accessories ; Australia ; | BB1: Index Numbers ; Cleaning, repair and hire of clothing and footwear ; Australia ; | BC1: Index Numbers ; Housing ; Australia ; | BD1: Index Numbers ; Rents ; Australia ; | BE1: Index Numbers ; Rents ; Australia ; | BF1: Index Numbers ; New dwelling purchase by owner-occupiers ; Australia ; | BG1: Index Numbers ; New dwelling purchase by owner-occupiers ; Australia ; | BH1: Index Numbers ; Other housing ; Australia ; | BI1: Index Numbers ; Maintenance and repair of the dwelling ; Australia ; | BJ1: Index Numbers ; Property rates and charges ; Australia ; | BK1: Index Numbers ; Utilities ; Australia ; | BL1: Index Numbers ; Water and sewerage ; Australia ; | BM1: Index Numbers ; Electricity ; Australia ; | BN1: Index Numbers ; Gas and other household fuels ; Australia ; | BO1: Index Numbers ; Furnishings, household equipment and services ; Australia ; | BP1: Index Numbers ; Furniture and furnishings ; Australia ; | BQ1: Index Numbers ; Furniture ; Australia ; | BR1: Index Numbers ; Carpets and other floor coverings ; Australia ; | BS1: Index Numbers ; Household textiles ; Australia ; | BT1: Index Numbers ; Household textiles ; Australia ; | BU1: Index Numbers ; Household appliances, utensils and tools ; Australia ; | BV1: Index Numbers ; Major household appliances ; Australia ; | BW1: Index Numbers ; Small electric household appliances ; Australia ; | BX1: Index Numbers ; Glassware, tableware and household utensils ; Australia ; | BY1: Index Numbers ; Tools and equipment for house and garden ; Australia ; | BZ1: Index Numbers ; Non-durable household products ; Australia ; | CA1: Index Numbers ; Cleaning and maintenance products ; Australia ; | CB1: Index Numbers ; Personal care products ; Australia ; | CC1: Index Numbers ; Other non-durable household products ; Australia ; | CD1: Index Numbers ; Domestic and household services ; Australia ; | CE1: Index Numbers ; Child care ; Australia ; | CF1: Index Numbers ; Hairdressing and personal grooming services ; Australia ; | CG1: Index Numbers ; Other household services ; Australia ; | CH1: Index Numbers ; Health ; Australia ; | CI1: Index Numbers ; Medical products, appliances and equipment ; Australia ; | CJ1: Index Numbers ; Pharmaceutical products ; Australia ; | CK1: Index Numbers ; Therapeutic appliances and equipment ; Australia ; | CL1: Index Numbers ; Medical, dental and hospital services ; Australia ; | CM1: Index Numbers ; Medical and hospital services ; Australia ; | CN1: Index Numbers ; Dental services ; Australia ; | CO1: Index Numbers ; Transport ; Australia ; | CP1: Index Numbers ; Private motoring ; Australia ; | CQ1: Index Numbers ; Motor vehicles ; Australia ; | CR1: Index Numbers ; Spare parts and accessories for motor vehicles ; Australia ; | CS1: Index Numbers ; Automotive fuel ; Australia ; | CT1: Index Numbers ; Maintenance and repair of motor vehicles ; Australia ; | CU1: Index Numbers ; Other services in respect of motor vehicles ; Australia ; | CV1: Index Numbers ; Urban transport fares ; Australia ; | CW1: Index Numbers ; Urban transport fares ; Australia ; | CX1: Index Numbers ; Communication ; Australia ; | CY1: Index Numbers ; Communication ; Australia ; | CZ1: Index Numbers ; Postal services ; Australia ; | DA1: Index Numbers ; Telecommunication equipment and services ; Australia ; | DB1: Index Numbers ; Recreation and culture ; Australia ; | DC1: Index Numbers ; Audio, visual and computing equipment and services ; Australia ; | DD1: Index Numbers ; Audio, visual and computing equipment ; Australia ; | DE1: Index Numbers ; Audio, visual and computing media and services ; Australia ; | DF1: Index Numbers ; Newspapers, books and stationery ; Australia ; | DG1: Index Numbers ; Books ; Australia ; | DH1: Index Numbers ; Newspapers, magazines and stationery ; Australia ; | DI1: Index Numbers ; Holiday travel and accommodation ; Australia ; | DJ1: Index Numbers ; Domestic holiday travel and accommodation ; Australia ; | DK1: Index Numbers ; International holiday travel and accommodation ; Australia ; | DL1: Index Numbers ; Other recreation, sport and culture ; Australia ; | DM1: Index Numbers ; Equipment for sports, camping and open-air recreation ; Australia ; | DN1: Index Numbers ; Games, toys and hobbies ; Australia ; | DO1: Index Numbers ; Pets and related products ; Australia ; | DP1: Index Numbers ; Veterinary and other services for pets ; Australia ; | DQ1: Index Numbers ; Sports participation ; Australia ; | DR1: Index Numbers ; Other recreational, sporting and cultural services ; Australia ; | DS1: Index Numbers ; Education ; Australia ; | DT1: Index Numbers ; Education ; Australia ; | DU1: Index Numbers ; Preschool and primary education ; Australia ; | DV1: Index Numbers ; Secondary education ; Australia ; | DW1: Index Numbers ; Tertiary education ; Australia ; | DX1: Index Numbers ; Insurance and financial services ; Australia ; | DY1: Index Numbers ; Insurance ; Australia ; | DZ1: Index Numbers ; Insurance ; Australia ; | EA1: Index Numbers ; Financial services ; Australia ; | EB1: Index Numbers ; Deposit and loan facilities (direct charges) ; Australia ; | EC1: Index Numbers ; Other financial services ; Australia ; | ED1: Percentage Change from Previous Period ; All groups CPI ; Australia ; | EE1: Percentage Change from Previous Period ; Food and non-alcoholic beverages ; Australia ; | EF1: Percentage Change from Previous Period ; Bread and cereal products ; Australia ; | EG1: Percentage Change from Previous Period ; Bread ; Australia ; | EH1: Percentage Change from Previous Period ; Cakes and biscuits ; Australia ; | EI1: Percentage Change from Previous Period ; Breakfast cereals ; Australia ; | EJ1: Percentage Change from Previous Period ; Other cereal products ; Australia ; | EK1: Percentage Change from Previous Period ; Meat and seafoods ; Australia ; | EL1: Percentage Change from Previous Period ; Beef and veal ; Australia ; | EM1: Percentage Change from Previous Period ; Pork ; Australia ; | EN1: Percentage Change from Previous Period ; Lamb and goat ; Australia ; | EO1: Percentage Change from Previous Period ; Poultry ; Australia ; | EP1: Percentage Change from Previous Period ; Other meats ; Australia ; | EQ1: Percentage Change from Previous Period ; Fish and other seafood ; Australia ; | ER1: Percentage Change from Previous Period ; Dairy and related products ; Australia ; | ES1: Percentage Change from Previous Period ; Milk ; Australia ; | ET1: Percentage Change from Previous Period ; Cheese ; Australia ; | EU1: Percentage Change from Previous Period ; Ice cream and other dairy products ; Australia ; | EV1: Percentage Change from Previous Period ; Fruit and vegetables ; Australia ; | EW1: Percentage Change from Previous Period ; Fruit ; Australia ; | EX1: Percentage Change from Previous Period ; Vegetables ; Australia ; | EY1: Percentage Change from Previous Period ; Food products n.e.c. ; Australia ; | EZ1: Percentage Change from Previous Period ; Eggs ; Australia ; | FA1: Percentage Change from Previous Period ; Jams, honey and spreads ; Australia ; | FB1: Percentage Change from Previous Period ; Food additives and condiments ; Australia ; | FC1: Percentage Change from Previous Period ; Oils and fats ; Australia ; | FD1: Percentage Change from Previous Period ; Snacks and confectionery ; Australia ; | FE1: Percentage Change from Previous Period ; Other food products n.e.c. ; Australia ; | FF1: Percentage Change from Previous Period ; Non-alcoholic beverages ; Australia ; | FG1: Percentage Change from Previous Period ; Coffee, tea and cocoa ; Australia ; | FH1: Percentage Change from Previous Period ; Waters, soft drinks and juices ; Australia ; | FI1: Percentage Change from Previous Period ; Meals out and take away foods ; Australia ; | FJ1: Percentage Change from Previous Period ; Restaurant meals ; Australia ; | FK1: Percentage Change from Previous Period ; Take away and fast foods ; Australia ; | FL1: Percentage Change from Previous Period ; Alcohol and tobacco ; Australia ; | FM1: Percentage Change from Previous Period ; Alcoholic beverages ; Australia ; | FN1: Percentage Change from Previous Period ; Spirits ; Australia ; | FO1: Percentage Change from Previous Period ; Wine ; Australia ; | FP1: Percentage Change from Previous Period ; Beer ; Australia ; | FQ1: Percentage Change from Previous Period ; Tobacco ; Australia ; | FR1: Percentage Change from Previous Period ; Tobacco ; Australia ; | FS1: Percentage Change from Previous Period ; Clothing and footwear ; Australia ; | FT1: Percentage Change from Previous Period ; Garments ; Australia ; | FU1: Percentage Change from Previous Period ; Garments for men ; Australia ; | FV1: Percentage Change from Previous Period ; Garments for women ; Australia ; | FW1: Percentage Change from Previous Period ; Garments for infants and children ; Australia ; | FX1: Percentage Change from Previous Period ; Footwear ; Australia ; | FY1: Percentage Change from Previous Period ; Footwear for men ; Australia ; | FZ1: Percentage Change from Previous Period ; Footwear for women ; Australia ; | GA1: Percentage Change from Previous Period ; Footwear for infants and children ; Australia ; | GB1: Percentage Change from Previous Period ; Accessories and clothing services ; Australia ; | GC1: Percentage Change from Previous Period ; Accessories ; Australia ; | GD1: Percentage Change from Previous Period ; Cleaning, repair and hire of clothing and footwear ; Australia ; | GE1: Percentage Change from Previous Period ; Housing ; Australia ; | GF1: Percentage Change from Previous Period ; Rents ; Australia ; | GG1: Percentage Change from Previous Period ; Rents ; Australia ; | GH1: Percentage Change from Previous Period ; New dwelling purchase by owner-occupiers ; Australia ; | GI1: Percentage Change from Previous Period ; New dwelling purchase by owner-occupiers ; Australia ; | GJ1: Percentage Change from Previous Period ; Other housing ; Australia ; | GK1: Percentage Change from Previous Period ; Maintenance and repair of the dwelling ; Australia ; | GL1: Percentage Change from Previous Period ; Property rates and charges ; Australia ; | GM1: Percentage Change from Previous Period ; Utilities ; Australia ; | GN1: Percentage Change from Previous Period ; Water and sewerage ; Australia ; | GO1: Percentage Change from Previous Period ; Electricity ; Australia ; | GP1: Percentage Change from Previous Period ; Gas and other household fuels ; Australia ; | GQ1: Percentage Change from Previous Period ; Furnishings, household equipment and services ; Australia ; | GR1: Percentage Change from Previous Period ; Furniture and furnishings ; Australia ; | GS1: Percentage Change from Previous Period ; Furniture ; Australia ; | GT1: Percentage Change from Previous Period ; Carpets and other floor coverings ; Australia ; | GU1: Percentage Change from Previous Period ; Household textiles ; Australia ; | GV1: Percentage Change from Previous Period ; Household textiles ; Australia ; | GW1: Percentage Change from Previous Period ; Household appliances, utensils and tools ; Australia ; | GX1: Percentage Change from Previous Period ; Major household appliances ; Australia ; | GY1: Percentage Change from Previous Period ; Small electric household appliances ; Australia ; | GZ1: Percentage Change from Previous Period ; Glassware, tableware and household utensils ; Australia ; | HA1: Percentage Change from Previous Period ; Tools and equipment for house and garden ; Australia ; | HB1: Percentage Change from Previous Period ; Non-durable household products ; Australia ; | HC1: Percentage Change from Previous Period ; Cleaning and maintenance products ; Australia ; | HD1: Percentage Change from Previous Period ; Personal care products ; Australia ; | HE1: Percentage Change from Previous Period ; Other non-durable household products ; Australia ; | HF1: Percentage Change from Previous Period ; Domestic and household services ; Australia ; | HG1: Percentage Change from Previous Period ; Child care ; Australia ; | HH1: Percentage Change from Previous Period ; Hairdressing and personal grooming services ; Australia ; | HI1: Percentage Change from Previous Period ; Other household services ; Australia ; | HJ1: Percentage Change from Previous Period ; Health ; Australia ; | HK1: Percentage Change from Previous Period ; Medical products, appliances and equipment ; Australia ; | HL1: Percentage Change from Previous Period ; Pharmaceutical products ; Australia ; | HM1: Percentage Change from Previous Period ; Therapeutic appliances and equipment ; Australia ; | HN1: Percentage Change from Previous Period ; Medical, dental and hospital services ; Australia ; | HO1: Percentage Change from Previous Period ; Medical and hospital services ; Australia ; | HP1: Percentage Change from Previous Period ; Dental services ; Australia ; | HQ1: Percentage Change from Previous Period ; Transport ; Australia ; | HR1: Percentage Change from Previous Period ; Private motoring ; Australia ; | HS1: Percentage Change from Previous Period ; Motor vehicles ; Australia ; | HT1: Percentage Change from Previous Period ; Spare parts and accessories for motor vehicles ; Australia ; | HU1: Percentage Change from Previous Period ; Automotive fuel ; Australia ; | HV1: Percentage Change from Previous Period ; Maintenance and repair of motor vehicles ; Australia ; | HW1: Percentage Change from Previous Period ; Other services in respect of motor vehicles ; Australia ; | HX1: Percentage Change from Previous Period ; Urban transport fares ; Australia ; | HY1: Percentage Change from Previous Period ; Urban transport fares ; Australia ; | HZ1: Percentage Change from Previous Period ; Communication ; Australia ; | IA1: Percentage Change from Previous Period ; Communication ; Australia ; | IB1: Percentage Change from Previous Period ; Postal services ; Australia ; | IC1: Percentage Change from Previous Period ; Telecommunication equipment and services ; Australia ; | ID1: Percentage Change from Previous Period ; Recreation and culture ; Australia ; | IE1: Percentage Change from Previous Period ; Audio, visual and computing equipment and services ; Australia ; | IF1: Percentage Change from Previous Period ; Audio, visual and computing equipment ; Australia ; | IG1: Percentage Change from Previous Period ; Audio, visual and computing media and services ; Australia ; | IH1: Percentage Change from Previous Period ; Newspapers, books and stationery ; Australia ; | II1: Percentage Change from Previous Period ; Books ; Australia ; | IJ1: Percentage Change from Previous Period ; Newspapers, magazines and stationery ; Australia ; | IK1: Percentage Change from Previous Period ; Holiday travel and accommodation ; Australia ; | IL1: Percentage Change from Previous Period ; Domestic holiday travel and accommodation ; Australia ; | IM1: Percentage Change from Previous Period ; International holiday travel and accommodation ; Australia ; | IN1: Percentage Change from Previous Period ; Other recreation, sport and culture ; Australia ; | IO1: Percentage Change from Previous Period ; Equipment for sports, camping and open-air recreation ; Australia ; | IP1: Percentage Change from Previous Period ; Games, toys and hobbies ; Australia ; | IQ1: Percentage Change from Previous Period ; Pets and related products ; Australia ;
